Workbook

Sheet コーリングサポ
D2: 令和３年 | Q2: 令和4年 | R2: 令和４年 | T2: 30000 | AD2: 令和５年 | AE2: 令和４年 | AG2: 30000 | AQ2: 令和６年 | AR2: 令和４年 | AT2: 30000 | BD2: 令和７年 | BE2: 令和４年 | BG2: 30000
E3: ４月 | F3: ５月 | G3: ６月 | H3: ７月 | I3: ８月 | J3: ９月 | K3: １０月 | L3: １１月 | M3: １２月 | N3: １月 | O3: ２月 | P3: ３月 | R3: ４月 | S3: ５月 | T3: ６月 | U3: ７月 | V3: ８月 | W3: ９月 | X3: １０月 | Y3: １１月 | Z3: １２月 | AA3: １月 | AB3: ２月 | AC3: ３月 | AE3: 1月 | AF3: 2月 | AG3: 3月 | AH3: 4月 | AI3: 5月 | AJ3: 6月 | AK3: 7月 | AL3: 8月 | AM3: 9月 | AN3: 10月 | AO3: 11月 | AP3: 12月 | AR3: 1月 | AS3: 2月 | AT3: 3月 | AU3: 4月 | AV3: 5月 | AW3: 6月 | AX3: 7月 | AY3: 8月 | AZ3: 9月 | BA3: 10月 | BB3: 11月 | BC3: 12月 | BE3: 1月 | BF3: 2月 | BG3: 3月 | BH3: 4月 | BI3: 5月 | BJ3: 6月 | BK3: 7月 | BL3: 8月 | BM3: 9月 | BN3: 10月 | BO3: 11月 | BP3: 12月
A4: 稼働日 | E4: 22 | F4: 20 | G4: 23 | H4: 22 | I4: 23 | J4: 22 | K4: 23 | L4: 22 | M4: 18 | N4: 19 | O4: 19 | P4: 23 | R4: 20 | S4: 19 | T4: 22 | U4: 21 | V4: 20 | W4: 21 | X4: 21 | Y4: 21 | Z4: 19 | AA4: 18 | AB4: 20 | AC4: 23 | AE4: 22 | AF4: 20 | AG4: 23 | AH4: 22 | AI4: 23 | AJ4: 22 | AK4: 23 | AL4: 22 | AM4: 22 | AN4: 23 | AO4: 22 | AP4: 22 | AR4: 22 | AS4: 20 | AT4: 23 | AU4: 22 | AV4: 23 | AW4: 22 | AX4: 23 | AY4: 22 | AZ4: 22 | BA4: 23 | BB4: 22 | BC4: 22 | BE4: 22 | BF4: 20 | BG4: 23 | BH4: 22 | BI4: 23 | BJ4: 22 | BK4: 23 | BL4: 22 | BM4: 22 | BN4: 23 | BO4: 22 | BP4: 22
A5: 稼働率 | E5: 0.8 | F5: 0.8 | G5: 0.8 | H5: 0.8 | I5: 0.8 | J5: 0.8 | K5: 0.8 | L5: 0.8 | M5: 0.8 | N5: 0.8 | O5: 0.8 | P5: 0.8 | R5: 0.8 | S5: 0.8 | T5: 0.8 | U5: 0.8 | V5: 0.8 | W5: 0.8 | X5: 0.8 | Y5: 0.8 | Z5: 0.8 | AA5: 0.8 | AB5: 0.8 | AC5: 0.8 | AE5: 0.8 | AF5: 0.8 | AG5: 0.8 | AH5: 0.8 | AI5: 0.8 | AJ5: 0.8 | AK5: 0.8 | AL5: 0.8 | AM5: 0.8 | AN5: 0.8 | AO5: 0.8 | AP5: 0.8 | AR5: 0.8 | AS5: 0.8 | AT5: 0.8 | AU5: 0.8 | AV5: 0.8 | AW5: 0.8 | AX5: 0.8 | AY5: 0.8 | AZ5: 0.8 | BA5: 0.8 | BB5: 0.8 | BC5: 0.8 | BE5: 0.8 | BF5: 0.8 | BG5: 0.8 | BH5: 0.8 | BI5: 0.8 | BJ5: 0.8 | BK5: 0.8 | BL5: 0.8 | BM5: 0.8 | BN5: 0.8 | BO5: 0.8 | BP5: 0.8
A6: 就労B利用者数 | AR6: 10 | AS6: 10 | AT6: 10 | AU6: 10 | AV6: 10 | AW6: 10 | AX6: 10 | AY6: 10 | AZ6: 10 | BA6: 10 | BB6: 10 | BC6: 10 | BE6: 10 | BF6: 10 | BG6: 10 | BH6: 10 | BI6: 10 | BJ6: 10 | BK6: 10 | BL6: 10 | BM6: 10 | BN6: 10 | BO6: 10 | BP6: 10
A7: 就労B施設外利用者数 | AR7: 10 | AS7: 10 | AT7: 10 | AU7: 10 | AV7: 10 | AW7: 10 | AX7: 10 | AY7: 10 | AZ7: 10 | BA7: 10 | BB7: 10 | BC7: 10 | BE7: 10 | BF7: 10 | BG7: 10 | BH7: 10 | BI7: 10 | BJ7: 10 | BK7: 10 | BL7: 10 | BM7: 10 | BN7: 10 | BO7: 10 | BP7: 10
A8: B合計 | E8: =SUM(E6:E7) -> 0 | F8: =SUM(F6:F7) -> 0 | G8: =SUM(G6:G7) -> 0 | H8: =SUM(H6:H7) -> 0 | I8: =SUM(I6:I7) -> 0 | J8: =SUM(J6:J7) -> 0 | K8: =SUM(K6:K7) -> 0 | L8: =SUM(L6:L7) -> 0 | ... P8: =SUM(P6:P7) -> 0 | R8: =SUM(R6:R7) -> 0 | S8: =SUM(S6:S7) -> 0 | T8: =SUM(T6:T7) -> 0 | U8: =SUM(U6:U7) -> 0 | V8: =SUM(V6:V7) -> 0 | W8: =SUM(W6:W7) -> 0 | X8: =SUM(X6:X7) -> 0 | Y8: =SUM(Y6:Y7) -> 0 | ... AC8: =SUM(AC6:AC7) -> 0 | AE8: =SUM(AE6:AE7) -> 0 | AF8: =SUM(AF6:AF7) -> 0 | AG8: =SUM(AG6:AG7) -> 0 | AH8: =SUM(AH6:AH7) -> 0 | AI8: =SUM(AI6:AI7) -> 0 | AJ8: =SUM(AJ6:AJ7) -> 0 | AK8: =SUM(AK6:AK7) -> 0 | AL8: =SUM(AL6:AL7) -> 0 | ... AP8: =SUM(AP6:AP7) -> 0 | AR8: =SUM(AR6:AR7) -> 20 | AS8: =SUM(AS6:AS7) -> 20 | AT8: =SUM(AT6:AT7) -> 20 | AU8: =SUM(AU6:AU7) -> 20 | AV8: =SUM(AV6:AV7) -> 20 | AW8: =SUM(AW6:AW7) -> 20 | AX8: =SUM(AX6:AX7) -> 20 | AY8: =SUM(AY6:AY7) -> 20 | ... BC8: =SUM(BC6:BC7) -> 20 | BE8: =SUM(BE6:BE7) -> 20 | BF8: =SUM(BF6:BF7) -> 20 | BG8: =SUM(BG6:BG7) -> 20 | BH8: =SUM(BH6:BH7) -> 20 | BI8: =SUM(BI6:BI7) -> 20 | BJ8: =SUM(BJ6:BJ7) -> 20 | BK8: =SUM(BK6:BK7) -> 20 | BL8: =SUM(BL6:BL7) -> 20 | ... BP8: =SUM(BP6:BP7) -> 20
A9: 就労移行利用者数 | L9: 4 | M9: 6 | N9: 8 | O9: 10 | P9: 12 | R9: 13 | S9: 14 | T9: 15 | U9: 16 | V9: 17 | W9: 17 | X9: 17 | Y9: 17 | Z9: 17 | AA9: 17 | AB9: 17 | AC9: 17 | AE9: 10 | AF9: 10 | AG9: 10 | AH9: 10 | AI9: 10 | AJ9: 10 | AK9: 10 | AL9: 10 | AM9: 10 | AN9: 10 | AO9: 10 | AP9: 10 | AR9: 10 | AS9: 10 | AT9: 10 | AU9: 10 | AV9: 10 | AW9: 10 | AX9: 10 | AY9: 10 | AZ9: 10 | BA9: 10 | BB9: 10 | BC9: 10 | BE9: 10 | BF9: 10 | BG9: 10 | BH9: 10 | BI9: 10 | BJ9: 10 | BK9: 10 | BL9: 10 | BM9: 10 | BN9: 10 | BO9: 10 | BP9: 10
A10: 就労移行施設外利用者数 | R10: 1 | S10: 2 | T10: 4 | U10: 6 | V10: 8 | W10: 8 | X10: 8 | Y10: 8 | Z10: 8 | AA10: 8 | AB10: 8 | AC10: 8 | AE10: 10 | AF10: 10 | AG10: 10 | AH10: 10 | AI10: 10 | AJ10: 10 | AK10: 10 | AL10: 10 | AM10: 10 | AN10: 10 | AO10: 10 | AP10: 10 | AR10: 10 | AS10: 10 | AT10: 10 | AU10: 10 | AV10: 10 | AW10: 10 | AX10: 10 | AY10: 10 | AZ10: 10 | BA10: 10 | BB10: 10 | BC10: 10 | BE10: 10 | BF10: 10 | BG10: 10 | BH10: 10 | BI10: 10 | BJ10: 10 | BK10: 10 | BL10: 10 | BM10: 10 | BN10: 10 | BO10: 10 | BP10: 10
A11: 移行合計 | E11: =SUM(E9:E10) -> 0 | F11: =SUM(F9:F10) -> 0 | G11: =SUM(G9:G10) -> 0 | H11: =SUM(H9:H10) -> 0 | I11: =SUM(I9:I10) -> 0 | J11: =SUM(J9:J10) -> 0 | K11: =SUM(K9:K10) -> 0 | L11: =SUM(L9:L10) -> 4 | ... P11: =SUM(P9:P10) -> 12 | R11: =SUM(R9:R10) -> 14 | S11: =SUM(S9:S10) -> 16 | T11: =SUM(T9:T10) -> 19 | U11: =SUM(U9:U10) -> 22 | V11: =SUM(V9:V10) -> 25 | W11: =SUM(W9:W10) -> 25 | X11: =SUM(X9:X10) -> 25 | Y11: =SUM(Y9:Y10) -> 25 | ... AC11: =SUM(AC9:AC10) -> 25 | AE11: =SUM(AE9:AE10) -> 20 | AF11: =SUM(AF9:AF10) -> 20 | AG11: =SUM(AG9:AG10) -> 20 | AH11: =SUM(AH9:AH10) -> 20 | AI11: =SUM(AI9:AI10) -> 20 | AJ11: =SUM(AJ9:AJ10) -> 20 | AK11: =SUM(AK9:AK10) -> 20 | AL11: =SUM(AL9:AL10) -> 20 | ... AP11: =SUM(AP9:AP10) -> 20 | AR11: =SUM(AR9:AR10) -> 20 | AS11: =SUM(AS9:AS10) -> 20 | AT11: =SUM(AT9:AT10) -> 20 | AU11: =SUM(AU9:AU10) -> 20 | AV11: =SUM(AV9:AV10) -> 20 | AW11: =SUM(AW9:AW10) -> 20 | AX11: =SUM(AX9:AX10) -> 20 | AY11: =SUM(AY9:AY10) -> 20 | ... BC11: =SUM(BC9:BC10) -> 20 | BE11: =SUM(BE9:BE10) -> 20 | BF11: =SUM(BF9:BF10) -> 20 | BG11: =SUM(BG9:BG10) -> 20 | BH11: =SUM(BH9:BH10) -> 20 | BI11: =SUM(BI9:BI10) -> 20 | BJ11: =SUM(BJ9:BJ10) -> 20 | BK11: =SUM(BK9:BK10) -> 20 | BL11: =SUM(BL9:BL10) -> 20 | ... BP11: =SUM(BP9:BP10) -> 20
A12: 合計人数 | E12: =E8:F8+E11 -> 0 | F12: =F8:G8+F11 -> 0 | G12: =G8:H8+G11 -> 0 | H12: =H8:I8+H11 -> 0 | I12: =I8:J8+I11 -> 0 | J12: =J8:K8+J11 -> 0 | K12: =K8:L8+K11 -> 0 | L12: =L8:M8+L11 -> 4 | ... P12: =P8:Q8+P11 -> 12 | R12: =R8:S8+R11 -> 14 | S12: =S8:T8+S11 -> 16 | T12: =T8:U8+T11 -> 19 | U12: =U8:V8+U11 -> 22 | V12: =V8:W8+V11 -> 25 | W12: =W8:X8+W11 -> 25 | X12: =X8:Y8+X11 -> 25 | Y12: =Y8:Z8+Y11 -> 25 | ... AC12: =AC8:AD8+AC11 -> 25 | AE12: =AE8:AF8+AE11 -> 20 | AF12: =AF8:AG8+AF11 -> 20 | AG12: =AG8:AH8+AG11 -> 20 | AH12: =AH8:AI8+AH11 -> 20 | AI12: =AI8:AJ8+AI11 -> 20 | AJ12: =AJ8:AK8+AJ11 -> 20 | AK12: =AK8:AL8+AK11 -> 20 | AL12: =AL8:AM8+AL11 -> 20 | ... AO12: =AO8:AP8+AO11 -> 20 | AP12: =AP8:AP8+AP11 -> 20 | AR12: =AR8:AS8+AR11 -> 40 | AS12: =AS8:AT8+AS11 -> 40 | AT12: =AT8:AU8+AT11 -> 40 | AU12: =AU8:AV8+AU11 -> 40 | AV12: =AV8:AW8+AV11 -> 40 | AW12: =AW8:AX8+AW11 -> 40 | AX12: =AX8:AY8+AX11 -> 40 | AY12: =AY8:AZ8+AY11 -> 40 | ... BB12: =BB8:BC8+BB11 -> 40 | BC12: =BC8:BC8+BC11 -> 40 | BE12: =BE8:BF8+BE11 -> 40 | BF12: =BF8:BG8+BF11 -> 40 | BG12: =BG8:BH8+BG11 -> 40 | BH12: =BH8:BI8+BH11 -> 40 | BI12: =BI8:BJ8+BI11 -> 40 | BJ12: =BJ8:BK8+BJ11 -> 40 | BK12: =BK8:BL8+BK11 -> 40 | BL12: =BL8:BM8+BL11 -> 40 | ... BO12: =BO8:BP8+BO11 -> 40 | BP12: =BP8:BP8+BP11 -> 40
A14: B通常給付金 | E14: =ROUNDDOWN(E6*E23*E4*E5,-2) -> 0 | F14: =ROUNDDOWN(F6*F23*F4*F5,-2) -> 0 | G14: =ROUNDDOWN(G6*G23*G4*G5,-2) -> 0 | H14: =ROUNDDOWN(H6*H23*H4*H5,-2) -> 0 | I14: =ROUNDDOWN(I6*I23*I4*I5,-2) -> 0 | J14: =ROUNDDOWN(J6*J23*J4*J5,-2) -> 0 | K14: =ROUNDDOWN(K6*K23*K4*K5,-2) -> 0 | L14: =ROUNDDOWN(L6*L23*L4*L5,-2) -> 0 | ... P14: =ROUNDDOWN(P6*P23*P4*P5,-2) -> 0 | R14: =ROUNDDOWN(R6*R23*R4*R5,-2) -> 0 | S14: =ROUNDDOWN(S6*S23*S4*S5,-2) -> 0 | T14: =ROUNDDOWN(T6*T23*T4*T5,-2) -> 0 | U14: =ROUNDDOWN(U6*U23*U4*U5,-2) -> 0 | V14: =ROUNDDOWN(V6*V23*V4*V5,-2) -> 0 | W14: =ROUNDDOWN(W6*W23*W4*W5,-2) -> 0 | X14: =ROUNDDOWN(X6*X23*X4*X5,-2) -> 0 | Y14: =ROUNDDOWN(Y6*Y23*Y4*Y5,-2) -> 0 | ... AC14: =ROUNDDOWN(AC6*AC23*AC4*AC5,-2) -> 0 | AE14: =ROUNDDOWN(AE6*AE23*AE4*AE5,-2) -> 0 | AF14: =ROUNDDOWN(AF6*AF23*AF4*AF5,-2) -> 0 | AG14: =ROUNDDOWN(AG6*AG23*AG4*AG5,-2) -> 0 | AH14: =ROUNDDOWN(AH6*AH23*AH4*AH5,-2) -> 0 | AI14: =ROUNDDOWN(AI6*AI23*AI4*AI5,-2) -> 0 | AJ14: =ROUNDDOWN(AJ6*AJ23*AJ4*AJ5,-2) -> 0 | AK14: =ROUNDDOWN(AK6*AK23*AK4*AK5,-2) -> 0 | AL14: =ROUNDDOWN(AL6*AL23*AL4*AL5,-2) -> 0 | ... AP14: =ROUNDDOWN(AP6*AP23*AP4*AP5,-2) -> 0 | AR14: =ROUNDDOWN(AR6*AR23*AR4*AR5,-2) -> 1036600 | AS14: =ROUNDDOWN(AS6*AS23*AS4*AS5,-2) -> 942400 | AT14: =ROUNDDOWN(AT6*AT23*AT4*AT5,-2) -> 1083700 | AU14: =ROUNDDOWN(AU6*AU23*AU4*AU5,-2) -> 1036600 | AV14: =ROUNDDOWN(AV6*AV23*AV4*AV5,-2) -> 1083700 | AW14: =ROUNDDOWN(AW6*AW23*AW4*AW5,-2) -> 1036600 | AX14: =ROUNDDOWN(AX6*AX23*AX4*AX5,-2) -> 1083700 | AY14: =ROUNDDOWN(AY6*AY23*AY4*AY5,-2) -> 1036600 | ... BC14: =ROUNDDOWN(BC6*BC23*BC4*BC5,-2) -> 1036600 | BE14: =ROUNDDOWN(BE6*BE23*BE4*BE5,-2) -> 1036600 | BF14: =ROUNDDOWN(BF6*BF23*BF4*BF5,-2) -> 942400 | BG14: =ROUNDDOWN(BG6*BG23*BG4*BG5,-2) -> 1083700 | BH14: =ROUNDDOWN(BH6*BH23*BH4*BH5,-2) -> 1036600 | BI14: =ROUNDDOWN(BI6*BI23*BI4*BI5,-2) -> 1083700 | BJ14: =ROUNDDOWN(BJ6*BJ23*BJ4*BJ5,-2) -> 1036600 | BK14: =ROUNDDOWN(BK6*BK23*BK4*BK5,-2) -> 1083700 | BL14: =ROUNDDOWN(BL6*BL23*BL4*BL5,-2) -> 1036600 | ... BP14: =ROUNDDOWN(BP6*BP23*BP4*BP5,-2) -> 1036600
A15: B施設外給付金 | E15: =ROUNDDOWN(E7*E24*E4*E29,-2) -> 0 | F15: =F7*F24*F4*F29 -> 0 | G15: =G7*G24*G4*G29 -> 0 | H15: =H7*H24*H4*H29 -> 0 | I15: =I7*I24*I4*I29 -> 0 | J15: =J7*J24*J4*J29 -> 0 | K15: =K7*K24*K4*K29 -> 0 | L15: =L7*L24*L4*L29 -> 0 | M15: =M7*M24*M4*M29 -> 0 | ... P15: =P7*P24*P4*P29 -> 0 | R15: =ROUNDDOWN(R7*R24*R4*R29,-2) -> 0 | S15: =S7*S24*S4*S29 -> 0 | T15: =T7*T24*T4*T29 -> 0 | U15: =U7*U24*U4*U29 -> 0 | V15: =V7*V24*V4*V29 -> 0 | W15: =W7*W24*W4*W29 -> 0 | X15: =X7*X24*X4*X29 -> 0 | Y15: =Y7*Y24*Y4*Y29 -> 0 | Z15: =Z7*Z24*Z4*Z29 -> 0 | ... AC15: =AC7*AC24*AC4*AC29 -> 0 | AE15: =ROUNDDOWN(AE7*AE24*AE4*AE29,-2) -> 0 | AF15: =AF7*AF24*AF4*AF29 -> 0 | AG15: =AG7*AG24*AG4*AG29 -> 0 | AH15: =AH7*AH24*AH4*AH29 -> 0 | AI15: =AI7*AI24*AI4*AI29 -> 0 | AJ15: =AJ7*AJ24*AJ4*AJ29 -> 0 | AK15: =AK7*AK24*AK4*AK29 -> 0 | AL15: =AL7*AL24*AL4*AL29 -> 0 | AM15: =AM7*AM24*AM4*AM29 -> 0 | ... AP15: =AP7*AP24*AP4*AP29 -> 0 | AR15: =ROUNDDOWN(AR7*AR24*AR4*AR29,-2) -> 1136800 | AS15: =AS7*AS24*AS4*AS29 -> 1033500 | AT15: =AT7*AT24*AT4*AT29 -> 1188525 | AU15: =AU7*AU24*AU4*AU29 -> 1136850 | AV15: =AV7*AV24*AV4*AV29 -> 1188525 | AW15: =AW7*AW24*AW4*AW29 -> 1136850 | AX15: =AX7*AX24*AX4*AX29 -> 1188525 | AY15: =AY7*AY24*AY4*AY29 -> 1136850 | AZ15: =AZ7*AZ24*AZ4*AZ29 -> 1136850 | ... BC15: =BC7*BC24*BC4*BC29 -> 1136850 | BE15: =ROUNDDOWN(BE7*BE24*BE4*BE29,-2) -> 1136800 | BF15: =BF7*BF24*BF4*BF29 -> 1033500 | BG15: =BG7*BG24*BG4*BG29 -> 1188525 | BH15: =BH7*BH24*BH4*BH29 -> 1136850 | BI15: =BI7*BI24*BI4*BI29 -> 1188525 | BJ15: =BJ7*BJ24*BJ4*BJ29 -> 1136850 | BK15: =BK7*BK24*BK4*BK29 -> 1188525 | BL15: =BL7*BL24*BL4*BL29 -> 1136850 | BM15: =BM7*BM24*BM4*BM29 -> 1136850 | ... BP15: =BP7*BP24*BP4*BP29 -> 1136850
A16: B加算 | E16: =ROUNDDOWN(((E6+E7)*(E27+E28*0.8))*E4,-2) -> 0 | F16: =ROUNDDOWN(((F6+F7)*(F27+F28*0.8))*F4,-2) -> 0 | G16: =ROUNDDOWN(((G6+G7)*(G27+G28*0.8))*G4,-2) -> 0 | H16: =ROUNDDOWN(((H6+H7)*(H27+H28*0.8))*H4,-2) -> 0 | I16: =ROUNDDOWN(((I6+I7)*(I27+I28*0.8))*I4,-2) -> 0 | J16: =ROUNDDOWN(((J6+J7)*(J27+J28*0.8))*J4,-2) -> 0 | K16: =ROUNDDOWN(((K6+K7)*(K27+K28*0.8))*K4,-2) -> 0 | L16: =ROUNDDOWN(((L6+L7)*(L27+L28*0.8))*L4,-2) -> 0 | ... P16: =ROUNDDOWN(((P6+P7)*(P27+P28*0.8))*P4,-2) -> 0 | R16: =ROUNDDOWN(((R6+R7)*(R27+R28*0.8))*R4,-2) -> 0 | S16: =ROUNDDOWN(((S6+S7)*(S27+S28*0.8))*S4,-2) -> 0 | T16: =ROUNDDOWN(((T6+T7)*(T27+T28*0.8))*T4,-2) -> 0 | U16: =ROUNDDOWN(((U6+U7)*(U27+U28*0.8))*U4,-2) -> 0 | V16: =ROUNDDOWN(((V6+V7)*(V27+V28*0.8))*V4,-2) -> 0 | W16: =ROUNDDOWN(((W6+W7)*(W27+W28*0.8))*W4,-2) -> 0 | X16: =ROUNDDOWN(((X6+X7)*(X27+X28*0.8))*X4,-2) -> 0 | Y16: =ROUNDDOWN(((Y6+Y7)*(Y27+Y28*0.8))*Y4,-2) -> 0 | ... AC16: =ROUNDDOWN(((AC6+AC7)*(AC27+AC28*0.8))*AC4,-2) -> 0 | AE16: =ROUNDDOWN(((AE6+AE7)*(AE27+AE28*0.8))*AE4,-2) -> 0 | AF16: =ROUNDDOWN(((AF6+AF7)*(AF27+AF28*0.8))*AF4,-2) -> 0 | AG16: =ROUNDDOWN(((AG6+AG7)*(AG27+AG28*0.8))*AG4,-2) -> 0 | AH16: =ROUNDDOWN(((AH6+AH7)*(AH27+AH28*0.8))*AH4,-2) -> 0 | AI16: =ROUNDDOWN(((AI6+AI7)*(AI27+AI28*0.8))*AI4,-2) -> 0 | AJ16: =ROUNDDOWN(((AJ6+AJ7)*(AJ27+AJ28*0.8))*AJ4,-2) -> 0 | AK16: =ROUNDDOWN(((AK6+AK7)*(AK27+AK28*0.8))*AK4,-2) -> 0 | AL16: =ROUNDDOWN(((AL6+AL7)*(AL27+AL28*0.8))*AL4,-2) -> 0 | ... AP16: =ROUNDDOWN(((AP6+AP7)*(AP27+AP28*0.8))*AP4,-2) -> 0 | AR16: =ROUNDDOWN(((AR6+AR7)*(AR27+AR28*0.8))*AR4,-2) -> 581600 | AS16: =ROUNDDOWN(((AS6+AS7)*(AS27+AS28*0.8))*AS4,-2) -> 528800 | AT16: =ROUNDDOWN(((AT6+AT7)*(AT27+AT28*0.8))*AT4,-2) -> 608100 | AU16: =ROUNDDOWN(((AU6+AU7)*(AU27+AU28*0.8))*AU4,-2) -> 581600 | AV16: =ROUNDDOWN(((AV6+AV7)*(AV27+AV28*0.8))*AV4,-2) -> 608100 | AW16: =ROUNDDOWN(((AW6+AW7)*(AW27+AW28*0.8))*AW4,-2) -> 581600 | AX16: =ROUNDDOWN(((AX6+AX7)*(AX27+AX28*0.8))*AX4,-2) -> 608100 | AY16: =ROUNDDOWN(((AY6+AY7)*(AY27+AY28*0.8))*AY4,-2) -> 581600 | ... BC16: =ROUNDDOWN(((BC6+BC7)*(BC27+BC28*0.8))*BC4,-2) -> 581600 | BE16: =ROUNDDOWN(((BE6+BE7)*(BE27+BE28*0.8))*BE4,-2) -> 581600 | BF16: =ROUNDDOWN(((BF6+BF7)*(BF27+BF28*0.8))*BF4,-2) -> 528800 | BG16: =ROUNDDOWN(((BG6+BG7)*(BG27+BG28*0.8))*BG4,-2) -> 608100 | BH16: =ROUNDDOWN(((BH6+BH7)*(BH27+BH28*0.8))*BH4,-2) -> 581600 | BI16: =ROUNDDOWN(((BI6+BI7)*(BI27+BI28*0.8))*BI4,-2) -> 608100 | BJ16: =ROUNDDOWN(((BJ6+BJ7)*(BJ27+BJ28*0.8))*BJ4,-2) -> 581600 | BK16: =ROUNDDOWN(((BK6+BK7)*(BK27+BK28*0.8))*BK4,-2) -> 608100 | BL16: =ROUNDDOWN(((BL6+BL7)*(BL27+BL28*0.8))*BL4,-2) -> 581600 | ... BP16: =ROUNDDOWN(((BP6+BP7)*(BP27+BP28*0.8))*BP4,-2) -> 581600
A17: 移行通常給付金 | E17: =ROUNDDOWN(E9*E25*E4*E5,-2) -> 0 | F17: =ROUNDDOWN(F9*F25*F4*F5,-2) -> 0 | G17: =ROUNDDOWN(G9*G25*G4*G5,-2) -> 0 | H17: =ROUNDDOWN(H9*H25*H4*H5,-2) -> 0 | I17: =ROUNDDOWN(I9*I25*I4*I5,-2) -> 0 | J17: =ROUNDDOWN(J9*J25*J4*J5,-2) -> 0 | K17: =ROUNDDOWN(K9*K25*K4*K5,-2) -> 0 | L17: =ROUNDDOWN(L9*L25*L4*L5,-2) -> 577200 | ... P17: =ROUNDDOWN(P9*P25*P4*P5,-2) -> 1810500 | R17: =ROUNDDOWN(R9*R25*R4*R5,-2) -> 1705600 | S17: =ROUNDDOWN(S9*S25*S4*S5,-2) -> 1744900 | T17: =ROUNDDOWN(T9*T25*T4*T5,-2) -> 2164800 | U17: =ROUNDDOWN(U9*U25*U4*U5,-2) -> 2204100 | V17: =ROUNDDOWN(V9*V25*V4*V5,-2) -> 2230400 | W17: =ROUNDDOWN(W9*W25*W4*W5,-2) -> 2341900 | X17: =ROUNDDOWN(X9*X25*X4*X5,-2) -> 2341900 | Y17: =ROUNDDOWN(Y9*Y25*Y4*Y5,-2) -> 2341900 | ... AC17: =ROUNDDOWN(AC9*AC25*AC4*AC5,-2) -> 2564900 | AE17: =ROUNDDOWN(AE9*AE25*AE4*AE5,-2) -> 1422000 | AF17: =ROUNDDOWN(AF9*AF25*AF4*AF5,-2) -> 1292800 | AG17: =ROUNDDOWN(AG9*AG25*AG4*AG5,-2) -> 1486700 | AH17: =ROUNDDOWN(AH9*AH25*AH4*AH5,-2) -> 1422000 | AI17: =ROUNDDOWN(AI9*AI25*AI4*AI5,-2) -> 1486700 | AJ17: =ROUNDDOWN(AJ9*AJ25*AJ4*AJ5,-2) -> 1422000 | AK17: =ROUNDDOWN(AK9*AK25*AK4*AK5,-2) -> 1486700 | AL17: =ROUNDDOWN(AL9*AL25*AL4*AL5,-2) -> 1422000 | ... AP17: =ROUNDDOWN(AP9*AP25*AP4*AP5,-2) -> 1422000 | AR17: =ROUNDDOWN(AR9*AR25*AR4*AR5,-2) -> 1422000 | AS17: =ROUNDDOWN(AS9*AS25*AS4*AS5,-2) -> 1292800 | AT17: =ROUNDDOWN(AT9*AT25*AT4*AT5,-2) -> 1486700 | AU17: =ROUNDDOWN(AU9*AU25*AU4*AU5,-2) -> 1422000 | AV17: =ROUNDDOWN(AV9*AV25*AV4*AV5,-2) -> 1486700 | AW17: =ROUNDDOWN(AW9*AW25*AW4*AW5,-2) -> 1422000 | AX17: =ROUNDDOWN(AX9*AX25*AX4*AX5,-2) -> 1486700 | AY17: =ROUNDDOWN(AY9*AY25*AY4*AY5,-2) -> 1422000 | ... BC17: =ROUNDDOWN(BC9*BC25*BC4*BC5,-2) -> 1422000 | BE17: =ROUNDDOWN(BE9*BE25*BE4*BE5,-2) -> 1422000 | BF17: =ROUNDDOWN(BF9*BF25*BF4*BF5,-2) -> 1292800 | BG17: =ROUNDDOWN(BG9*BG25*BG4*BG5,-2) -> 1486700 | BH17: =ROUNDDOWN(BH9*BH25*BH4*BH5,-2) -> 1422000 | BI17: =ROUNDDOWN(BI9*BI25*BI4*BI5,-2) -> 1486700 | BJ17: =ROUNDDOWN(BJ9*BJ25*BJ4*BJ5,-2) -> 1422000 | BK17: =ROUNDDOWN(BK9*BK25*BK4*BK5,-2) -> 1486700 | BL17: =ROUNDDOWN(BL9*BL25*BL4*BL5,-2) -> 1422000 | ... BP17: =ROUNDDOWN(BP9*BP25*BP4*BP5,-2) -> 1422000
A18: 移行施設外給付金 | E18: =ROUNDDOWN(E10*E26*E4*E5,-2) -> 0 | F18: =ROUNDDOWN(F10*F26*F4*F5,-2) -> 0 | G18: =ROUNDDOWN(G10*G26*G4*G5,-2) -> 0 | H18: =ROUNDDOWN(H10*H26*H4*H5,-2) -> 0 | I18: =ROUNDDOWN(I10*I26*I4*I5,-2) -> 0 | J18: =ROUNDDOWN(J10*J26*J4*J5,-2) -> 0 | K18: =ROUNDDOWN(K10*K26*K4*K5,-2) -> 0 | L18: =ROUNDDOWN(L10*L26*L4*L5,-2) -> 0 | ... P18: =ROUNDDOWN(P10*P26*P4*P5,-2) -> 0 | R18: =ROUNDDOWN(R10*R26*R4*R5,-2) -> 131200 | S18: =ROUNDDOWN(S10*S26*S4*S5,-2) -> 249200 | T18: =ROUNDDOWN(T10*T26*T4*T5,-2) -> 577200 | U18: =ROUNDDOWN(U10*U26*U4*U5,-2) -> 826500 | V18: =ROUNDDOWN(V10*V26*V4*V5,-2) -> 1049600 | W18: =ROUNDDOWN(W10*W26*W4*W5,-2) -> 1102000 | X18: =ROUNDDOWN(X10*X26*X4*X5,-2) -> 1102000 | Y18: =ROUNDDOWN(Y10*Y26*Y4*Y5,-2) -> 1102000 | ... AC18: =ROUNDDOWN(AC10*AC26*AC4*AC5,-2) -> 1207000 | AE18: =ROUNDDOWN(AE10*AE26*AE4*AE5,-2) -> 1598000 | AF18: =ROUNDDOWN(AF10*AF26*AF4*AF5,-2) -> 1452800 | AG18: =ROUNDDOWN(AG10*AG26*AG4*AG5,-2) -> 1670700 | AH18: =ROUNDDOWN(AH10*AH26*AH4*AH5,-2) -> 1598000 | AI18: =ROUNDDOWN(AI10*AI26*AI4*AI5,-2) -> 1670700 | AJ18: =ROUNDDOWN(AJ10*AJ26*AJ4*AJ5,-2) -> 1598000 | AK18: =ROUNDDOWN(AK10*AK26*AK4*AK5,-2) -> 1670700 | AL18: =ROUNDDOWN(AL10*AL26*AL4*AL5,-2) -> 1598000 | ... AP18: =ROUNDDOWN(AP10*AP26*AP4*AP5,-2) -> 1598000 | AR18: =ROUNDDOWN(AR10*AR26*AR4*AR5,-2) -> 1598000 | AS18: =ROUNDDOWN(AS10*AS26*AS4*AS5,-2) -> 1452800 | AT18: =ROUNDDOWN(AT10*AT26*AT4*AT5,-2) -> 1670700 | AU18: =ROUNDDOWN(AU10*AU26*AU4*AU5,-2) -> 1598000 | AV18: =ROUNDDOWN(AV10*AV26*AV4*AV5,-2) -> 1670700 | AW18: =ROUNDDOWN(AW10*AW26*AW4*AW5,-2) -> 1598000 | AX18: =ROUNDDOWN(AX10*AX26*AX4*AX5,-2) -> 1670700 | AY18: =ROUNDDOWN(AY10*AY26*AY4*AY5,-2) -> 1598000 | ... BC18: =ROUNDDOWN(BC10*BC26*BC4*BC5,-2) -> 1598000 | BE18: =ROUNDDOWN(BE10*BE26*BE4*BE5,-2) -> 1598000 | BF18: =ROUNDDOWN(BF10*BF26*BF4*BF5,-2) -> 1452800 | BG18: =ROUNDDOWN(BG10*BG26*BG4*BG5,-2) -> 1670700 | BH18: =ROUNDDOWN(BH10*BH26*BH4*BH5,-2) -> 1598000 | BI18: =ROUNDDOWN(BI10*BI26*BI4*BI5,-2) -> 1670700 | BJ18: =ROUNDDOWN(BJ10*BJ26*BJ4*BJ5,-2) -> 1598000 | BK18: =ROUNDDOWN(BK10*BK26*BK4*BK5,-2) -> 1670700 | BL18: =ROUNDDOWN(BL10*BL26*BL4*BL5,-2) -> 1598000 | ... BP18: =ROUNDDOWN(BP10*BP26*BP4*BP5,-2) -> 1598000
A19: 移行加算 | E19: =ROUNDDOWN((E9+E10)*E4*E5*E28,-2) -> 0 | F19: =ROUNDDOWN((F9+F10)*F4*F5*F28,-2) -> 0 | G19: =ROUNDDOWN((G9+G10)*G4*G5*G28,-2) -> 0 | H19: =ROUNDDOWN((H9+H10)*H4*H5*H28,-2) -> 0 | I19: =ROUNDDOWN((I9+I10)*I4*I5*I28,-2) -> 0 | J19: =ROUNDDOWN((J9+J10)*J4*J5*J28,-2) -> 0 | K19: =ROUNDDOWN((K9+K10)*K4*K5*K28,-2) -> 0 | L19: =ROUNDDOWN((L9+L10)*L4*L5*L28,-2) -> 38000 | ... P19: =ROUNDDOWN((P9+P10)*P4*P5*P28,-2) -> 119200 | R19: =ROUNDDOWN((R9+R10)*R4*R5*R28,-2) -> 120900 | S19: =ROUNDDOWN((S9+S10)*S4*S5*S28,-2) -> 131300 | T19: =ROUNDDOWN((T9+T10)*T4*T5*T28,-2) -> 180500 | U19: =ROUNDDOWN((U9+U10)*U4*U5*U28,-2) -> 199500 | V19: =ROUNDDOWN((V9+V10)*V4*V5*V28,-2) -> 216000 | W19: =ROUNDDOWN((W9+W10)*W4*W5*W28,-2) -> 226800 | X19: =ROUNDDOWN((X9+X10)*X4*X5*X28,-2) -> 226800 | Y19: =ROUNDDOWN((Y9+Y10)*Y4*Y5*Y28,-2) -> 226800 | ... AC19: =ROUNDDOWN((AC9+AC10)*AC4*AC5*AC28,-2) -> 248400 | AE19: =ROUNDDOWN((AE9+AE10)*AE4*AE5*AE28,-2) -> 190000 | AF19: =ROUNDDOWN((AF9+AF10)*AF4*AF5*AF28,-2) -> 172800 | AG19: =ROUNDDOWN((AG9+AG10)*AG4*AG5*AG28,-2) -> 198700 | AH19: =ROUNDDOWN((AH9+AH10)*AH4*AH5*AH28,-2) -> 190000 | AI19: =ROUNDDOWN((AI9+AI10)*AI4*AI5*AI28,-2) -> 198700 | AJ19: =ROUNDDOWN((AJ9+AJ10)*AJ4*AJ5*AJ28,-2) -> 190000 | AK19: =ROUNDDOWN((AK9+AK10)*AK4*AK5*AK28,-2) -> 198700 | AL19: =ROUNDDOWN((AL9+AL10)*AL4*AL5*AL28,-2) -> 190000 | ... AP19: =ROUNDDOWN((AP9+AP10)*AP4*AP5*AP28,-2) -> 190000 | AR19: =ROUNDDOWN((AR9+AR10)*AR4*AR5*AR28,-2) -> 190000 | AS19: =ROUNDDOWN((AS9+AS10)*AS4*AS5*AS28,-2) -> 172800 | AT19: =ROUNDDOWN((AT9+AT10)*AT4*AT5*AT28,-2) -> 198700 | AU19: =ROUNDDOWN((AU9+AU10)*AU4*AU5*AU28,-2) -> 190000 | AV19: =ROUNDDOWN((AV9+AV10)*AV4*AV5*AV28,-2) -> 198700 | AW19: =ROUNDDOWN((AW9+AW10)*AW4*AW5*AW28,-2) -> 190000 | AX19: =ROUNDDOWN((AX9+AX10)*AX4*AX5*AX28,-2) -> 198700 | AY19: =ROUNDDOWN((AY9+AY10)*AY4*AY5*AY28,-2) -> 190000 | ... BC19: =ROUNDDOWN((BC9+BC10)*BC4*BC5*BC28,-2) -> 190000 | BE19: =ROUNDDOWN((BE9+BE10)*BE4*BE5*BE28,-2) -> 190000 | BF19: =ROUNDDOWN((BF9+BF10)*BF4*BF5*BF28,-2) -> 172800 | BG19: =ROUNDDOWN((BG9+BG10)*BG4*BG5*BG28,-2) -> 198700 | BH19: =ROUNDDOWN((BH9+BH10)*BH4*BH5*BH28,-2) -> 190000 | BI19: =ROUNDDOWN((BI9+BI10)*BI4*BI5*BI28,-2) -> 198700 | BJ19: =ROUNDDOWN((BJ9+BJ10)*BJ4*BJ5*BJ28,-2) -> 190000 | BK19: =ROUNDDOWN((BK9+BK10)*BK4*BK5*BK28,-2) -> 198700 | BL19: =ROUNDDOWN((BL9+BL10)*BL4*BL5*BL28,-2) -> 190000 | ... BP19: =ROUNDDOWN((BP9+BP10)*BP4*BP5*BP28,-2) -> 190000
A20: 給付費合計 | E20: =SUM(E14:E19) -> 0 | F20: =SUM(F14:F19) -> 0 | G20: =SUM(G14:G19) -> 0 | H20: =SUM(H14:H19) -> 0 | I20: =SUM(I14:I19) -> 0 | J20: =SUM(J14:J19) -> 0 | K20: =SUM(K14:K19) -> 0 | L20: =SUM(L14:L19) -> 615200 | ... P20: =SUM(P14:P19) -> 1929700 | R20: =SUM(R14:R19) -> 1957700 | S20: =SUM(S14:S19) -> 2125400 | T20: =SUM(T14:T19) -> 2922500 | U20: =SUM(U14:U19) -> 3230100 | V20: =SUM(V14:V19) -> 3496000 | W20: =SUM(W14:W19) -> 3670700 | X20: =SUM(X14:X19) -> 3670700 | Y20: =SUM(Y14:Y19) -> 3670700 | ... AC20: =SUM(AC14:AC19) -> 4020300 | AE20: =SUM(AE14:AE19) -> 3210000 | AF20: =SUM(AF14:AF19) -> 2918400 | AG20: =SUM(AG14:AG19) -> 3356100 | AH20: =SUM(AH14:AH19) -> 3210000 | AI20: =SUM(AI14:AI19) -> 3356100 | AJ20: =SUM(AJ14:AJ19) -> 3210000 | AK20: =SUM(AK14:AK19) -> 3356100 | AL20: =SUM(AL14:AL19) -> 3210000 | ... AP20: =SUM(AP14:AP19) -> 3210000 | AR20: =SUM(AR14:AR19) -> 5965000 | AS20: =SUM(AS14:AS19) -> 5423100 | AT20: =SUM(AT14:AT19) -> 6236425 | AU20: =SUM(AU14:AU19) -> 5965050 | AV20: =SUM(AV14:AV19) -> 6236425 | AW20: =SUM(AW14:AW19) -> 5965050 | AX20: =SUM(AX14:AX19) -> 6236425 | AY20: =SUM(AY14:AY19) -> 5965050 | ... BC20: =SUM(BC14:BC19) -> 5965050 | BE20: =SUM(BE14:BE19) -> 5965000 | BF20: =SUM(BF14:BF19) -> 5423100 | BG20: =SUM(BG14:BG19) -> 6236425 | BH20: =SUM(BH14:BH19) -> 5965050 | BI20: =SUM(BI14:BI19) -> 6236425 | BJ20: =SUM(BJ14:BJ19) -> 5965050 | BK20: =SUM(BK14:BK19) -> 6236425 | BL20: =SUM(BL14:BL19) -> 5965050 | ... BP20: =SUM(BP14:BP19) -> 5965050
A21: 給付費合計（千円） | E21: =E20/1000 -> 0 | F21: =F20/1000 -> 0 | G21: =G20/1000 -> 0 | H21: =H20/1000 -> 0 | I21: =I20/1000 -> 0 | J21: =J20/1000 -> 0 | K21: =K20/1000 -> 0 | L21: =L20/1000 -> 615.2 | ... P21: =P20/1000 -> 1929.7 | R21: =R20/1000 -> 1957.7 | S21: =S20/1000 -> 2125.4 | T21: =T20/1000 -> 2922.5 | U21: =U20/1000 -> 3230.1 | V21: =V20/1000 -> 3496 | W21: =W20/1000 -> 3670.7 | X21: =X20/1000 -> 3670.7 | Y21: =Y20/1000 -> 3670.7 | ... AC21: =AC20/1000 -> 4020.3 | AE21: =AE20/1000 -> 3210 | AF21: =AF20/1000 -> 2918.4 | AG21: =AG20/1000 -> 3356.1 | AH21: =AH20/1000 -> 3210 | AI21: =AI20/1000 -> 3356.1 | AJ21: =AJ20/1000 -> 3210 | AK21: =AK20/1000 -> 3356.1 | AL21: =AL20/1000 -> 3210 | ... AP21: =AP20/1000 -> 3210 | AR21: =AR20/1000 -> 5965 | AS21: =AS20/1000 -> 5423.1 | AT21: =AT20/1000 -> 6236.425 | AU21: =AU20/1000 -> 5965.05 | AV21: =AV20/1000 -> 6236.425 | AW21: =AW20/1000 -> 5965.05 | AX21: =AX20/1000 -> 6236.425 | AY21: =AY20/1000 -> 5965.05 | ... BC21: =BC20/1000 -> 5965.05 | BE21: =BE20/1000 -> 5965 | BF21: =BF20/1000 -> 5423.1 | BG21: =BG20/1000 -> 6236.425 | BH21: =BH20/1000 -> 5965.05 | BI21: =BI20/1000 -> 6236.425 | BJ21: =BJ20/1000 -> 5965.05 | BK21: =BK20/1000 -> 6236.425 | BL21: =BL20/1000 -> 5965.05 | ... BP21: =BP20/1000 -> 5965.05
A23: B基本報酬 | E23: 5890 | F23: 5890 | G23: 5890 | H23: 5890 | I23: 5890 | J23: 5890 | K23: 5890 | L23: 5890 | M23: 5890 | N23: 5890 | O23: 5890 | P23: 5890 | R23: 5890 | S23: 5890 | T23: 5890 | U23: 5890 | V23: 5890 | W23: 5890 | X23: 5890 | Y23: 5890 | Z23: 5890 | AA23: 5890 | AB23: 5890 | AC23: 5890 | AE23: 5890 | AF23: 5890 | AG23: 5890 | AH23: 5890 | AI23: 5890 | AJ23: 5890 | AK23: 5890 | AL23: 5890 | AM23: 5890 | AN23: 5890 | AO23: 5890 | AP23: 5890 | AR23: 5890 | AS23: 5890 | AT23: 5890 | AU23: 5890 | AV23: 5890 | AW23: 5890 | AX23: 5890 | AY23: 5890 | AZ23: 5890 | BA23: 5890 | BB23: 5890 | BC23: 5890 | BE23: 5890 | BF23: 5890 | BG23: 5890 | BH23: 5890 | BI23: 5890 | BJ23: 5890 | BK23: 5890 | BL23: 5890 | BM23: 5890 | BN23: 5890 | BO23: 5890 | BP23: 5890
A24: B施設外基本報酬 | E24: 6890 | F24: 6890 | G24: 6890 | H24: 6890 | I24: 6890 | J24: 6890 | K24: 6890 | L24: 6890 | M24: 6890 | N24: 6890 | O24: 6890 | P24: 6890 | R24: 6890 | S24: 6890 | T24: 6890 | U24: 6890 | V24: 6890 | W24: 6890 | X24: 6890 | Y24: 6890 | Z24: 6890 | AA24: 6890 | AB24: 6890 | AC24: 6890 | AE24: 6890 | AF24: 6890 | AG24: 6890 | AH24: 6890 | AI24: 6890 | AJ24: 6890 | AK24: 6890 | AL24: 6890 | AM24: 6890 | AN24: 6890 | AO24: 6890 | AP24: 6890 | AR24: 6890 | AS24: 6890 | AT24: 6890 | AU24: 6890 | AV24: 6890 | AW24: 6890 | AX24: 6890 | AY24: 6890 | AZ24: 6890 | BA24: 6890 | BB24: 6890 | BC24: 6890 | BE24: 6890 | BF24: 6890 | BG24: 6890 | BH24: 6890 | BI24: 6890 | BJ24: 6890 | BK24: 6890 | BL24: 6890 | BM24: 6890 | BN24: 6890 | BO24: 6890 | BP24: 6890
A25: 移行基本報酬 | E25: 8200 | F25: =E25 -> 8200 | G25: =F25 -> 8200 | H25: =G25 -> 8200 | I25: =H25 -> 8200 | J25: =I25 -> 8200 | K25: =J25 -> 8200 | L25: =K25 -> 8200 | M25: =L25 -> 8200 | ... O25: =N25 -> 8200 | P25: 8200 | R25: =P25 -> 8200 | S25: =R25 -> 8200 | T25: =S25 -> 8200 | U25: =T25 -> 8200 | V25: =U25 -> 8200 | W25: =V25 -> 8200 | X25: =W25 -> 8200 | Y25: =X25 -> 8200 | Z25: =Y25 -> 8200 | ... AC25: =AB25 -> 8200 | AE25: 8080 | AF25: 8080 | AG25: 8080 | AH25: 8080 | AI25: 8080 | AJ25: 8080 | AK25: 8080 | AL25: 8080 | AM25: 8080 | AN25: 8080 | AO25: 8080 | AP25: 8080 | AR25: 8080 | AS25: 8080 | AT25: 8080 | AU25: 8080 | AV25: 8080 | AW25: 8080 | AX25: 8080 | AY25: 8080 | AZ25: 8080 | BA25: 8080 | BB25: 8080 | BC25: 8080 | BE25: 8080 | BF25: 8080 | BG25: 8080 | BH25: 8080 | BI25: 8080 | BJ25: 8080 | BK25: 8080 | BL25: 8080 | BM25: 8080 | BN25: 8080 | BO25: 8080 | BP25: 8080
A26: 移行施設外基本報酬 | E26: =E25 -> 8200 | F26: =F25 -> 8200 | G26: =G25 -> 8200 | H26: =H25 -> 8200 | I26: =I25 -> 8200 | J26: =J25 -> 8200 | K26: =K25 -> 8200 | L26: =L25 -> 8200 | ... P26: =P25 -> 8200 | R26: =R25 -> 8200 | S26: =S25 -> 8200 | T26: =T25 -> 8200 | U26: =U25 -> 8200 | V26: =V25 -> 8200 | W26: =W25 -> 8200 | X26: =X25 -> 8200 | Y26: =Y25 -> 8200 | ... AC26: =AC25 -> 8200 | AE26: 9080 | AF26: 9080 | AG26: 9080 | AH26: 9080 | AI26: 9080 | AJ26: 9080 | AK26: 9080 | AL26: 9080 | AM26: 9080 | AN26: 9080 | AO26: 9080 | AP26: 9080 | AR26: 9080 | AS26: 9080 | AT26: 9080 | AU26: 9080 | AV26: 9080 | AW26: 9080 | AX26: 9080 | AY26: 9080 | AZ26: 9080 | BA26: 9080 | BB26: 9080 | BC26: 9080 | BE26: 9080 | BF26: 9080 | BG26: 9080 | BH26: 9080 | BI26: 9080 | BJ26: 9080 | BK26: 9080 | BL26: 9080 | BM26: 9080 | BN26: 9080 | BO26: 9080 | BP26: 9080
A27: 目標工賃達成指導員加算 | E27: 890 | F27: 890 | G27: 890 | H27: 890 | I27: 890 | J27: 890 | K27: 890 | L27: 890 | M27: 890 | N27: 890 | O27: 890 | P27: 890 | R27: 890 | S27: 890 | T27: 890 | U27: 890 | V27: 890 | W27: 890 | X27: 890 | Y27: 890 | Z27: 890 | AA27: 890 | AB27: 890 | AC27: 890 | AE27: 890 | AF27: 890 | AG27: 890 | AH27: 890 | AI27: 890 | AJ27: 890 | AK27: 890 | AL27: 890 | AM27: 890 | AN27: 890 | AO27: 890 | AP27: 890 | AR27: 890 | AS27: 890 | AT27: 890 | AU27: 890 | AV27: 890 | AW27: 890 | AX27: 890 | AY27: 890 | AZ27: 890 | BA27: 890 | BB27: 890 | BC27: 890 | BE27: 890 | BF27: 890 | BG27: 890 | BH27: 890 | BI27: 890 | BJ27: 890 | BK27: 890 | BL27: 890 | BM27: 890 | BN27: 890 | BO27: 890 | BP27: 890
A28: 送迎加算 | E28: 540 | F28: 540 | G28: 540 | H28: 540 | I28: 540 | J28: 540 | K28: 540 | L28: 540 | M28: 540 | N28: 540 | O28: 540 | P28: 540 | R28: 540 | S28: 540 | T28: 540 | U28: 540 | V28: 540 | W28: 540 | X28: 540 | Y28: 540 | Z28: 540 | AA28: 540 | AB28: 540 | AC28: 540 | AE28: 540 | AF28: 540 | AG28: 540 | AH28: 540 | AI28: 540 | AJ28: 540 | AK28: 540 | AL28: 540 | AM28: 540 | AN28: 540 | AO28: 540 | AP28: 540 | AR28: 540 | AS28: 540 | AT28: 540 | AU28: 540 | AV28: 540 | AW28: 540 | AX28: 540 | AY28: 540 | AZ28: 540 | BA28: 540 | BB28: 540 | BC28: 540 | BE28: 540 | BF28: 540 | BG28: 540 | BH28: 540 | BI28: 540 | BJ28: 540 | BK28: 540 | BL28: 540 | BM28: 540 | BN28: 540 | BO28: 540 | BP28: 540
A29: 稼働率 | E29: 0.8 | F29: 0.8 | G29: 0.8 | H29: 0.8 | I29: 0.8 | J29: 0.8 | K29: 0.8 | L29: 0.8 | M29: 0.8 | N29: 0.8 | O29: 0.8 | P29: 0.8 | R29: 0.75 | S29: 0.75 | T29: 0.75 | U29: 0.75 | V29: 0.75 | W29: 0.75 | X29: 0.75 | Y29: 0.75 | Z29: 0.75 | AA29: 0.75 | AB29: 0.75 | AC29: 0.75 | AE29: 0.75 | AF29: 0.75 | AG29: 0.75 | AH29: 0.75 | AI29: 0.75 | AJ29: 0.75 | AK29: 0.75 | AL29: 0.75 | AM29: 0.75 | AN29: 0.75 | AO29: 0.75 | AP29: 0.75 | AR29: 0.75 | AS29: 0.75 | AT29: 0.75 | AU29: 0.75 | AV29: 0.75 | AW29: 0.75 | AX29: 0.75 | AY29: 0.75 | AZ29: 0.75 | BA29: 0.75 | BB29: 0.75 | BC29: 0.75 | BE29: 0.75 | BF29: 0.75 | BG29: 0.75 | BH29: 0.75 | BI29: 0.75 | BJ29: 0.75 | BK29: 0.75 | BL29: 0.75 | BM29: 0.75 | BN29: 0.75 | BO29: 0.75 | BP29: 0.75
A32: B人員配置 | E32: =ROUNDUP(E6/7.5,0) -> 0 | F32: =ROUNDUP(F6/7.5,0) -> 0 | G32: =ROUNDUP(G6/7.5,1) -> 0 | H32: =ROUNDUP(H6/7.5,1) -> 0 | I32: =ROUNDUP(I6/7.5,1) -> 0 | J32: =ROUNDUP(J6/7.5,1) -> 0 | K32: =ROUNDUP(K6/7.5,1) -> 0 | L32: =ROUNDUP(L6/7.5,1) -> 0 | M32: =ROUNDUP(M6/7.5,1) -> 0 | N32: =ROUNDUP(N6/7.5,1) -> 0 | ... P32: =ROUNDUP(P6/7.5,1) -> 0 | R32: =ROUNDUP(R6/7.5,0) -> 0 | S32: =ROUNDUP(S6/7.5,0) -> 0 | T32: =ROUNDUP(T6/7.5,1) -> 0 | U32: =ROUNDUP(U6/7.5,1) -> 0 | V32: =ROUNDUP(V6/7.5,1) -> 0 | W32: =ROUNDUP(W6/7.5,1) -> 0 | X32: =ROUNDUP(X6/7.5,1) -> 0 | Y32: =ROUNDUP(Y6/7.5,1) -> 0 | Z32: =ROUNDUP(Z6/7.5,1) -> 0 | AA32: =ROUNDUP(AA6/7.5,1) -> 0 | ... AC32: =ROUNDUP(AC6/7.5,1) -> 0 | AE32: =ROUNDUP(AE6/7.5,0) -> 0 | AF32: =ROUNDUP(AF6/7.5,0) -> 0 | AG32: =ROUNDUP(AG6/7.5,1) -> 0 | AH32: =ROUNDUP(AH6/7.5,1) -> 0 | AI32: =ROUNDUP(AI6/7.5,1) -> 0 | AJ32: =ROUNDUP(AJ6/7.5,1) -> 0 | AK32: =ROUNDUP(AK6/7.5,1) -> 0 | AL32: =ROUNDUP(AL6/7.5,1) -> 0 | AM32: =ROUNDUP(AM6/7.5,1) -> 0 | AN32: =ROUNDUP(AN6/7.5,1) -> 0 | ... AP32: =ROUNDUP(AP6/7.5,1) -> 0 | AR32: =ROUNDUP(AR6/7.5,0) -> 2 | AS32: =ROUNDUP(AS6/7.5,0) -> 2 | AT32: =ROUNDUP(AT6/7.5,1) -> 1.4 | AU32: =ROUNDUP(AU6/7.5,1) -> 1.4 | AV32: =ROUNDUP(AV6/7.5,1) -> 1.4 | AW32: =ROUNDUP(AW6/7.5,1) -> 1.4 | AX32: =ROUNDUP(AX6/7.5,1) -> 1.4 | AY32: =ROUNDUP(AY6/7.5,1) -> 1.4 | AZ32: =ROUNDUP(AZ6/7.5,1) -> 1.4 | BA32: =ROUNDUP(BA6/7.5,1) -> 1.4 | ... BC32: =ROUNDUP(BC6/7.5,1) -> 1.4 | BE32: =ROUNDUP(BE6/7.5,0) -> 2 | BF32: =ROUNDUP(BF6/7.5,0) -> 2 | BG32: =ROUNDUP(BG6/7.5,1) -> 1.4 | BH32: =ROUNDUP(BH6/7.5,1) -> 1.4 | BI32: =ROUNDUP(BI6/7.5,1) -> 1.4 | BJ32: =ROUNDUP(BJ6/7.5,1) -> 1.4 | BK32: =ROUNDUP(BK6/7.5,1) -> 1.4 | BL32: =ROUNDUP(BL6/7.5,1) -> 1.4 | BM32: =ROUNDUP(BM6/7.5,1) -> 1.4 | BN32: =ROUNDUP(BN6/7.5,1) -> 1.4 | ... BP32: =ROUNDUP(BP6/7.5,1) -> 1.4
A33: B人工賃向上・施設外 | E33: =IF(E7/7.5<1,2,1+E7/7.5) -> 2 | F33: =IF(F7/7.5<1,2,1+F7/7.5) -> 2 | G33: =IF(G7/7.5<1,2,1+G7/7.5) -> 2 | H33: =IF(H7/7.5<1,2,1+H7/7.5) -> 2 | I33: =IF(I7/7.5<1,2,1+I7/7.5) -> 2 | J33: =IF(J7/7.5<1,2,1+J7/7.5) -> 2 | K33: =IF(K7/7.5<1,2,1+K7/7.5) -> 2 | L33: =IF(L7/7.5<1,2,1+L7/7.5) -> 2 | ... P33: =IF(P7/7.5<1,2,1+P7/7.5) -> 2 | R33: =IF(R7/7.5<1,2,1+R7/7.5) -> 2 | S33: =IF(S7/7.5<1,2,1+S7/7.5) -> 2 | T33: =IF(T7/7.5<1,2,1+T7/7.5) -> 2 | U33: =IF(U7/7.5<1,2,1+U7/7.5) -> 2 | V33: =IF(V7/7.5<1,2,1+V7/7.5) -> 2 | W33: =IF(W7/7.5<1,2,1+W7/7.5) -> 2 | X33: =IF(X7/7.5<1,2,1+X7/7.5) -> 2 | Y33: =IF(Y7/7.5<1,2,1+Y7/7.5) -> 2 | ... AC33: =IF(AC7/7.5<1,2,1+AC7/7.5) -> 2 | AE33: =IF(AE7/7.5<1,2,1+AE7/7.5) -> 2 | AF33: =IF(AF7/7.5<1,2,1+AF7/7.5) -> 2 | AG33: =IF(AG7/7.5<1,2,1+AG7/7.5) -> 2 | AH33: =IF(AH7/7.5<1,2,1+AH7/7.5) -> 2 | AI33: =IF(AI7/7.5<1,2,1+AI7/7.5) -> 2 | AJ33: =IF(AJ7/7.5<1,2,1+AJ7/7.5) -> 2 | AK33: =IF(AK7/7.5<1,2,1+AK7/7.5) -> 2 | AL33: =IF(AL7/7.5<1,2,1+AL7/7.5) -> 2 | ... AP33: =IF(AP7/7.5<1,2,1+AP7/7.5) -> 2 | AR33: =IF(AR7/7.5<1,2,1+AR7/7.5) -> 2.3333333 | AS33: =IF(AS7/7.5<1,2,1+AS7/7.5) -> 2.3333333 | AT33: =IF(AT7/7.5<1,2,1+AT7/7.5) -> 2.3333333 | AU33: =IF(AU7/7.5<1,2,1+AU7/7.5) -> 2.3333333 | AV33: =IF(AV7/7.5<1,2,1+AV7/7.5) -> 2.3333333 | AW33: =IF(AW7/7.5<1,2,1+AW7/7.5) -> 2.3333333 | AX33: =IF(AX7/7.5<1,2,1+AX7/7.5) -> 2.3333333 | AY33: =IF(AY7/7.5<1,2,1+AY7/7.5) -> 2.3333333 | ... BC33: =IF(BC7/7.5<1,2,1+BC7/7.5) -> 2.3333333 | BE33: =IF(BE7/7.5<1,2,1+BE7/7.5) -> 2.3333333 | BF33: =IF(BF7/7.5<1,2,1+BF7/7.5) -> 2.3333333 | BG33: =IF(BG7/7.5<1,2,1+BG7/7.5) -> 2.3333333 | BH33: =IF(BH7/7.5<1,2,1+BH7/7.5) -> 2.3333333 | BI33: =IF(BI7/7.5<1,2,1+BI7/7.5) -> 2.3333333 | BJ33: =IF(BJ7/7.5<1,2,1+BJ7/7.5) -> 2.3333333 | BK33: =IF(BK7/7.5<1,2,1+BK7/7.5) -> 2.3333333 | BL33: =IF(BL7/7.5<1,2,1+BL7/7.5) -> 2.3333333 | ... BP33: =IF(BP7/7.5<1,2,1+BP7/7.5) -> 2.3333333
A34: 移行人員配置 | E34: =ROUNDUP(E9/6,0) -> 0 | F34: =(F9+F10)/6 -> 0 | G34: =(G9+G10)/6 -> 0 | H34: =(H9+H10)/6 -> 0 | I34: =(I9+I10)/6 -> 0 | J34: =(J9+J10)/6 -> 0 | K34: =(K9+K10)/6 -> 0 | L34: =(L9+L10)/6 -> 0.66666667 | M34: =(M9+M10)/6 -> 1 | ... P34: =(P9+P10)/6 -> 2 | R34: =ROUNDUP(R9/6,1) -> 2.2 | S34: =(S9+S10)/6 -> 2.6666667 | T34: =(T9+T10)/6 -> 3.1666667 | U34: =(U9+U10)/6 -> 3.6666667 | V34: =(V9+V10)/6 -> 4.1666667 | W34: =(W9+W10)/6 -> 4.1666667 | X34: =(X9+X10)/6 -> 4.1666667 | Y34: =(Y9+Y10)/6 -> 4.1666667 | Z34: =(Z9+Z10)/6 -> 4.1666667 | ... AC34: =(AC9+AC10)/6 -> 4.1666667 | AE34: =ROUNDUP(AE9/6,1) -> 1.7 | AF34: =(AF9+AF10)/6 -> 3.3333333 | AG34: =(AG9+AG10)/6 -> 3.3333333 | AH34: =(AH9+AH10)/6 -> 3.3333333 | AI34: =(AI9+AI10)/6 -> 3.3333333 | AJ34: =(AJ9+AJ10)/6 -> 3.3333333 | AK34: =(AK9+AK10)/6 -> 3.3333333 | AL34: =(AL9+AL10)/6 -> 3.3333333 | AM34: =(AM9+AM10)/6 -> 3.3333333 | ... AP34: =(AP9+AP10)/6 -> 3.3333333 | AR34: =ROUNDUP(AR9/6,1) -> 1.7 | AS34: =(AS9+AS10)/6 -> 3.3333333 | AT34: =(AT9+AT10)/6 -> 3.3333333 | AU34: =(AU9+AU10)/6 -> 3.3333333 | AV34: =(AV9+AV10)/6 -> 3.3333333 | AW34: =(AW9+AW10)/6 -> 3.3333333 | AX34: =(AX9+AX10)/6 -> 3.3333333 | AY34: =(AY9+AY10)/6 -> 3.3333333 | AZ34: =(AZ9+AZ10)/6 -> 3.3333333 | ... BC34: =(BC9+BC10)/6 -> 3.3333333 | BE34: =ROUNDUP(BE9/6,1) -> 1.7 | BF34: =(BF9+BF10)/6 -> 3.3333333 | BG34: =(BG9+BG10)/6 -> 3.3333333 | BH34: =(BH9+BH10)/6 -> 3.3333333 | BI34: =(BI9+BI10)/6 -> 3.3333333 | BJ34: =(BJ9+BJ10)/6 -> 3.3333333 | BK34: =(BK9+BK10)/6 -> 3.3333333 | BL34: =(BL9+BL10)/6 -> 3.3333333 | BM34: =(BM9+BM10)/6 -> 3.3333333 | ... BP34: =(BP9+BP10)/6 -> 3.3333333
A35: 移行就労支援員配置 | E35: =IF((E9+E10)/15<1,1,(E9+E10)/15) -> 1 | F35: =IF((F9+F10)/15<1,1,(F9+F10)/15) -> 1 | G35: =IF((G9+G10)/15<1,1,(G9+G10)/15) -> 1 | H35: =IF((H9+H10)/15<1,1,(H9+H10)/15) -> 1 | I35: =IF((I9+I10)/15<1,1,(I9+I10)/15) -> 1 | J35: =IF((J9+J10)/15<1,1,(J9+J10)/15) -> 1 | K35: =IF((K9+K10)/15<1,1,(K9+K10)/15) -> 1 | L35: =IF((L9+L10)/15<1,1,(L9+L10)/15) -> 1 | ... P35: =IF((P9+P10)/15<1,1,(P9+P10)/15) -> 1 | R35: =IF((R9+R10)/15<1,1,(R9+R10)/15) -> 1 | S35: =IF((S9+S10)/15<1,1,(S9+S10)/15) -> 1.0666667 | T35: =IF((T9+T10)/15<1,1,(T9+T10)/15) -> 1.2666667 | U35: =IF((U9+U10)/15<1,1,(U9+U10)/15) -> 1.4666667 | V35: =IF((V9+V10)/15<1,1,(V9+V10)/15) -> 1.6666667 | W35: =IF((W9+W10)/15<1,1,(W9+W10)/15) -> 1.6666667 | X35: =IF((X9+X10)/15<1,1,(X9+X10)/15) -> 1.6666667 | Y35: =IF((Y9+Y10)/15<1,1,(Y9+Y10)/15) -> 1.6666667 | ... AC35: =IF((AC9+AC10)/15<1,1,(AC9+AC10)/15) -> 1.6666667 | AE35: =IF((AE9+AE10)/15<1,1,(AE9+AE10)/15) -> 1.3333333 | AF35: =IF((AF9+AF10)/15<1,1,(AF9+AF10)/15) -> 1.3333333 | AG35: =IF((AG9+AG10)/15<1,1,(AG9+AG10)/15) -> 1.3333333 | AH35: =IF((AH9+AH10)/15<1,1,(AH9+AH10)/15) -> 1.3333333 | AI35: =IF((AI9+AI10)/15<1,1,(AI9+AI10)/15) -> 1.3333333 | AJ35: =IF((AJ9+AJ10)/15<1,1,(AJ9+AJ10)/15) -> 1.3333333 | AK35: =IF((AK9+AK10)/15<1,1,(AK9+AK10)/15) -> 1.3333333 | AL35: =IF((AL9+AL10)/15<1,1,(AL9+AL10)/15) -> 1.3333333 | ... AP35: =IF((AP9+AP10)/15<1,1,(AP9+AP10)/15) -> 1.3333333 | AR35: =IF((AR9+AR10)/15<1,1,(AR9+AR10)/15) -> 1.3333333 | AS35: =IF((AS9+AS10)/15<1,1,(AS9+AS10)/15) -> 1.3333333 | AT35: =IF((AT9+AT10)/15<1,1,(AT9+AT10)/15) -> 1.3333333 | AU35: =IF((AU9+AU10)/15<1,1,(AU9+AU10)/15) -> 1.3333333 | AV35: =IF((AV9+AV10)/15<1,1,(AV9+AV10)/15) -> 1.3333333 | AW35: =IF((AW9+AW10)/15<1,1,(AW9+AW10)/15) -> 1.3333333 | AX35: =IF((AX9+AX10)/15<1,1,(AX9+AX10)/15) -> 1.3333333 | AY35: =IF((AY9+AY10)/15<1,1,(AY9+AY10)/15) -> 1.3333333 | ... BC35: =IF((BC9+BC10)/15<1,1,(BC9+BC10)/15) -> 1.3333333 | BE35: =IF((BE9+BE10)/15<1,1,(BE9+BE10)/15) -> 1.3333333 | BF35: =IF((BF9+BF10)/15<1,1,(BF9+BF10)/15) -> 1.3333333 | BG35: =IF((BG9+BG10)/15<1,1,(BG9+BG10)/15) -> 1.3333333 | BH35: =IF((BH9+BH10)/15<1,1,(BH9+BH10)/15) -> 1.3333333 | BI35: =IF((BI9+BI10)/15<1,1,(BI9+BI10)/15) -> 1.3333333 | BJ35: =IF((BJ9+BJ10)/15<1,1,(BJ9+BJ10)/15) -> 1.3333333 | BK35: =IF((BK9+BK10)/15<1,1,(BK9+BK10)/15) -> 1.3333333 | BL35: =IF((BL9+BL10)/15<1,1,(BL9+BL10)/15) -> 1.3333333 | ... BP35: =IF((BP9+BP10)/15<1,1,(BP9+BP10)/15) -> 1.3333333
A36: 移行施設外支援配置 | E36: =IF(E10/6<1,1,E10/6) -> 1 | F36: =IF(F10/6<1,1,F10/6) -> 1 | G36: =IF(G10/6<1,1,G10/6) -> 1 | H36: =IF(H10/6<1,1,H10/6) -> 1 | I36: =IF(I10/6<1,1,I10/6) -> 1 | J36: =IF(J10/6<1,1,J10/6) -> 1 | K36: =IF(K10/6<1,1,K10/6) -> 1 | L36: =IF(L10/6<1,1,L10/6) -> 1 | ... P36: =IF(P10/6<1,1,P10/6) -> 1 | R36: =IF(R10/6<1,1,R10/6) -> 1 | S36: =IF(S10/6<1,1,S10/6) -> 1 | T36: =IF(T10/6<1,1,T10/6) -> 1 | U36: =IF(U10/6<1,1,U10/6) -> 1 | V36: =IF(V10/6<1,1,V10/6) -> 1.3333333 | W36: =IF(W10/6<1,1,W10/6) -> 1.3333333 | X36: =IF(X10/6<1,1,X10/6) -> 1.3333333 | Y36: =IF(Y10/6<1,1,Y10/6) -> 1.3333333 | ... AC36: =IF(AC10/6<1,1,AC10/6) -> 1.3333333 | AE36: =IF(AE10/6<1,1,AE10/6) -> 1.6666667 | AF36: =IF(AF10/6<1,1,AF10/6) -> 1.6666667 | AG36: =IF(AG10/6<1,1,AG10/6) -> 1.6666667 | AH36: =IF(AH10/6<1,1,AH10/6) -> 1.6666667 | AI36: =IF(AI10/6<1,1,AI10/6) -> 1.6666667 | AJ36: =IF(AJ10/6<1,1,AJ10/6) -> 1.6666667 | AK36: =IF(AK10/6<1,1,AK10/6) -> 1.6666667 | AL36: =IF(AL10/6<1,1,AL10/6) -> 1.6666667 | ... AP36: =IF(AP10/6<1,1,AP10/6) -> 1.6666667 | AR36: =IF(AR10/6<1,1,AR10/6) -> 1.6666667 | AS36: =IF(AS10/6<1,1,AS10/6) -> 1.6666667 | AT36: =IF(AT10/6<1,1,AT10/6) -> 1.6666667 | AU36: =IF(AU10/6<1,1,AU10/6) -> 1.6666667 | AV36: =IF(AV10/6<1,1,AV10/6) -> 1.6666667 | AW36: =IF(AW10/6<1,1,AW10/6) -> 1.6666667 | AX36: =IF(AX10/6<1,1,AX10/6) -> 1.6666667 | AY36: =IF(AY10/6<1,1,AY10/6) -> 1.6666667 | ... BC36: =IF(BC10/6<1,1,BC10/6) -> 1.6666667 | BE36: =IF(BE10/6<1,1,BE10/6) -> 1.6666667 | BF36: =IF(BF10/6<1,1,BF10/6) -> 1.6666667 | BG36: =IF(BG10/6<1,1,BG10/6) -> 1.6666667 | BH36: =IF(BH10/6<1,1,BH10/6) -> 1.6666667 | BI36: =IF(BI10/6<1,1,BI10/6) -> 1.6666667 | BJ36: =IF(BJ10/6<1,1,BJ10/6) -> 1.6666667 | BK36: =IF(BK10/6<1,1,BK10/6) -> 1.6666667 | BL36: =IF(BL10/6<1,1,BL10/6) -> 1.6666667 | ... BP36: =IF(BP10/6<1,1,BP10/6) -> 1.6666667
A38: 管理者 山﨑 | K38: =900*7*20 -> 126000 | L38: 126000 | M38: 126000 | N38: 220000 | O38: 220000 | P38: 220000 | R38: =P38 -> 220000 | S38: =R38 -> 220000 | T38: =S38 -> 220000 | U38: 220000 | V38: =U38 -> 220000 | W38: =V38 -> 220000 | X38: =W38 -> 220000 | Y38: =X38 -> 220000 | Z38: =Y38 -> 220000 | AA38: =Z38 -> 220000 | AB38: =AA38 -> 220000 | AC38: =AB38 -> 220000 | BE38: 180000 | BF38: 180000 | BG38: 180000 | BH38: 180000 | BI38: 180000 | BJ38: 180000 | BK38: 180000 | BL38: 180000 | BM38: 180000 | BN38: 180000 | BO38: 180000 | BP38: 180000
A39: サビ管 田中 ⇒ 山内（１２月） | L39: 120000 | M39: 120000 | N39: 180000 | O39: 180000 | P39: 180000 | R39: =P39 -> 180000 | S39: =R39 -> 180000 | T39: =S39 -> 180000 | U39: =T39 -> 180000 | V39: =U39 -> 180000 | W39: =V39 -> 180000 | X39: =W39 -> 180000 | Y39: =X39 -> 180000 | Z39: =Y39 -> 180000 | ... AC39: =AB39 -> 180000
A40: 職業指導員 渡邊 | L40: =900*7*20 -> 126000 | M40: 126000 | N40: 126000 | O40: 180000 | P40: 180000 | R40: 200000 | S40: =R40 -> 200000 | T40: =S40 -> 200000 | U40: =T40 -> 200000 | V40: =U40 -> 200000 | W40: =V40 -> 200000 | X40: =W40 -> 200000 | Y40: =X40 -> 200000 | Z40: =Y40 -> 200000 | ... AC40: =AB40 -> 200000 | BE40: 150000 | BF40: 150000 | BG40: 150000 | BH40: 150000 | BI40: 150000 | BJ40: 150000 | BK40: 150000 | BL40: 150000 | BM40: 150000 | BN40: 150000 | BO40: 150000 | BP40: 150000
A41: 職業指導員 村上 | L41: =900*7*20 -> 126000 | M41: 126000 | N41: 126000 | O41: 180000 | P41: 180000 | R41: 200000 | S41: =R41 -> 200000 | T41: =S41 -> 200000 | U41: =T41 -> 200000 | V41: =U41 -> 200000 | W41: =V41 -> 200000 | X41: =W41 -> 200000 | Y41: =X41 -> 200000 | Z41: =Y41 -> 200000 | ... AC41: =AB41 -> 200000 | BE41: 180000 | BF41: 180000 | BG41: 180000 | BH41: 180000 | BI41: 180000 | BJ41: 180000 | BK41: 180000 | BL41: 180000 | BM41: 180000 | BN41: 180000 | BO41: 180000 | BP41: 180000
A42: 生活支援員 山内ノ | L42: 120000 | M42: 120000 | N42: 120000 | O42: 120000 | P42: 120000 | R42: 180000 | S42: =R42 -> 180000 | T42: =S42 -> 180000 | U42: 180000 | V42: =U42 -> 180000 | W42: =V42 -> 180000 | X42: =W42 -> 180000 | Y42: =X42 -> 180000 | Z42: =Y42 -> 180000 | AA42: =Z42 -> 180000 | AB42: =AA42 -> 180000 | AC42: =AB42 -> 180000 | BE42: 180000 | BF42: 180000 | BG42: 180000 | BH42: 180000 | BI42: 180000 | BJ42: 180000 | BK42: 180000 | BL42: 180000 | BM42: 180000 | BN42: 180000 | BO42: 180000 | BP42: 180000
A43: 就労支援員 山内ユ | L43: 180000 | M43: 180000 | N43: 0 | O43: 0 | P43: 0 | R43: =P43 -> 0 | S43: =R43 -> 0 | T43: =S43 -> 0 | U43: =T43 -> 0 | V43: =U43 -> 0 | W43: =V43 -> 0 | X43: =W43 -> 0 | Y43: =X43 -> 0 | Z43: =Y43 -> 0 | ... AC43: =AB43 -> 0 | BE43: 180000 | BF43: 180000 | BG43: 180000 | BH43: 180000 | BI43: 180000 | BJ43: 180000 | BK43: 180000 | BL43: 180000 | BM43: 180000 | BN43: 180000 | BO43: 180000 | BP43: 180000
A44: 就労支援員 住吉 | L44: 126000 | M44: 126000 | N44: 126000 | BE44: 150000 | BF44: 150000 | BG44: 150000 | BH44: 150000 | BI44: 150000 | BJ44: 150000 | BK44: 150000 | BL44: 150000 | BM44: 150000 | BN44: 150000 | BO44: 150000 | BP44: 150000
A45: 就労支援員 山内チ（役員報酬） | L45: 80000 | M45: 80000 | N45: 80000 | O45: 80000 | P45: 80000 | R45: =P45 -> 80000 | S45: =R45 -> 80000 | T45: =S45 -> 80000 | U45: =T45 -> 80000 | V45: =U45 -> 80000 | W45: =V45 -> 80000 | X45: =W45 -> 80000 | Y45: =X45 -> 80000 | Z45: =Y45 -> 80000 | ... AC45: =AB45 -> 80000 | BE45: 250000 | BF45: 250000 | BG45: 250000 | BH45: 250000 | BI45: 250000 | BJ45: 250000 | BK45: 250000 | BL45: 250000 | BM45: 250000 | BN45: 250000 | BO45: 250000 | BP45: 250000
A46: 生活支援員等 | R46: 126000 | S46: =R46 -> 126000 | T46: =S46 -> 126000 | U46: =T46 -> 126000 | V46: =U46 -> 126000 | W46: =V46 -> 126000 | X46: =W46 -> 126000 | Y46: =X46 -> 126000 | Z46: =Y46 -> 126000 | ... AC46: =AB46 -> 126000 | BE46: 180000 | BF46: 180000 | BG46: 180000 | BH46: 180000 | BI46: 180000 | BJ46: 180000 | BK46: 180000 | BL46: 180000 | BM46: 180000 | BN46: 180000 | BO46: 180000 | BP46: 180000
...

Sheet 基礎
A1: R3年 | S1: R４年
D2: ４月 | E2: ５月 | F2: ６月 | G2: ７月 | H2: ８月 | I2: ９月 | J2: １０月 | K2: １１月 | L2: １２月 | M2: １月 | N2: ２月 | O2: ３月 | P2: 合計 | Q2: 対売上比率 | V2: ４月 | W2: ５月 | X2: ６月 | Y2: ７月 | Z2: ８月 | AA2: ９月 | AB2: １０月 | AC2: １１月 | AD2: １２月 | AE2: １月 | AF2: ２月 | AG2: ３月 | AH2: 合計 | AI2: 対売上比率
A3: 総売上 | D3: =D5+D9+D13+D12 -> 0 | E3: =E5+E9+E13+E12 -> 0 | F3: =F5+F9+F13+F12 -> 0 | G3: =G5+G9+G13+G12 -> 0 | H3: =H5+H9+H13+H12 -> 0 | I3: =I5+I9+I13+I12 -> 0 | J3: =J5+J9+J13+J12 -> 0 | K3: =K5+K9+K13+K12 -> 615200 | ... O3: =O5+O9+O13+O12 -> 1929700 | P3: =SUM(D3:O3) -> 5691000 | Q3: =P3/P3 -> 1 | T3: 総売上 | V3: =V5+V9+V13+V12 -> 1957700 | W3: =W5+W9+W13+W12 -> 2125400 | X3: =X5+X9+X13+X12 -> 2922500 | Y3: =Y5+Y9+Y13+Y12 -> 3230100 | Z3: =Z5+Z9+Z13+Z12 -> 3496000 | AA3: =AA5+AA9+AA13+AA12 -> 3670700 | AB3: =AB5+AB9+AB13+AB12 -> 3670700 | AC3: =AC5+AC9+AC13+AC12 -> 3670700 | ... AG3: =AG5+AG9+AG13+AG12 -> 4020300 | AH3: =SUM(V3:AG3) -> 38727500 | AI3: =AH3/P3 -> 6.8050431
C4: 利用者総数 | D4: =コーリングサポ!E12 -> 0 | E4: =コーリングサポ!F12 -> 0 | F4: =コーリングサポ!G12 -> 0 | G4: =コーリングサポ!H12 -> 0 | H4: =コーリングサポ!I12 -> 0 | I4: =コーリングサポ!J12 -> 0 | J4: =コーリングサポ!K12 -> 0 | K4: =コーリングサポ!L12 -> 4 | ... O4: =コーリングサポ!P12 -> 12 | U4: 利用者総数 | V4: =コーリングサポ!R12 -> 14 | W4: =コーリングサポ!S12 -> 16 | X4: =コーリングサポ!T12 -> 19 | Y4: =コーリングサポ!U12 -> 22 | Z4: =コーリングサポ!V12 -> 25 | AA4: =コーリングサポ!W12 -> 25 | AB4: =コーリングサポ!X12 -> 25 | AC4: =コーリングサポ!Y12 -> 25 | ... AG4: =コーリングサポ!AC12 -> 25
B5: 訓練給付金等 | D5: =SUM(D6:D8) -> 0 | E5: =SUM(E6:E8) -> 0 | F5: =SUM(F6:F8) -> 0 | G5: =SUM(G6:G8) -> 0 | H5: =SUM(H6:H8) -> 0 | I5: =SUM(I6:I8) -> 0 | J5: =SUM(J6:J8) -> 0 | K5: =SUM(K6:K8) -> 615200 | ... O5: =SUM(O6:O8) -> 1929700 | P5: =SUM(D5:O5) -> 5691000 | Q5: =IF(P5=0,"",P5/$P$3) -> 1 | T5: 訓練給付金等 | V5: =SUM(V6:V8) -> 1957700 | W5: =SUM(W6:W8) -> 2125400 | X5: =SUM(X6:X8) -> 2922500 | Y5: =SUM(Y6:Y8) -> 3230100 | Z5: =SUM(Z6:Z8) -> 3496000 | AA5: =SUM(AA6:AA8) -> 3670700 | AB5: =SUM(AB6:AB8) -> 3670700 | AC5: =SUM(AC6:AC8) -> 3670700 | ... AG5: =SUM(AG6:AG8) -> 4020300 | AH5: =SUM(V5:AG5) -> 38727500 | AI5: =IF(AH5=0,"",AH5/AH$3) -> 1
C6: コーリングサポ笠岡 | D6: =コーリングサポ!E20 -> 0 | E6: =コーリングサポ!F20 -> 0 | F6: =コーリングサポ!G20 -> 0 | G6: =コーリングサポ!H20 -> 0 | H6: =コーリングサポ!I20 -> 0 | I6: =コーリングサポ!J20 -> 0 | J6: =コーリングサポ!K20 -> 0 | K6: =コーリングサポ!L20 -> 615200 | ... O6: =コーリングサポ!P20 -> 1929700 | P6: =SUM(D6:O6) -> 5691000 | Q6: =IF(P6=0,"",P6/$P$3) -> 1 | U6: コーリングサポ笠岡 | V6: =コーリングサポ!R20 -> 1957700 | W6: =コーリングサポ!S20 -> 2125400 | X6: =コーリングサポ!T20 -> 2922500 | Y6: =コーリングサポ!U20 -> 3230100 | Z6: =コーリングサポ!V20 -> 3496000 | AA6: =コーリングサポ!W20 -> 3670700 | AB6: =コーリングサポ!X20 -> 3670700 | AC6: =コーリングサポ!Y20 -> 3670700 | ... AG6: =コーリングサポ!AC20 -> 4020300 | AH6: =SUM(V6:AG6) -> 38727500 | AI6: =IF(AH6=0,"",AH6/AH$3) -> 1
AH7: =SUM(V7:AG7) -> 0 | AI7: =IF(AH7=0,"",AH7/AH$3)
P8: =SUM(D8:O8)*5000 -> 0 | Q8: =IF(P8=0,"",P8/$P$3) | AH8: =SUM(V8:AG8) -> 0 | AI8: =IF(AH8=0,"",AH8/AH$3)
B9: 福祉的就労売上 | D9: =SUM(D10:D11) -> 0 | E9: =SUM(E10:E11) -> 0 | F9: =SUM(F10:F11) -> 0 | G9: =SUM(G10:G11) -> 0 | H9: =SUM(H10:H11) -> 0 | I9: =SUM(I10:I11) -> 0 | J9: =SUM(J10:J11) -> 0 | K9: =SUM(K10:K11) -> 0 | ... O9: =SUM(O10:O11) -> 0 | P9: =SUM(D9:O9) -> 0 | Q9: =IF(P9=0,"",P9/$P$3) | T9: 福祉的就労売上 | V9: =SUM(V10:V11) -> 0 | W9: =SUM(W10:W11) -> 0 | X9: =SUM(X10:X11) -> 0 | Y9: =SUM(Y10:Y11) -> 0 | Z9: =SUM(Z10:Z11) -> 0 | AA9: =SUM(AA10:AA11) -> 0 | AB9: =SUM(AB10:AB11) -> 0 | AC9: =SUM(AC10:AC11) -> 0 | ... AG9: =SUM(AG10:AG11) -> 0 | AH9: =SUM(V9:AG9) -> 0 | AI9: =IF(AH9=0,"",AH9/AH$3)
C10: シェル（笠岡） | P10: =SUM(D10:O10) -> 0 | Q10: =IF(P10=0,"",P10/$P$3) | U10: シェル（笠岡） | AH10: =SUM(V10:AG10) -> 0 | AI10: =IF(AH10=0,"",AH10/AH$3)
Q11: =IF(P11=0,"",P11/$P$3) | AH11: =SUM(V11:AG11) -> 0 | AI11: =IF(AH11=0,"",AH11/AH$3)
B12: 特定困難者受給 | P12: =SUM(D12:O12) -> 0 | T12: 特定困難者受給 | AH12: =SUM(V12:AG12) -> 0 | AI12: =IF(AH12=0,"",AH12/AH$3)
B13: その他収入 | P13: =SUM(D13:O13) -> 0 | Q13: =IF(P13=0,"",P13/$P$3) | T13: その他収入 | AH13: =SUM(V13:AG13) -> 0 | AI13: =IF(AH13=0,"",AH13/AH$3)
B14: 事業原価 | D14: =SUM(D16:D20) -> 0 | E14: =SUM(E16:E20) -> 0 | F14: =SUM(F16:F20) -> 0 | G14: =SUM(G16:G20) -> 0 | H14: =SUM(H16:H20) -> 36300 | I14: =SUM(I16:I20) -> 108300 | J14: =SUM(J16:J20) -> 287670 | K14: =K15+K21 -> 1386510 | L14: =L15+L21 -> 1386510 | M14: =M15+M21 -> 1357130 | N14: =N15+N21 -> 1336790 | O14: =O15+O21 -> 1336790 | P14: =SUM(D14:O14) -> 7236000 | Q14: =IF(P14=0,"",P14/$P$3) -> 1.2714813 | T14: 部門別経費 | V14: =V15+V21 -> 1759410 | W14: =SUM(W16:W20) -> 1759410 | X14: =SUM(X16:X20) -> 1759410 | Y14: =SUM(Y16:Y20) -> 1759410 | Z14: =SUM(Z16:Z20) -> 1759410 | AA14: =SUM(AA16:AA20) -> 1759410 | AB14: =SUM(AB16:AB20) -> 1759410 | AC14: =SUM(AC16:AC20) -> 1759410 | AD14: =SUM(AD16:AD20) -> 2663410 | ... AG14: =SUM(AG16:AG20) -> 1759410 | AH14: =SUM(V14:AG14) -> 22016920 | AI14: =IF(AH14=0,"",AH14/AH$3) -> 0.56850868
B15: 訓練給付金等 | D15: =SUM(D16:D20) -> 0 | E15: =SUM(E16:E20) -> 0 | F15: =SUM(F16:F20) -> 0 | G15: =SUM(G16:G20) -> 0 | H15: =SUM(H16:H20) -> 36300 | I15: =SUM(I16:I20) -> 108300 | J15: =SUM(J16:J20) -> 287670 | K15: =SUM(K16:K20) -> 1386510 | ... O15: =SUM(O16:O20) -> 1336790 | P15: =SUM(D15:O15) -> 7236000 | T15: 訓練給付金等 | V15: =SUM(V16:V20) -> 1759410 | W15: =SUM(W16:W20) -> 1759410 | X15: =SUM(X16:X20) -> 1759410 | Y15: =SUM(Y16:Y20) -> 1759410 | Z15: =SUM(Z16:Z20) -> 1759410 | AA15: =SUM(AA16:AA20) -> 1759410 | AB15: =SUM(AB16:AB20) -> 1759410 | AC15: =SUM(AC16:AC20) -> 1759410 | ... AG15: =SUM(AG16:AG20) -> 1759410 | AH15: =SUM(V15:AG15) -> 22016920 | AI15: =IF(AH15=0,"",AH15/AH$3) -> 0.56850868
C16: 人件費 | D16: =コーリングサポ!E54 -> 0 | E16: =コーリングサポ!F54 -> 0 | F16: =コーリングサポ!G54 -> 0 | G16: =コーリングサポ!H54 -> 0 | H16: =コーリングサポ!I54 -> 33000 | I16: =コーリングサポ!J54 -> 33000 | J16: =コーリングサポ!K54 -> 159000 | K16: =コーリングサポ!L54 -> 1127000 | ... O16: =コーリングサポ!P54 -> 1083000 | P16: =SUM(D16:O16) -> 5746000 | Q16: =IF(P16=0,"",P16/$P$3) -> 1.0096644 | U16: 人件費 | V16: =コーリングサポ!R54 -> 1457000 | W16: =コーリングサポ!S54 -> 1457000 | X16: =コーリングサポ!T54 -> 1457000 | Y16: =コーリングサポ!U54 -> 1457000 | Z16: =コーリングサポ!V54 -> 1457000 | AA16: =コーリングサポ!W54 -> 1457000 | AB16: =コーリングサポ!X54 -> 1457000 | AC16: =コーリングサポ!Y54 -> 1457000 | ... AG16: =コーリングサポ!AC54 -> 1457000 | AH16: =SUM(V16:AG16) -> 18284000 | AI16: =IF(AH16=0,"",AH16/AH$3) -> 0.4721193
C17: 社会保険料 | D17: =コーリングサポ!E55 -> 0 | E17: =コーリングサポ!F55 -> 0 | F17: =コーリングサポ!G55 -> 0 | G17: =コーリングサポ!H55 -> 0 | H17: =コーリングサポ!I55 -> 3300 | I17: =コーリングサポ!J55 -> 3300 | J17: =コーリングサポ!K55 -> 20670 | K17: =コーリングサポ!L55 -> 146510 | ... O17: =コーリングサポ!P55 -> 140790 | P17: =SUM(D17:O17) -> 745000 | Q17: =IF(P17=0,"",P17/$P$3) -> 0.13090845 | U17: 社会保険料 | V17: =コーリングサポ!R55 -> 189410 | W17: =コーリングサポ!S55 -> 189410 | X17: =コーリングサポ!T55 -> 189410 | Y17: =コーリングサポ!U55 -> 189410 | Z17: =コーリングサポ!V55 -> 189410 | AA17: =コーリングサポ!W55 -> 189410 | AB17: =コーリングサポ!X55 -> 189410 | AC17: =コーリングサポ!Y55 -> 189410 | ... AG17: =コーリングサポ!AC55 -> 189410 | AH17: =SUM(V17:AG17) -> 2376920 | AI17: =IF(AH17=0,"",AH17/AH$3) -> 0.061375508
C18: 管理費（家賃水道光熱燃料等） | D18: =コーリングサポ!E62 -> 0 | E18: =コーリングサポ!F62 -> 0 | F18: =コーリングサポ!G62 -> 0 | G18: =コーリングサポ!H62 -> 0 | H18: =コーリングサポ!I62 -> 0 | I18: =コーリングサポ!J62 -> 72000 | J18: =コーリングサポ!K62 -> 108000 | K18: =コーリングサポ!L62 -> 113000 | ... O18: =コーリングサポ!P62 -> 113000 | P18: =SUM(D18:O18) -> 745000 | Q18: =IF(P18=0,"",P18/$P$3) -> 0.13090845 | U18: 管理費（水道光熱燃料等） | V18: =コーリングサポ!R62 -> 113000 | W18: =コーリングサポ!S62 -> 113000 | X18: =コーリングサポ!T62 -> 113000 | Y18: =コーリングサポ!U62 -> 113000 | Z18: =コーリングサポ!V62 -> 113000 | AA18: =コーリングサポ!W62 -> 113000 | AB18: =コーリングサポ!X62 -> 113000 | AC18: =コーリングサポ!Y62 -> 113000 | ... AG18: =コーリングサポ!AC62 -> 113000 | AH18: =SUM(V18:AG18) -> 1356000 | AI18: =IF(AH18=0,"",AH18/AH$3) -> 0.035013879
C19: 燃料代 | Q19: =IF(P19=0,"",P19/$P$3) | U19: 燃料代 | AH19: =SUM(V19:AG19) -> 0 | AI19: =IF(AH19=0,"",AH19/AH$3)
C20: 諸費 | Q20: =IF(P20=0,"",P20/$P$3) | U20: 諸費 | AH20: =SUM(V20:AG20) -> 0 | AI20: =IF(AH20=0,"",AH20/AH$3)
B21: 福祉的就労 | D21: =SUM(D22:D25) -> 0 | E21: =SUM(E22:E25) -> 0 | F21: =SUM(F22:F25) -> 0 | G21: =SUM(G22:G25) -> 0 | H21: =SUM(H22:H25) -> 0 | I21: =SUM(I22:I25) -> 0 | J21: =SUM(J22:J25) -> 0 | K21: =SUM(K22:K25) -> 0 | ... O21: =SUM(O22:O25) -> 0 | P21: =SUM(D21:O21) -> 0 | Q21: =IF(P21=0,"",P21/$P$3) | T21: 福祉的就労 | V21: =SUM(V22:V25) -> 0 | W21: =SUM(W22:W25) -> 0 | X21: =SUM(X22:X25) -> 0 | Y21: =SUM(Y22:Y25) -> 0 | Z21: =SUM(Z22:Z25) -> 0 | AA21: =SUM(AA22:AA25) -> 0 | AB21: =SUM(AB22:AB25) -> 0 | AC21: =SUM(AC22:AC25) -> 0 | ... AG21: =SUM(AG22:AG25) -> 0 | AH21: =SUM(V21:AG21) -> 0 | AI21: =IF(AH21=0,"",AH21/AH$3)
C22: 工賃 | P22: =SUM(D22:O22) -> 0 | Q22: =IF(P22=0,"",P22/$P$3) | U22: 工賃 | V22: =V9 -> 0 | W22: =W10+W11 -> 0 | X22: =X10+X11 -> 0 | Y22: =Y10+Y11 -> 0 | Z22: =Z10+Z11 -> 0 | AA22: =AA10+AA11 -> 0 | AB22: =AB10+AB11 -> 0 | AC22: =AC10+AC11 -> 0 | AD22: =AD10+AD11 -> 0 | ... AG22: =AG10+AG11 -> 0 | AH22: =SUM(V22:AG22) -> 0 | AI22: =IF(AH22=0,"",AH22/AH$3)
C23: 材料経費 | P23: =SUM(D23:O23) -> 0 | Q23: =IF(P23=0,"",P23/$P$3) | U23: 材料経費 | AH23: =SUM(V23:AG23) -> 0 | AI23: =IF(AH23=0,"",AH23/AH$3)
C24: 投資的費用 | P24: =SUM(D24:O24) -> 0 | Q24: =IF(P24=0,"",P24/$P$3) | U24: 投資的費用 | AH24: =SUM(V24:AG24) -> 0 | AI24: =IF(AH24=0,"",AH24/AH$3)
P25: =SUM(D25:O25) -> 0 | Q25: =IF(P25=0,"",P25/$P$3) | AH25: =SUM(V25:AG25) -> 0 | AI25: =IF(AH25=0,"",AH25/AH$3)
A26: （売上総利益） | D26: =D3-D14 -> 0 | E26: =E3-E14 -> 0 | F26: =F3-F14 -> 0 | G26: =G3-G14 -> 0 | H26: =H3-H14 -> -36300 | I26: =I3-I14 -> -108300 | J26: =J3-J14 -> -287670 | K26: =K3-K14 -> -771310 | ... O26: =O3-O14 -> 592910 | P26: =SUM(D26:O26) -> -1545000 | Q26: =IF(P26=0,"",P26/$P$3) -> -0.27148129 | T26: （売上総利益） | V26: =V3-V14 -> 198290 | W26: =W3-W14 -> 365990 | X26: =X3-X14 -> 1163090 | Y26: =Y3-Y14 -> 1470690 | Z26: =Z3-Z14 -> 1736590 | AA26: =AA3-AA14 -> 1911290 | AB26: =AB3-AB14 -> 1911290 | AC26: =AC3-AC14 -> 1911290 | ... AG26: =AG3-AG14 -> 2260890 | AH26: =SUM(V26:AG26) -> 16710580 | AI26: =IF(AH26=0,"",AH26/AH$3) -> 0.43149132
A27: （販管費） | D27: =SUM(D28:D35) -> 0 | E27: =SUM(E28:E35) -> 0 | F27: =SUM(F28:F35) -> 0 | G27: =SUM(G28:G35) -> 215200 | H27: =SUM(H28:H35) -> 275200 | I27: =SUM(I28:I35) -> 275200 | J27: =SUM(J28:J35) -> 275200 | K27: =SUM(K28:K35) -> 366400 | ... O27: =SUM(O28:O35) -> 366400 | P27: =SUM(D27:O27) -> 2872800 | Q27: =IF(P27=0,"",P27/$P$3) -> 0.50479705 | T27: （販管費） | V27: =SUM(V28:V35) -> 513500 | W27: =SUM(W28:W35) -> 513500 | X27: =SUM(X28:X35) -> 513500 | Y27: =SUM(Y28:Y35) -> 513500 | Z27: =SUM(Z28:Z35) -> 513500 | AA27: =SUM(AA28:AA35) -> 513500 | AB27: =SUM(AB28:AB35) -> 513500 | AC27: =SUM(AC28:AC35) -> 513500 | ... AG27: =SUM(AG28:AG35) -> 513500 | AH27: =SUM(V27:AG27) -> 6162000 | AI27: =IF(AH27=0,"",AH27/AH$3) -> 0.15911174
C28: 役員報酬（代表） | G28: 180000 | H28: 180000 | I28: 180000 | J28: 180000 | K28: 180000 | L28: 180000 | M28: 180000 | N28: 180000 | O28: 180000 | P28: =SUM(D28:O28) -> 1620000 | Q28: =IF(P28=0,"",P28/$P$3) -> 0.28465999 | U28: 役員報酬 | V28: 300000 | W28: 300000 | X28: 300000 | Y28: 300000 | Z28: 300000 | AA28: 300000 | AB28: 300000 | AC28: 300000 | AD28: 300000 | AE28: 300000 | AF28: 300000 | AG28: 300000 | AH28: =SUM(V28:AG28) -> 3600000 | AI28: =IF(AH28=0,"",AH28/AH$3) -> 0.092957201
C29: 他役員 | K29: 80000 | L29: 80000 | M29: 80000 | N29: 80000 | O29: 80000 | P29: =SUM(D29:O29) -> 400000 | Q29: =IF(P29=0,"",P29/$P$3) -> 0.070286417 | U29: 給料手当 | V29: 80000 | W29: 80000 | X29: 80000 | Y29: 80000 | Z29: 80000 | AA29: 80000 | AB29: 80000 | AC29: 80000 | AD29: 80000 | AE29: 80000 | AF29: 80000 | AG29: 80000 | AH29: =SUM(V29:AG29) -> 960000 | AI29: =IF(AH29=0,"",AH29/AH$3) -> 0.024788587
C30: 法定福利費 | D30: =(D28+D29)*0.1 -> 0 | E30: =(E28+E29)*0.1 -> 0 | F30: =(F28+F29)*0.1 -> 0 | G30: =(G28+G29)*0.14 -> 25200 | H30: =(H28+H29)*0.14 -> 25200 | I30: =(I28+I29)*0.14 -> 25200 | J30: =(J28+J29)*0.14 -> 25200 | K30: =(K28+K29)*0.14 -> 36400 | L30: =(L28+L29)*0.14 -> 36400 | M30: =(M28+M29)*0.14 -> 36400 | N30: =(N28+N29)*0.14 -> 36400 | O30: =(O28+O29)*0.14 -> 36400 | P30: =SUM(D30:O30) -> 282800 | Q30: =IF(P30=0,"",P30/$P$3) -> 0.049692497 | U30: 法定福利費 | V30: =(V28)*0.145 -> 43500 | W30: =(W28)*0.145 -> 43500 | X30: =(X28)*0.145 -> 43500 | Y30: =(Y28)*0.145 -> 43500 | Z30: =(Z28)*0.145 -> 43500 | AA30: =(AA28)*0.145 -> 43500 | AB30: =(AB28)*0.145 -> 43500 | AC30: =(AC28)*0.145 -> 43500 | ... AG30: =(AG28)*0.145 -> 43500 | AH30: =SUM(V30:AG30) -> 522000 | AI30: =IF(AH30=0,"",AH30/AH$3) -> 0.013478794
C31: 諸経費 | H31: 30000 | I31: 30000 | J31: 30000 | K31: 30000 | L31: 30000 | M31: 30000 | N31: 30000 | O31: 30000 | P31: =SUM(D31:O31) -> 240000 | Q31: =IF(P31=0,"",P31/$P$3) -> 0.04217185 | U31: 諸経費 | V31: 30000 | W31: =V31 -> 30000 | X31: =W31 -> 30000 | Y31: =X31 -> 30000 | Z31: =Y31 -> 30000 | AA31: =Z31 -> 30000 | AB31: =AA31 -> 30000 | AC31: =AB31 -> 30000 | AD31: =AC31 -> 30000 | ... AG31: =AF31 -> 30000 | AH31: =SUM(V31:AG31) -> 360000 | AI31: =IF(AH31=0,"",AH31/AH$3) -> 0.0092957201
C32: 本部管理費 | H32: 30000 | I32: 30000 | J32: 30000 | K32: 30000 | L32: 30000 | M32: 30000 | N32: 30000 | O32: 30000 | P32: =SUM(D32:O32) -> 240000 | Q32: =IF(P32=0,"",P32/$P$3) -> 0.04217185 | U32: 本部管理費 | V32: 50000 | W32: =V32 -> 50000 | X32: =W32 -> 50000 | Y32: =X32 -> 50000 | Z32: =Y32 -> 50000 | AA32: =Z32 -> 50000 | AB32: =AA32 -> 50000 | AC32: =AB32 -> 50000 | AD32: =AC32 -> 50000 | ... AG32: =AF32 -> 50000 | AH32: =SUM(V32:AG32) -> 600000 | AI32: =IF(AH32=0,"",AH32/AH$3) -> 0.015492867
C33: システム管理費 | P33: =SUM(D33:O33) -> 0 | Q33: =IF(P33=0,"",P33/$P$3) | U33: リース料 | AH33: =SUM(V33:AG33) -> 0 | AI33: =IF(AH33=0,"",AH33/AH$3)
C34: 地代家賃 | G34: 10000 | H34: 10000 | I34: 10000 | J34: 10000 | K34: 10000 | L34: 10000 | M34: 10000 | N34: 10000 | O34: 10000 | P34: =SUM(D34:O34) -> 90000 | Q34: =IF(P34=0,"",P34/$P$3) -> 0.015814444 | U34: 地代家賃 | V34: 10000 | W34: 10000 | X34: 10000 | Y34: 10000 | Z34: 10000 | AA34: 10000 | AB34: 10000 | AC34: 10000 | AD34: 10000 | AE34: 10000 | AF34: 10000 | AG34: 10000 | AH34: =SUM(V34:AG34) -> 120000 | AI34: =IF(AH34=0,"",AH34/AH$3) -> 0.0030985734
C35: 減価償却 | P35: =SUM(D35:O35) -> 0 | Q35: =IF(P35=0,"",P35/$P$3) | U35: 減価償却 | V35: =$P$35/10 -> 0 | W35: =$P$35/10 -> 0 | X35: =$P$35/10 -> 0 | Y35: =$P$35/10 -> 0 | Z35: =$P$35/10 -> 0 | AA35: =$P$35/10 -> 0 | AB35: =$P$35/10 -> 0 | AC35: =$P$35/10 -> 0 | ... AG35: =$P$35/10 -> 0 | AH35: =SUM(V35:AG35) -> 0 | AI35: =IF(AH35=0,"",AH35/AH$3)
A36: （営業利益） | D36: =D26-D27 -> 0 | E36: =E26-E27 -> 0 | F36: =F26-F27 -> 0 | G36: =G26-G27 -> -215200 | H36: =H26-H27 -> -311500 | I36: =I26-I27 -> -383500 | J36: =J26-J27 -> -562870 | K36: =K26-K27 -> -1137710 | ... O36: =O26-O27 -> 226510 | P36: =SUM(D36:O36) -> -4417800 | Q36: =IF(P36=0,"",P36/$P$3) -> -0.77627833 | T36: （営業利益） | V36: =V26-V27 -> -315210 | W36: =W26-W27 -> -147510 | X36: =X26-X27 -> 649590 | Y36: =Y26-Y27 -> 957190 | Z36: =Z26-Z27 -> 1223090 | AA36: =AA26-AA27 -> 1397790 | AB36: =AB26-AB27 -> 1397790 | AC36: =AC26-AC27 -> 1397790 | ... AG36: =AG26-AG27 -> 1747390 | AH36: =SUM(V36:AG36) -> 10548580 | AI36: =IF(AH36=0,"",AH36/AH$3) -> 0.27237958
A37: （営業外収益） | P37: =SUM(D37:O37) -> 0 | Q37: =IF(P37=0,"",P37/$P$3) | T37: （営業外収益） | AH37: =SUM(V37:AG37) -> 0 | AI37: =IF(AH37=0,"",AH37/AH$3)
A38: （営業外損失） | D38: =SUM(D39:D40) -> 0 | E38: =SUM(E39:E40) -> 0 | F38: =SUM(F39:F40) -> 0 | G38: =SUM(G39:G40) -> 0 | H38: =SUM(H39:H40) -> 0 | I38: =SUM(I39:I40) -> 0 | J38: =SUM(J39:J40) -> 0 | K38: =SUM(K39:K40) -> 0 | ... O38: =SUM(O39:O40) -> 0 | P38: =SUM(D38:O38) -> 0 | Q38: =IF(P38=0,"",P38/$P$3) | T38: （営業外損失） | V38: =SUM(V39:V40) -> 0 | W38: =SUM(W39:W40) -> 0 | X38: =SUM(X39:X40) -> 0 | Y38: =SUM(Y39:Y40) -> 0 | Z38: =SUM(Z39:Z40) -> 0 | AA38: =SUM(AA39:AA40) -> 0 | AB38: =SUM(AB39:AB40) -> 0 | AC38: =SUM(AC39:AC40) -> 0 | ... AG38: =SUM(AG39:AG40) -> 0 | AH38: =SUM(V38:AG38) -> 0 | AI38: =IF(AH38=0,"",AH38/AH$3)
C39: 支払利息 | P39: =SUM(D39:O39) -> 0 | Q39: =IF(P39=0,"",P39/$P$3) | U39: 支払利息 | AH39: =SUM(V39:AG39) -> 0 | AI39: =IF(AH39=0,"",AH39/AH$3)
C40: 雑損失 | P40: =SUM(D40:O40) -> 0 | Q40: =IF(P40=0,"",P40/$P$3) | U40: 雑損失 | AH40: =SUM(V40:AG40) -> 0 | AI40: =IF(AH40=0,"",AH40/AH$3)
...

Sheet 表紙
A7: コーリングサポ笠岡 事業計画 及び 資産状況

Sheet 事業計画書
E3: 事 業 計 画 書
D6: サービスの種類 | I6: （ 就労継続支援事業（Ｂ型） | W6: ）
D7: 事業所又は施設名 | I7: （シェル | W7: ）
D9: 項目 | O9: 内容
C11: 1 事業の内容
L12: 障害者の日常生活及び社会生活を総合的に支援するための法律に規定される「就労継続支援事業（Ｂ型）」を、下記業務を通じて適切に実施する。
L15: （１）就労継続支援Ｂ型計画の作成 （２）食事の提供 （３）身体等の介護 （４）就労に必要な知識、能力を向上するための訓練 （５）就労の機会の提供及び生産活動 （６）実習先企業等の紹介 （７）求職活動支援 （８）職場定着支援 （９）生活相談 （１０）健康管理 （１１）訪問支援 （１２）送迎サービス （１３）施設外支援の実施 （１４）施設外就労の実施 （１５）前各号に掲げる便宜に附帯する便宜 （２）から（１４）に附帯するその他必要な介護、訓練、支援、相談、助言。
L22: 就労業務としては、パソコンを使ったデータ入力業務、地域新聞作成業務、慰労演劇業務、畑作支援業務を準備している。
C25: ２ 事業実施の予定時期 | L25: 平成29年3月1日
C27: ３ 従業者等の予定人員
L28: （１） | M28: 管理者 1名
L29: （２） | M29: サービス管理責任者 １名（管理者と兼務）
L30: （３） | M30: 従業者 ３名
M31: （うち、常勤職員３名）
C33: ４ 利用者の推定数及び 通常の事業地域内外比率
L34: （１） | M34: 利用者の推定数
M35: 通常の事業の実施地域及び近隣地域からの利用
M36: ２０名
L37: （２） | M37: 通常の事業の実施地域内外の利用者比率（見込み）
M38: ＜笠岡市＞ | P38: ９０％
M39: ＜福山市＞ | P39: １０％

Sheet 財産目録
E3: 財 産 目 録
D6: サービスの種類 | I6: （ 就労継続支援事業Ｂ型 | W6: ）
A7: カイト今治 事業計画 及び 資産状況 | D7: 事業所又は施設名 | I7: （ シェル | W7: ）
C10: Ⅰ 資産の部 | W10: 円
E11: １ 基本財産（ 固定性項目 ）
F12: （ 内 訳 ）
F13: （ １ ） | H13: 車両 | W13: 円
F14: （ ２ ） | H14: その他 | P14: ０ | W14: 円
E15: ２ 運用財産（ 流動性項目 ）
F16: （ 内 訳 ）
F17: （ １ ） | H17: 現金・預金 | P17: １，５００，０００ | W17: 円
