Workbook

Sheet 事業評価【A案・税引前】
E1: 1 | F1: 2 | G1: 3 | H1: 4 | I1: 5 | J1: 6 | K1: 7 | L1: 8 | M1: 9
B2: 企業価値A案（税引前） | M2: 【千円】
D3: H23年度 | E3: H24年度 | F3: H25年度 | G3: H26年度 | H3: H27年度 | I3: H28年度 | J3: H29年度 | K3: H30年度 | L3: H31年度 | M3: H32年度
B4: 前年度繰越 | D4: 0 | E4: =D40 -> #REF! | F4: =E40 -> #REF! | G4: =F40 -> #REF! | H4: =G40 -> #REF! | I4: =H40 -> #REF! | J4: =I40 -> #REF! | K4: =J40 -> #REF! | L4: =K40 -> #REF! | M4: =L40 -> #REF!
B5: 経常収入 | D5: =SUM(基礎!D50:O50) -> 100000 | E5: =SUM(基礎!U50:AF50) -> 12207511 | F5: =SUM(基礎!AL50:AW50) -> 15790055 | G5: =SUM(基礎!BC50:BN50) -> 751036.8 | H5: =SUM(基礎!BT50:CE50) -> 352000 | I5: =SUM(基礎!CK50:CV50) -> 6000 | J5: =SUM(基礎!DB50:DM50) -> 0 | K5: =SUM(基礎!DS50:ED50) -> 0 | L5: =SUM(基礎!EJ50:EU50) -> 0 | M5: =SUM(基礎!FA50:FL50) -> 0
C6: 店舗現金売上 | D6: =SUM(基礎!D51:O51) -> 0 | E6: =SUM(基礎!U51:AF51) -> 11727511 | F6: =SUM(基礎!AL51:AW51) -> 15070055 | G6: =SUM(基礎!BC51:BN51) -> 281600 | H6: =SUM(基礎!BT51:CE51) -> 281600 | I6: =SUM(基礎!CK51:CV51) -> 0 | J6: =SUM(基礎!DB51:DM51) -> 0 | K6: =SUM(基礎!DS51:ED51) -> 0 | L6: =SUM(基礎!EJ51:EU51) -> 0 | M6: =SUM(基礎!FA51:FL51) -> 0
C7: 店舗催事売掛入金 | D7: =SUM(基礎!D52:O52) -> 0 | E7: =SUM(基礎!U52:AF52) -> 480000 | F7: =SUM(基礎!AL52:AW52) -> 720000 | G7: =SUM(基礎!BC52:BN52) -> 409436.8 | H7: =SUM(基礎!BT52:CE52) -> 70400 | I7: =SUM(基礎!CK52:CV52) -> 6000 | J7: =SUM(基礎!DB52:DM52) -> 0 | K7: =SUM(基礎!DS52:ED52) -> 0 | L7: =SUM(基礎!EJ52:EU52) -> 0 | M7: =SUM(基礎!FA52:FL52) -> 0
C8: FCロイヤリティ | D8: =SUM(基礎!D53:O53) -> 100000 | E8: =SUM(基礎!U53:AF53) -> 0 | F8: =SUM(基礎!AL53:AW53) -> 0 | G8: =SUM(基礎!BC53:BN53) -> 60000 | H8: =SUM(基礎!BT53:CE53) -> 0 | I8: =SUM(基礎!CK53:CV53) -> 0 | J8: =SUM(基礎!DB53:DM53) -> 0 | K8: =SUM(基礎!DS53:ED53) -> 0 | L8: =SUM(基礎!EJ53:EU53) -> 0 | M8: =SUM(基礎!FA53:FL53) -> 0
C9: 他収入 | D9: =SUM(基礎!D54:O54) -> 0 | E9: =SUM(基礎!U54:AF54) -> 0 | F9: =SUM(基礎!AL54:AW54) -> 0 | G9: =SUM(基礎!BC54:BN54) -> 0 | H9: =SUM(基礎!BT54:CE54) -> 0 | I9: =SUM(基礎!CK54:CV54) -> 0 | J9: =SUM(基礎!DB54:DM54) -> 0 | K9: =SUM(基礎!DS54:ED54) -> 0 | L9: =SUM(基礎!EJ54:EU54) -> 0 | M9: =SUM(基礎!FA54:FL54) -> 0
B10: 経常支出 | D10: =SUM(基礎!D55:O55) -> 0 | E10: =SUM(基礎!U55:AF55) -> 9628066.7 | F10: =SUM(基礎!AL55:AW55) -> 11109826 | G10: =SUM(基礎!BC55:BN55) -> 625120 | H10: =SUM(基礎!BT55:CE55) -> 393160 | I10: =SUM(基礎!CK55:CV55) -> #REF! | J10: =SUM(基礎!DB55:DM55) -> #REF! | K10: =SUM(基礎!DS55:ED55) -> #REF! | L10: =SUM(基礎!EJ55:EU55) -> #REF! | M10: =SUM(基礎!FA55:FL55) -> #REF!
C11: 店舗仕入買掛 | D11: =SUM(基礎!D56:O56) -> 0 | E11: =SUM(基礎!U56:AF56) -> 1052000 | F11: =SUM(基礎!AL56:AW56) -> 662000 | G11: =SUM(基礎!BC56:BN56) -> 80500 | H11: =SUM(基礎!BT56:CE56) -> 88000 | I11: =SUM(基礎!CK56:CV56) -> 7500 | J11: =SUM(基礎!DB56:DM56) -> 0 | K11: =SUM(基礎!DS56:ED56) -> 0 | L11: =SUM(基礎!EJ56:EU56) -> 0 | M11: =SUM(基礎!FA56:FL56) -> 0
C12: 店舗人件費 | D12: =SUM(基礎!D57:O57) -> 0 | E12: =SUM(基礎!U57:AF57) -> 8576066.7 | F12: =SUM(基礎!AL57:AW57) -> 10447826 | G12: =SUM(基礎!BC57:BN57) -> 352600 | H12: =SUM(基礎!BT57:CE57) -> 105600 | I12: =SUM(基礎!CK57:CV57) -> 9000 | J12: =SUM(基礎!DB57:DM57) -> 0 | K12: =SUM(基礎!DS57:ED57) -> 0 | L12: =SUM(基礎!EJ57:EU57) -> 0 | M12: =SUM(基礎!FA57:FL57) -> 0
C13: 販管費（ｻｲﾄ１） | D13: =SUM(基礎!D58:O58) -> 0 | E13: =SUM(基礎!U58:AF58) -> 0 | F13: =SUM(基礎!AL58:AW58) -> 0 | G13: =SUM(基礎!BC58:BN58) -> 192020 | H13: =SUM(基礎!BT58:CE58) -> 199560 | I13: =SUM(基礎!CK58:CV58) -> 335428 | J13: =SUM(基礎!DB58:DM58) -> #REF! | K13: =SUM(基礎!DS58:ED58) -> #REF! | L13: =SUM(基礎!EJ58:EU58) -> #REF! | M13: =SUM(基礎!FA58:FL58) -> #REF!
C14: 販管費（ｻｲﾄ２） | D14: =SUM(基礎!D59:O59) -> 0 | E14: =SUM(基礎!U59:AF59) -> 0 | F14: =SUM(基礎!AL59:AW59) -> 0 | G14: =SUM(基礎!BC59:BN59) -> 0 | H14: =SUM(基礎!BT59:CE59) -> 0 | I14: =SUM(基礎!CK59:CV59) -> 0 | J14: =SUM(基礎!DB59:DM59) -> 0 | K14: =SUM(基礎!DS59:ED59) -> 0 | L14: =SUM(基礎!EJ59:EU59) -> 0 | M14: =SUM(基礎!FA59:FL59) -> 0
C15: 支払利息 | D15: =SUM(基礎!D60:O60) -> 0 | E15: =SUM(基礎!U60:AF60) -> 0 | F15: =SUM(基礎!AL60:AW60) -> 0 | G15: =SUM(基礎!BC60:BN60) -> 0 | H15: =SUM(基礎!BT60:CE60) -> 0 | I15: =SUM(基礎!CK60:CV60) -> 0 | J15: =SUM(基礎!DB60:DM60) -> 0 | K15: =SUM(基礎!DS60:ED60) -> 0 | L15: =SUM(基礎!EJ60:EU60) -> 0 | M15: =SUM(基礎!FA60:FL60) -> 0
C16: 固定資産購入等 | D16: =SUM(基礎!D61:O61) -> 0 | E16: =SUM(基礎!U61:AF61) -> 0 | F16: =SUM(基礎!AL61:AW61) -> 0 | G16: =SUM(基礎!BC61:BN61) -> 0 | H16: =SUM(基礎!BT61:CE61) -> 0 | I16: =SUM(基礎!CK61:CV61) -> 0 | J16: =SUM(基礎!DB61:DM61) -> 0 | K16: =SUM(基礎!DS61:ED61) -> 0 | L16: =SUM(基礎!EJ61:EU61) -> 0 | M16: =SUM(基礎!FA61:FL61) -> 0
C17: 他支出 | D17: =SUM(基礎!D62:O62) -> 0 | E17: =SUM(基礎!U62:AF62) -> 0 | F17: =SUM(基礎!AL62:AW62) -> 0 | G17: =SUM(基礎!BC62:BN62) -> 0 | H17: =SUM(基礎!BT62:CE62) -> 0 | I17: =SUM(基礎!CK62:CV62) -> #REF! | J17: =SUM(基礎!DB62:DM62) -> #REF! | K17: =SUM(基礎!DS62:ED62) -> #REF! | L17: =SUM(基礎!EJ62:EU62) -> #REF! | M17: =SUM(基礎!FA62:FL62) -> #REF!
B18: 経常収支差額 | D18: =SUM(基礎!D63:O63) -> 100000 | E18: =SUM(基礎!U63:AF63) -> 2579444.1 | F18: =SUM(基礎!AL63:AW63) -> 4680229.2 | G18: =SUM(基礎!BC63:BN63) -> 125916.8 | H18: =SUM(基礎!BT63:CE63) -> -41160 | I18: =SUM(基礎!CK63:CV63) -> #REF! | J18: =SUM(基礎!DB63:DM63) -> #REF! | K18: =SUM(基礎!DS63:ED63) -> #REF! | L18: =SUM(基礎!EJ63:EU63) -> #REF! | M18: =SUM(基礎!FA63:FL63) -> #REF!
B19: 財務収入 | D19: =SUM(D20:D27) -> #REF! | E19: =SUM(基礎!U64:AF64) -> 0 | F19: =SUM(基礎!AL64:AW64) -> 0 | G19: =SUM(基礎!BC64:BN64) -> -120000000 | H19: =SUM(基礎!BT64:CE64) -> 0 | I19: =SUM(基礎!CK64:CV64) -> -26000 | J19: =SUM(基礎!DB64:DM64) -> 0 | K19: =SUM(基礎!DS64:ED64) -> 0 | L19: =SUM(基礎!EJ64:EU64) -> 0 | M19: =SUM(基礎!FA64:FL64) -> 0
C20: 資本金 | D20: 0 | E20: =SUM(基礎!U65:AF65) -> 0 | F20: =SUM(基礎!AL65:AW65) -> 0 | G20: =SUM(基礎!BC65:BN65) -> 0 | H20: =SUM(基礎!BT65:CE65) -> 0 | I20: =SUM(基礎!CK65:CV65) -> 0 | J20: =SUM(基礎!DB65:DM65) -> 0 | K20: =SUM(基礎!DS65:ED65) -> 0 | L20: =SUM(基礎!EJ65:EU65) -> 0 | M20: =SUM(基礎!FA65:FL65) -> 0
C21: 役員借入 | D21: =SUM(基礎!D66:O66) -> 0 | E21: =SUM(基礎!U66:AF66) -> 0 | F21: =SUM(基礎!AL66:AW66) -> 0 | G21: =SUM(基礎!BC66:BN66) -> 0 | H21: =SUM(基礎!BT66:CE66) -> 0 | I21: =SUM(基礎!CK66:CV66) -> -26000 | J21: =SUM(基礎!DB66:DM66) -> 0 | K21: =SUM(基礎!DS66:ED66) -> 0 | L21: =SUM(基礎!EJ66:EU66) -> 0 | M21: =SUM(基礎!FA66:FL66) -> 0
C22: 金融機関借入 | D22: =SUM(基礎!D67:O67) -> 0 | E22: =SUM(基礎!U67:AF67) -> 0 | F22: =SUM(基礎!AL67:AW67) -> 0 | G22: =SUM(基礎!BC67:BN67) -> 0 | H22: =SUM(基礎!BT67:CE67) -> 0 | I22: =SUM(基礎!CK67:CV67) -> 0 | J22: =SUM(基礎!DB67:DM67) -> 0 | K22: =SUM(基礎!DS67:ED67) -> 0 | L22: =SUM(基礎!EJ67:EU67) -> 0 | M22: =SUM(基礎!FA67:FL67) -> 0
C23: 固定資産売却 | D23: =SUM(基礎!D68:O68) -> 0 | E23: =SUM(基礎!U68:AF68) -> 0 | F23: =SUM(基礎!AL68:AW68) -> 0 | G23: =SUM(基礎!BC68:BN68) -> 0 | H23: =SUM(基礎!BT68:CE68) -> 0 | I23: =SUM(基礎!CK68:CV68) -> 0 | J23: =SUM(基礎!DB68:DM68) -> 0 | K23: =SUM(基礎!DS68:ED68) -> 0 | L23: =SUM(基礎!EJ68:EU68) -> 0 | M23: =SUM(基礎!FA68:FL68) -> 0
C24: FC保証金 | D24: =SUM(基礎!D69:O69) -> 0 | E24: =SUM(基礎!U69:AF69) -> 0 | F24: =SUM(基礎!AL69:AW69) -> 0 | G24: =SUM(基礎!BC69:BN69) -> -120000000 | H24: =SUM(基礎!BT69:CE69) -> 0 | I24: =SUM(基礎!CK69:CV69) -> 0 | J24: =SUM(基礎!DB69:DM69) -> 0 | K24: =SUM(基礎!DS69:ED69) -> 0 | L24: =SUM(基礎!EJ69:EU69) -> 0 | M24: =SUM(基礎!FA69:FL69) -> 0
C25: 地区本部保証金 | D25: =SUM(基礎!#REF!) -> #REF! | E25: =SUM(基礎!#REF!) -> #REF! | F25: =SUM(基礎!#REF!) -> #REF! | G25: =SUM(基礎!#REF!) -> #REF! | H25: =SUM(基礎!#REF!) -> #REF! | I25: =SUM(基礎!#REF!) -> #REF! | J25: =SUM(基礎!#REF!) -> #REF! | K25: =SUM(基礎!#REF!) -> #REF! | ... M25: =SUM(基礎!#REF!) -> #REF!
C26: 減価償却 | D26: =SUM(基礎!#REF!) -> #REF! | E26: =SUM(基礎!#REF!) -> #REF! | F26: =SUM(基礎!#REF!) -> #REF! | G26: =SUM(基礎!#REF!) -> #REF! | H26: =SUM(基礎!#REF!) -> #REF! | I26: =SUM(基礎!#REF!) -> #REF! | J26: =SUM(基礎!#REF!) -> #REF! | K26: =SUM(基礎!#REF!) -> #REF! | ... M26: =SUM(基礎!#REF!) -> #REF!
C27: その他 | D27: =SUM(基礎!#REF!) -> #REF! | E27: =SUM(基礎!#REF!) -> #REF! | F27: =SUM(基礎!#REF!) -> #REF! | G27: =SUM(基礎!#REF!) -> #REF! | H27: =SUM(基礎!#REF!) -> #REF! | I27: =SUM(基礎!#REF!) -> #REF! | J27: =SUM(基礎!#REF!) -> #REF! | K27: =SUM(基礎!#REF!) -> #REF! | ... M27: =SUM(基礎!#REF!) -> #REF!
B28: 財務支出 | D28: =SUM(D29:D35) -> #REF! | E28: =SUM(E29:E35) -> #REF! | F28: =SUM(F29:F35) -> #REF! | G28: =SUM(G29:G35) -> #REF! | H28: =SUM(H29:H35) -> #REF! | I28: =SUM(I29:I35) -> #REF! | J28: =SUM(J29:J35) -> #REF! | K28: =SUM(K29:K35) -> #REF! | ... N28: =SUM(N29:N35) -> 0
C29: 役員返済 | D29: 24000 | E29: 24000 | F29: 24000 | G29: 24000 | H29: 24000 | I29: 0 | J29: 0 | K29: 0 | L29: 0 | M29: 0
C30: 金融機関返済 | D30: =SUM(基礎!D72:O72) -> 0 | E30: =SUM(基礎!U72:AF72) -> 0 | F30: =SUM(基礎!AL72:AW72) -> 0 | G30: =SUM(基礎!BC72:BN72) -> 0 | H30: =SUM(基礎!BT72:CE72) -> 0 | I30: =SUM(基礎!CK72:CV72) -> 1112 | J30: =SUM(基礎!DB72:DM72) -> 0 | K30: =SUM(基礎!DS72:ED72) -> 0 | L30: =SUM(基礎!EJ72:EU72) -> 0 | M30: =SUM(基礎!FA72:FL72) -> 0
C31: FC保証金返却 | D31: =SUM(基礎!#REF!) -> #REF! | E31: =SUM(基礎!#REF!) -> #REF! | F31: =SUM(基礎!#REF!) -> #REF! | G31: =SUM(基礎!#REF!) -> #REF! | H31: =SUM(基礎!#REF!) -> #REF! | I31: =SUM(基礎!#REF!) -> #REF! | J31: =SUM(基礎!#REF!) -> #REF! | K31: =SUM(基礎!#REF!) -> #REF! | ... M31: =SUM(基礎!#REF!) -> #REF!
C32: 地区本部保証金返却 | D32: =SUM(基礎!#REF!) -> #REF! | E32: =SUM(基礎!#REF!) -> #REF! | F32: =SUM(基礎!#REF!) -> #REF! | G32: =SUM(基礎!#REF!) -> #REF! | H32: =SUM(基礎!#REF!) -> #REF! | I32: =SUM(基礎!#REF!) -> #REF! | J32: =SUM(基礎!#REF!) -> #REF! | K32: =SUM(基礎!#REF!) -> #REF! | ... M32: =SUM(基礎!#REF!) -> #REF!
C33: FC本部（システム等） | D33: =SUM(基礎!#REF!) -> #REF! | E33: =SUM(基礎!#REF!) -> #REF! | F33: =SUM(基礎!#REF!) -> #REF! | G33: =SUM(基礎!#REF!) -> #REF! | H33: =SUM(基礎!#REF!) -> #REF! | I33: =SUM(基礎!#REF!) -> #REF! | J33: =SUM(基礎!#REF!) -> #REF! | K33: =SUM(基礎!#REF!) -> #REF! | ... M33: =SUM(基礎!#REF!) -> #REF!
C34: 店舗出店コスト | D34: =SUM(基礎!#REF!) -> #REF! | E34: =SUM(基礎!#REF!) -> #REF! | F34: =SUM(基礎!#REF!) -> #REF! | G34: =SUM(基礎!#REF!) -> #REF! | H34: =SUM(基礎!#REF!) -> #REF! | I34: =SUM(基礎!#REF!) -> #REF! | J34: =SUM(基礎!#REF!) -> #REF! | K34: =SUM(基礎!#REF!) -> #REF! | ... M34: =SUM(基礎!#REF!) -> #REF!
C35: その他 | D35: =SUM(基礎!D73:O73) -> 0 | E35: =SUM(基礎!U73:AF73) -> 0 | F35: =SUM(基礎!AL73:AW73) -> 0 | G35: =SUM(基礎!BC73:BN73) -> 0 | H35: =SUM(基礎!BT73:CE73) -> 0 | I35: =SUM(基礎!CK73:CV73) -> 0 | J35: =SUM(基礎!DB73:DM73) -> 0 | K35: =SUM(基礎!DS73:ED73) -> 0 | L35: =SUM(基礎!EJ73:EU73) -> 0 | M35: =SUM(基礎!FA73:FL73) -> 0
B36: 財務収支差額 | D36: =D19-D28 -> #REF! | E36: =E19-E28 -> #REF! | F36: =F19-F28 -> #REF! | G36: =G19-G28 -> #REF! | H36: =H19-H28 -> #REF! | I36: =I19-I28 -> #REF! | J36: =J19-J28 -> #REF! | K36: =K19-K28 -> #REF! | ... M36: =M19-M28 -> #REF!
B37: CF | D37: =D18+D36 -> #REF! | E37: =E18+E36 -> #REF! | F37: =F18+F36 -> #REF! | G37: =G18+G36 -> #REF! | H37: =H18+H36 -> #REF! | I37: =I18+I36 -> #REF! | J37: =J18+J36 -> #REF! | K37: =K18+K36 -> #REF! | ... M37: =M18+M36 -> #REF!
B38: 税金 | D38: =PL!D44 -> 40000 | E38: =PL!E44 -> 2707115.4 | F38: =PL!F44 -> 2553539.4 | G38: =PL!G44 -> -20160 | H38: =PL!H44 -> -25344 | I38: =PL!I44 -> #REF! | J38: =PL!J44 -> #REF! | K38: =PL!K44 -> #REF! | ... M38: =PL!M44 -> #REF!
B39: 税引後CF | D39: =D37-D38 -> #REF! | E39: =E37-E38 -> #REF! | F39: =F37-F38 -> #REF! | G39: =G37-G38 -> #REF! | H39: =H37-H38 -> #REF! | I39: =I37-I38 -> #REF! | J39: =J37-J38 -> #REF! | K39: =K37-K38 -> #REF! | ... M39: =M37-M38 -> #REF!
B40: 翌年度繰越 | D40: =D4+D39 -> #REF! | E40: =E4+E39 -> #REF! | F40: =F4+F39 -> #REF! | G40: =G4+G39 -> #REF! | H40: =H4+H39 -> #REF! | I40: =I4+I39 -> #REF! | J40: =J4+J39 -> #REF! | K40: =K4+K39 -> #REF! | ... M40: =M4+M39 -> #REF!
...

Sheet 事業評価【A案・税引後】
E1: 1 | F1: 2 | G1: 3 | H1: 4 | I1: 5 | J1: 6 | K1: 7 | L1: 8 | M1: 9
B2: 企業価値A案（税引後） | M2: 【千円】
D3: H23年度 | E3: H24年度 | F3: H25年度 | G3: H26年度 | H3: H27年度 | I3: H28年度 | J3: H29年度 | K3: H30年度 | L3: H31年度 | M3: H32年度
B4: 前年度繰越 | D4: 0 | E4: =D40 -> #REF! | F4: =E40 -> #REF! | G4: =F40 -> #REF! | H4: =G40 -> #REF! | I4: =H40 -> #REF! | J4: =I40 -> #REF! | K4: =J40 -> #REF! | L4: =K40 -> #REF! | M4: =L40 -> #REF!
B5: 経常収入 | D5: =SUM(基礎!D50:O50) -> 100000 | E5: =SUM(基礎!U50:AF50) -> 12207511 | F5: =SUM(基礎!AL50:AW50) -> 15790055 | G5: =SUM(基礎!BC50:BN50) -> 751036.8 | H5: =SUM(基礎!BT50:CE50) -> 352000 | I5: =SUM(基礎!CK50:CV50) -> 6000 | J5: =SUM(基礎!DB50:DM50) -> 0 | K5: =SUM(基礎!DS50:ED50) -> 0 | L5: =SUM(基礎!EJ50:EU50) -> 0 | M5: =SUM(基礎!FA50:FL50) -> 0
C6: 店舗現金売上 | D6: =SUM(基礎!D51:O51) -> 0 | E6: =SUM(基礎!U51:AF51) -> 11727511 | F6: =SUM(基礎!AL51:AW51) -> 15070055 | G6: =SUM(基礎!BC51:BN51) -> 281600 | H6: =SUM(基礎!BT51:CE51) -> 281600 | I6: =SUM(基礎!CK51:CV51) -> 0 | J6: =SUM(基礎!DB51:DM51) -> 0 | K6: =SUM(基礎!DS51:ED51) -> 0 | L6: =SUM(基礎!EJ51:EU51) -> 0 | M6: =SUM(基礎!FA51:FL51) -> 0
C7: 店舗催事売掛入金 | D7: =SUM(基礎!D52:O52) -> 0 | E7: =SUM(基礎!U52:AF52) -> 480000 | F7: =SUM(基礎!AL52:AW52) -> 720000 | G7: =SUM(基礎!BC52:BN52) -> 409436.8 | H7: =SUM(基礎!BT52:CE52) -> 70400 | I7: =SUM(基礎!CK52:CV52) -> 6000 | J7: =SUM(基礎!DB52:DM52) -> 0 | K7: =SUM(基礎!DS52:ED52) -> 0 | L7: =SUM(基礎!EJ52:EU52) -> 0 | M7: =SUM(基礎!FA52:FL52) -> 0
C8: FCロイヤリティ | D8: =SUM(基礎!D53:O53) -> 100000 | E8: =SUM(基礎!U53:AF53) -> 0 | F8: =SUM(基礎!AL53:AW53) -> 0 | G8: =SUM(基礎!BC53:BN53) -> 60000 | H8: =SUM(基礎!BT53:CE53) -> 0 | I8: =SUM(基礎!CK53:CV53) -> 0 | J8: =SUM(基礎!DB53:DM53) -> 0 | K8: =SUM(基礎!DS53:ED53) -> 0 | L8: =SUM(基礎!EJ53:EU53) -> 0 | M8: =SUM(基礎!FA53:FL53) -> 0
C9: 他収入 | D9: =SUM(基礎!D54:O54) -> 0 | E9: =SUM(基礎!U54:AF54) -> 0 | F9: =SUM(基礎!AL54:AW54) -> 0 | G9: =SUM(基礎!BC54:BN54) -> 0 | H9: =SUM(基礎!BT54:CE54) -> 0 | I9: =SUM(基礎!CK54:CV54) -> 0 | J9: =SUM(基礎!DB54:DM54) -> 0 | K9: =SUM(基礎!DS54:ED54) -> 0 | L9: =SUM(基礎!EJ54:EU54) -> 0 | M9: =SUM(基礎!FA54:FL54) -> 0
B10: 経常支出 | D10: =SUM(基礎!D55:O55) -> 0 | E10: =SUM(基礎!U55:AF55) -> 9628066.7 | F10: =SUM(基礎!AL55:AW55) -> 11109826 | G10: =SUM(基礎!BC55:BN55) -> 625120 | H10: =SUM(基礎!BT55:CE55) -> 393160 | I10: =SUM(基礎!CK55:CV55) -> #REF! | J10: =SUM(基礎!DB55:DM55) -> #REF! | K10: =SUM(基礎!DS55:ED55) -> #REF! | L10: =SUM(基礎!EJ55:EU55) -> #REF! | M10: =SUM(基礎!FA55:FL55) -> #REF!
C11: 店舗仕入買掛 | D11: =SUM(基礎!D56:O56) -> 0 | E11: =SUM(基礎!U56:AF56) -> 1052000 | F11: =SUM(基礎!AL56:AW56) -> 662000 | G11: =SUM(基礎!BC56:BN56) -> 80500 | H11: =SUM(基礎!BT56:CE56) -> 88000 | I11: =SUM(基礎!CK56:CV56) -> 7500 | J11: =SUM(基礎!DB56:DM56) -> 0 | K11: =SUM(基礎!DS56:ED56) -> 0 | L11: =SUM(基礎!EJ56:EU56) -> 0 | M11: =SUM(基礎!FA56:FL56) -> 0
C12: 店舗人件費 | D12: =SUM(基礎!D57:O57) -> 0 | E12: =SUM(基礎!U57:AF57) -> 8576066.7 | F12: =SUM(基礎!AL57:AW57) -> 10447826 | G12: =SUM(基礎!BC57:BN57) -> 352600 | H12: =SUM(基礎!BT57:CE57) -> 105600 | I12: =SUM(基礎!CK57:CV57) -> 9000 | J12: =SUM(基礎!DB57:DM57) -> 0 | K12: =SUM(基礎!DS57:ED57) -> 0 | L12: =SUM(基礎!EJ57:EU57) -> 0 | M12: =SUM(基礎!FA57:FL57) -> 0
C13: 販管費（ｻｲﾄ１） | D13: =SUM(基礎!D58:O58) -> 0 | E13: =SUM(基礎!U58:AF58) -> 0 | F13: =SUM(基礎!AL58:AW58) -> 0 | G13: =SUM(基礎!BC58:BN58) -> 192020 | H13: =SUM(基礎!BT58:CE58) -> 199560 | I13: =SUM(基礎!CK58:CV58) -> 335428 | J13: =SUM(基礎!DB58:DM58) -> #REF! | K13: =SUM(基礎!DS58:ED58) -> #REF! | L13: =SUM(基礎!EJ58:EU58) -> #REF! | M13: =SUM(基礎!FA58:FL58) -> #REF!
C14: 販管費（ｻｲﾄ２） | D14: =SUM(基礎!D59:O59) -> 0 | E14: =SUM(基礎!U59:AF59) -> 0 | F14: =SUM(基礎!AL59:AW59) -> 0 | G14: =SUM(基礎!BC59:BN59) -> 0 | H14: =SUM(基礎!BT59:CE59) -> 0 | I14: =SUM(基礎!CK59:CV59) -> 0 | J14: =SUM(基礎!DB59:DM59) -> 0 | K14: =SUM(基礎!DS59:ED59) -> 0 | L14: =SUM(基礎!EJ59:EU59) -> 0 | M14: =SUM(基礎!FA59:FL59) -> 0
C15: 支払利息 | D15: =SUM(基礎!D60:O60) -> 0 | E15: =SUM(基礎!U60:AF60) -> 0 | F15: =SUM(基礎!AL60:AW60) -> 0 | G15: =SUM(基礎!BC60:BN60) -> 0 | H15: =SUM(基礎!BT60:CE60) -> 0 | I15: =SUM(基礎!CK60:CV60) -> 0 | J15: =SUM(基礎!DB60:DM60) -> 0 | K15: =SUM(基礎!DS60:ED60) -> 0 | L15: =SUM(基礎!EJ60:EU60) -> 0 | M15: =SUM(基礎!FA60:FL60) -> 0
C16: 固定資産購入等 | D16: =SUM(基礎!D61:O61) -> 0 | E16: =SUM(基礎!U61:AF61) -> 0 | F16: =SUM(基礎!AL61:AW61) -> 0 | G16: =SUM(基礎!BC61:BN61) -> 0 | H16: =SUM(基礎!BT61:CE61) -> 0 | I16: =SUM(基礎!CK61:CV61) -> 0 | J16: =SUM(基礎!DB61:DM61) -> 0 | K16: =SUM(基礎!DS61:ED61) -> 0 | L16: =SUM(基礎!EJ61:EU61) -> 0 | M16: =SUM(基礎!FA61:FL61) -> 0
C17: 他支出 | D17: =SUM(基礎!D62:O62) -> 0 | E17: =SUM(基礎!U62:AF62) -> 0 | F17: =SUM(基礎!AL62:AW62) -> 0 | G17: =SUM(基礎!BC62:BN62) -> 0 | H17: =SUM(基礎!BT62:CE62) -> 0 | I17: =SUM(基礎!CK62:CV62) -> #REF! | J17: =SUM(基礎!DB62:DM62) -> #REF! | K17: =SUM(基礎!DS62:ED62) -> #REF! | L17: =SUM(基礎!EJ62:EU62) -> #REF! | M17: =SUM(基礎!FA62:FL62) -> #REF!
B18: 経常収支差額 | D18: =SUM(基礎!D63:O63) -> 100000 | E18: =SUM(基礎!U63:AF63) -> 2579444.1 | F18: =SUM(基礎!AL63:AW63) -> 4680229.2 | G18: =SUM(基礎!BC63:BN63) -> 125916.8 | H18: =SUM(基礎!BT63:CE63) -> -41160 | I18: =SUM(基礎!CK63:CV63) -> #REF! | J18: =SUM(基礎!DB63:DM63) -> #REF! | K18: =SUM(基礎!DS63:ED63) -> #REF! | L18: =SUM(基礎!EJ63:EU63) -> #REF! | M18: =SUM(基礎!FA63:FL63) -> #REF!
B19: 財務収入 | D19: =SUM(D20:D27) -> #REF! | E19: =SUM(基礎!U64:AF64) -> 0 | F19: =SUM(基礎!AL64:AW64) -> 0 | G19: =SUM(基礎!BC64:BN64) -> -120000000 | H19: =SUM(基礎!BT64:CE64) -> 0 | I19: =SUM(基礎!CK64:CV64) -> -26000 | J19: =SUM(基礎!DB64:DM64) -> 0 | K19: =SUM(基礎!DS64:ED64) -> 0 | L19: =SUM(基礎!EJ64:EU64) -> 0 | M19: =SUM(基礎!FA64:FL64) -> 0
C20: 資本金 | D20: 0 | E20: =SUM(基礎!U65:AF65) -> 0 | F20: =SUM(基礎!AL65:AW65) -> 0 | G20: =SUM(基礎!BC65:BN65) -> 0 | H20: =SUM(基礎!BT65:CE65) -> 0 | I20: =SUM(基礎!CK65:CV65) -> 0 | J20: =SUM(基礎!DB65:DM65) -> 0 | K20: =SUM(基礎!DS65:ED65) -> 0 | L20: =SUM(基礎!EJ65:EU65) -> 0 | M20: =SUM(基礎!FA65:FL65) -> 0
C21: 役員借入 | D21: =SUM(基礎!D66:O66) -> 0 | E21: =SUM(基礎!U66:AF66) -> 0 | F21: =SUM(基礎!AL66:AW66) -> 0 | G21: =SUM(基礎!BC66:BN66) -> 0 | H21: =SUM(基礎!BT66:CE66) -> 0 | I21: =SUM(基礎!CK66:CV66) -> -26000 | J21: =SUM(基礎!DB66:DM66) -> 0 | K21: =SUM(基礎!DS66:ED66) -> 0 | L21: =SUM(基礎!EJ66:EU66) -> 0 | M21: =SUM(基礎!FA66:FL66) -> 0
C22: 金融機関借入 | D22: =SUM(基礎!D67:O67) -> 0 | E22: =SUM(基礎!U67:AF67) -> 0 | F22: =SUM(基礎!AL67:AW67) -> 0 | G22: =SUM(基礎!BC67:BN67) -> 0 | H22: =SUM(基礎!BT67:CE67) -> 0 | I22: =SUM(基礎!CK67:CV67) -> 0 | J22: =SUM(基礎!DB67:DM67) -> 0 | K22: =SUM(基礎!DS67:ED67) -> 0 | L22: =SUM(基礎!EJ67:EU67) -> 0 | M22: =SUM(基礎!FA67:FL67) -> 0
C23: 固定資産売却 | D23: =SUM(基礎!D68:O68) -> 0 | E23: =SUM(基礎!U68:AF68) -> 0 | F23: =SUM(基礎!AL68:AW68) -> 0 | G23: =SUM(基礎!BC68:BN68) -> 0 | H23: =SUM(基礎!BT68:CE68) -> 0 | I23: =SUM(基礎!CK68:CV68) -> 0 | J23: =SUM(基礎!DB68:DM68) -> 0 | K23: =SUM(基礎!DS68:ED68) -> 0 | L23: =SUM(基礎!EJ68:EU68) -> 0 | M23: =SUM(基礎!FA68:FL68) -> 0
C24: FC保証金 | D24: =SUM(基礎!D69:O69) -> 0 | E24: =SUM(基礎!U69:AF69) -> 0 | F24: =SUM(基礎!AL69:AW69) -> 0 | G24: =SUM(基礎!BC69:BN69) -> -120000000 | H24: =SUM(基礎!BT69:CE69) -> 0 | I24: =SUM(基礎!CK69:CV69) -> 0 | J24: =SUM(基礎!DB69:DM69) -> 0 | K24: =SUM(基礎!DS69:ED69) -> 0 | L24: =SUM(基礎!EJ69:EU69) -> 0 | M24: =SUM(基礎!FA69:FL69) -> 0
C25: 地区本部保証金 | D25: =SUM(基礎!#REF!) -> #REF! | E25: =SUM(基礎!#REF!) -> #REF! | F25: =SUM(基礎!#REF!) -> #REF! | G25: =SUM(基礎!#REF!) -> #REF! | H25: =SUM(基礎!#REF!) -> #REF! | I25: =SUM(基礎!#REF!) -> #REF! | J25: =SUM(基礎!#REF!) -> #REF! | K25: =SUM(基礎!#REF!) -> #REF! | ... M25: =SUM(基礎!#REF!) -> #REF!
C26: 減価償却 | D26: =SUM(基礎!#REF!) -> #REF! | E26: =SUM(基礎!#REF!) -> #REF! | F26: =SUM(基礎!#REF!) -> #REF! | G26: =SUM(基礎!#REF!) -> #REF! | H26: =SUM(基礎!#REF!) -> #REF! | I26: =SUM(基礎!#REF!) -> #REF! | J26: =SUM(基礎!#REF!) -> #REF! | K26: =SUM(基礎!#REF!) -> #REF! | ... M26: =SUM(基礎!#REF!) -> #REF!
C27: その他 | D27: =SUM(基礎!#REF!) -> #REF! | E27: =SUM(基礎!#REF!) -> #REF! | F27: =SUM(基礎!#REF!) -> #REF! | G27: =SUM(基礎!#REF!) -> #REF! | H27: =SUM(基礎!#REF!) -> #REF! | I27: =SUM(基礎!#REF!) -> #REF! | J27: =SUM(基礎!#REF!) -> #REF! | K27: =SUM(基礎!#REF!) -> #REF! | ... M27: =SUM(基礎!#REF!) -> #REF!
B28: 財務支出 | D28: =SUM(D29:D35) -> #REF! | E28: =SUM(E29:E35) -> #REF! | F28: =SUM(F29:F35) -> #REF! | G28: =SUM(G29:G35) -> #REF! | H28: =SUM(H29:H35) -> #REF! | I28: =SUM(I29:I35) -> #REF! | J28: =SUM(J29:J35) -> #REF! | K28: =SUM(K29:K35) -> #REF! | ... N28: =SUM(N29:N35) -> 0
C29: 役員返済 | D29: 24000 | E29: 24000 | F29: 24000 | G29: 24000 | H29: 24000 | I29: 0 | J29: 0 | K29: 0 | L29: 0 | M29: 0
C30: 金融機関返済 | D30: =SUM(基礎!D72:O72) -> 0 | E30: =SUM(基礎!U72:AF72) -> 0 | F30: =SUM(基礎!AL72:AW72) -> 0 | G30: =SUM(基礎!BC72:BN72) -> 0 | H30: =SUM(基礎!BT72:CE72) -> 0 | I30: =SUM(基礎!CK72:CV72) -> 1112 | J30: =SUM(基礎!DB72:DM72) -> 0 | K30: =SUM(基礎!DS72:ED72) -> 0 | L30: =SUM(基礎!EJ72:EU72) -> 0 | M30: =SUM(基礎!FA72:FL72) -> 0
C31: FC保証金返却 | D31: =SUM(基礎!#REF!) -> #REF! | E31: =SUM(基礎!#REF!) -> #REF! | F31: =SUM(基礎!#REF!) -> #REF! | G31: =SUM(基礎!#REF!) -> #REF! | H31: =SUM(基礎!#REF!) -> #REF! | I31: =SUM(基礎!#REF!) -> #REF! | J31: =SUM(基礎!#REF!) -> #REF! | K31: =SUM(基礎!#REF!) -> #REF! | ... M31: =SUM(基礎!#REF!) -> #REF!
C32: 地区本部保証金返却 | D32: =SUM(基礎!#REF!) -> #REF! | E32: =SUM(基礎!#REF!) -> #REF! | F32: =SUM(基礎!#REF!) -> #REF! | G32: =SUM(基礎!#REF!) -> #REF! | H32: =SUM(基礎!#REF!) -> #REF! | I32: =SUM(基礎!#REF!) -> #REF! | J32: =SUM(基礎!#REF!) -> #REF! | K32: =SUM(基礎!#REF!) -> #REF! | ... M32: =SUM(基礎!#REF!) -> #REF!
C33: FC本部（システム等） | D33: =SUM(基礎!#REF!) -> #REF! | E33: =SUM(基礎!#REF!) -> #REF! | F33: =SUM(基礎!#REF!) -> #REF! | G33: =SUM(基礎!#REF!) -> #REF! | H33: =SUM(基礎!#REF!) -> #REF! | I33: =SUM(基礎!#REF!) -> #REF! | J33: =SUM(基礎!#REF!) -> #REF! | K33: =SUM(基礎!#REF!) -> #REF! | ... M33: =SUM(基礎!#REF!) -> #REF!
C34: 店舗出店コスト | D34: =SUM(基礎!#REF!) -> #REF! | E34: =SUM(基礎!#REF!) -> #REF! | F34: =SUM(基礎!#REF!) -> #REF! | G34: =SUM(基礎!#REF!) -> #REF! | H34: =SUM(基礎!#REF!) -> #REF! | I34: =SUM(基礎!#REF!) -> #REF! | J34: =SUM(基礎!#REF!) -> #REF! | K34: =SUM(基礎!#REF!) -> #REF! | ... M34: =SUM(基礎!#REF!) -> #REF!
C35: その他 | D35: =SUM(基礎!D73:O73) -> 0 | E35: =SUM(基礎!U73:AF73) -> 0 | F35: =SUM(基礎!AL73:AW73) -> 0 | G35: =SUM(基礎!BC73:BN73) -> 0 | H35: =SUM(基礎!BT73:CE73) -> 0 | I35: =SUM(基礎!CK73:CV73) -> 0 | J35: =SUM(基礎!DB73:DM73) -> 0 | K35: =SUM(基礎!DS73:ED73) -> 0 | L35: =SUM(基礎!EJ73:EU73) -> 0 | M35: =SUM(基礎!FA73:FL73) -> 0
B36: 財務収支差額 | D36: =D19-D28 -> #REF! | E36: =E19-E28 -> #REF! | F36: =F19-F28 -> #REF! | G36: =G19-G28 -> #REF! | H36: =H19-H28 -> #REF! | I36: =I19-I28 -> #REF! | J36: =J19-J28 -> #REF! | K36: =K19-K28 -> #REF! | ... M36: =M19-M28 -> #REF!
B37: CF | D37: =D18+D36 -> #REF! | E37: =E18+E36 -> #REF! | F37: =F18+F36 -> #REF! | G37: =G18+G36 -> #REF! | H37: =H18+H36 -> #REF! | I37: =I18+I36 -> #REF! | J37: =J18+J36 -> #REF! | K37: =K18+K36 -> #REF! | ... M37: =M18+M36 -> #REF!
B38: 税金 | D38: =PL!D44 -> 40000 | E38: =PL!E44 -> 2707115.4 | F38: =PL!F44 -> 2553539.4 | G38: =PL!G44 -> -20160 | H38: =PL!H44 -> -25344 | I38: =PL!I44 -> #REF! | J38: =PL!J44 -> #REF! | K38: =PL!K44 -> #REF! | ... M38: =PL!M44 -> #REF!
B39: 税引後CF | D39: =D37-D38 -> #REF! | E39: =E37-E38 -> #REF! | F39: =F37-F38 -> #REF! | G39: =G37-G38 -> #REF! | H39: =H37-H38 -> #REF! | I39: =I37-I38 -> #REF! | J39: =J37-J38 -> #REF! | K39: =K37-K38 -> #REF! | ... M39: =M37-M38 -> #REF!
B40: 翌年度繰越 | D40: =D4+D39 -> #REF! | E40: =E4+E39 -> #REF! | F40: =F4+F39 -> #REF! | G40: =G4+G39 -> #REF! | H40: =H4+H39 -> #REF! | I40: =I4+I39 -> #REF! | J40: =J4+J39 -> #REF! | K40: =K4+K39 -> #REF! | ... M40: =M4+M39 -> #REF!
...

Sheet 予備
D1: H23年度 | H1: H24年度 | L1: H25年度 | P1: H26年度 | T1: H27年度 | X1: H28年度 | AB1: H29年度 | AF1: H30年度
D2: Phase 1：基盤構築フェーズ | I2: Phase 2：高成長フェーズ（目標は100%成長） | P2: Phase3：安定成長フェーズ（目標は50%成長） | X2: Phase4：海外進出基盤構築フェーズ | AB2: Phase5：海外成長フェーズ | AF2: Phase6：海外安定成長フェーズ
C3: 月平均売上 | D3: 5 | E3: 6-8 | F3: 9-11 | G3: 12-2 | H3: 3-5 | I3: 6-8 | J3: 9-11 | K3: 12-2 | L3: 3-5 | M3: 6-8 | N3: 9-11 | O3: 12-2 | P3: 3-5 | Q3: 6-8 | R3: 9-11 | S3: 12-2 | T3: 3-5 | U3: 6-8 | V3: 9-11 | W3: 12-2 | X3: 3-5 | Y3: 6-8 | Z3: 9-11 | AA3: 12-2 | AB3: 3-5 | AC3: 6-8 | AD3: 9-11 | AE3: 12-2 | AF3: 3-5 | AG3: 6-8 | AH3: 9-11 | AI3: 12-2
A4: 直営 | B4: 都市型 | C4: 9000 | D4: 1 | E4: 1 | F4: 1 | G4: 2 | H4: 3 | I4: 3 | J4: 3 | K4: 3 | L4: 3 | M4: 4 | N4: 5 | O4: 6 | P4: 6 | Q4: 6 | R4: 7 | S4: 7 | T4: 7 | U4: 9 | V4: 9 | W4: 10 | X4: 10 | Y4: 12 | Z4: 14 | AA4: 16 | AB4: 18 | AC4: 20 | AD4: 22 | AE4: 24 | AF4: 26 | AG4: 28 | AH4: 30 | AI4: 31
B5: サテライト型 | C5: 6000 | D5: 1 | E5: 1 | F5: 1 | G5: 2 | H5: 3 | I5: 3 | J5: 3 | K5: 3 | L5: 3 | M5: 4 | N5: 5 | O5: 6 | P5: 6 | Q5: 6 | R5: 6 | S5: 7 | T5: 7 | U5: 9 | V5: 9 | W5: 10 | X5: 11 | Y5: 12 | Z5: 13 | AA5: 14 | AB5: 14 | AC5: 15 | AD5: 16 | AE5: 18 | AF5: 18 | AG5: 19 | AH5: 20 | AI5: 20
B6: 郊外型 | C6: 7500 | D6: 1 | E6: 1 | F6: 1 | G6: 2 | H6: 2 | I6: 2 | J6: 3 | K6: 3 | L6: 3 | M6: 4 | N6: 4 | O6: 5 | P6: 6 | Q6: 6 | R6: 6 | S6: 7 | T6: 7 | U6: 9 | V6: 9 | W6: 10 | X6: 10 | Y6: 10 | Z6: 10 | AA6: 10 | AB6: 10 | AC6: 10 | AD6: 10 | AE6: 12 | AF6: 12 | AG6: 12 | AH6: 13 | AI6: 13
B7: SC内 | C7: 6000 | D7: 1 | E7: 1 | F7: 1 | G7: 2 | H7: 2 | I7: 2 | J7: 2 | K7: 2 | L7: 2 | M7: 2 | N7: 2 | O7: 3 | P7: 3 | Q7: 3 | R7: 3 | S7: 4 | T7: 4 | U7: 4 | V7: 4 | W7: 5 | X7: 5 | Y7: 5 | Z7: 5 | AA7: 5 | AB7: 5 | AC7: 5 | AD7: 5 | AE7: 6 | AF7: 6 | AG7: 6 | AH7: 6 | AI7: 6
B8: 売上小計 | D8: =(($C4*D4)+($C5*D5)+($C6*D6)+($C7*D7))*1 -> 28500 | E8: =(($C4*E4)+($C5*E5)+($C6*E6)+($C7*E7))*3 -> 85500 | F8: =(($C4*F4)+($C5*F5)+($C6*F6)+($C7*F7))*3 -> 85500 | G8: =(($C4*G4)+($C5*G5)+($C6*G6)+($C7*G7))*3 -> 171000 | H8: =(($C4*H4)+($C5*H5)+($C6*H6)+($C7*H7))*3 -> 216000 | I8: =(($C4*I4)+($C5*I5)+($C6*I6)+($C7*I7))*3 -> 216000 | J8: =(($C4*J4)+($C5*J5)+($C6*J6)+($C7*J7))*3 -> 238500 | K8: =(($C4*K4)+($C5*K5)+($C6*K6)+($C7*K7))*3 -> 238500 | L8: =(($C4*L4)+($C5*L5)+($C6*L6)+($C7*L7))*3 -> 238500 | ... AI8: =(($C4*AI4)+($C5*AI5)+($C6*AI6)+($C7*AI7))*3 -> 1597500
B9: 店舗数 | D9: =SUM(D4:D7) -> 4 | E9: =SUM(E4:E7) -> 4 | F9: =SUM(F4:F7) -> 4 | G9: =SUM(G4:G7) -> 8 | H9: =SUM(H4:H7) -> 10 | I9: =SUM(I4:I7) -> 10 | J9: =SUM(J4:J7) -> 11 | K9: =SUM(K4:K7) -> 11 | ... AI9: =SUM(AI4:AI7) -> 70
A11: FC | B11: 都市型 | C11: =9000 -> 9000 | E11: 1 | F11: 2 | G11: 2 | H11: 3 | I11: 4 | J11: 4 | K11: 6 | L11: 6 | M11: 9 | N11: 9 | O11: 12 | P11: 14 | Q11: 16 | R11: 18 | S11: 20 | T11: 22 | U11: 24 | V11: 26 | W11: 28 | X11: 31 | Y11: 34 | Z11: 37 | AA11: 40 | AB11: 43 | AC11: 46 | AD11: 49 | AE11: 54 | AF11: 55 | AG11: 58 | AH11: 61 | AI11: 64
B12: サテライト型 | C12: =6000 -> 6000 | E12: 1 | F12: 1 | G12: 2 | H12: 2 | I12: 4 | J12: 4 | K12: 6 | L12: 6 | M12: 9 | N12: 9 | O12: 12 | P12: 14 | Q12: 16 | R12: 18 | S12: 20 | T12: 22 | U12: 24 | V12: 26 | W12: 28 | X12: 31 | Y12: 34 | Z12: 37 | AA12: 42 | AB12: 43 | AC12: 46 | AD12: 49 | AE12: 54 | AF12: 55 | AG12: 58 | AH12: 61 | AI12: 64
B13: 郊外型 | C13: =7500 -> 7500 | E13: 1 | F13: 1 | G13: 2 | H13: 2 | I13: 4 | J13: 4 | K13: 6 | L13: 6 | M13: 9 | N13: 9 | O13: 12 | P13: 14 | Q13: 16 | R13: 18 | S13: 20 | T13: 22 | U13: 24 | V13: 26 | W13: 28 | X13: 31 | Y13: 34 | Z13: 37 | AA13: 40 | AB13: 43 | AC13: 46 | AD13: 49 | AE13: 52 | AF13: 55 | AG13: 58 | AH13: 61 | AI13: 64
B14: SC内 | C14: =6000 -> 6000 | E14: 1 | F14: 2 | G14: 2 | H14: 2 | I14: 2 | J14: 2 | K14: 3 | L14: 3 | M14: 3 | N14: 4 | O14: 4 | P14: 4 | Q14: 4 | R14: 4 | S14: 5 | T14: 5 | U14: 5 | V14: 5 | W14: 6 | X14: 6 | Y14: 6 | Z14: 6 | AA14: 8 | AB14: 8 | AC14: 10 | AD14: 10 | AE14: 10 | AF14: 12 | AG14: 12 | AH14: 12 | AI14: 13
B15: 店舗売上小計 | D15: =(($C11*D11)+($C12*D12)+($C13*D13)+($C14*D14))*3 -> 0 | E15: =(($C11*E11)+($C12*E12)+($C13*E13)+($C14*E14))*3 -> 85500 | F15: =(($C11*F11)+($C12*F12)+($C13*F13)+($C14*F14))*3 -> 130500 | G15: =(($C11*G11)+($C12*G12)+($C13*G13)+($C14*G14))*3 -> 171000 | H15: =(($C11*H11)+($C12*H12)+($C13*H13)+($C14*H14))*3 -> 198000 | I15: =(($C11*I11)+($C12*I12)+($C13*I13)+($C14*I14))*3 -> 306000 | J15: =(($C11*J11)+($C12*J12)+($C13*J13)+($C14*J14))*3 -> 306000 | K15: =(($C11*K11)+($C12*K12)+($C13*K13)+($C14*K14))*3 -> 459000 | ... AI15: =(($C11*AI11)+($C12*AI12)+($C13*AI13)+($C14*AI14))*3 -> 4554000
B16: ロイヤルティ売上 | D16: =D15*0.06 -> 0 | E16: =E15*0.06 -> 5130 | F16: =F15*0.06 -> 7830 | G16: =G15*0.06 -> 10260 | H16: =H15*0.06 -> 11880 | I16: =I15*0.06 -> 18360 | J16: =J15*0.06 -> 18360 | K16: =K15*0.06 -> 27540 | ... AI16: =AI15*0.06 -> 273240
B17: 店舗数 | D17: =SUM(D11:D14) -> 0 | E17: =SUM(E11:E14) -> 4 | F17: =SUM(F11:F14) -> 6 | G17: =SUM(G11:G14) -> 8 | H17: =SUM(H11:H14) -> 9 | I17: =SUM(I11:I14) -> 14 | J17: =SUM(J11:J14) -> 14 | K17: =SUM(K11:K14) -> 21 | ... AI17: =SUM(AI11:AI14) -> 205
B19: 全店舗数 | D19: =D9+D17 -> 4 | E19: =E9+E17 -> 8 | F19: =F9+F17 -> 10 | G19: =G9+G17 -> 16 | H19: =H9+H17 -> 19 | I19: =I9+I17 -> 24 | J19: =J9+J17 -> 25 | K19: =K9+K17 -> 32 | ... AI19: =AI9+AI17 -> 275
B20: 直営FC合計売上 | D20: =D8+D16 -> 28500 | E20: =E8+E16 -> 90630 | F20: =F8+F16 -> 93330 | G20: =G8+G16 -> 181260 | H20: =H8+H16 -> 227880 | I20: =I8+I16 -> 234360 | J20: =J8+J16 -> 256860 | K20: =K8+K16 -> 266040 | ... AI20: =AI8+AI16 -> 1870740
B21: 年間売上 | G21: =SUM(D20:G20) -> 393720 | K21: =SUM(H20:K20) -> 985140 | O21: =SUM(L20:O20) -> 1492920 | S21: =SUM(P20:S20) -> 2242260 | W21: =SUM(T20:W20) -> 3096180 | AA21: =SUM(X20:AA20) -> 4169340 | AE21: =SUM(AB20:AE20) -> 5540940 | AI21: =SUM(AF20:AI20) -> 7064820
B22: 前年比 | K22: =K21/G21 -> 2.5021335 | O22: =O21/K21 -> 1.5154394 | S22: =S21/O21 -> 1.5019291 | W22: =W21/S21 -> 1.3808301 | AA22: =AA21/W21 -> 1.3466078 | AE22: =AE21/AA21 -> 1.3289729 | AI22: =AI21/AE21 -> 1.2750219
K23: ※２年目までに政令指定都市をカバー | O23: ※３年目までに中核市をカバー | S23: ※４年目終了で上場基準を満たして上場準備。海外進出準備 | AI23: ※５年間で展開して店舗数を３年間で達成し倍増する
W24: ※５年目終了で上場し、海外進出に向けて資金調達
U25: ■海外展開分
X26: Phase4：海外進出基盤構築フェーズ | AB26: Phase5：海外成長フェーズ
W27: 月平均売上 | X27: 3-5 | Y27: 6-8 | Z27: 9-11 | AA27: 12-2 | AB27: 3-5 | AC27: 6-8 | AD27: 9-11 | AE27: 12-2 | AF27: 3-5 | AG27: 6-8 | AH27: 9-11 | AI27: 12-2
U28: 直営 | V28: 都市型 | W28: 500 | X28: 3 | Y28: 3 | Z28: 3 | AA28: 5 | AB28: 6 | AC28: 9 | AD28: 12 | AE28: 15 | AF28: 17 | AG28: 19 | AH28: 21 | AI28: 23
V29: サテライト型 | W29: 200 | X29: 3 | Y29: 3 | Z29: 3 | AA29: 5 | AB29: 6 | AC29: 9 | AD29: 12 | AE29: 15 | AF29: 17 | AG29: 19 | AH29: 21 | AI29: 23
V30: 郊外型 | W30: 250 | X30: 3 | Y30: 3 | Z30: 3 | AA30: 5 | AB30: 6 | AC30: 9 | AD30: 12 | AE30: 15 | AF30: 17 | AG30: 19 | AH30: 21 | AI30: 23
V31: SC内 | W31: 100 | X31: 3 | Y31: 3 | Z31: 3 | AA31: 5 | AB31: 6 | AC31: 9 | AD31: 12 | AE31: 15 | AF31: 17 | AG31: 19 | AH31: 21 | AI31: 23
V32: 売上小計 | X32: =(($W28*X28)+($W29*X29)+($W30*X30)+($W31*X31))*3 -> 9450 | Y32: =(($W28*Y28)+($W29*Y29)+($W30*Y30)+($W31*Y31))*3 -> 9450 | Z32: =(($W28*Z28)+($W29*Z29)+($W30*Z30)+($W31*Z31))*3 -> 9450 | AA32: =(($W28*AA28)+($W29*AA29)+($W30*AA30)+($W31*AA31))*3 -> 15750 | AB32: =(($W28*AB28)+($W29*AB29)+($W30*AB30)+($W31*AB31))*3 -> 18900 | AC32: =(($W28*AC28)+($W29*AC29)+($W30*AC30)+($W31*AC31))*3 -> 28350 | AD32: =(($W28*AD28)+($W29*AD29)+($W30*AD30)+($W31*AD31))*3 -> 37800 | AE32: =(($W28*AE28)+($W29*AE29)+($W30*AE30)+($W31*AE31))*3 -> 47250 | ... AI32: =(($W28*AI28)+($W29*AI29)+($W30*AI30)+($W31*AI31))*3 -> 72450
V33: 店舗数 | X33: =SUM(X28:X31) -> 12 | Y33: =SUM(Y28:Y31) -> 12 | Z33: =SUM(Z28:Z31) -> 12 | AA33: =SUM(AA28:AA31) -> 20 | AB33: =SUM(AB28:AB31) -> 24 | AC33: =SUM(AC28:AC31) -> 36 | AD33: =SUM(AD28:AD31) -> 48 | AE33: =SUM(AE28:AE31) -> 60 | ... AI33: =SUM(AI28:AI31) -> 92
U35: FC | V35: 都市型 | W35: 500 | X35: 0 | Y35: 0 | Z35: 1 | AA35: 1 | AB35: 3 | AC35: 5 | AD35: 11 | AE35: 17 | AF35: 29 | AG35: 41 | AH35: 53 | AI35: 65
V36: サテライト型 | W36: 200 | X36: 0 | Y36: 0 | Z36: 1 | AA36: 1 | AB36: 3 | AC36: 5 | AD36: 11 | AE36: 17 | AF36: 29 | AG36: 41 | AH36: 53 | AI36: 65
V37: 郊外型 | W37: 250 | X37: 0 | Y37: 0 | Z37: 1 | AA37: 1 | AB37: 3 | AC37: 5 | AD37: 11 | AE37: 17 | AF37: 29 | AG37: 41 | AH37: 53 | AI37: 65
V38: SC内 | W38: 100 | X38: 0 | Y38: 0 | Z38: 1 | AA38: 1 | AB38: 3 | AC38: 5 | AD38: 11 | AE38: 17 | AF38: 29 | AG38: 41 | AH38: 53 | AI38: 65
V39: 店舗売上小計 | X39: =(($W35*X35)+($W36*X36)+($W37*X37)+($W38*X38))*3 -> 0 | Y39: =(($W35*Y35)+($W36*Y36)+($W37*Y37)+($W38*Y38))*3 -> 0 | Z39: =(($W35*Z35)+($W36*Z36)+($W37*Z37)+($W38*Z38))*3 -> 3150 | AA39: =(($W35*AA35)+($W36*AA36)+($W37*AA37)+($W38*AA38))*3 -> 3150 | AB39: =(($W35*AB35)+($W36*AB36)+($W37*AB37)+($W38*AB38))*3 -> 9450 | AC39: =(($W35*AC35)+($W36*AC36)+($W37*AC37)+($W38*AC38))*3 -> 15750 | AD39: =(($W35*AD35)+($W36*AD36)+($W37*AD37)+($W38*AD38))*3 -> 34650 | AE39: =(($W35*AE35)+($W36*AE36)+($W37*AE37)+($W38*AE38))*3 -> 53550 | ... AI39: =(($W35*AI35)+($W36*AI36)+($W37*AI37)+($W38*AI38))*3 -> 204750
V40: ロイヤルティ売上 | X40: =X39*0.06 -> 0 | Y40: =Y39*0.06 -> 0 | Z40: =Z39*0.06 -> 189 | AA40: =AA39*0.06 -> 189 | AB40: =AB39*0.06 -> 567 | AC40: =AC39*0.06 -> 945 | AD40: =AD39*0.06 -> 2079 | AE40: =AE39*0.06 -> 3213 | ... AI40: =AI39*0.06 -> 12285
V41: 店舗数 | X41: =SUM(X35:X38) -> 0 | Y41: =SUM(Y35:Y38) -> 0 | Z41: =SUM(Z35:Z38) -> 4 | AA41: =SUM(AA35:AA38) -> 4 | AB41: =SUM(AB35:AB38) -> 12 | AC41: =SUM(AC35:AC38) -> 20 | AD41: =SUM(AD35:AD38) -> 44 | AE41: =SUM(AE35:AE38) -> 68 | ... AI41: =SUM(AI35:AI38) -> 260
V43: 海外店舗数 | X43: =X33+X41 -> 12 | Y43: =Y33+Y41 -> 12 | Z43: =Z33+Z41 -> 16 | AA43: =AA33+AA41 -> 24 | AB43: =AB33+AB41 -> 36 | AC43: =AC33+AC41 -> 56 | AD43: =AD33+AD41 -> 92 | AE43: =AE33+AE41 -> 128 | ... AI43: =AI33+AI41 -> 352
V44: 直営FC合計売上 | X44: =X32+X40 -> 9450 | Y44: =Y32+Y40 -> 9450 | Z44: =Z32+Z40 -> 9639 | AA44: =AA32+AA40 -> 15939 | AB44: =AB32+AB40 -> 19467 | AC44: =AC32+AC40 -> 29295 | AD44: =AD32+AD40 -> 39879 | AE44: =AE32+AE40 -> 50463 | ... AI44: =AI32+AI40 -> 84735
...

Sheet 売上計画 
AJ1: ※５年間で展開して店舗数を３年間で達成し倍増する
E2: 2011 | Q2: 2012 | AC2: 2013 | AO2: 2014 | BA2: 2015 | BM2: 2016 | BY2: 2017 | CK2: 2018
C3: 月平均売上 | E3: Mar | F3: Apr | G3: May | H3: Jun | I3: Jul | J3: Aug | K3: Sep | L3: Oct | M3: Nov | N3: Dec | O3: Jan | P3: Feb | Q3: Mar | R3: Apr | S3: May | T3: Jun | U3: Jul | V3: Aug | W3: Sep | X3: Oct | Y3: Nov | Z3: Dec | AA3: Jan | AB3: Feb | AC3: Mar | AD3: Apr | AE3: May | AF3: Jun | AG3: Jul | AH3: Aug | AI3: Sep | AJ3: Oct | AK3: Nov | AL3: Dec | AM3: Jan | AN3: Feb | AO3: Mar | AP3: Apr | AQ3: May | AR3: Jun | AS3: Jul | AT3: Aug | AU3: Sep | AV3: Oct | AW3: Nov | AX3: Dec | AY3: Jan | AZ3: Feb | BA3: Mar | BB3: Apr | BC3: May | BD3: Jun | BE3: Jul | BF3: Aug | BG3: Sep | BH3: Oct | BI3: Nov | BJ3: Dec | BK3: Jan | BL3: Feb | BM3: Mar | BN3: Apr | BO3: May | BP3: Jun | BQ3: Jul | BR3: Aug | BS3: Sep | BT3: Oct | BU3: Nov | BV3: Dec | BW3: Jan | BX3: Feb | BY3: Mar | BZ3: Apr | CA3: May | CB3: Jun | CC3: Jul | CD3: Aug | CE3: Sep | CF3: Oct | CG3: Nov | CH3: Dec | CI3: Jan | CJ3: Feb | CK3: Mar | CL3: Apr | CM3: May | CN3: Jun | CO3: Jul | CP3: Aug | CQ3: Sep | CR3: Oct | CS3: Nov | CT3: Dec | CU3: Jan | CV3: Feb
A4: 直営 | B4: 都市型 | C4: 7500 | G4: 1 | H4: 1 | I4: 1 | J4: 1 | K4: 1 | L4: 1 | M4: 1 | N4: 2 | O4: 2 | P4: 2 | Q4: 2 | R4: 2 | S4: 2 | T4: 3 | U4: 3 | V4: 3 | W4: 3 | X4: 3 | Y4: 4 | Z4: 4 | AA4: 4 | AB4: 4 | AC4: 6 | AD4: 6 | AE4: 6 | AF4: 7 | AG4: 7 | AH4: 7 | AI4: 8 | AJ4: 8 | AK4: 8 | AL4: 8 | AM4: 8 | AN4: 8 | AO4: 9 | AP4: 9 | AQ4: 9 | AR4: 10 | AS4: 10 | AT4: 10 | AU4: 11 | AV4: 11 | AW4: 11 | AX4: 12 | AY4: 12 | AZ4: 12 | BA4: 13 | BB4: 13 | BC4: 13 | BD4: 14 | BE4: 14 | BF4: 14 | BG4: 15 | BH4: 15 | BI4: 15 | BJ4: 16 | BK4: 16 | BL4: 16 | BM4: 17 | BN4: 17 | BO4: 17 | BP4: 18 | BQ4: 18 | BR4: 18 | BS4: 19 | BT4: 19 | BU4: 19 | BV4: 20 | BW4: 20 | BX4: 20 | BY4: 21 | BZ4: 21 | CA4: 21 | CB4: 22 | CC4: 22 | CD4: 22 | CE4: 23 | CF4: 23 | CG4: 23 | CH4: 24 | CI4: 24 | CJ4: 24 | CK4: 25 | CL4: 25 | CM4: 25 | CN4: 26 | CO4: 26 | CP4: 26 | CQ4: 27 | CR4: 27 | CS4: 27 | CT4: 28 | CU4: 28 | CV4: 28
B5: サテライト型 | C5: 6000 | G5: 1 | H5: 1 | I5: 1 | J5: 1 | K5: 1 | L5: 1 | M5: 1 | N5: 2 | O5: 2 | P5: 2 | Q5: 2 | R5: 2 | S5: 2 | T5: 3 | U5: 3 | V5: 3 | W5: 3 | X5: 3 | Y5: 4 | Z5: 4 | AA5: 4 | AB5: 4 | AC5: 6 | AD5: 6 | AE5: 6 | AF5: 7 | AG5: 7 | AH5: 7 | AI5: 8 | AJ5: 8 | AK5: 8 | AL5: 8 | AM5: 8 | AN5: 8 | AO5: 9 | AP5: 9 | AQ5: 9 | AR5: 10 | AS5: 10 | AT5: 10 | AU5: 11 | AV5: 11 | AW5: 11 | AX5: 12 | AY5: 12 | AZ5: 12 | BA5: 13 | BB5: 13 | BC5: 13 | BD5: 14 | BE5: 14 | BF5: 14 | BG5: 15 | BH5: 15 | BI5: 15 | BJ5: 16 | BK5: 16 | BL5: 16 | BM5: 17 | BN5: 17 | BO5: 17 | BP5: 18 | BQ5: 18 | BR5: 18 | BS5: 19 | BT5: 19 | BU5: 19 | BV5: 20 | BW5: 20 | BX5: 20 | BY5: 21 | BZ5: 21 | CA5: 21 | CB5: 22 | CC5: 22 | CD5: 22 | CE5: 23 | CF5: 23 | CG5: 23 | CH5: 24 | CI5: 24 | CJ5: 24 | CK5: 25 | CL5: 25 | CM5: 25 | CN5: 26 | CO5: 26 | CP5: 26 | CQ5: 27 | CR5: 27 | CS5: 27 | CT5: 28 | CU5: 28 | CV5: 28
B6: 郊外型 | C6: 6000 | G6: 1 | H6: 1 | I6: 1 | J6: 1 | K6: 1 | L6: 1 | M6: 1 | N6: 2 | O6: 2 | P6: 2 | Q6: 2 | R6: 2 | S6: 2 | T6: 3 | U6: 3 | V6: 3 | W6: 3 | X6: 3 | Y6: 4 | Z6: 4 | AA6: 4 | AB6: 4 | AC6: 6 | AD6: 6 | AE6: 6 | AF6: 7 | AG6: 7 | AH6: 7 | AI6: 8 | AJ6: 8 | AK6: 8 | AL6: 8 | AM6: 8 | AN6: 8 | AO6: 9 | AP6: 9 | AQ6: 9 | AR6: 10 | AS6: 10 | AT6: 10 | AU6: 11 | AV6: 11 | AW6: 11 | AX6: 12 | AY6: 12 | AZ6: 12 | BA6: 13 | BB6: 13 | BC6: 13 | BD6: 14 | BE6: 14 | BF6: 14 | BG6: 15 | BH6: 15 | BI6: 15 | BJ6: 16 | BK6: 16 | BL6: 16 | BM6: 17 | BN6: 17 | BO6: 17 | BP6: 18 | BQ6: 18 | BR6: 18 | BS6: 19 | BT6: 19 | BU6: 19 | BV6: 20 | BW6: 20 | BX6: 20 | BY6: 21 | BZ6: 21 | CA6: 21 | CB6: 22 | CC6: 22 | CD6: 22 | CE6: 23 | CF6: 23 | CG6: 23 | CH6: 24 | CI6: 24 | CJ6: 24 | CK6: 25 | CL6: 25 | CM6: 25 | CN6: 26 | CO6: 26 | CP6: 26 | CQ6: 27 | CR6: 27 | CS6: 27 | CT6: 28 | CU6: 28 | CV6: 28
B7: SC内 | C7: 4500 | G7: 1 | H7: 1 | I7: 1 | J7: 1 | K7: 1 | L7: 1 | M7: 1 | N7: 2 | O7: 2 | P7: 2 | Q7: 2 | R7: 2 | S7: 2 | T7: 3 | U7: 3 | V7: 3 | W7: 3 | X7: 3 | Y7: 4 | Z7: 4 | AA7: 4 | AB7: 4 | AC7: 6 | AD7: 6 | AE7: 6 | AF7: 7 | AG7: 7 | AH7: 7 | AI7: 8 | AJ7: 8 | AK7: 8 | AL7: 8 | AM7: 8 | AN7: 8 | AO7: 9 | AP7: 9 | AQ7: 9 | AR7: 9 | AS7: 9 | AT7: 9 | AU7: 10 | AV7: 10 | AW7: 10 | AX7: 10 | AY7: 10 | AZ7: 10 | BA7: 11 | BB7: 11 | BC7: 11 | BD7: 11 | BE7: 11 | BF7: 11 | BG7: 11 | BH7: 11 | BI7: 11 | BJ7: 11 | BK7: 11 | BL7: 11 | BM7: 12 | BN7: 12 | BO7: 12 | BP7: 12 | BQ7: 12 | BR7: 12 | BS7: 13 | BT7: 13 | BU7: 13 | BV7: 13 | BW7: 13 | BX7: 13 | BY7: 14 | BZ7: 14 | CA7: 14 | CB7: 14 | CC7: 14 | CD7: 14 | CE7: 15 | CF7: 15 | CG7: 15 | CH7: 15 | CI7: 15 | CJ7: 15 | CK7: 16 | CL7: 16 | CM7: 16 | CN7: 16 | CO7: 16 | CP7: 16 | CQ7: 17 | CR7: 17 | CS7: 17 | CT7: 17 | CU7: 17 | CV7: 17
B8: 売上小計 | E8: =$C4*E4+$C5*E5+$C6*E6+$C7*E7 -> 0 | F8: =$C4*F4+$C5*F5+$C6*F6+$C7*F7 -> 0 | G8: =$C4*G4+$C5*G5+$C6*G6+$C7*G7 -> 24000 | H8: =$C4*H4+$C5*H5+$C6*H6+$C7*H7 -> 24000 | I8: =$C4*I4+$C5*I5+$C6*I6+$C7*I7 -> 24000 | J8: =$C4*J4+$C5*J5+$C6*J6+$C7*J7 -> 24000 | K8: =$C4*K4+$C5*K5+$C6*K6+$C7*K7 -> 24000 | L8: =$C4*L4+$C5*L5+$C6*L6+$C7*L7 -> 24000 | ... CV8: =$C4*CV4+$C5*CV5+$C6*CV6+$C7*CV7 -> 622500
B9: 店舗数 | E9: =SUM(E4:E7) -> 0 | F9: =SUM(F4:F7) -> 0 | G9: =SUM(G4:G7) -> 4 | H9: =SUM(H4:H7) -> 4 | I9: =SUM(I4:I7) -> 4 | J9: =SUM(J4:J7) -> 4 | K9: =SUM(K4:K7) -> 4 | L9: =SUM(L4:L7) -> 4 | ... CV9: =SUM(CV4:CV7) -> 101
A11: FC | B11: 都市型 | C11: 7500 | E11: 0 | F11: 0 | G11: 1 | H11: 1 | I11: 1 | J11: 1 | K11: 1 | L11: 1 | M11: 1 | N11: 2 | O11: 2 | P11: 2 | Q11: 3 | R11: 3 | S11: 3 | T11: 4 | U11: 4 | V11: 4 | W11: 4 | X11: 4 | Y11: 5 | Z11: 5 | AA11: 5 | AB11: 5 | AC11: 7 | AD11: 7 | AE11: 7 | AF11: 8 | AG11: 8 | AH11: 8 | AI11: 9 | AJ11: 9 | AK11: 9 | AL11: 10 | AM11: 10 | AN11: 10 | AO11: 11 | AP11: 11 | AQ11: 11 | AR11: 13 | AS11: 13 | AT11: 13 | AU11: 15 | AV11: 15 | AW11: 15 | AX11: 17 | AY11: 17 | AZ11: 17 | BA11: 19 | BB11: 19 | BC11: 19 | BD11: 21 | BE11: 21 | BF11: 21 | BG11: 23 | BH11: 23 | BI11: 23 | BJ11: 25 | BK11: 25 | BL11: 25 | BM11: 27 | BN11: 27 | BO11: 27 | BP11: 29 | BQ11: 29 | BR11: 29 | BS11: 31 | BT11: 31 | BU11: 31 | BV11: 33 | BW11: 33 | BX11: 33 | BY11: 35 | BZ11: 35 | CA11: 35 | CB11: 37 | CC11: 37 | CD11: 37 | CE11: 39 | CF11: 39 | CG11: 39 | CH11: 41 | CI11: 41 | CJ11: 41 | CK11: 43 | CL11: 43 | CM11: 43 | CN11: 45 | CO11: 45 | CP11: 45 | CQ11: 47 | CR11: 47 | CS11: 47 | CT11: 49 | CU11: 49 | CV11: 49
B12: サテライト型 | C12: 6000 | E12: 0 | F12: 0 | G12: 0 | H12: 0 | I12: 0 | J12: 0 | K12: 0 | L12: 0 | M12: 0 | N12: 1 | O12: 1 | P12: 1 | Q12: 2 | R12: 2 | S12: 2 | T12: 3 | U12: 3 | V12: 3 | W12: 3 | X12: 3 | Y12: 4 | Z12: 4 | AA12: 4 | AB12: 4 | AC12: 6 | AD12: 6 | AE12: 6 | AF12: 7 | AG12: 7 | AH12: 7 | AI12: 8 | AJ12: 8 | AK12: 8 | AL12: 9 | AM12: 9 | AN12: 9 | AO12: 10 | AP12: 10 | AQ12: 10 | AR12: 12 | AS12: 12 | AT12: 12 | AU12: 15 | AV12: 15 | AW12: 15 | AX12: 17 | AY12: 17 | AZ12: 17 | BA12: 19 | BB12: 19 | BC12: 19 | BD12: 21 | BE12: 21 | BF12: 21 | BG12: 23 | BH12: 23 | BI12: 23 | BJ12: 25 | BK12: 25 | BL12: 25 | BM12: 27 | BN12: 27 | BO12: 27 | BP12: 29 | BQ12: 29 | BR12: 29 | BS12: 31 | BT12: 31 | BU12: 31 | BV12: 33 | BW12: 33 | BX12: 33 | BY12: 35 | BZ12: 35 | CA12: 35 | CB12: 37 | CC12: 37 | CD12: 37 | CE12: 39 | CF12: 39 | CG12: 39 | CH12: 41 | CI12: 41 | CJ12: 41 | CK12: 43 | CL12: 43 | CM12: 43 | CN12: 45 | CO12: 45 | CP12: 45 | CQ12: 47 | CR12: 47 | CS12: 47 | CT12: 49 | CU12: 49 | CV12: 49
B13: 郊外型 | C13: 6000 | G13: 2 | H13: 3 | I13: 3 | J13: 3 | K13: 3 | L13: 3 | M13: 3 | N13: 4 | O13: 4 | P13: 4 | Q13: 4 | R13: 4 | S13: 4 | T13: 5 | U13: 5 | V13: 5 | W13: 5 | X13: 5 | Y13: 6 | Z13: 6 | AA13: 6 | AB13: 6 | AC13: 8 | AD13: 8 | AE13: 8 | AF13: 9 | AG13: 9 | AH13: 9 | AI13: 10 | AJ13: 10 | AK13: 10 | AL13: 11 | AM13: 11 | AN13: 11 | AO13: 12 | AP13: 12 | AQ13: 12 | AR13: 14 | AS13: 14 | AT13: 14 | AU13: 15 | AV13: 15 | AW13: 15 | AX13: 16 | AY13: 16 | AZ13: 16 | BA13: 17 | BB13: 17 | BC13: 17 | BD13: 18 | BE13: 18 | BF13: 18 | BG13: 19 | BH13: 19 | BI13: 19 | BJ13: 20 | BK13: 20 | BL13: 20 | BM13: 21 | BN13: 21 | BO13: 21 | BP13: 22 | BQ13: 22 | BR13: 22 | BS13: 23 | BT13: 23 | BU13: 23 | BV13: 24 | BW13: 24 | BX13: 24 | BY13: 25 | BZ13: 25 | CA13: 25 | CB13: 26 | CC13: 26 | CD13: 26 | CE13: 27 | CF13: 27 | CG13: 27 | CH13: 28 | CI13: 28 | CJ13: 28 | CK13: 29 | CL13: 29 | CM13: 29 | CN13: 30 | CO13: 30 | CP13: 30 | CQ13: 31 | CR13: 31 | CS13: 31 | CT13: 32 | CU13: 32 | CV13: 32
B14: SC内 | C14: 4500 | E14: 0 | F14: 0 | G14: 0 | H14: 1 | I14: 1 | J14: 1 | K14: 1 | L14: 1 | M14: 2 | N14: 2 | O14: 3 | P14: 3 | Q14: 3 | R14: 3 | S14: 3 | T14: 4 | U14: 4 | V14: 4 | W14: 4 | X14: 4 | Y14: 5 | Z14: 5 | AA14: 5 | AB14: 5 | AC14: 7 | AD14: 7 | AE14: 7 | AF14: 8 | AG14: 8 | AH14: 8 | AI14: 9 | AJ14: 9 | AK14: 9 | AL14: 10 | AM14: 10 | AN14: 10 | AO14: 10 | AP14: 10 | AQ14: 10 | AR14: 10 | AS14: 10 | AT14: 10 | AU14: 10 | AV14: 10 | AW14: 10 | AX14: 10 | AY14: 10 | AZ14: 10 | BA14: 11 | BB14: 11 | BC14: 11 | BD14: 11 | BE14: 11 | BF14: 11 | BG14: 12 | BH14: 12 | BI14: 12 | BJ14: 12 | BK14: 12 | BL14: 12 | BM14: 13 | BN14: 13 | BO14: 13 | BP14: 13 | BQ14: 13 | BR14: 13 | BS14: 14 | BT14: 14 | BU14: 14 | BV14: 14 | BW14: 14 | BX14: 14 | BY14: 15 | BZ14: 15 | CA14: 15 | CB14: 15 | CC14: 15 | CD14: 15 | CE14: 16 | CF14: 16 | CG14: 16 | CH14: 16 | CI14: 16 | CJ14: 16 | CK14: 17 | CL14: 17 | CM14: 17 | CN14: 17 | CO14: 17 | CP14: 17 | CQ14: 18 | CR14: 18 | CS14: 18 | CT14: 18 | CU14: 18 | CV14: 18
B15: 店舗売上小計 | E15: =$C11*E11+$C12*E12+$C13*E13+$C14*E14 -> 0 | F15: =$C11*F11+$C12*F12+$C13*F13+$C14*F14 -> 0 | G15: =$C11*G11+$C12*G12+$C13*G13+$C14*G14 -> 19500 | H15: =$C11*H11+$C12*H12+$C13*H13+$C14*H14 -> 30000 | I15: =$C11*I11+$C12*I12+$C13*I13+$C14*I14 -> 30000 | J15: =$C11*J11+$C12*J12+$C13*J13+$C14*J14 -> 30000 | K15: =$C11*K11+$C12*K12+$C13*K13+$C14*K14 -> 30000 | L15: =$C11*L11+$C12*L12+$C13*L13+$C14*L14 -> 30000 | ... CV15: =$C11*CV11+$C12*CV12+$C13*CV13+$C14*CV14 -> 934500
B16: ロイヤルティ売上 | C16: 0.06 | E16: =$C16*E15 -> 0 | F16: =$C16*F15 -> 0 | G16: =$C16*G15 -> 1170 | H16: =$C16*H15 -> 1800 | I16: =$C16*I15 -> 1800 | J16: =$C16*J15 -> 1800 | K16: =$C16*K15 -> 1800 | L16: =$C16*L15 -> 1800 | ... CV16: =$C16*CV15 -> 56070
B17: 店舗数 | E17: =SUM(E11:E14) -> 0 | F17: =SUM(F11:F14) -> 0 | G17: =SUM(G11:G14) -> 3 | H17: =SUM(H11:H14) -> 5 | I17: =SUM(I11:I14) -> 5 | J17: =SUM(J11:J14) -> 5 | K17: =SUM(K11:K14) -> 5 | L17: =SUM(L11:L14) -> 5 | ... CV17: =SUM(CV11:CV14) -> 148
B19: 全店舗数 | E19: =E9+E17 -> 0 | F19: =F9+F17 -> 0 | G19: =G9+G17 -> 7 | H19: =H9+H17 -> 9 | I19: =I9+I17 -> 9 | J19: =J9+J17 -> 9 | K19: =K9+K17 -> 9 | L19: =L9+L17 -> 9 | ... CV19: =CV9+CV17 -> 249
B20: 総売上 | E20: =E8+E16 -> 0 | F20: =F8+F16 -> 0 | G20: =G8+G16 -> 25170 | H20: =H8+H16 -> 25800 | I20: =I8+I16 -> 25800 | J20: =J8+J16 -> 25800 | K20: =K8+K16 -> 25800 | L20: =L8+L16 -> 25800 | ... CV20: =CV8+CV16 -> 678570
B21: 年間売上 | P21: =SUM(E20:P20) -> 334500 | AB21: =SUM(Q20:AB20) -> 958560 | AN21: =SUM(AC20:AN20) -> 2234880 | AZ21: =SUM(AO20:AZ20) -> 3197880 | BL21: =SUM(BA20:BL20) -> 4318020 | BX21: =SUM(BM20:BX20) -> 5436540 | CJ21: =SUM(BY20:CJ20) -> 6582060 | CV21: =SUM(CK20:CV20) -> 7727580
B23: マイルストーン | AB23: ※２年目までに政令指定都市をカバー | AN23: ※３年目までに中核市をカバー | AZ23: ※４年目終了で上場基準を満たして上場準備。海外進出準備 | BL23: ※5期中で上場し、海外進出資金を得る
E26: Ph1：基盤構築フェーズ | G26: Ph 2：高成長フェーズ（目標は50〜100%成長） | M26: Ph3：安定成長フェーズ（目標は20%成長）
E27: 2011 | G27: 2012 | I27: 2013 | K27: 2014 | M27: 2015 | O27: 2016 | Q27: 2017 | S27: 2018
E28: 1H | F28: 2H | G28: 1H | H28: 2H | I28: 1H | J28: 2H | K28: 1H | L28: 2H | M28: 1H | N28: 2H | O28: 1H | P28: 2H | Q28: 1H | R28: 2H | S28: 1H | T28: 2H
B29: 直営店 | C29: 店舗数合計 | E29: =SUM(E9:J9) -> 16 | F29: =SUM(K9:P9) -> 36 | G29: =SUM(Q9:V9) -> 60 | H29: =SUM(W9:AB9) -> 88 | I29: =SUM(AC9:AH9) -> 156 | J29: =SUM(AI9:AN9) -> 192 | K29: =SUM(AO9:AT9) -> 225 | L29: =SUM(AU9:AZ9) -> 267 | M29: =SUM(BA9:BF9) -> 309 | N29: =SUM(BG9:BL9) -> 345 | O29: =SUM(BM9:BR9) -> 387 | P29: =SUM(BS9:BX9) -> 429 | Q29: =SUM(BY9:CD9) -> 471 | R29: =SUM(CE9:CJ9) -> 513 | S29: =SUM(CK9:CP9) -> 555 | T29: =SUM(CQ9:CV9) -> 597
C30: 売上高 | E30: =SUM(E8:J8) -> 96000 | F30: =SUM(K8:P8) -> 216000 | G30: =SUM(Q8:V8) -> 360000 | H30: =SUM(W8:AB8) -> 528000 | I30: =SUM(AC8:AH8) -> 936000 | J30: =SUM(AI8:AN8) -> 1152000 | K30: =SUM(AO8:AT8) -> 1354500 | L30: =SUM(AU8:AZ8) -> 1615500 | M30: =SUM(BA8:BF8) -> 1876500 | N30: =SUM(BG8:BL8) -> 2110500 | O30: =SUM(BM8:BR8) -> 2371500 | P30: =SUM(BS8:BX8) -> 2632500 | Q30: =SUM(BY8:CD8) -> 2893500 | R30: =SUM(CE8:CJ8) -> 3154500 | S30: =SUM(CK8:CP8) -> 3415500 | T30: =SUM(CQ8:CV8) -> 3676500
B31: FC店 | C31: 店舗数合計 | E31: =SUM(E17:J17) -> 18 | F31: =SUM(K17:P17) -> 45 | G31: =SUM(Q17:V17) -> 84 | H31: =SUM(W17:AB17) -> 112 | I31: =SUM(AC17:AH17) -> 180 | J31: =SUM(AI17:AN17) -> 228 | K31: =SUM(AO17:AT17) -> 276 | L31: =SUM(AU17:AZ17) -> 345 | M31: =SUM(BA17:BF17) -> 411 | N31: =SUM(BG17:BL17) -> 477 | O31: =SUM(BM17:BR17) -> 543 | P31: =SUM(BS17:BX17) -> 609 | Q31: =SUM(BY17:CD17) -> 675 | R31: =SUM(CE17:CJ17) -> 741 | S31: =SUM(CK17:CP17) -> 807 | T31: =SUM(CQ17:CV17) -> 873
C32: 売上高 | E32: =SUM(E16:J16) -> 6570 | F32: =SUM(K16:P16) -> 15930 | G32: =SUM(Q16:V16) -> 30240 | H32: =SUM(W16:AB16) -> 40320 | I32: =SUM(AC16:AH16) -> 64800 | J32: =SUM(AI16:AN16) -> 82080 | K32: =SUM(AO16:AT16) -> 100440 | L32: =SUM(AU16:AZ16) -> 127440 | M32: =SUM(BA16:BF16) -> 152820 | N32: =SUM(BG16:BL16) -> 178200 | O32: =SUM(BM16:BR16) -> 203580 | P32: =SUM(BS16:BX16) -> 228960 | Q32: =SUM(BY16:CD16) -> 254340 | R32: =SUM(CE16:CJ16) -> 279720 | S32: =SUM(CK16:CP16) -> 305100 | T32: =SUM(CQ16:CV16) -> 330480
B33: 合計 | C33: 店舗数合計 | E33: =E29+E31 -> 34 | F33: =F29+F31 -> 81 | G33: =G29+G31 -> 144 | H33: =H29+H31 -> 200 | I33: =I29+I31 -> 336 | J33: =J29+J31 -> 420 | K33: =K29+K31 -> 501 | L33: =L29+L31 -> 612 | ... T33: =T29+T31 -> 1470
C34: 売上高 | E34: =E30+E32 -> 102570 | F34: =F30+F32 -> 231930 | G34: =G30+G32 -> 390240 | H34: =H30+H32 -> 568320 | I34: =I30+I32 -> 1000800 | J34: =J30+J32 -> 1234080 | K34: =K30+K32 -> 1454940 | L34: =L30+L32 -> 1742940 | ... T34: =T30+T32 -> 4006980
B35: 年間売上 | F35: =E34+F34 -> 334500 | H35: =G34+H34 -> 958560 | J35: =I34+J34 -> 2234880 | L35: =K34+L34 -> 3197880 | N35: =M34+N34 -> 4318020 | P35: =O34+P34 -> 5436540 | R35: =Q34+R34 -> 6582060 | T35: =S34+T34 -> 7727580
E37: 2011 | F37: 2012 | G37: 2013 | H37: 2014 | I37: 2015 | J37: 2016 | K37: 2017 | L37: 2018 | N37: 店舗計画 | O37: 2011 | P37: 2012 | Q37: 2013 | R37: 2014 | S37: 2015 | T37: 2016 | U37: 2017 | V37: 2018
B38: 直営店 | C38: 店舗数合計 | E38: =SUM(E29:F29) -> 52 | F38: =SUM(G29:H29) -> 148 | G38: =SUM(I29:J29) -> 348 | H38: =SUM(K29:L29) -> 492 | I38: =SUM(M29:N29) -> 654 | J38: =SUM(O29:P29) -> 816 | K38: =SUM(Q29:R29) -> 984 | L38: =SUM(S29:T29) -> 1152 | N38: 5 | O38: 13 | P38: 18 | Q38: 36 | R38: 34 | S38: 35 | T38: 36 | U38: 36 | V38: 36
C39: 売上高 | E39: =SUM(E30:F30) -> 312000 | F39: =SUM(G30:H30) -> 888000 | G39: =SUM(I30:J30) -> 2088000 | H39: =SUM(K30:L30) -> 2970000 | I39: =SUM(M30:N30) -> 3987000 | J39: =SUM(O30:P30) -> 5004000 | K39: =SUM(Q30:R30) -> 6048000 | L39: =SUM(S30:T30) -> 7092000 | N39: 大元 | O39: 千田
B40: FC店 | C40: 店舗数合計 | E40: =SUM(E33:F33) -> 115 | F40: =SUM(G31:H31) -> 196 | G40: =SUM(I31:J31) -> 408 | H40: =SUM(K31:L31) -> 621 | I40: =SUM(M31:N31) -> 888 | J40: =SUM(O31:P31) -> 1152 | K40: =SUM(Q31:R31) -> 1416 | L40: =SUM(S31:T31) -> 1680 | N40: 自由が丘 | O40: 赤坂
C41: 売上高 | E41: =SUM(E32:F32) -> 22500 | F41: =SUM(G32:H32) -> 70560 | G41: =SUM(I32:J32) -> 146880 | H41: =SUM(K32:L32) -> 227880 | I41: =SUM(M32:N32) -> 331020 | J41: =SUM(O32:P32) -> 432540 | K41: =SUM(Q32:R32) -> 534060 | L41: =SUM(S32:T32) -> 635580 | N41: 都立大学 | O41: 葛西
B42: 合計 | C42: 店舗数合計 | E42: =E38+E40 -> 167 | F42: =F38+F40 -> 344 | G42: =G38+G40 -> 756 | H42: =H38+H40 -> 1113 | I42: =I38+I40 -> 1542 | J42: =J38+J40 -> 1968 | K42: =K38+K40 -> 2400 | L42: =L38+L40 -> 2832 | N42: 豊中緑丘 | O42: 鷺沼
C43: 売上高 | E43: =E39+E41 -> 334500 | F43: =F39+F41 -> 958560 | G43: =G39+G41 -> 2234880 | H43: =H39+H41 -> 3197880 | I43: =I39+I41 -> 4318020 | J43: =J39+J41 -> 5436540 | K43: =K39+K41 -> 6582060 | L43: =L39+L41 -> 7727580 | N43: 静岡 | O43: 倉敷
B44: 売上高成長率 | F44: =F43/E43 -> 2.8656502 | G44: =G43/F43 -> 2.3314972 | H44: =H43/G43 -> 1.4308956 | I44: =I43/H43 -> 1.3502758 | J44: =J43/I43 -> 1.2590354 | K44: =K43/J43 -> 1.2107075 | L44: =L43/K43 -> 1.1740367

Sheet 営業権譲渡関連
B1: 譲渡スキーム
I2: 単位：千円
B3: 資金調達（短期） | G3: 資金使途（短期）
B4: 調達主体 | C4: 調達方法 | D4: 金額 | G4: 総額 | H4: 使途名称 | I4: 主体者
B5: アドタッチ | C5: カーブス | D5: 40,000～ | E5: ⇒ | G5: 30000 | H5: 個人借入（超） | I5: アドタッチ
G6: 9,000？ | H6: アドプロ債務 | I6: アドタッチ
G7: 残 | H7: アド運転資金 | I7: アドタッチ
B8: 和良 | C8: 資本＋私募債 | D8: 30000 | E8: 営業権譲渡金⇒ | G8: 30000 | H8: 和良運転資金(4月以前） | I8: アドタッチ
B9: 和良 | C9: 債務引受 | D9: 110000 | E9: 営業権譲渡金⇒ | G9: 110000 | H9: 金融（和良） | I9: アドタッチ
B10: 和良 | C10: 債務引受 | D10: 20000 | E10: 営業権譲渡金⇒ | G10: 20000 | H10: リース残債 | I10: アドタッチ
B11: 和良 | C11: 私募債等 | D11: =260000-D8-D9-D10 -> 100000 | E11: 営業権譲渡金⇒ | G11: 112000 | H11: 個人借入（中） | I11: アドタッチ
D12: ↑但し私募債等が100,000千円に満たない場合は差額分÷100万/月額で返済
D13: またリース債務等の額が想定額より大きい場合は減額調整。
B15: 営業権金額 | D15: 上限：260,000

Sheet Sheet2
B2: 初期３ヶ月
B3: 管理者兼サビ管 | C3: 900円/時間 | D3: ６．５時間 | E3: ２２日 | F3: =900*6.5*22 -> 128700
B4: 職業指導員 | C4: ８００円/時間 | D4: ６．５時間 | E4: ２２日 | F4: =800*6.5*22 -> 114400
B5: 生活支援員 | C5: ８００円/時間 | D5: ６．５時間 | E5: ２２日 | F5: =800*6.5*22 -> 114400
B6: 生活支援員 | C6: ８００円/時間 | D6: ３時間 | E6: ２２日 | F6: =800*3*22 -> 52800
F9: =SUM(F3:F6) -> 410300 | G9: =F4+F5+F6 -> 281600
C10: 雇用保険 | D10: ７／１０００ | F10: =F9/1000*7 -> 2872.1
B12: 初期３ヶ月
B13: 管理者兼サビ管 | C13: 1200円/時間 | D13: ６．５時間 | E13: ２２日 | F13: =1200*6.5*22 -> 171600
B14: 職業指導員 | C14: 9００円/時間 | D14: ６．５時間 | E14: ２２日 | F14: =900*6.5*22 -> 128700
B15: 生活支援員 | C15: 900円/時間 | D15: ６．５時間 | E15: ２２日 | F15: =900*6.5*22 -> 128700
B16: 生活支援員 | C16: 900円/時間 | D16: ３時間 | E16: ２２日 | F16: =900*3*22 -> 59400
F19: =SUM(F13:F16) -> 488400 | G19: =F14+F15+F16 -> 316800
C20: 雇用保険 | D20: ７／１０００ | F20: =F19/1000*7 -> 3418.8

Sheet 基礎
A1: H28年度 P/L | S1: H29年度 | AJ1: H24年度 | BA1: H26年度 | BR1: H27年度 | CI1: H28年度 | CZ1: H29年度 | DQ1: H30年度 | EH1: H31年度 | EY1: H32年度
D2: 4月 | E2: 5月 | F2: 6月 | G2: 7月 | H2: 8月 | I2: 9月 | J2: 10月 | K2: 11月 | L2: 12月 | M2: 1月 | N2: 2月 | O2: 3月 | P2: 合計 | Q2: 対売上比率 | U2: 4月 | V2: 5月 | W2: 6月 | X2: 7月 | Y2: 8月 | Z2: 9月 | AA2: 10月 | AB2: 11月 | AC2: 12月 | AD2: 1月 | AE2: 2月 | AF2: 3月 | AG2: 合計 | AH2: 対売上比率 | AL2: 4月 | AM2: 5月 | AN2: 6月 | AO2: 7月 | AP2: 8月 | AQ2: 9月 | AR2: 10月 | AS2: 11月 | AT2: 12月 | AU2: 1月 | AV2: 2月 | AW2: 3月 | AX2: 合計 | AY2: 対売上比率 | BC2: 3月 | BD2: 4月 | BE2: 5月 | BF2: 6月 | BG2: 7月 | BH2: 8月 | BI2: 9月 | BJ2: 10月 | BK2: 11月 | BL2: 12月 | BM2: 1月 | BN2: 2月 | BO2: 合計 | BP2: 対売上比率 | BT2: 3月 | BU2: 4月 | BV2: 5月 | BW2: 6月 | BX2: 7月 | BY2: 8月 | BZ2: 9月 | CA2: 10月 | CB2: 11月 | CC2: 12月 | CD2: 1月 | CE2: 2月 | CF2: 合計 | CG2: 対売上比率 | CK2: 3月 | CL2: 4月 | CM2: 5月 | CN2: 6月 | CO2: 7月 | CP2: 8月 | CQ2: 9月 | CR2: 10月 | CS2: 11月 | CT2: 12月 | CU2: 1月 | CV2: 2月 | CW2: 合計 | CX2: 対売上比率 | DB2: 3月 | DC2: 4月 | DD2: 5月 | DE2: 6月 | DF2: 7月 | DG2: 8月 | DH2: 9月 | DI2: 10月 | DJ2: 11月 | DK2: 12月 | DL2: 1月 | DM2: 2月 | DN2: 合計 | DO2: 対売上比率 | DS2: 3月 | DT2: 4月 | DU2: 5月 | DV2: 6月 | DW2: 7月 | DX2: 8月 | DY2: 9月 | DZ2: 10月 | EA2: 11月 | EB2: 12月 | EC2: 1月 | ED2: 2月 | EE2: 合計 | EF2: 対売上比率 | EJ2: 3月 | EK2: 4月 | EL2: 5月 | EM2: 6月 | EN2: 7月 | EO2: 8月 | EP2: 9月 | EQ2: 10月 | ER2: 11月 | ES2: 12月 | ET2: 1月 | EU2: 2月 | EV2: 合計 | EW2: 対売上比率 | FA2: 3月 | FB2: 4月 | FC2: 5月 | FD2: 6月 | FE2: 7月 | FF2: 8月 | FG2: 9月 | FH2: 10月 | FI2: 11月 | FJ2: 12月 | FK2: 1月 | FL2: 2月 | FM2: 合計 | FN2: 対売上比率
B3: 総売上 | D3: =D4+D9+D15+D17+D16 -> 0 | E3: =E4+E9+E15+E17+E16 -> 0 | F3: =F4+F9+F15+F17+F16 -> 0 | G3: =G4+G9+G15+G17+G16 -> 0 | H3: =H4+H9+H15+H17+H16 -> 0 | I3: =I4+I9+I15+I17+I16 -> 0 | J3: =J4+J9+J15+J17+J16 -> 0 | K3: =K4+K9+K15+K17+K16 -> 0 | ... O3: =O4+O9+O15+O17+O16 -> 0 | P3: =SUM(D3:O3) -> 100000 | Q3: =P3/P3 -> 1 | S3: 総売上 | U3: =U4+U9+U15+U17+U16 -> 1031370 | V3: =V4+V9+V15+V17+V16 -> 1186064 | W3: =W4+W9+W15+W17+W16 -> 1186064 | X3: =X4+X9+X15+X17+X16 -> 1353888 | Y3: =Y4+Y9+Y15+Y17+Y16 -> 1353888 | Z3: =Z4+Z9+Z15+Z17+Z16 -> 1461712 | AA3: =AA4+AA9+AA15+AA17+AA16 -> 1461712 | AB3: =AB4+AB9+AB15+AB17+AB16 -> 1569536 | ... AF3: =AF4+AF9+AF15+AF17+AF16 -> 1785184 | AG3: =SUM(U3:AF3) -> 17313674 | AH3: =AG3/P3 -> 173.13674 | AJ3: 総売上 | AL3: =AL4+AL9+AL15+AL17+AL16 -> 1091370 | AM3: =AM4+AM9+AM15+AM17+AM16 -> 1246064 | AN3: =AN4+AN9+AN15+AN17+AN16 -> 1246064 | AO3: =AO4+AO9+AO15+AO17+AO16 -> 1353888 | AP3: =AP4+AP9+AP15+AP17+AP16 -> 1353888 | AQ3: =AQ4+AQ9+AQ15+AQ17+AQ16 -> 1461712 | AR3: =AR4+AR9+AR15+AR17+AR16 -> 1461712 | AS3: =AS4+AS9+AS15+AS17+AS16 -> 1569536 | ... AW3: =AW4+AW9+AW15+AW17+AW16 -> 1785184 | AX3: =SUM(AL3:AW3) -> 17493674 | AY3: =AX3/AG3 -> 1.0103964 | BA3: 総売上 | BC3: =BC4+BC9+BC15+BC17+BC16 -> 29000 | BD3: =BD4+BD9+BD15+BD17+BD16 -> 29000 | BE3: =BE4+BE9+BE15+BE17+BE16 -> 29000 | BF3: =BF4+BF9+BF15+BF17+BF16 -> 29000 | BG3: =BG4+BG9+BG15+BG17+BG16 -> 29000 | BH3: =BH4+BH9+BH15+BH17+BH16 -> 28000 | BI3: =BI4+BI9+BI15+BI17+BI16 -> 29000 | BJ3: =BJ4+BJ9+BJ15+BJ17+BJ16 -> 30000 | ... BN3: =BN4+BN9+BN15+BN17+BN16 -> 30000 | BO3: =SUM(BC3:BN3) -> 352000 | BP3: =BO3/AX3 -> 0.020121559 | BR3: 総売上 | BT3: =BT4+BT9+BT15+BT17+BT16 -> 29000 | BU3: =BU4+BU9+BU15+BU17+BU16 -> 29000 | BV3: =BV4+BV9+BV15+BV17+BV16 -> 29000 | BW3: =BW4+BW9+BW15+BW17+BW16 -> 29000 | BX3: =BX4+BX9+BX15+BX17+BX16 -> 29000 | BY3: =BY4+BY9+BY15+BY17+BY16 -> 28000 | BZ3: =BZ4+BZ9+BZ15+BZ17+BZ16 -> 29000 | CA3: =CA4+CA9+CA15+CA17+CA16 -> 30000 | ... CE3: =CE4+CE9+CE15+CE17+CE16 -> 30000 | CF3: =SUM(BT3:CE3) -> 352000 | CG3: =CF3/BO3 -> 1 | CI3: 総売上 | CK3: =CK4+CK9+CK15+CK17+CK16 -> 0 | CL3: =CL4+CL9+CL15+CL17+CL16 -> 0 | CM3: =CM4+CM9+CM15+CM17+CM16 -> 0 | CN3: =CN4+CN9+CN15+CN17+CN16 -> 0 | CO3: =CO4+CO9+CO15+CO17+CO16 -> 0 | CP3: =CP4+CP9+CP15+CP17+CP16 -> 0 | CQ3: =CQ4+CQ9+CQ15+CQ17+CQ16 -> 0 | CR3: =CR4+CR9+CR15+CR17+CR16 -> 0 | ... CV3: =CV4+CV9+CV15+CV17+CV16 -> 0 | CW3: =SUM(CK3:CV3) -> 0 | CX3: =CW3/CF3 -> 0 | CZ3: 総売上 | DB3: =DB4+DB9+DB15+DB17+DB16 -> 0 | DC3: =DC4+DC9+DC15+DC17+DC16 -> 0 | DD3: =DD4+DD9+DD15+DD17+DD16 -> 0 | DE3: =DE4+DE9+DE15+DE17+DE16 -> 0 | DF3: =DF4+DF9+DF15+DF17+DF16 -> 0 | DG3: =DG4+DG9+DG15+DG17+DG16 -> 0 | DH3: =DH4+DH9+DH15+DH17+DH16 -> 0 | DI3: =DI4+DI9+DI15+DI17+DI16 -> 0 | ... DM3: =DM4+DM9+DM15+DM17+DM16 -> 0 | DN3: =SUM(DB3:DM3) -> 0 | DO3: =DN3/CW3 -> #DIV/0! | DQ3: 総売上 | DS3: =DS4+DS9+DS15+DS17+DS16 -> 0 | DT3: =DT4+DT9+DT15+DT17+DT16 -> 0 | DU3: =DU4+DU9+DU15+DU17+DU16 -> 0 | DV3: =DV4+DV9+DV15+DV17+DV16 -> 0 | DW3: =DW4+DW9+DW15+DW17+DW16 -> 0 | DX3: =DX4+DX9+DX15+DX17+DX16 -> 0 | DY3: =DY4+DY9+DY15+DY17+DY16 -> 0 | DZ3: =DZ4+DZ9+DZ15+DZ17+DZ16 -> 0 | ... ED3: =ED4+ED9+ED15+ED17+ED16 -> 0 | EE3: =SUM(DS3:ED3) -> 0 | EF3: =EE3/DN3 -> #DIV/0! | EH3: 総売上 | EJ3: =EJ4+EJ9+EJ15+EJ17+EJ16 -> 0 | EK3: =EK4+EK9+EK15+EK17+EK16 -> 0 | EL3: =EL4+EL9+EL15+EL17+EL16 -> 0 | EM3: =EM4+EM9+EM15+EM17+EM16 -> 0 | EN3: =EN4+EN9+EN15+EN17+EN16 -> 0 | EO3: =EO4+EO9+EO15+EO17+EO16 -> 0 | EP3: =EP4+EP9+EP15+EP17+EP16 -> 0 | EQ3: =EQ4+EQ9+EQ15+EQ17+EQ16 -> 0 | ... EU3: =EU4+EU9+EU15+EU17+EU16 -> 0 | EV3: =SUM(EJ3:EU3) -> 0 | EW3: =EV3/EE3 -> #DIV/0! | EY3: 総売上 | FA3: =FA4+FA9+FA15+FA17+FA16 -> 0 | FB3: =FB4+FB9+FB15+FB17+FB16 -> 0 | FC3: =FC4+FC9+FC15+FC17+FC16 -> 0 | FD3: =FD4+FD9+FD15+FD17+FD16 -> 0 | FE3: =FE4+FE9+FE15+FE17+FE16 -> 0 | FF3: =FF4+FF9+FF15+FF17+FF16 -> 0 | FG3: =FG4+FG9+FG15+FG17+FG16 -> 0 | FH3: =FH4+FH9+FH15+FH17+FH16 -> 0 | ... FL3: =FL4+FL9+FL15+FL17+FL16 -> 0 | FM3: =SUM(FA3:FL3) -> 0 | FN3: =FM3/EV3 -> #DIV/0!
