Workbook

Sheet Claude Log
A1: Turn # | B1: Date | C1: User Request | D1: Action Taken | E1: Details | F1: Outcome
A2: 1 | B2: 46070 | C2: 「初年度末BS」シートが追加されたか確認してほしいとのリクエスト | D2: シートの存在と内容を確認 | E2: H23年度B/Sシート。借方（資産）と貸方（負債・資本）の構成を確認。数式は「初年度 損益資金計画」シートを参照。 | F2: シート確認完了。貸借差額235,200円あり（資産2,865,360 vs 負債・資本3,100,560）。修正要否をユーザーに確認中。
A3: 2 | B3: 46069 | C3: 全シートのデータを読み込んで内容を確認してほしい | D3: 6シート全てを読み込み、内容の概要をまとめて報告 | E3: 表紙（空白）、収支計画書（人材配置等）（R3～R7年の5年分の利用者数・給付費・人件費等）、損益及び資金計画書（R3・R4年度の損益計算書＋資金繰表）、稼働カレンダー（2021～2023年）を読み込み。損益計画書は数式で構成されており資金繰りシミュレーションが組まれている。 | F3: 全データ読み込み完了。R3年度は営業赤字▲5,847,900円、R4年度は経常利益18,371,340円で黒字転換。ユーザーからの次の指示を待機中。
A4: 3 | B4: 46069 | C4: 損益及び資金計画書を各年度1シートに分割してほしい | D4: 元シートを複製し、R3年度・R4年度の独立シートを作成。#REF!エラーを全て修正。 | E4: 元シート(R3+R4横並び)を2回複製。R3シートからR4列(S:AI)削除、R4シートからR3列(A:R)削除。R4シートで発生した#REF!エラー（減価償却=0、対売上比率、資金繰りのR3参照6箇所）を全て静的値で修正。前月繰越▲2,287,140円等。元シートはバックアップとして保持。 | F4: R3年度・R4年度シート作成完了。全数値が元シートと一致（総売上・営業利益・経常利益・期末繰越）。エラー0件。
A5: 4 | B5: 46069 | C5: 収支計画書（人材配置等）も各年度に分けてほしい | D5: 元シートを5回複製し、R3～R7年度の独立シートを作成。年度間参照エラーを修正。 | E5: 5年度分(R3:D-P, R4:Q-AC, R5:AD-AP, R6:AQ-BC, R7:BD-BP)を各シートに分割。R4年度で年度間参照（行25移行基本報酬=P25、行38-62の人件費・固定費=P列参照）が#REF!エラー化 → 元の値(8200, 230000, 126000等)で静的修正。全5シートエラー0件、給付費合計が元データと完全一致を確認。元シートはバックアップ保持。 | F5: R3～R7年度の収支計画書5シート作成完了。全数値一致・エラー0件。
A6: 5 | B6: 46069 | C6: R3〜R7全収支計画書の罫線途切れ・レイアウト統一を依頼 | D6: 5シートの罫線とフォントサイズをR3基準で統一修正 | E6: R5-R7: フォントサイズをsz:6に統一(E列〜P列の全データエリア)。R6: 行39-55の罫線完全欠落を修正(A-P全列)。R7: E38:P38のbottom罫線欠落、E57:P57のbottom罫線欠落を修正。R5-R7: D38/D48のright:medium罫線修正、D58-D62のleft/right:thin統一。 | F6: 全5シートの罫線パターンがR3基準と一致。フォントサイズ統一完了。検証済み。
A7: 6 | B7: 46069 | C7: 5か年計画の開始年月を設定するシートを作成したい。稼働日数と基本報酬単価も含める。 | D7: 「設定」シートを新規作成。計画開始設定（年・月・年度区切り）、5か年度一覧（自動生成）、報酬単価・稼働率テーブルを配置。 | E7: 開始年(西暦)→令和自動変換。年度区切り(4月/1月)ドロップダウン。年度名称・西暦・期間を数式で自動生成。報酬単価6項目×5年度(既存データから初期値設定)。稼働日数・稼働率も年度別入力。入力セルは黄色背景・青文字、計算セルは灰色背景。データ検証(年:2020-2050, 月:1-12)追加。 | F7: 設定シート完成。B4=2021(令和3年)開始、4月始まりで5年分自動生成。初期値は既存R3-R7データに基づき設定済み。
A8: 6 | B8: 46069 | C8: 稼働日を「歴日−8日」の数式に変更してほしいと依頼 | D8: 全5シートの収支計画書の稼働日（行4）を動的数式に変更。設定シートの年間稼働日も連動数式に更新 | E8: 数式: =DAY(EOMONTH(DATE(年,月,1),0))-8 を使用。R3〜R7の各収支計画書E4:P4に適用。設定シートC14等は=SUM('RX年度 収支計画書'!E4:P4)で自動集計。損益資金計画シートには稼働日行は存在しなかった | F8: 全5シート（R3〜R7収支計画書）の稼働日が歴日-8の動的数式に変更完了。設定シートの年間稼働日も連動。例: 4月=30-8=22日, 2月=28-8=20日（閏年は29-8=21日）
A9: 7 | B9: 46069 | C9: R3損益資金計画のA1等の年度固定値を設定シートに基づき自動変更してほしい | D9: 全7シートの年度表記を設定シート参照の数式に変更 | E9: R3/R4損益資金計画のA1、R3〜R7収支計画書のD2を設定シートの年度名称(C11,E11,G11,I11,K11)への参照数式に変更。ユーザーはB4を2026、B7を8に変更済みで、全シートが「令和8年度」〜「令和12年度」に自動更新された | F9: 全7シートの年度表記が設定シート連動に変更完了。設定シートの開始年を変えるだけで全シート一括更新される
A10: 8 | B10: 46069 | C10: 設定シートに基本報酬単価・社会保険料率等の毎年変更項目の参照を作成してほしい | D10: 設定シートに社会保険料率(行26)を追加。全5シートの収支計画書(R3〜R7)の報酬単価・稼働率・社保率を設定シート参照数式に書き換え | E10: 設定シート: セクション名を「基本報酬単価・料率設定」に変更、行26に社会保険料率を追加(R3/R4=13%, R5-R7=15%)。各収支計画書: 行23-29(単価6項目+稼働率)を=設定!$X$Yの絶対参照に、行55(社保)を=E54*設定!$X$26に変更。E列設定後copyToRangeでF〜P列に展開。稼働率はR3=0.8, R4-R7=0.8に統一（設定シート値を反映） | F10: 全5シートの報酬単価・稼働率・社会保険料率が設定シートから一元管理可能に。設定シートの値を変えるだけで全シート一括更新される
A11: 9 | B11: 46069 | C11: シート名を設定シートの年度名に基づいて変更してほしい | D11: 全7シート(損益資金計画2枚+収支計画書5枚)を設定シートの年度名称でリネーム | E11: R3年度→令和8年度, R4年度→令和9年度, R5年度→令和10年度, R6年度→令和11年度, R7年度→令和12年度。Excelがシート間参照の数式を自動更新。注意: シート名は数式で動的に変更不可のため、設定シートの年度変更時は再度リネームが必要 | F11: 全7シートが令和8〜12年度の名称に変更完了。シート間参照も自動更新済み
A12: 10 | B12: 46069 | C12: シート名を「初年度」「2年目」〜「5年目」の表現に変更してほしい | D12: 全7シートを初年度/2年目〜5年目の表記にリネーム | E12: 令和X年度→初年度〜5年目に変更。損益資金計画2枚+収支計画書5枚。設定シート等のシート間参照数式もExcelが自動更新済み | F12: 完了。年度に依存しない汎用的なシート名になり、設定シートで年度を変えてもシート名変更不要
A13: 11 | B13: 46070 | C13: 初年度末BSの貸借差額235,200円の修正依頼 | D13: E4とE5の数式を修正し、重複参照と不要項目を除去 | E13: E4: O34(地代家賃=10,000)がE3と重複→除去。E5: O30(法定福利費=25,200)がE4と重複→除去。E5: O22(工賃=200,000)は月次支払済のため除去。修正後: E4=146,200、E5=1,267,060 | F13: 貸借一致: 資産合計2,865,360 = 負債・資本合計2,865,360。差額0円。
... A16: 14 | B16: 46070 | C16: ユーザーが追加したPL・CFシートの内容確認を依頼 | D16: PLシート(sheetId:25)とCFシート(sheetId:26)の全データ・数式・構造を確認 | E16: PL: 5年分(H23-H27)の損益計算書。外部ファイル(和良経営管理表)から数式リンク。D-H列にデータあり。下部にサマリー(行46-51)と比率分析(行53-58)。CF: 5年分のキャッシュフロー計算書。経常収支・財務収支・DCF評価額を含む。I-M列は年度番号と割引率パラメータ。全数式が外部ファイル参照。 | F16: PL・CF両シートとも外部ファイル[和良経営管理表(Ver1.0).xlsx]基礎シートへの数式リンクで構成。旧年度(H23-H27)のデータ。I-M列は削除済みだが年度番号のみ残存。
A17: Turn 16 | B17: 46070 | C17: PLシートに損益資金計画（初年度～5年目）のデータを反映させてほしい | D17: PLシートの行ラベル書き換え、年度ヘッダー更新、数式リンク作成 | E17: 行構造: 旧飲食FC用→福祉事業用に全面書き換え。3行挿入(原価内訳5→8項目)。D-H列を各年度の損益資金計画!P列にリンク。年度ヘッダー=設定シート参照。税金=IF(経常利益<0,0,経常利益*0.4)。サマリー行49-54・比率行56-61も再計算。 | F17: PL完成: 令和8-12年度の5年間PL。総売上2,719,700→78,124,100へ成長。初年度赤字(-5,847,900)、2年目以降黒字化。全セル数式リンク済み、動的更新対応。
A18: 18 | B18: 46070 | C18: CFシート更新依頼（CFお願い）- 損益資金計画データとリンク | D18: CFシート全面更新: ラベル変更、5年分の数式作成、DCF評価更新 | E18: 行ラベルを飲食FC→福祉事業に変更（訓練給付金、就労売上、人件費等）。D-H列に5年分の数式を設定。数式パターン: =SUM('N年目 損益資金計画'!D行:O行)で月次→年間合計。内部計算式: 経常収支差額=収入-支出、CF=経常+財務、税引後CF=CF-税金、翌年度繰越=前年度+税引後CF。DCF行(43-48)も更新。年度ヘッダーは設定シート参照。 | F18: CF完了。全数式エラーなし。5年目翌年度繰越=64,316,221円。2年目以降の財務収支は損益資金計画未入力のため0。割引率(I43)未設定のためDCF割引未適用。
A19: 19 | B19: 46070 | C19: 設定シートにサービス種類（A型・B型・移行支援）、定員数（入力）、必要人員数（自動計算）のセクションを追加してほしい | D19: 設定シート行32-49に2セクション追加: 入力セクション（サービス種類/定員/配置比率）+ 自動計算セクション（利用者数/管理者/サビ管/指導員・支援員/就労支援員/合計） | E19: 入力: B35=サービス種類(ドロップダウン:A型/B型/移行支援)、B36=定員数(整数1-200)、B37=配置比率(ドロップダウン:6:1/7.5:1/10:1)。自動計算: B42=定員×0.9(利用者数)、B43=管理者1名固定、B44=サビ管(60人以下:1)、B45=指導員・支援員(利用者数÷配置比率)、B46=就労支援員(移行支援のみ:利用者数÷15)、B48=合計。法定人員配置基準に基づく計算式。デフォルト: B型/定員20/7.5:1。 | F19: 完了。B型・定員20名・7.5:1で利用者数18人→合計4.4人（管理者1+サビ管1+指導員・支援員2.4+就労支援員0）。ドロップダウン変更で自動再計算される。
A20: Turn 20 | B20: 46070 | C20: 人件費計算シート完成（前ターン継続）。初年度の総合計行追加、数式検証、その後2年目～5年目のテンプレートを展開、5年間サマリーテーブル作成 | D20: 人件費計算シート(sheetId:27)に5年分完成。各年度: 個人別給与10人枠+社保5項目+合計行。サマリーテーブルを行118-125に追加 | E20: 構造: R13-32(初年度), R34-53(2年目), R55-74(3年目), R76-95(4年目), R97-116(5年目), R118-125(サマリー)。社保率はB5:B9参照。介護保険はSUMPRODUCTで○印のみ計算。初年度は入社月制御付き。月額ヘッダーのテキスト比較問題を発見・修正済。年間合計: 初年度¥6,167,440, 2-5年目各¥15,291,360 | F20: 5年分完成。合計: 給与¥58,120,000+社保¥9,212,880=人件費¥67,332,880。次: 損益資金計画・収支計画書へのリンク接続
A21: Turn 21 | B21: 46070 | C21: 5つの損益資金計画シート（初年度～5年目）をドロップダウン式で1シートに集約できるか質問 | D21: 損益資金計画（集約）シート作成。A1にドロップダウン、CHOOSE関数で全セルを動的参照 | E21: INDIRECT関数がブロックされたため、CHOOSE($U$2,各シート!$X$Y)方式に切替。A1:P73全セル（ラベル+数値）を5シート対応のCHOOSE関数化。U2=MATCH(A1,S1:S5)でインデックス算出。S1:T5にルックアップテーブル配置・グループ化で非表示。書式はcopyFrom(formats)でソースシートから複製。ゼロ非表示:#,##0;-#,##0;""。相対参照ずれバグを発見→絶対参照($X$Y)で全数式を再構築。行1-2フリーズ。P1に「▼年度切替」表示。 | F21: 完成。A1ドロップダウンで初年度～5年目を切替可能。初年度表示確認済: 総売上2,719,700、経常利益-5,847,900。2年目切替時は総売上39,574,500に変わる見込み。元の5シートは変更なし。
A22: Turn 22 | B22: 46070 | C22: 初年度 損益資金計画のA43が集約シートに反映されていない→設定シート連動に変更を選択 | D22: 全5シートの損益資金計画A43を設定シート連動の数式に変更 | E22: 各シートA43: 旧「ＲX年度 資金繰表」(固定値) → 新=設定!X11&" 資金繰表"(数式)。初年度=C11, 2年目=E11, 3年目=G11, 4年目=I11, 5年目=K11。集約シートのCHOOSE関数は変更不要（元シートのA43を参照しているため自動反映）。 | F22: 完了。全5シートA43が設定シート連動に。初年度=令和8年度 資金繰表、2年目=令和9年度 資金繰表...5年目=令和12年度 資金繰表。集約シートでも正常反映確認済み。

Sheet 設定
A1: ５か年 収支計画 設定シート
A3: ■ 計画開始設定
A4: 開始年（西暦） | B4: 2026 | C4: ← 年を入力
A5: 開始月 | B5: 4 | C5: ← 月を入力（1〜12）
A6: 年度区切り | B6: 4月始まり | C6: ← 4月始まり / 1月始まり
A7: 令和年対応 | B7: =B4-2018 -> 8 | C7: ← 自動計算（令和）
A9: ■ ５か年度 一覧（自動生成）
C10: 初年度 | E10: 2年度 | G10: 3年度 | I10: 4年度 | K10: 5年度
A11: 年度名称 | C11: ="令和"&B7&"年度" -> 令和8年度 | E11: ="令和"&B7+1&"年度" -> 令和9年度 | G11: ="令和"&B7+2&"年度" -> 令和10年度 | I11: ="令和"&B7+3&"年度" -> 令和11年度 | K11: ="令和"&B7+4&"年度" -> 令和12年度
A12: 西暦 | C12: =B4&"年" -> 2026年 | E12: =B4+1&"年" -> 2027年 | G12: =B4+2&"年" -> 2028年 | I12: =B4+3&"年" -> 2029年 | K12: =B4+4&"年" -> 2030年
A13: 期間 | C13: =B5&"月〜"&IF(B6="4月始まり","3月","12月") -> 4月〜3月 | E13: =IF(B6="4月始まり","4月〜3月","1月〜12月") -> 4月〜3月 | G13: =E13 -> 4月〜3月 | I13: =E13 -> 4月〜3月 | K13: =E13 -> 4月〜3月
A14: 稼働日数（年間） | C14: =SUM('初年度 収支計画書'!E4:P4) -> 269 | D14: 日 | E14: =SUM('2年目 収支計画書'!E4:P4) -> 269 | F14: 日 | G14: =SUM('3年目 収支計画書'!E4:P4) -> 269 | H14: 日 | I14: =SUM('4年目 収支計画書'!E4:P4) -> 270 | J14: 日 | K14: =SUM('5年目 収支計画書'!E4:P4) -> 269 | L14: 日
A16: ■ 基本報酬単価・料率設定
A17: 項目 | C17: =C11 -> 令和8年度 | E17: =E11 -> 令和9年度 | G17: =G11 -> 令和10年度 | I17: =I11 -> 令和11年度 | K17: =K11 -> 令和12年度
A18: B基本報酬 | C18: 5890 | E18: 5890 | G18: 5890 | I18: 5890 | K18: 5890
A19: B施設外基本報酬 | C19: 6890 | E19: 6890 | G19: 6890 | I19: 6890 | K19: 6890
A20: 移行基本報酬 | C20: 8200 | E20: 8200 | G20: 8080 | I20: 8080 | K20: 8080
A21: 移行施設外基本報酬 | C21: 8200 | E21: 8200 | G21: 9080 | I21: 9080 | K21: 9080
A22: 目標工賃達成指導員加算 | C22: 890 | E22: 890 | G22: 890 | I22: 890 | K22: 890
A23: 送迎加算 | C23: 540 | E23: 540 | G23: 540 | I23: 540 | K23: 540
A25: 稼働率 | C25: 0.8 | E25: 0.8 | G25: 0.8 | I25: 0.8 | K25: 0.8
A26: 社会保険料率 | C26: 0.13 | E26: 0.13 | G26: 0.15 | I26: 0.15 | K26: 0.15
A28: ■ 凡例
A29: █ 黄色背景・青文字 | B29: 入力セル（変更可能）
A30: █ 灰色背景 | B30: 自動計算セル（変更不可）
A32: ■ サービス種類・定員・人員配置設定
A34: 項目 | B34: 設定値 | C34: 説明
A35: サービス種類 | B35: 移行支援 | C35: ← A型 / B型 / 移行支援
A36: 定員数 | B36: 20 | C36: ← 人数を入力
A37: 配置比率 | B37: 7.5:1 | C37: ← 6:1 / 7.5:1 / 10:1（移行支援は6:1固定）
A39: ■ 必要人員数（自動計算）
A41: 職種 | B41: 必要人数（常勤換算） | C41: 算出根拠
A42: 利用者数（定員×0.9） | B42: =B36*0.9 -> 18 | C42: 定員×0.9（新規指定6ヶ月未満の場合）
A43: 管理者 | B43: 1 | C43: 常勤1人（サビ管兼務可）
A44: サービス管理責任者 | B44: =IF(B42<=60,1,1+ROUNDUP((B42-60)/40,0)) -> 1 | C44: 利用者60人以下:1人、61人以上:+40人ごとに1人
A45: 職業指導員・生活支援員 | B45: =ROUNDUP(B42/IF(B37="6:1",6,IF(B37="7.5:1",7.5,10)),1) -> 2.4 | C45: ="利用者数÷"&IF(B37="6:1","6",IF(B37="7.5:1","7.5","10"))&"（常勤換算）※いずれか1人以上常勤" -> 利用者数÷7.5（常勤換算）※いずれか1人以上常勤
A46: 就労支援員 | B46: =IF(B35="移行支援",MAX(1,ROUNDUP(B42/15,1)),0) -> 1.2 | C46: =IF(B35="移行支援","利用者数÷15（常勤換算）※移行支援のみ","※移行支援のみ配置") -> 利用者数÷15（常勤換算）※移行支援のみ
A48: 合計必要人員数 | B48: =B43+B44+B45+B46 -> 5.6 | C48: ="管理者+サビ管+指導員・支援員"&IF(B35="移行支援","+就労支援員","") -> 管理者+サビ管+指導員・支援員+就労支援員
A49: ※管理者とサビ管の兼務が可能な場合、実質的な最低人数は合計-1人

Sheet 損益資金計画（集約）
A1: 2年目 | B1: =CHOOSE($U$2,'初年度 損益資金計画'!$A$1,'2年目 損益資金計画'!$A$1,'3年目 損益資金計画'!$A$1,'4年目 損益資金計画'!$A$1,'5年目 損益資金計画'!$A$1) -> 令和9年度 | D1: =CHOOSE($U$2,'初年度 損益資金計画'!$D$1,'2年目 損益資金計画'!$D$1,'3年目 損益資金計画'!$D$1,'4年目 損益資金計画'!$D$1,'5年目 損益資金計画'!$D$1) -> 0 | E1: =CHOOSE($U$2,'初年度 損益資金計画'!$E$1,'2年目 損益資金計画'!$E$1,'3年目 損益資金計画'!$E$1,'4年目 損益資金計画'!$E$1,'5年目 損益資金計画'!$E$1) -> 0 | F1: =CHOOSE($U$2,'初年度 損益資金計画'!$F$1,'2年目 損益資金計画'!$F$1,'3年目 損益資金計画'!$F$1,'4年目 損益資金計画'!$F$1,'5年目 損益資金計画'!$F$1) -> 0 | G1: =CHOOSE($U$2,'初年度 損益資金計画'!$G$1,'2年目 損益資金計画'!$G$1,'3年目 損益資金計画'!$G$1,'4年目 損益資金計画'!$G$1,'5年目 損益資金計画'!$G$1) -> 0 | H1: =CHOOSE($U$2,'初年度 損益資金計画'!$H$1,'2年目 損益資金計画'!$H$1,'3年目 損益資金計画'!$H$1,'4年目 損益資金計画'!$H$1,'5年目 損益資金計画'!$H$1) -> 0 | I1: =CHOOSE($U$2,'初年度 損益資金計画'!$I$1,'2年目 損益資金計画'!$I$1,'3年目 損益資金計画'!$I$1,'4年目 損益資金計画'!$I$1,'5年目 損益資金計画'!$I$1) -> 0 | J1: =CHOOSE($U$2,'初年度 損益資金計画'!$J$1,'2年目 損益資金計画'!$J$1,'3年目 損益資金計画'!$J$1,'4年目 損益資金計画'!$J$1,'5年目 損益資金計画'!$J$1) -> 0 | K1: =CHOOSE($U$2,'初年度 損益資金計画'!$K$1,'2年目 損益資金計画'!$K$1,'3年目 損益資金計画'!$K$1,'4年目 損益資金計画'!$K$1,'5年目 損益資金計画'!$K$1) -> 0 | L1: =CHOOSE($U$2,'初年度 損益資金計画'!$L$1,'2年目 損益資金計画'!$L$1,'3年目 損益資金計画'!$L$1,'4年目 損益資金計画'!$L$1,'5年目 損益資金計画'!$L$1) -> 0 | M1: =CHOOSE($U$2,'初年度 損益資金計画'!$M$1,'2年目 損益資金計画'!$M$1,'3年目 損益資金計画'!$M$1,'4年目 損益資金計画'!$M$1,'5年目 損益資金計画'!$M$1) -> 0 | N1: =CHOOSE($U$2,'初年度 損益資金計画'!$N$1,'2年目 損益資金計画'!$N$1,'3年目 損益資金計画'!$N$1,'4年目 損益資金計画'!$N$1,'5年目 損益資金計画'!$N$1) -> 0 | O1: =CHOOSE($U$2,'初年度 損益資金計画'!$O$1,'2年目 損益資金計画'!$O$1,'3年目 損益資金計画'!$O$1,'4年目 損益資金計画'!$O$1,'5年目 損益資金計画'!$O$1) -> 0 | P1: =CHOOSE($U$2,'初年度 損益資金計画'!$P$1,'2年目 損益資金計画'!$P$1,'3年目 損益資金計画'!$P$1,'4年目 損益資金計画'!$P$1,'5年目 損益資金計画'!$P$1) -> 0 | S1: 初年度 | T1: 初年度 損益資金計画 | U1: YearIndex
A2: =CHOOSE($U$2,'初年度 損益資金計画'!$A$2,'2年目 損益資金計画'!$A$2,'3年目 損益資金計画'!$A$2,'4年目 損益資金計画'!$A$2,'5年目 損益資金計画'!$A$2) -> 0 | D2: =CHOOSE($U$2,'初年度 損益資金計画'!$D$2,'2年目 損益資金計画'!$D$2,'3年目 損益資金計画'!$D$2,'4年目 損益資金計画'!$D$2,'5年目 損益資金計画'!$D$2) -> ４月 | E2: =CHOOSE($U$2,'初年度 損益資金計画'!$E$2,'2年目 損益資金計画'!$E$2,'3年目 損益資金計画'!$E$2,'4年目 損益資金計画'!$E$2,'5年目 損益資金計画'!$E$2) -> ５月 | F2: =CHOOSE($U$2,'初年度 損益資金計画'!$F$2,'2年目 損益資金計画'!$F$2,'3年目 損益資金計画'!$F$2,'4年目 損益資金計画'!$F$2,'5年目 損益資金計画'!$F$2) -> ６月 | G2: =CHOOSE($U$2,'初年度 損益資金計画'!$G$2,'2年目 損益資金計画'!$G$2,'3年目 損益資金計画'!$G$2,'4年目 損益資金計画'!$G$2,'5年目 損益資金計画'!$G$2) -> ７月 | H2: =CHOOSE($U$2,'初年度 損益資金計画'!$H$2,'2年目 損益資金計画'!$H$2,'3年目 損益資金計画'!$H$2,'4年目 損益資金計画'!$H$2,'5年目 損益資金計画'!$H$2) -> ８月 | I2: =CHOOSE($U$2,'初年度 損益資金計画'!$I$2,'2年目 損益資金計画'!$I$2,'3年目 損益資金計画'!$I$2,'4年目 損益資金計画'!$I$2,'5年目 損益資金計画'!$I$2) -> ９月 | J2: =CHOOSE($U$2,'初年度 損益資金計画'!$J$2,'2年目 損益資金計画'!$J$2,'3年目 損益資金計画'!$J$2,'4年目 損益資金計画'!$J$2,'5年目 損益資金計画'!$J$2) -> １０月 | K2: =CHOOSE($U$2,'初年度 損益資金計画'!$K$2,'2年目 損益資金計画'!$K$2,'3年目 損益資金計画'!$K$2,'4年目 損益資金計画'!$K$2,'5年目 損益資金計画'!$K$2) -> １１月 | L2: =CHOOSE($U$2,'初年度 損益資金計画'!$L$2,'2年目 損益資金計画'!$L$2,'3年目 損益資金計画'!$L$2,'4年目 損益資金計画'!$L$2,'5年目 損益資金計画'!$L$2) -> １２月 | M2: =CHOOSE($U$2,'初年度 損益資金計画'!$M$2,'2年目 損益資金計画'!$M$2,'3年目 損益資金計画'!$M$2,'4年目 損益資金計画'!$M$2,'5年目 損益資金計画'!$M$2) -> １月 | N2: =CHOOSE($U$2,'初年度 損益資金計画'!$N$2,'2年目 損益資金計画'!$N$2,'3年目 損益資金計画'!$N$2,'4年目 損益資金計画'!$N$2,'5年目 損益資金計画'!$N$2) -> ２月 | O2: =CHOOSE($U$2,'初年度 損益資金計画'!$O$2,'2年目 損益資金計画'!$O$2,'3年目 損益資金計画'!$O$2,'4年目 損益資金計画'!$O$2,'5年目 損益資金計画'!$O$2) -> ３月 | P2: =CHOOSE($U$2,'初年度 損益資金計画'!$P$2,'2年目 損益資金計画'!$P$2,'3年目 損益資金計画'!$P$2,'4年目 損益資金計画'!$P$2,'5年目 損益資金計画'!$P$2) -> 合計 | S2: 2年目 | T2: 2年目 損益資金計画 | U2: =MATCH(A1,$S$1:$S$5,0) -> 2
A3: =CHOOSE($U$2,'初年度 損益資金計画'!$A$3,'2年目 損益資金計画'!$A$3,'3年目 損益資金計画'!$A$3,'4年目 損益資金計画'!$A$3,'5年目 損益資金計画'!$A$3) -> 総売上 | D3: =CHOOSE($U$2,'初年度 損益資金計画'!$D$3,'2年目 損益資金計画'!$D$3,'3年目 損益資金計画'!$D$3,'4年目 損益資金計画'!$D$3,'5年目 損益資金計画'!$D$3) -> 1898400 | E3: =CHOOSE($U$2,'初年度 損益資金計画'!$E$3,'2年目 損益資金計画'!$E$3,'3年目 損益資金計画'!$E$3,'4年目 損益資金計画'!$E$3,'5年目 損益資金計画'!$E$3) -> 2359800 | F3: =CHOOSE($U$2,'初年度 損益資金計画'!$F$3,'2年目 損益資金計画'!$F$3,'3年目 損益資金計画'!$F$3,'4年目 損益資金計画'!$F$3,'5年目 損益資金計画'!$F$3) -> 2807300 | G3: =CHOOSE($U$2,'初年度 損益資金計画'!$G$3,'2年目 損益資金計画'!$G$3,'3年目 損益資金計画'!$G$3,'4年目 損益資金計画'!$G$3,'5年目 損益資金計画'!$G$3) -> 2849200 | H3: =CHOOSE($U$2,'初年度 損益資金計画'!$H$3,'2年目 損益資金計画'!$H$3,'3年目 損益資金計画'!$H$3,'4年目 損益資金計画'!$H$3,'5年目 損益資金計画'!$H$3) -> 3156900 | I3: =CHOOSE($U$2,'初年度 損益資金計画'!$I$3,'2年目 損益資金計画'!$I$3,'3年目 損益資金計画'!$I$3,'4年目 損益資金計画'!$I$3,'5年目 損益資金計画'!$I$3) -> 3436500 | J3: =CHOOSE($U$2,'初年度 損益資金計画'!$J$3,'2年目 損益資金計画'!$J$3,'3年目 損益資金計画'!$J$3,'4年目 損益資金計画'!$J$3,'5年目 損益資金計画'!$J$3) -> 3583400 | K3: =CHOOSE($U$2,'初年度 損益資金計画'!$K$3,'2年目 損益資金計画'!$K$3,'3年目 損益資金計画'!$K$3,'4年目 損益資金計画'!$K$3,'5年目 損益資金計画'!$K$3) -> 3730200 | L3: =CHOOSE($U$2,'初年度 損益資金計画'!$L$3,'2年目 損益資金計画'!$L$3,'3年目 損益資金計画'!$L$3,'4年目 損益資金計画'!$L$3,'5年目 損益資金計画'!$L$3) -> 3555300 | M3: =CHOOSE($U$2,'初年度 損益資金計画'!$M$3,'2年目 損益資金計画'!$M$3,'3年目 損益資金計画'!$M$3,'4年目 損益資金計画'!$M$3,'5年目 損益資金計画'!$M$3) -> 3520400 | N3: =CHOOSE($U$2,'初年度 損益資金計画'!$N$3,'2年目 損益資金計画'!$N$3,'3年目 損益資金計画'!$N$3,'4年目 損益資金計画'!$N$3,'5年目 損益資金計画'!$N$3) -> 3996000 | O3: =CHOOSE($U$2,'初年度 損益資金計画'!$O$3,'2年目 損益資金計画'!$O$3,'3年目 損益資金計画'!$O$3,'4年目 損益資金計画'!$O$3,'5年目 損益資金計画'!$O$3) -> 4681100 | P3: =CHOOSE($U$2,'初年度 損益資金計画'!$P$3,'2年目 損益資金計画'!$P$3,'3年目 損益資金計画'!$P$3,'4年目 損益資金計画'!$P$3,'5年目 損益資金計画'!$P$3) -> 39574500 | S3: 3年目 | T3: 3年目 損益資金計画
A4: =CHOOSE($U$2,'初年度 損益資金計画'!$A$4,'2年目 損益資金計画'!$A$4,'3年目 損益資金計画'!$A$4,'4年目 損益資金計画'!$A$4,'5年目 損益資金計画'!$A$4) -> 0 | B4: =CHOOSE($U$2,'初年度 損益資金計画'!$B$4,'2年目 損益資金計画'!$B$4,'3年目 損益資金計画'!$B$4,'4年目 損益資金計画'!$B$4,'5年目 損益資金計画'!$B$4) -> 0 | C4: =CHOOSE($U$2,'初年度 損益資金計画'!$C$4,'2年目 損益資金計画'!$C$4,'3年目 損益資金計画'!$C$4,'4年目 損益資金計画'!$C$4,'5年目 損益資金計画'!$C$4) -> 利用者総数 | D4: =CHOOSE($U$2,'初年度 損益資金計画'!$D$4,'2年目 損益資金計画'!$D$4,'3年目 損益資金計画'!$D$4,'4年目 損益資金計画'!$D$4,'5年目 損益資金計画'!$D$4) -> 10 | E4: =CHOOSE($U$2,'初年度 損益資金計画'!$E$4,'2年目 損益資金計画'!$E$4,'3年目 損益資金計画'!$E$4,'4年目 損益資金計画'!$E$4,'5年目 損益資金計画'!$E$4) -> 14 | F4: =CHOOSE($U$2,'初年度 損益資金計画'!$F$4,'2年目 損益資金計画'!$F$4,'3年目 損益資金計画'!$F$4,'4年目 損益資金計画'!$F$4,'5年目 損益資金計画'!$F$4) -> 15 | G4: =CHOOSE($U$2,'初年度 損益資金計画'!$G$4,'2年目 損益資金計画'!$G$4,'3年目 損益資金計画'!$G$4,'4年目 損益資金計画'!$G$4,'5年目 損益資金計画'!$G$4) -> 16 | H4: =CHOOSE($U$2,'初年度 損益資金計画'!$H$4,'2年目 損益資金計画'!$H$4,'3年目 損益資金計画'!$H$4,'4年目 損益資金計画'!$H$4,'5年目 損益資金計画'!$H$4) -> 19 | I4: =CHOOSE($U$2,'初年度 損益資金計画'!$I$4,'2年目 損益資金計画'!$I$4,'3年目 損益資金計画'!$I$4,'4年目 損益資金計画'!$I$4,'5年目 損益資金計画'!$I$4) -> 20 | J4: =CHOOSE($U$2,'初年度 損益資金計画'!$J$4,'2年目 損益資金計画'!$J$4,'3年目 損益資金計画'!$J$4,'4年目 損益資金計画'!$J$4,'5年目 損益資金計画'!$J$4) -> 21 | K4: =CHOOSE($U$2,'初年度 損益資金計画'!$K$4,'2年目 損益資金計画'!$K$4,'3年目 損益資金計画'!$K$4,'4年目 損益資金計画'!$K$4,'5年目 損益資金計画'!$K$4) -> 22 | L4: =CHOOSE($U$2,'初年度 損益資金計画'!$L$4,'2年目 損益資金計画'!$L$4,'3年目 損益資金計画'!$L$4,'4年目 損益資金計画'!$L$4,'5年目 損益資金計画'!$L$4) -> 23 | M4: =CHOOSE($U$2,'初年度 損益資金計画'!$M$4,'2年目 損益資金計画'!$M$4,'3年目 損益資金計画'!$M$4,'4年目 損益資金計画'!$M$4,'5年目 損益資金計画'!$M$4) -> 24 | N4: =CHOOSE($U$2,'初年度 損益資金計画'!$N$4,'2年目 損益資金計画'!$N$4,'3年目 損益資金計画'!$N$4,'4年目 損益資金計画'!$N$4,'5年目 損益資金計画'!$N$4) -> 25 | O4: =CHOOSE($U$2,'初年度 損益資金計画'!$O$4,'2年目 損益資金計画'!$O$4,'3年目 損益資金計画'!$O$4,'4年目 損益資金計画'!$O$4,'5年目 損益資金計画'!$O$4) -> 26 | P4: =CHOOSE($U$2,'初年度 損益資金計画'!$P$4,'2年目 損益資金計画'!$P$4,'3年目 損益資金計画'!$P$4,'4年目 損益資金計画'!$P$4,'5年目 損益資金計画'!$P$4) -> 0 | S4: 4年目 | T4: 4年目 損益資金計画
B5: =CHOOSE($U$2,'初年度 損益資金計画'!$B$5,'2年目 損益資金計画'!$B$5,'3年目 損益資金計画'!$B$5,'4年目 損益資金計画'!$B$5,'5年目 損益資金計画'!$B$5) -> 訓練給付金等 | D5: =CHOOSE($U$2,'初年度 損益資金計画'!$D$5,'2年目 損益資金計画'!$D$5,'3年目 損益資金計画'!$D$5,'4年目 損益資金計画'!$D$5,'5年目 損益資金計画'!$D$5) -> 1398400 | E5: =CHOOSE($U$2,'初年度 損益資金計画'!$E$5,'2年目 損益資金計画'!$E$5,'3年目 損益資金計画'!$E$5,'4年目 損益資金計画'!$E$5,'5年目 損益資金計画'!$E$5) -> 1859800 | F5: =CHOOSE($U$2,'初年度 損益資金計画'!$F$5,'2年目 損益資金計画'!$F$5,'3年目 損益資金計画'!$F$5,'4年目 損益資金計画'!$F$5,'5年目 損益資金計画'!$F$5) -> 2307300 | G5: =CHOOSE($U$2,'初年度 損益資金計画'!$G$5,'2年目 損益資金計画'!$G$5,'3年目 損益資金計画'!$G$5,'4年目 損益資金計画'!$G$5,'5年目 損益資金計画'!$G$5) -> 2349200 | H5: =CHOOSE($U$2,'初年度 損益資金計画'!$H$5,'2年目 損益資金計画'!$H$5,'3年目 損益資金計画'!$H$5,'4年目 損益資金計画'!$H$5,'5年目 損益資金計画'!$H$5) -> 2656900 | I5: =CHOOSE($U$2,'初年度 損益資金計画'!$I$5,'2年目 損益資金計画'!$I$5,'3年目 損益資金計画'!$I$5,'4年目 損益資金計画'!$I$5,'5年目 損益資金計画'!$I$5) -> 2936500 | J5: =CHOOSE($U$2,'初年度 損益資金計画'!$J$5,'2年目 損益資金計画'!$J$5,'3年目 損益資金計画'!$J$5,'4年目 損益資金計画'!$J$5,'5年目 損益資金計画'!$J$5) -> 3083400 | K5: =CHOOSE($U$2,'初年度 損益資金計画'!$K$5,'2年目 損益資金計画'!$K$5,'3年目 損益資金計画'!$K$5,'4年目 損益資金計画'!$K$5,'5年目 損益資金計画'!$K$5) -> 3230200 | L5: =CHOOSE($U$2,'初年度 損益資金計画'!$L$5,'2年目 損益資金計画'!$L$5,'3年目 損益資金計画'!$L$5,'4年目 損益資金計画'!$L$5,'5年目 損益資金計画'!$L$5) -> 3055300 | M5: =CHOOSE($U$2,'初年度 損益資金計画'!$M$5,'2年目 損益資金計画'!$M$5,'3年目 損益資金計画'!$M$5,'4年目 損益資金計画'!$M$5,'5年目 損益資金計画'!$M$5) -> 3020400 | N5: =CHOOSE($U$2,'初年度 損益資金計画'!$N$5,'2年目 損益資金計画'!$N$5,'3年目 損益資金計画'!$N$5,'4年目 損益資金計画'!$N$5,'5年目 損益資金計画'!$N$5) -> 3496000 | O5: =CHOOSE($U$2,'初年度 損益資金計画'!$O$5,'2年目 損益資金計画'!$O$5,'3年目 損益資金計画'!$O$5,'4年目 損益資金計画'!$O$5,'5年目 損益資金計画'!$O$5) -> 4181100 | P5: =CHOOSE($U$2,'初年度 損益資金計画'!$P$5,'2年目 損益資金計画'!$P$5,'3年目 損益資金計画'!$P$5,'4年目 損益資金計画'!$P$5,'5年目 損益資金計画'!$P$5) -> 33574500 | S5: 5年目 | T5: 5年目 損益資金計画
B6: =CHOOSE($U$2,'初年度 損益資金計画'!$B$6,'2年目 損益資金計画'!$B$6,'3年目 損益資金計画'!$B$6,'4年目 損益資金計画'!$B$6,'5年目 損益資金計画'!$B$6) -> 0 | C6: =CHOOSE($U$2,'初年度 損益資金計画'!$C$6,'2年目 損益資金計画'!$C$6,'3年目 損益資金計画'!$C$6,'4年目 損益資金計画'!$C$6,'5年目 損益資金計画'!$C$6) -> コーリングサポ笠岡 | D6: =CHOOSE($U$2,'初年度 損益資金計画'!$D$6,'2年目 損益資金計画'!$D$6,'3年目 損益資金計画'!$D$6,'4年目 損益資金計画'!$D$6,'5年目 損益資金計画'!$D$6) -> 1398400 | E6: =CHOOSE($U$2,'初年度 損益資金計画'!$E$6,'2年目 損益資金計画'!$E$6,'3年目 損益資金計画'!$E$6,'4年目 損益資金計画'!$E$6,'5年目 損益資金計画'!$E$6) -> 1859800 | F6: =CHOOSE($U$2,'初年度 損益資金計画'!$F$6,'2年目 損益資金計画'!$F$6,'3年目 損益資金計画'!$F$6,'4年目 損益資金計画'!$F$6,'5年目 損益資金計画'!$F$6) -> 2307300 | G6: =CHOOSE($U$2,'初年度 損益資金計画'!$G$6,'2年目 損益資金計画'!$G$6,'3年目 損益資金計画'!$G$6,'4年目 損益資金計画'!$G$6,'5年目 損益資金計画'!$G$6) -> 2349200 | H6: =CHOOSE($U$2,'初年度 損益資金計画'!$H$6,'2年目 損益資金計画'!$H$6,'3年目 損益資金計画'!$H$6,'4年目 損益資金計画'!$H$6,'5年目 損益資金計画'!$H$6) -> 2656900 | I6: =CHOOSE($U$2,'初年度 損益資金計画'!$I$6,'2年目 損益資金計画'!$I$6,'3年目 損益資金計画'!$I$6,'4年目 損益資金計画'!$I$6,'5年目 損益資金計画'!$I$6) -> 2936500 | J6: =CHOOSE($U$2,'初年度 損益資金計画'!$J$6,'2年目 損益資金計画'!$J$6,'3年目 損益資金計画'!$J$6,'4年目 損益資金計画'!$J$6,'5年目 損益資金計画'!$J$6) -> 3083400 | K6: =CHOOSE($U$2,'初年度 損益資金計画'!$K$6,'2年目 損益資金計画'!$K$6,'3年目 損益資金計画'!$K$6,'4年目 損益資金計画'!$K$6,'5年目 損益資金計画'!$K$6) -> 3230200 | L6: =CHOOSE($U$2,'初年度 損益資金計画'!$L$6,'2年目 損益資金計画'!$L$6,'3年目 損益資金計画'!$L$6,'4年目 損益資金計画'!$L$6,'5年目 損益資金計画'!$L$6) -> 3055300 | M6: =CHOOSE($U$2,'初年度 損益資金計画'!$M$6,'2年目 損益資金計画'!$M$6,'3年目 損益資金計画'!$M$6,'4年目 損益資金計画'!$M$6,'5年目 損益資金計画'!$M$6) -> 3020400 | N6: =CHOOSE($U$2,'初年度 損益資金計画'!$N$6,'2年目 損益資金計画'!$N$6,'3年目 損益資金計画'!$N$6,'4年目 損益資金計画'!$N$6,'5年目 損益資金計画'!$N$6) -> 3496000 | O6: =CHOOSE($U$2,'初年度 損益資金計画'!$O$6,'2年目 損益資金計画'!$O$6,'3年目 損益資金計画'!$O$6,'4年目 損益資金計画'!$O$6,'5年目 損益資金計画'!$O$6) -> 4181100 | P6: =CHOOSE($U$2,'初年度 損益資金計画'!$P$6,'2年目 損益資金計画'!$P$6,'3年目 損益資金計画'!$P$6,'4年目 損益資金計画'!$P$6,'5年目 損益資金計画'!$P$6) -> 33574500
C7: =CHOOSE($U$2,'初年度 損益資金計画'!$C$7,'2年目 損益資金計画'!$C$7,'3年目 損益資金計画'!$C$7,'4年目 損益資金計画'!$C$7,'5年目 損益資金計画'!$C$7) -> 0 | D7: =CHOOSE($U$2,'初年度 損益資金計画'!$D$7,'2年目 損益資金計画'!$D$7,'3年目 損益資金計画'!$D$7,'4年目 損益資金計画'!$D$7,'5年目 損益資金計画'!$D$7) -> 0 | E7: =CHOOSE($U$2,'初年度 損益資金計画'!$E$7,'2年目 損益資金計画'!$E$7,'3年目 損益資金計画'!$E$7,'4年目 損益資金計画'!$E$7,'5年目 損益資金計画'!$E$7) -> 0 | F7: =CHOOSE($U$2,'初年度 損益資金計画'!$F$7,'2年目 損益資金計画'!$F$7,'3年目 損益資金計画'!$F$7,'4年目 損益資金計画'!$F$7,'5年目 損益資金計画'!$F$7) -> 0 | G7: =CHOOSE($U$2,'初年度 損益資金計画'!$G$7,'2年目 損益資金計画'!$G$7,'3年目 損益資金計画'!$G$7,'4年目 損益資金計画'!$G$7,'5年目 損益資金計画'!$G$7) -> 0 | H7: =CHOOSE($U$2,'初年度 損益資金計画'!$H$7,'2年目 損益資金計画'!$H$7,'3年目 損益資金計画'!$H$7,'4年目 損益資金計画'!$H$7,'5年目 損益資金計画'!$H$7) -> 0 | I7: =CHOOSE($U$2,'初年度 損益資金計画'!$I$7,'2年目 損益資金計画'!$I$7,'3年目 損益資金計画'!$I$7,'4年目 損益資金計画'!$I$7,'5年目 損益資金計画'!$I$7) -> 0 | J7: =CHOOSE($U$2,'初年度 損益資金計画'!$J$7,'2年目 損益資金計画'!$J$7,'3年目 損益資金計画'!$J$7,'4年目 損益資金計画'!$J$7,'5年目 損益資金計画'!$J$7) -> 0 | K7: =CHOOSE($U$2,'初年度 損益資金計画'!$K$7,'2年目 損益資金計画'!$K$7,'3年目 損益資金計画'!$K$7,'4年目 損益資金計画'!$K$7,'5年目 損益資金計画'!$K$7) -> 0 | L7: =CHOOSE($U$2,'初年度 損益資金計画'!$L$7,'2年目 損益資金計画'!$L$7,'3年目 損益資金計画'!$L$7,'4年目 損益資金計画'!$L$7,'5年目 損益資金計画'!$L$7) -> 0 | M7: =CHOOSE($U$2,'初年度 損益資金計画'!$M$7,'2年目 損益資金計画'!$M$7,'3年目 損益資金計画'!$M$7,'4年目 損益資金計画'!$M$7,'5年目 損益資金計画'!$M$7) -> 0 | N7: =CHOOSE($U$2,'初年度 損益資金計画'!$N$7,'2年目 損益資金計画'!$N$7,'3年目 損益資金計画'!$N$7,'4年目 損益資金計画'!$N$7,'5年目 損益資金計画'!$N$7) -> 0 | O7: =CHOOSE($U$2,'初年度 損益資金計画'!$O$7,'2年目 損益資金計画'!$O$7,'3年目 損益資金計画'!$O$7,'4年目 損益資金計画'!$O$7,'5年目 損益資金計画'!$O$7) -> 0 | P7: =CHOOSE($U$2,'初年度 損益資金計画'!$P$7,'2年目 損益資金計画'!$P$7,'3年目 損益資金計画'!$P$7,'4年目 損益資金計画'!$P$7,'5年目 損益資金計画'!$P$7) -> 0
C8: =CHOOSE($U$2,'初年度 損益資金計画'!$C$8,'2年目 損益資金計画'!$C$8,'3年目 損益資金計画'!$C$8,'4年目 損益資金計画'!$C$8,'5年目 損益資金計画'!$C$8) -> 0 | D8: =CHOOSE($U$2,'初年度 損益資金計画'!$D$8,'2年目 損益資金計画'!$D$8,'3年目 損益資金計画'!$D$8,'4年目 損益資金計画'!$D$8,'5年目 損益資金計画'!$D$8) -> 0 | E8: =CHOOSE($U$2,'初年度 損益資金計画'!$E$8,'2年目 損益資金計画'!$E$8,'3年目 損益資金計画'!$E$8,'4年目 損益資金計画'!$E$8,'5年目 損益資金計画'!$E$8) -> 0 | F8: =CHOOSE($U$2,'初年度 損益資金計画'!$F$8,'2年目 損益資金計画'!$F$8,'3年目 損益資金計画'!$F$8,'4年目 損益資金計画'!$F$8,'5年目 損益資金計画'!$F$8) -> 0 | G8: =CHOOSE($U$2,'初年度 損益資金計画'!$G$8,'2年目 損益資金計画'!$G$8,'3年目 損益資金計画'!$G$8,'4年目 損益資金計画'!$G$8,'5年目 損益資金計画'!$G$8) -> 0 | H8: =CHOOSE($U$2,'初年度 損益資金計画'!$H$8,'2年目 損益資金計画'!$H$8,'3年目 損益資金計画'!$H$8,'4年目 損益資金計画'!$H$8,'5年目 損益資金計画'!$H$8) -> 0 | I8: =CHOOSE($U$2,'初年度 損益資金計画'!$I$8,'2年目 損益資金計画'!$I$8,'3年目 損益資金計画'!$I$8,'4年目 損益資金計画'!$I$8,'5年目 損益資金計画'!$I$8) -> 0 | J8: =CHOOSE($U$2,'初年度 損益資金計画'!$J$8,'2年目 損益資金計画'!$J$8,'3年目 損益資金計画'!$J$8,'4年目 損益資金計画'!$J$8,'5年目 損益資金計画'!$J$8) -> 0 | K8: =CHOOSE($U$2,'初年度 損益資金計画'!$K$8,'2年目 損益資金計画'!$K$8,'3年目 損益資金計画'!$K$8,'4年目 損益資金計画'!$K$8,'5年目 損益資金計画'!$K$8) -> 0 | L8: =CHOOSE($U$2,'初年度 損益資金計画'!$L$8,'2年目 損益資金計画'!$L$8,'3年目 損益資金計画'!$L$8,'4年目 損益資金計画'!$L$8,'5年目 損益資金計画'!$L$8) -> 0 | M8: =CHOOSE($U$2,'初年度 損益資金計画'!$M$8,'2年目 損益資金計画'!$M$8,'3年目 損益資金計画'!$M$8,'4年目 損益資金計画'!$M$8,'5年目 損益資金計画'!$M$8) -> 0 | N8: =CHOOSE($U$2,'初年度 損益資金計画'!$N$8,'2年目 損益資金計画'!$N$8,'3年目 損益資金計画'!$N$8,'4年目 損益資金計画'!$N$8,'5年目 損益資金計画'!$N$8) -> 0 | O8: =CHOOSE($U$2,'初年度 損益資金計画'!$O$8,'2年目 損益資金計画'!$O$8,'3年目 損益資金計画'!$O$8,'4年目 損益資金計画'!$O$8,'5年目 損益資金計画'!$O$8) -> 0 | P8: =CHOOSE($U$2,'初年度 損益資金計画'!$P$8,'2年目 損益資金計画'!$P$8,'3年目 損益資金計画'!$P$8,'4年目 損益資金計画'!$P$8,'5年目 損益資金計画'!$P$8) -> 0
B9: =CHOOSE($U$2,'初年度 損益資金計画'!$B$9,'2年目 損益資金計画'!$B$9,'3年目 損益資金計画'!$B$9,'4年目 損益資金計画'!$B$9,'5年目 損益資金計画'!$B$9) -> 福祉的就労売上 | D9: =CHOOSE($U$2,'初年度 損益資金計画'!$D$9,'2年目 損益資金計画'!$D$9,'3年目 損益資金計画'!$D$9,'4年目 損益資金計画'!$D$9,'5年目 損益資金計画'!$D$9) -> 500000 | E9: =CHOOSE($U$2,'初年度 損益資金計画'!$E$9,'2年目 損益資金計画'!$E$9,'3年目 損益資金計画'!$E$9,'4年目 損益資金計画'!$E$9,'5年目 損益資金計画'!$E$9) -> 500000 | F9: =CHOOSE($U$2,'初年度 損益資金計画'!$F$9,'2年目 損益資金計画'!$F$9,'3年目 損益資金計画'!$F$9,'4年目 損益資金計画'!$F$9,'5年目 損益資金計画'!$F$9) -> 500000 | G9: =CHOOSE($U$2,'初年度 損益資金計画'!$G$9,'2年目 損益資金計画'!$G$9,'3年目 損益資金計画'!$G$9,'4年目 損益資金計画'!$G$9,'5年目 損益資金計画'!$G$9) -> 500000 | H9: =CHOOSE($U$2,'初年度 損益資金計画'!$H$9,'2年目 損益資金計画'!$H$9,'3年目 損益資金計画'!$H$9,'4年目 損益資金計画'!$H$9,'5年目 損益資金計画'!$H$9) -> 500000 | I9: =CHOOSE($U$2,'初年度 損益資金計画'!$I$9,'2年目 損益資金計画'!$I$9,'3年目 損益資金計画'!$I$9,'4年目 損益資金計画'!$I$9,'5年目 損益資金計画'!$I$9) -> 500000 | J9: =CHOOSE($U$2,'初年度 損益資金計画'!$J$9,'2年目 損益資金計画'!$J$9,'3年目 損益資金計画'!$J$9,'4年目 損益資金計画'!$J$9,'5年目 損益資金計画'!$J$9) -> 500000 | K9: =CHOOSE($U$2,'初年度 損益資金計画'!$K$9,'2年目 損益資金計画'!$K$9,'3年目 損益資金計画'!$K$9,'4年目 損益資金計画'!$K$9,'5年目 損益資金計画'!$K$9) -> 500000 | L9: =CHOOSE($U$2,'初年度 損益資金計画'!$L$9,'2年目 損益資金計画'!$L$9,'3年目 損益資金計画'!$L$9,'4年目 損益資金計画'!$L$9,'5年目 損益資金計画'!$L$9) -> 500000 | M9: =CHOOSE($U$2,'初年度 損益資金計画'!$M$9,'2年目 損益資金計画'!$M$9,'3年目 損益資金計画'!$M$9,'4年目 損益資金計画'!$M$9,'5年目 損益資金計画'!$M$9) -> 500000 | N9: =CHOOSE($U$2,'初年度 損益資金計画'!$N$9,'2年目 損益資金計画'!$N$9,'3年目 損益資金計画'!$N$9,'4年目 損益資金計画'!$N$9,'5年目 損益資金計画'!$N$9) -> 500000 | O9: =CHOOSE($U$2,'初年度 損益資金計画'!$O$9,'2年目 損益資金計画'!$O$9,'3年目 損益資金計画'!$O$9,'4年目 損益資金計画'!$O$9,'5年目 損益資金計画'!$O$9) -> 500000 | P9: =CHOOSE($U$2,'初年度 損益資金計画'!$P$9,'2年目 損益資金計画'!$P$9,'3年目 損益資金計画'!$P$9,'4年目 損益資金計画'!$P$9,'5年目 損益資金計画'!$P$9) -> 6000000
B10: =CHOOSE($U$2,'初年度 損益資金計画'!$B$10,'2年目 損益資金計画'!$B$10,'3年目 損益資金計画'!$B$10,'4年目 損益資金計画'!$B$10,'5年目 損益資金計画'!$B$10) -> 0 | C10: =CHOOSE($U$2,'初年度 損益資金計画'!$C$10,'2年目 損益資金計画'!$C$10,'3年目 損益資金計画'!$C$10,'4年目 損益資金計画'!$C$10,'5年目 損益資金計画'!$C$10) -> 0 | D10: =CHOOSE($U$2,'初年度 損益資金計画'!$D$10,'2年目 損益資金計画'!$D$10,'3年目 損益資金計画'!$D$10,'4年目 損益資金計画'!$D$10,'5年目 損益資金計画'!$D$10) -> 500000 | E10: =CHOOSE($U$2,'初年度 損益資金計画'!$E$10,'2年目 損益資金計画'!$E$10,'3年目 損益資金計画'!$E$10,'4年目 損益資金計画'!$E$10,'5年目 損益資金計画'!$E$10) -> 500000 | F10: =CHOOSE($U$2,'初年度 損益資金計画'!$F$10,'2年目 損益資金計画'!$F$10,'3年目 損益資金計画'!$F$10,'4年目 損益資金計画'!$F$10,'5年目 損益資金計画'!$F$10) -> 500000 | G10: =CHOOSE($U$2,'初年度 損益資金計画'!$G$10,'2年目 損益資金計画'!$G$10,'3年目 損益資金計画'!$G$10,'4年目 損益資金計画'!$G$10,'5年目 損益資金計画'!$G$10) -> 500000 | H10: =CHOOSE($U$2,'初年度 損益資金計画'!$H$10,'2年目 損益資金計画'!$H$10,'3年目 損益資金計画'!$H$10,'4年目 損益資金計画'!$H$10,'5年目 損益資金計画'!$H$10) -> 500000 | I10: =CHOOSE($U$2,'初年度 損益資金計画'!$I$10,'2年目 損益資金計画'!$I$10,'3年目 損益資金計画'!$I$10,'4年目 損益資金計画'!$I$10,'5年目 損益資金計画'!$I$10) -> 500000 | J10: =CHOOSE($U$2,'初年度 損益資金計画'!$J$10,'2年目 損益資金計画'!$J$10,'3年目 損益資金計画'!$J$10,'4年目 損益資金計画'!$J$10,'5年目 損益資金計画'!$J$10) -> 500000 | K10: =CHOOSE($U$2,'初年度 損益資金計画'!$K$10,'2年目 損益資金計画'!$K$10,'3年目 損益資金計画'!$K$10,'4年目 損益資金計画'!$K$10,'5年目 損益資金計画'!$K$10) -> 500000 | L10: =CHOOSE($U$2,'初年度 損益資金計画'!$L$10,'2年目 損益資金計画'!$L$10,'3年目 損益資金計画'!$L$10,'4年目 損益資金計画'!$L$10,'5年目 損益資金計画'!$L$10) -> 500000 | M10: =CHOOSE($U$2,'初年度 損益資金計画'!$M$10,'2年目 損益資金計画'!$M$10,'3年目 損益資金計画'!$M$10,'4年目 損益資金計画'!$M$10,'5年目 損益資金計画'!$M$10) -> 500000 | N10: =CHOOSE($U$2,'初年度 損益資金計画'!$N$10,'2年目 損益資金計画'!$N$10,'3年目 損益資金計画'!$N$10,'4年目 損益資金計画'!$N$10,'5年目 損益資金計画'!$N$10) -> 500000 | O10: =CHOOSE($U$2,'初年度 損益資金計画'!$O$10,'2年目 損益資金計画'!$O$10,'3年目 損益資金計画'!$O$10,'4年目 損益資金計画'!$O$10,'5年目 損益資金計画'!$O$10) -> 500000 | P10: =CHOOSE($U$2,'初年度 損益資金計画'!$P$10,'2年目 損益資金計画'!$P$10,'3年目 損益資金計画'!$P$10,'4年目 損益資金計画'!$P$10,'5年目 損益資金計画'!$P$10) -> 6000000
C11: =CHOOSE($U$2,'初年度 損益資金計画'!$C$11,'2年目 損益資金計画'!$C$11,'3年目 損益資金計画'!$C$11,'4年目 損益資金計画'!$C$11,'5年目 損益資金計画'!$C$11) -> 0 | D11: =CHOOSE($U$2,'初年度 損益資金計画'!$D$11,'2年目 損益資金計画'!$D$11,'3年目 損益資金計画'!$D$11,'4年目 損益資金計画'!$D$11,'5年目 損益資金計画'!$D$11) -> 0 | E11: =CHOOSE($U$2,'初年度 損益資金計画'!$E$11,'2年目 損益資金計画'!$E$11,'3年目 損益資金計画'!$E$11,'4年目 損益資金計画'!$E$11,'5年目 損益資金計画'!$E$11) -> 0 | F11: =CHOOSE($U$2,'初年度 損益資金計画'!$F$11,'2年目 損益資金計画'!$F$11,'3年目 損益資金計画'!$F$11,'4年目 損益資金計画'!$F$11,'5年目 損益資金計画'!$F$11) -> 0 | G11: =CHOOSE($U$2,'初年度 損益資金計画'!$G$11,'2年目 損益資金計画'!$G$11,'3年目 損益資金計画'!$G$11,'4年目 損益資金計画'!$G$11,'5年目 損益資金計画'!$G$11) -> 0 | H11: =CHOOSE($U$2,'初年度 損益資金計画'!$H$11,'2年目 損益資金計画'!$H$11,'3年目 損益資金計画'!$H$11,'4年目 損益資金計画'!$H$11,'5年目 損益資金計画'!$H$11) -> 0 | I11: =CHOOSE($U$2,'初年度 損益資金計画'!$I$11,'2年目 損益資金計画'!$I$11,'3年目 損益資金計画'!$I$11,'4年目 損益資金計画'!$I$11,'5年目 損益資金計画'!$I$11) -> 0 | J11: =CHOOSE($U$2,'初年度 損益資金計画'!$J$11,'2年目 損益資金計画'!$J$11,'3年目 損益資金計画'!$J$11,'4年目 損益資金計画'!$J$11,'5年目 損益資金計画'!$J$11) -> 0 | K11: =CHOOSE($U$2,'初年度 損益資金計画'!$K$11,'2年目 損益資金計画'!$K$11,'3年目 損益資金計画'!$K$11,'4年目 損益資金計画'!$K$11,'5年目 損益資金計画'!$K$11) -> 0 | L11: =CHOOSE($U$2,'初年度 損益資金計画'!$L$11,'2年目 損益資金計画'!$L$11,'3年目 損益資金計画'!$L$11,'4年目 損益資金計画'!$L$11,'5年目 損益資金計画'!$L$11) -> 0 | M11: =CHOOSE($U$2,'初年度 損益資金計画'!$M$11,'2年目 損益資金計画'!$M$11,'3年目 損益資金計画'!$M$11,'4年目 損益資金計画'!$M$11,'5年目 損益資金計画'!$M$11) -> 0 | N11: =CHOOSE($U$2,'初年度 損益資金計画'!$N$11,'2年目 損益資金計画'!$N$11,'3年目 損益資金計画'!$N$11,'4年目 損益資金計画'!$N$11,'5年目 損益資金計画'!$N$11) -> 0 | O11: =CHOOSE($U$2,'初年度 損益資金計画'!$O$11,'2年目 損益資金計画'!$O$11,'3年目 損益資金計画'!$O$11,'4年目 損益資金計画'!$O$11,'5年目 損益資金計画'!$O$11) -> 0 | P11: =CHOOSE($U$2,'初年度 損益資金計画'!$P$11,'2年目 損益資金計画'!$P$11,'3年目 損益資金計画'!$P$11,'4年目 損益資金計画'!$P$11,'5年目 損益資金計画'!$P$11) -> 0
B12: =CHOOSE($U$2,'初年度 損益資金計画'!$B$12,'2年目 損益資金計画'!$B$12,'3年目 損益資金計画'!$B$12,'4年目 損益資金計画'!$B$12,'5年目 損益資金計画'!$B$12) -> 特定困難者受給 | D12: =CHOOSE($U$2,'初年度 損益資金計画'!$D$12,'2年目 損益資金計画'!$D$12,'3年目 損益資金計画'!$D$12,'4年目 損益資金計画'!$D$12,'5年目 損益資金計画'!$D$12) -> 0 | E12: =CHOOSE($U$2,'初年度 損益資金計画'!$E$12,'2年目 損益資金計画'!$E$12,'3年目 損益資金計画'!$E$12,'4年目 損益資金計画'!$E$12,'5年目 損益資金計画'!$E$12) -> 0 | F12: =CHOOSE($U$2,'初年度 損益資金計画'!$F$12,'2年目 損益資金計画'!$F$12,'3年目 損益資金計画'!$F$12,'4年目 損益資金計画'!$F$12,'5年目 損益資金計画'!$F$12) -> 0 | G12: =CHOOSE($U$2,'初年度 損益資金計画'!$G$12,'2年目 損益資金計画'!$G$12,'3年目 損益資金計画'!$G$12,'4年目 損益資金計画'!$G$12,'5年目 損益資金計画'!$G$12) -> 0 | H12: =CHOOSE($U$2,'初年度 損益資金計画'!$H$12,'2年目 損益資金計画'!$H$12,'3年目 損益資金計画'!$H$12,'4年目 損益資金計画'!$H$12,'5年目 損益資金計画'!$H$12) -> 0 | I12: =CHOOSE($U$2,'初年度 損益資金計画'!$I$12,'2年目 損益資金計画'!$I$12,'3年目 損益資金計画'!$I$12,'4年目 損益資金計画'!$I$12,'5年目 損益資金計画'!$I$12) -> 0 | J12: =CHOOSE($U$2,'初年度 損益資金計画'!$J$12,'2年目 損益資金計画'!$J$12,'3年目 損益資金計画'!$J$12,'4年目 損益資金計画'!$J$12,'5年目 損益資金計画'!$J$12) -> 0 | K12: =CHOOSE($U$2,'初年度 損益資金計画'!$K$12,'2年目 損益資金計画'!$K$12,'3年目 損益資金計画'!$K$12,'4年目 損益資金計画'!$K$12,'5年目 損益資金計画'!$K$12) -> 0 | L12: =CHOOSE($U$2,'初年度 損益資金計画'!$L$12,'2年目 損益資金計画'!$L$12,'3年目 損益資金計画'!$L$12,'4年目 損益資金計画'!$L$12,'5年目 損益資金計画'!$L$12) -> 0 | M12: =CHOOSE($U$2,'初年度 損益資金計画'!$M$12,'2年目 損益資金計画'!$M$12,'3年目 損益資金計画'!$M$12,'4年目 損益資金計画'!$M$12,'5年目 損益資金計画'!$M$12) -> 0 | N12: =CHOOSE($U$2,'初年度 損益資金計画'!$N$12,'2年目 損益資金計画'!$N$12,'3年目 損益資金計画'!$N$12,'4年目 損益資金計画'!$N$12,'5年目 損益資金計画'!$N$12) -> 0 | O12: =CHOOSE($U$2,'初年度 損益資金計画'!$O$12,'2年目 損益資金計画'!$O$12,'3年目 損益資金計画'!$O$12,'4年目 損益資金計画'!$O$12,'5年目 損益資金計画'!$O$12) -> 0 | P12: =CHOOSE($U$2,'初年度 損益資金計画'!$P$12,'2年目 損益資金計画'!$P$12,'3年目 損益資金計画'!$P$12,'4年目 損益資金計画'!$P$12,'5年目 損益資金計画'!$P$12) -> 0
B13: =CHOOSE($U$2,'初年度 損益資金計画'!$B$13,'2年目 損益資金計画'!$B$13,'3年目 損益資金計画'!$B$13,'4年目 損益資金計画'!$B$13,'5年目 損益資金計画'!$B$13) -> その他収入 | D13: =CHOOSE($U$2,'初年度 損益資金計画'!$D$13,'2年目 損益資金計画'!$D$13,'3年目 損益資金計画'!$D$13,'4年目 損益資金計画'!$D$13,'5年目 損益資金計画'!$D$13) -> 0 | E13: =CHOOSE($U$2,'初年度 損益資金計画'!$E$13,'2年目 損益資金計画'!$E$13,'3年目 損益資金計画'!$E$13,'4年目 損益資金計画'!$E$13,'5年目 損益資金計画'!$E$13) -> 0 | F13: =CHOOSE($U$2,'初年度 損益資金計画'!$F$13,'2年目 損益資金計画'!$F$13,'3年目 損益資金計画'!$F$13,'4年目 損益資金計画'!$F$13,'5年目 損益資金計画'!$F$13) -> 0 | G13: =CHOOSE($U$2,'初年度 損益資金計画'!$G$13,'2年目 損益資金計画'!$G$13,'3年目 損益資金計画'!$G$13,'4年目 損益資金計画'!$G$13,'5年目 損益資金計画'!$G$13) -> 0 | H13: =CHOOSE($U$2,'初年度 損益資金計画'!$H$13,'2年目 損益資金計画'!$H$13,'3年目 損益資金計画'!$H$13,'4年目 損益資金計画'!$H$13,'5年目 損益資金計画'!$H$13) -> 0 | I13: =CHOOSE($U$2,'初年度 損益資金計画'!$I$13,'2年目 損益資金計画'!$I$13,'3年目 損益資金計画'!$I$13,'4年目 損益資金計画'!$I$13,'5年目 損益資金計画'!$I$13) -> 0 | J13: =CHOOSE($U$2,'初年度 損益資金計画'!$J$13,'2年目 損益資金計画'!$J$13,'3年目 損益資金計画'!$J$13,'4年目 損益資金計画'!$J$13,'5年目 損益資金計画'!$J$13) -> 0 | K13: =CHOOSE($U$2,'初年度 損益資金計画'!$K$13,'2年目 損益資金計画'!$K$13,'3年目 損益資金計画'!$K$13,'4年目 損益資金計画'!$K$13,'5年目 損益資金計画'!$K$13) -> 0 | L13: =CHOOSE($U$2,'初年度 損益資金計画'!$L$13,'2年目 損益資金計画'!$L$13,'3年目 損益資金計画'!$L$13,'4年目 損益資金計画'!$L$13,'5年目 損益資金計画'!$L$13) -> 0 | M13: =CHOOSE($U$2,'初年度 損益資金計画'!$M$13,'2年目 損益資金計画'!$M$13,'3年目 損益資金計画'!$M$13,'4年目 損益資金計画'!$M$13,'5年目 損益資金計画'!$M$13) -> 0 | N13: =CHOOSE($U$2,'初年度 損益資金計画'!$N$13,'2年目 損益資金計画'!$N$13,'3年目 損益資金計画'!$N$13,'4年目 損益資金計画'!$N$13,'5年目 損益資金計画'!$N$13) -> 0 | O13: =CHOOSE($U$2,'初年度 損益資金計画'!$O$13,'2年目 損益資金計画'!$O$13,'3年目 損益資金計画'!$O$13,'4年目 損益資金計画'!$O$13,'5年目 損益資金計画'!$O$13) -> 0 | P13: =CHOOSE($U$2,'初年度 損益資金計画'!$P$13,'2年目 損益資金計画'!$P$13,'3年目 損益資金計画'!$P$13,'4年目 損益資金計画'!$P$13,'5年目 損益資金計画'!$P$13) -> 0
A14: =CHOOSE($U$2,'初年度 損益資金計画'!$A$14,'2年目 損益資金計画'!$A$14,'3年目 損益資金計画'!$A$14,'4年目 損益資金計画'!$A$14,'5年目 損益資金計画'!$A$14) -> 0 | B14: =CHOOSE($U$2,'初年度 損益資金計画'!$B$14,'2年目 損益資金計画'!$B$14,'3年目 損益資金計画'!$B$14,'4年目 損益資金計画'!$B$14,'5年目 損益資金計画'!$B$14) -> 部門別経費 | D14: =CHOOSE($U$2,'初年度 損益資金計画'!$D$14,'2年目 損益資金計画'!$D$14,'3年目 損益資金計画'!$D$14,'4年目 損益資金計画'!$D$14,'5年目 損益資金計画'!$D$14) -> 1853830 | E14: =CHOOSE($U$2,'初年度 損益資金計画'!$E$14,'2年目 損益資金計画'!$E$14,'3年目 損益資金計画'!$E$14,'4年目 損益資金計画'!$E$14,'5年目 損益資金計画'!$E$14) -> 1353830 | F14: =CHOOSE($U$2,'初年度 損益資金計画'!$F$14,'2年目 損益資金計画'!$F$14,'3年目 損益資金計画'!$F$14,'4年目 損益資金計画'!$F$14,'5年目 損益資金計画'!$F$14) -> 1353830 | G14: =CHOOSE($U$2,'初年度 損益資金計画'!$G$14,'2年目 損益資金計画'!$G$14,'3年目 損益資金計画'!$G$14,'4年目 損益資金計画'!$G$14,'5年目 損益資金計画'!$G$14) -> 1353830 | H14: =CHOOSE($U$2,'初年度 損益資金計画'!$H$14,'2年目 損益資金計画'!$H$14,'3年目 損益資金計画'!$H$14,'4年目 損益資金計画'!$H$14,'5年目 損益資金計画'!$H$14) -> 1353830 | I14: =CHOOSE($U$2,'初年度 損益資金計画'!$I$14,'2年目 損益資金計画'!$I$14,'3年目 損益資金計画'!$I$14,'4年目 損益資金計画'!$I$14,'5年目 損益資金計画'!$I$14) -> 1353830 | J14: =CHOOSE($U$2,'初年度 損益資金計画'!$J$14,'2年目 損益資金計画'!$J$14,'3年目 損益資金計画'!$J$14,'4年目 損益資金計画'!$J$14,'5年目 損益資金計画'!$J$14) -> 1353830 | K14: =CHOOSE($U$2,'初年度 損益資金計画'!$K$14,'2年目 損益資金計画'!$K$14,'3年目 損益資金計画'!$K$14,'4年目 損益資金計画'!$K$14,'5年目 損益資金計画'!$K$14) -> 1353830 | L14: =CHOOSE($U$2,'初年度 損益資金計画'!$L$14,'2年目 損益資金計画'!$L$14,'3年目 損益資金計画'!$L$14,'4年目 損益資金計画'!$L$14,'5年目 損益資金計画'!$L$14) -> 2257830 | M14: =CHOOSE($U$2,'初年度 損益資金計画'!$M$14,'2年目 損益資金計画'!$M$14,'3年目 損益資金計画'!$M$14,'4年目 損益資金計画'!$M$14,'5年目 損益資金計画'!$M$14) -> 1353830 | N14: =CHOOSE($U$2,'初年度 損益資金計画'!$N$14,'2年目 損益資金計画'!$N$14,'3年目 損益資金計画'!$N$14,'4年目 損益資金計画'!$N$14,'5年目 損益資金計画'!$N$14) -> 1353830 | O14: =CHOOSE($U$2,'初年度 損益資金計画'!$O$14,'2年目 損益資金計画'!$O$14,'3年目 損益資金計画'!$O$14,'4年目 損益資金計画'!$O$14,'5年目 損益資金計画'!$O$14) -> 1353830 | P14: =CHOOSE($U$2,'初年度 損益資金計画'!$P$14,'2年目 損益資金計画'!$P$14,'3年目 損益資金計画'!$P$14,'4年目 損益資金計画'!$P$14,'5年目 損益資金計画'!$P$14) -> 17649960
A15: =CHOOSE($U$2,'初年度 損益資金計画'!$A$15,'2年目 損益資金計画'!$A$15,'3年目 損益資金計画'!$A$15,'4年目 損益資金計画'!$A$15,'5年目 損益資金計画'!$A$15) -> 0 | B15: =CHOOSE($U$2,'初年度 損益資金計画'!$B$15,'2年目 損益資金計画'!$B$15,'3年目 損益資金計画'!$B$15,'4年目 損益資金計画'!$B$15,'5年目 損益資金計画'!$B$15) -> 訓練給付金等 | D15: =CHOOSE($U$2,'初年度 損益資金計画'!$D$15,'2年目 損益資金計画'!$D$15,'3年目 損益資金計画'!$D$15,'4年目 損益資金計画'!$D$15,'5年目 損益資金計画'!$D$15) -> 1353830 | E15: =CHOOSE($U$2,'初年度 損益資金計画'!$E$15,'2年目 損益資金計画'!$E$15,'3年目 損益資金計画'!$E$15,'4年目 損益資金計画'!$E$15,'5年目 損益資金計画'!$E$15) -> 1353830 | F15: =CHOOSE($U$2,'初年度 損益資金計画'!$F$15,'2年目 損益資金計画'!$F$15,'3年目 損益資金計画'!$F$15,'4年目 損益資金計画'!$F$15,'5年目 損益資金計画'!$F$15) -> 1353830 | G15: =CHOOSE($U$2,'初年度 損益資金計画'!$G$15,'2年目 損益資金計画'!$G$15,'3年目 損益資金計画'!$G$15,'4年目 損益資金計画'!$G$15,'5年目 損益資金計画'!$G$15) -> 1353830 | H15: =CHOOSE($U$2,'初年度 損益資金計画'!$H$15,'2年目 損益資金計画'!$H$15,'3年目 損益資金計画'!$H$15,'4年目 損益資金計画'!$H$15,'5年目 損益資金計画'!$H$15) -> 1353830 | I15: =CHOOSE($U$2,'初年度 損益資金計画'!$I$15,'2年目 損益資金計画'!$I$15,'3年目 損益資金計画'!$I$15,'4年目 損益資金計画'!$I$15,'5年目 損益資金計画'!$I$15) -> 1353830 | J15: =CHOOSE($U$2,'初年度 損益資金計画'!$J$15,'2年目 損益資金計画'!$J$15,'3年目 損益資金計画'!$J$15,'4年目 損益資金計画'!$J$15,'5年目 損益資金計画'!$J$15) -> 1353830 | K15: =CHOOSE($U$2,'初年度 損益資金計画'!$K$15,'2年目 損益資金計画'!$K$15,'3年目 損益資金計画'!$K$15,'4年目 損益資金計画'!$K$15,'5年目 損益資金計画'!$K$15) -> 1353830 | L15: =CHOOSE($U$2,'初年度 損益資金計画'!$L$15,'2年目 損益資金計画'!$L$15,'3年目 損益資金計画'!$L$15,'4年目 損益資金計画'!$L$15,'5年目 損益資金計画'!$L$15) -> 2257830 | M15: =CHOOSE($U$2,'初年度 損益資金計画'!$M$15,'2年目 損益資金計画'!$M$15,'3年目 損益資金計画'!$M$15,'4年目 損益資金計画'!$M$15,'5年目 損益資金計画'!$M$15) -> 1353830 | N15: =CHOOSE($U$2,'初年度 損益資金計画'!$N$15,'2年目 損益資金計画'!$N$15,'3年目 損益資金計画'!$N$15,'4年目 損益資金計画'!$N$15,'5年目 損益資金計画'!$N$15) -> 1353830 | O15: =CHOOSE($U$2,'初年度 損益資金計画'!$O$15,'2年目 損益資金計画'!$O$15,'3年目 損益資金計画'!$O$15,'4年目 損益資金計画'!$O$15,'5年目 損益資金計画'!$O$15) -> 1353830 | P15: =CHOOSE($U$2,'初年度 損益資金計画'!$P$15,'2年目 損益資金計画'!$P$15,'3年目 損益資金計画'!$P$15,'4年目 損益資金計画'!$P$15,'5年目 損益資金計画'!$P$15) -> 17149960
A16: =CHOOSE($U$2,'初年度 損益資金計画'!$A$16,'2年目 損益資金計画'!$A$16,'3年目 損益資金計画'!$A$16,'4年目 損益資金計画'!$A$16,'5年目 損益資金計画'!$A$16) -> 0 | B16: =CHOOSE($U$2,'初年度 損益資金計画'!$B$16,'2年目 損益資金計画'!$B$16,'3年目 損益資金計画'!$B$16,'4年目 損益資金計画'!$B$16,'5年目 損益資金計画'!$B$16) -> 0 | C16: =CHOOSE($U$2,'初年度 損益資金計画'!$C$16,'2年目 損益資金計画'!$C$16,'3年目 損益資金計画'!$C$16,'4年目 損益資金計画'!$C$16,'5年目 損益資金計画'!$C$16) -> 人件費 | D16: =CHOOSE($U$2,'初年度 損益資金計画'!$D$16,'2年目 損益資金計画'!$D$16,'3年目 損益資金計画'!$D$16,'4年目 損益資金計画'!$D$16,'5年目 損益資金計画'!$D$16) -> 1091000 | E16: =CHOOSE($U$2,'初年度 損益資金計画'!$E$16,'2年目 損益資金計画'!$E$16,'3年目 損益資金計画'!$E$16,'4年目 損益資金計画'!$E$16,'5年目 損益資金計画'!$E$16) -> 1091000 | F16: =CHOOSE($U$2,'初年度 損益資金計画'!$F$16,'2年目 損益資金計画'!$F$16,'3年目 損益資金計画'!$F$16,'4年目 損益資金計画'!$F$16,'5年目 損益資金計画'!$F$16) -> 1091000 | G16: =CHOOSE($U$2,'初年度 損益資金計画'!$G$16,'2年目 損益資金計画'!$G$16,'3年目 損益資金計画'!$G$16,'4年目 損益資金計画'!$G$16,'5年目 損益資金計画'!$G$16) -> 1091000 | H16: =CHOOSE($U$2,'初年度 損益資金計画'!$H$16,'2年目 損益資金計画'!$H$16,'3年目 損益資金計画'!$H$16,'4年目 損益資金計画'!$H$16,'5年目 損益資金計画'!$H$16) -> 1091000 | I16: =CHOOSE($U$2,'初年度 損益資金計画'!$I$16,'2年目 損益資金計画'!$I$16,'3年目 損益資金計画'!$I$16,'4年目 損益資金計画'!$I$16,'5年目 損益資金計画'!$I$16) -> 1091000 | J16: =CHOOSE($U$2,'初年度 損益資金計画'!$J$16,'2年目 損益資金計画'!$J$16,'3年目 損益資金計画'!$J$16,'4年目 損益資金計画'!$J$16,'5年目 損益資金計画'!$J$16) -> 1091000 | K16: =CHOOSE($U$2,'初年度 損益資金計画'!$K$16,'2年目 損益資金計画'!$K$16,'3年目 損益資金計画'!$K$16,'4年目 損益資金計画'!$K$16,'5年目 損益資金計画'!$K$16) -> 1091000 | L16: =CHOOSE($U$2,'初年度 損益資金計画'!$L$16,'2年目 損益資金計画'!$L$16,'3年目 損益資金計画'!$L$16,'4年目 損益資金計画'!$L$16,'5年目 損益資金計画'!$L$16) -> 1891000 | M16: =CHOOSE($U$2,'初年度 損益資金計画'!$M$16,'2年目 損益資金計画'!$M$16,'3年目 損益資金計画'!$M$16,'4年目 損益資金計画'!$M$16,'5年目 損益資金計画'!$M$16) -> 1091000 | N16: =CHOOSE($U$2,'初年度 損益資金計画'!$N$16,'2年目 損益資金計画'!$N$16,'3年目 損益資金計画'!$N$16,'4年目 損益資金計画'!$N$16,'5年目 損益資金計画'!$N$16) -> 1091000 | O16: =CHOOSE($U$2,'初年度 損益資金計画'!$O$16,'2年目 損益資金計画'!$O$16,'3年目 損益資金計画'!$O$16,'4年目 損益資金計画'!$O$16,'5年目 損益資金計画'!$O$16) -> 1091000 | P16: =CHOOSE($U$2,'初年度 損益資金計画'!$P$16,'2年目 損益資金計画'!$P$16,'3年目 損益資金計画'!$P$16,'4年目 損益資金計画'!$P$16,'5年目 損益資金計画'!$P$16) -> 13892000
A17: =CHOOSE($U$2,'初年度 損益資金計画'!$A$17,'2年目 損益資金計画'!$A$17,'3年目 損益資金計画'!$A$17,'4年目 損益資金計画'!$A$17,'5年目 損益資金計画'!$A$17) -> 0 | C17: =CHOOSE($U$2,'初年度 損益資金計画'!$C$17,'2年目 損益資金計画'!$C$17,'3年目 損益資金計画'!$C$17,'4年目 損益資金計画'!$C$17,'5年目 損益資金計画'!$C$17) -> 社会保険料 | D17: =CHOOSE($U$2,'初年度 損益資金計画'!$D$17,'2年目 損益資金計画'!$D$17,'3年目 損益資金計画'!$D$17,'4年目 損益資金計画'!$D$17,'5年目 損益資金計画'!$D$17) -> 141830 | E17: =CHOOSE($U$2,'初年度 損益資金計画'!$E$17,'2年目 損益資金計画'!$E$17,'3年目 損益資金計画'!$E$17,'4年目 損益資金計画'!$E$17,'5年目 損益資金計画'!$E$17) -> 141830 | F17: =CHOOSE($U$2,'初年度 損益資金計画'!$F$17,'2年目 損益資金計画'!$F$17,'3年目 損益資金計画'!$F$17,'4年目 損益資金計画'!$F$17,'5年目 損益資金計画'!$F$17) -> 141830 | G17: =CHOOSE($U$2,'初年度 損益資金計画'!$G$17,'2年目 損益資金計画'!$G$17,'3年目 損益資金計画'!$G$17,'4年目 損益資金計画'!$G$17,'5年目 損益資金計画'!$G$17) -> 141830 | H17: =CHOOSE($U$2,'初年度 損益資金計画'!$H$17,'2年目 損益資金計画'!$H$17,'3年目 損益資金計画'!$H$17,'4年目 損益資金計画'!$H$17,'5年目 損益資金計画'!$H$17) -> 141830 | I17: =CHOOSE($U$2,'初年度 損益資金計画'!$I$17,'2年目 損益資金計画'!$I$17,'3年目 損益資金計画'!$I$17,'4年目 損益資金計画'!$I$17,'5年目 損益資金計画'!$I$17) -> 141830 | J17: =CHOOSE($U$2,'初年度 損益資金計画'!$J$17,'2年目 損益資金計画'!$J$17,'3年目 損益資金計画'!$J$17,'4年目 損益資金計画'!$J$17,'5年目 損益資金計画'!$J$17) -> 141830 | K17: =CHOOSE($U$2,'初年度 損益資金計画'!$K$17,'2年目 損益資金計画'!$K$17,'3年目 損益資金計画'!$K$17,'4年目 損益資金計画'!$K$17,'5年目 損益資金計画'!$K$17) -> 141830 | L17: =CHOOSE($U$2,'初年度 損益資金計画'!$L$17,'2年目 損益資金計画'!$L$17,'3年目 損益資金計画'!$L$17,'4年目 損益資金計画'!$L$17,'5年目 損益資金計画'!$L$17) -> 245830 | M17: =CHOOSE($U$2,'初年度 損益資金計画'!$M$17,'2年目 損益資金計画'!$M$17,'3年目 損益資金計画'!$M$17,'4年目 損益資金計画'!$M$17,'5年目 損益資金計画'!$M$17) -> 141830 | N17: =CHOOSE($U$2,'初年度 損益資金計画'!$N$17,'2年目 損益資金計画'!$N$17,'3年目 損益資金計画'!$N$17,'4年目 損益資金計画'!$N$17,'5年目 損益資金計画'!$N$17) -> 141830 | O17: =CHOOSE($U$2,'初年度 損益資金計画'!$O$17,'2年目 損益資金計画'!$O$17,'3年目 損益資金計画'!$O$17,'4年目 損益資金計画'!$O$17,'5年目 損益資金計画'!$O$17) -> 141830 | P17: =CHOOSE($U$2,'初年度 損益資金計画'!$P$17,'2年目 損益資金計画'!$P$17,'3年目 損益資金計画'!$P$17,'4年目 損益資金計画'!$P$17,'5年目 損益資金計画'!$P$17) -> 1805960
A18: =CHOOSE($U$2,'初年度 損益資金計画'!$A$18,'2年目 損益資金計画'!$A$18,'3年目 損益資金計画'!$A$18,'4年目 損益資金計画'!$A$18,'5年目 損益資金計画'!$A$18) -> 0 | C18: =CHOOSE($U$2,'初年度 損益資金計画'!$C$18,'2年目 損益資金計画'!$C$18,'3年目 損益資金計画'!$C$18,'4年目 損益資金計画'!$C$18,'5年目 損益資金計画'!$C$18) -> 管理費（水道光熱燃料等） | D18: =CHOOSE($U$2,'初年度 損益資金計画'!$D$18,'2年目 損益資金計画'!$D$18,'3年目 損益資金計画'!$D$18,'4年目 損益資金計画'!$D$18,'5年目 損益資金計画'!$D$18) -> 121000 | E18: =CHOOSE($U$2,'初年度 損益資金計画'!$E$18,'2年目 損益資金計画'!$E$18,'3年目 損益資金計画'!$E$18,'4年目 損益資金計画'!$E$18,'5年目 損益資金計画'!$E$18) -> 121000 | F18: =CHOOSE($U$2,'初年度 損益資金計画'!$F$18,'2年目 損益資金計画'!$F$18,'3年目 損益資金計画'!$F$18,'4年目 損益資金計画'!$F$18,'5年目 損益資金計画'!$F$18) -> 121000 | G18: =CHOOSE($U$2,'初年度 損益資金計画'!$G$18,'2年目 損益資金計画'!$G$18,'3年目 損益資金計画'!$G$18,'4年目 損益資金計画'!$G$18,'5年目 損益資金計画'!$G$18) -> 121000 | H18: =CHOOSE($U$2,'初年度 損益資金計画'!$H$18,'2年目 損益資金計画'!$H$18,'3年目 損益資金計画'!$H$18,'4年目 損益資金計画'!$H$18,'5年目 損益資金計画'!$H$18) -> 121000 | I18: =CHOOSE($U$2,'初年度 損益資金計画'!$I$18,'2年目 損益資金計画'!$I$18,'3年目 損益資金計画'!$I$18,'4年目 損益資金計画'!$I$18,'5年目 損益資金計画'!$I$18) -> 121000 | J18: =CHOOSE($U$2,'初年度 損益資金計画'!$J$18,'2年目 損益資金計画'!$J$18,'3年目 損益資金計画'!$J$18,'4年目 損益資金計画'!$J$18,'5年目 損益資金計画'!$J$18) -> 121000 | K18: =CHOOSE($U$2,'初年度 損益資金計画'!$K$18,'2年目 損益資金計画'!$K$18,'3年目 損益資金計画'!$K$18,'4年目 損益資金計画'!$K$18,'5年目 損益資金計画'!$K$18) -> 121000 | L18: =CHOOSE($U$2,'初年度 損益資金計画'!$L$18,'2年目 損益資金計画'!$L$18,'3年目 損益資金計画'!$L$18,'4年目 損益資金計画'!$L$18,'5年目 損益資金計画'!$L$18) -> 121000 | M18: =CHOOSE($U$2,'初年度 損益資金計画'!$M$18,'2年目 損益資金計画'!$M$18,'3年目 損益資金計画'!$M$18,'4年目 損益資金計画'!$M$18,'5年目 損益資金計画'!$M$18) -> 121000 | N18: =CHOOSE($U$2,'初年度 損益資金計画'!$N$18,'2年目 損益資金計画'!$N$18,'3年目 損益資金計画'!$N$18,'4年目 損益資金計画'!$N$18,'5年目 損益資金計画'!$N$18) -> 121000 | O18: =CHOOSE($U$2,'初年度 損益資金計画'!$O$18,'2年目 損益資金計画'!$O$18,'3年目 損益資金計画'!$O$18,'4年目 損益資金計画'!$O$18,'5年目 損益資金計画'!$O$18) -> 121000 | P18: =CHOOSE($U$2,'初年度 損益資金計画'!$P$18,'2年目 損益資金計画'!$P$18,'3年目 損益資金計画'!$P$18,'4年目 損益資金計画'!$P$18,'5年目 損益資金計画'!$P$18) -> 1452000
A19: =CHOOSE($U$2,'初年度 損益資金計画'!$A$19,'2年目 損益資金計画'!$A$19,'3年目 損益資金計画'!$A$19,'4年目 損益資金計画'!$A$19,'5年目 損益資金計画'!$A$19) -> 0 | C19: =CHOOSE($U$2,'初年度 損益資金計画'!$C$19,'2年目 損益資金計画'!$C$19,'3年目 損益資金計画'!$C$19,'4年目 損益資金計画'!$C$19,'5年目 損益資金計画'!$C$19) -> 燃料代 | D19: =CHOOSE($U$2,'初年度 損益資金計画'!$D$19,'2年目 損益資金計画'!$D$19,'3年目 損益資金計画'!$D$19,'4年目 損益資金計画'!$D$19,'5年目 損益資金計画'!$D$19) -> 0 | E19: =CHOOSE($U$2,'初年度 損益資金計画'!$E$19,'2年目 損益資金計画'!$E$19,'3年目 損益資金計画'!$E$19,'4年目 損益資金計画'!$E$19,'5年目 損益資金計画'!$E$19) -> 0 | F19: =CHOOSE($U$2,'初年度 損益資金計画'!$F$19,'2年目 損益資金計画'!$F$19,'3年目 損益資金計画'!$F$19,'4年目 損益資金計画'!$F$19,'5年目 損益資金計画'!$F$19) -> 0 | G19: =CHOOSE($U$2,'初年度 損益資金計画'!$G$19,'2年目 損益資金計画'!$G$19,'3年目 損益資金計画'!$G$19,'4年目 損益資金計画'!$G$19,'5年目 損益資金計画'!$G$19) -> 0 | H19: =CHOOSE($U$2,'初年度 損益資金計画'!$H$19,'2年目 損益資金計画'!$H$19,'3年目 損益資金計画'!$H$19,'4年目 損益資金計画'!$H$19,'5年目 損益資金計画'!$H$19) -> 0 | I19: =CHOOSE($U$2,'初年度 損益資金計画'!$I$19,'2年目 損益資金計画'!$I$19,'3年目 損益資金計画'!$I$19,'4年目 損益資金計画'!$I$19,'5年目 損益資金計画'!$I$19) -> 0 | J19: =CHOOSE($U$2,'初年度 損益資金計画'!$J$19,'2年目 損益資金計画'!$J$19,'3年目 損益資金計画'!$J$19,'4年目 損益資金計画'!$J$19,'5年目 損益資金計画'!$J$19) -> 0 | K19: =CHOOSE($U$2,'初年度 損益資金計画'!$K$19,'2年目 損益資金計画'!$K$19,'3年目 損益資金計画'!$K$19,'4年目 損益資金計画'!$K$19,'5年目 損益資金計画'!$K$19) -> 0 | L19: =CHOOSE($U$2,'初年度 損益資金計画'!$L$19,'2年目 損益資金計画'!$L$19,'3年目 損益資金計画'!$L$19,'4年目 損益資金計画'!$L$19,'5年目 損益資金計画'!$L$19) -> 0 | M19: =CHOOSE($U$2,'初年度 損益資金計画'!$M$19,'2年目 損益資金計画'!$M$19,'3年目 損益資金計画'!$M$19,'4年目 損益資金計画'!$M$19,'5年目 損益資金計画'!$M$19) -> 0 | N19: =CHOOSE($U$2,'初年度 損益資金計画'!$N$19,'2年目 損益資金計画'!$N$19,'3年目 損益資金計画'!$N$19,'4年目 損益資金計画'!$N$19,'5年目 損益資金計画'!$N$19) -> 0 | O19: =CHOOSE($U$2,'初年度 損益資金計画'!$O$19,'2年目 損益資金計画'!$O$19,'3年目 損益資金計画'!$O$19,'4年目 損益資金計画'!$O$19,'5年目 損益資金計画'!$O$19) -> 0 | P19: =CHOOSE($U$2,'初年度 損益資金計画'!$P$19,'2年目 損益資金計画'!$P$19,'3年目 損益資金計画'!$P$19,'4年目 損益資金計画'!$P$19,'5年目 損益資金計画'!$P$19) -> 0
A20: =CHOOSE($U$2,'初年度 損益資金計画'!$A$20,'2年目 損益資金計画'!$A$20,'3年目 損益資金計画'!$A$20,'4年目 損益資金計画'!$A$20,'5年目 損益資金計画'!$A$20) -> 0 | C20: =CHOOSE($U$2,'初年度 損益資金計画'!$C$20,'2年目 損益資金計画'!$C$20,'3年目 損益資金計画'!$C$20,'4年目 損益資金計画'!$C$20,'5年目 損益資金計画'!$C$20) -> 諸費 | D20: =CHOOSE($U$2,'初年度 損益資金計画'!$D$20,'2年目 損益資金計画'!$D$20,'3年目 損益資金計画'!$D$20,'4年目 損益資金計画'!$D$20,'5年目 損益資金計画'!$D$20) -> 0 | E20: =CHOOSE($U$2,'初年度 損益資金計画'!$E$20,'2年目 損益資金計画'!$E$20,'3年目 損益資金計画'!$E$20,'4年目 損益資金計画'!$E$20,'5年目 損益資金計画'!$E$20) -> 0 | F20: =CHOOSE($U$2,'初年度 損益資金計画'!$F$20,'2年目 損益資金計画'!$F$20,'3年目 損益資金計画'!$F$20,'4年目 損益資金計画'!$F$20,'5年目 損益資金計画'!$F$20) -> 0 | G20: =CHOOSE($U$2,'初年度 損益資金計画'!$G$20,'2年目 損益資金計画'!$G$20,'3年目 損益資金計画'!$G$20,'4年目 損益資金計画'!$G$20,'5年目 損益資金計画'!$G$20) -> 0 | H20: =CHOOSE($U$2,'初年度 損益資金計画'!$H$20,'2年目 損益資金計画'!$H$20,'3年目 損益資金計画'!$H$20,'4年目 損益資金計画'!$H$20,'5年目 損益資金計画'!$H$20) -> 0 | I20: =CHOOSE($U$2,'初年度 損益資金計画'!$I$20,'2年目 損益資金計画'!$I$20,'3年目 損益資金計画'!$I$20,'4年目 損益資金計画'!$I$20,'5年目 損益資金計画'!$I$20) -> 0 | J20: =CHOOSE($U$2,'初年度 損益資金計画'!$J$20,'2年目 損益資金計画'!$J$20,'3年目 損益資金計画'!$J$20,'4年目 損益資金計画'!$J$20,'5年目 損益資金計画'!$J$20) -> 0 | K20: =CHOOSE($U$2,'初年度 損益資金計画'!$K$20,'2年目 損益資金計画'!$K$20,'3年目 損益資金計画'!$K$20,'4年目 損益資金計画'!$K$20,'5年目 損益資金計画'!$K$20) -> 0 | L20: =CHOOSE($U$2,'初年度 損益資金計画'!$L$20,'2年目 損益資金計画'!$L$20,'3年目 損益資金計画'!$L$20,'4年目 損益資金計画'!$L$20,'5年目 損益資金計画'!$L$20) -> 0 | M20: =CHOOSE($U$2,'初年度 損益資金計画'!$M$20,'2年目 損益資金計画'!$M$20,'3年目 損益資金計画'!$M$20,'4年目 損益資金計画'!$M$20,'5年目 損益資金計画'!$M$20) -> 0 | N20: =CHOOSE($U$2,'初年度 損益資金計画'!$N$20,'2年目 損益資金計画'!$N$20,'3年目 損益資金計画'!$N$20,'4年目 損益資金計画'!$N$20,'5年目 損益資金計画'!$N$20) -> 0 | O20: =CHOOSE($U$2,'初年度 損益資金計画'!$O$20,'2年目 損益資金計画'!$O$20,'3年目 損益資金計画'!$O$20,'4年目 損益資金計画'!$O$20,'5年目 損益資金計画'!$O$20) -> 0 | P20: =CHOOSE($U$2,'初年度 損益資金計画'!$P$20,'2年目 損益資金計画'!$P$20,'3年目 損益資金計画'!$P$20,'4年目 損益資金計画'!$P$20,'5年目 損益資金計画'!$P$20) -> 0
A21: =CHOOSE($U$2,'初年度 損益資金計画'!$A$21,'2年目 損益資金計画'!$A$21,'3年目 損益資金計画'!$A$21,'4年目 損益資金計画'!$A$21,'5年目 損益資金計画'!$A$21) -> 0 | B21: =CHOOSE($U$2,'初年度 損益資金計画'!$B$21,'2年目 損益資金計画'!$B$21,'3年目 損益資金計画'!$B$21,'4年目 損益資金計画'!$B$21,'5年目 損益資金計画'!$B$21) -> 福祉的就労 | D21: =CHOOSE($U$2,'初年度 損益資金計画'!$D$21,'2年目 損益資金計画'!$D$21,'3年目 損益資金計画'!$D$21,'4年目 損益資金計画'!$D$21,'5年目 損益資金計画'!$D$21) -> 500000 | E21: =CHOOSE($U$2,'初年度 損益資金計画'!$E$21,'2年目 損益資金計画'!$E$21,'3年目 損益資金計画'!$E$21,'4年目 損益資金計画'!$E$21,'5年目 損益資金計画'!$E$21) -> 500000 | F21: =CHOOSE($U$2,'初年度 損益資金計画'!$F$21,'2年目 損益資金計画'!$F$21,'3年目 損益資金計画'!$F$21,'4年目 損益資金計画'!$F$21,'5年目 損益資金計画'!$F$21) -> 500000 | G21: =CHOOSE($U$2,'初年度 損益資金計画'!$G$21,'2年目 損益資金計画'!$G$21,'3年目 損益資金計画'!$G$21,'4年目 損益資金計画'!$G$21,'5年目 損益資金計画'!$G$21) -> 500000 | H21: =CHOOSE($U$2,'初年度 損益資金計画'!$H$21,'2年目 損益資金計画'!$H$21,'3年目 損益資金計画'!$H$21,'4年目 損益資金計画'!$H$21,'5年目 損益資金計画'!$H$21) -> 500000 | I21: =CHOOSE($U$2,'初年度 損益資金計画'!$I$21,'2年目 損益資金計画'!$I$21,'3年目 損益資金計画'!$I$21,'4年目 損益資金計画'!$I$21,'5年目 損益資金計画'!$I$21) -> 500000 | J21: =CHOOSE($U$2,'初年度 損益資金計画'!$J$21,'2年目 損益資金計画'!$J$21,'3年目 損益資金計画'!$J$21,'4年目 損益資金計画'!$J$21,'5年目 損益資金計画'!$J$21) -> 500000 | K21: =CHOOSE($U$2,'初年度 損益資金計画'!$K$21,'2年目 損益資金計画'!$K$21,'3年目 損益資金計画'!$K$21,'4年目 損益資金計画'!$K$21,'5年目 損益資金計画'!$K$21) -> 500000 | L21: =CHOOSE($U$2,'初年度 損益資金計画'!$L$21,'2年目 損益資金計画'!$L$21,'3年目 損益資金計画'!$L$21,'4年目 損益資金計画'!$L$21,'5年目 損益資金計画'!$L$21) -> 500000 | M21: =CHOOSE($U$2,'初年度 損益資金計画'!$M$21,'2年目 損益資金計画'!$M$21,'3年目 損益資金計画'!$M$21,'4年目 損益資金計画'!$M$21,'5年目 損益資金計画'!$M$21) -> 500000 | N21: =CHOOSE($U$2,'初年度 損益資金計画'!$N$21,'2年目 損益資金計画'!$N$21,'3年目 損益資金計画'!$N$21,'4年目 損益資金計画'!$N$21,'5年目 損益資金計画'!$N$21) -> 500000 | O21: =CHOOSE($U$2,'初年度 損益資金計画'!$O$21,'2年目 損益資金計画'!$O$21,'3年目 損益資金計画'!$O$21,'4年目 損益資金計画'!$O$21,'5年目 損益資金計画'!$O$21) -> 500000 | P21: =CHOOSE($U$2,'初年度 損益資金計画'!$P$21,'2年目 損益資金計画'!$P$21,'3年目 損益資金計画'!$P$21,'4年目 損益資金計画'!$P$21,'5年目 損益資金計画'!$P$21) -> 6000000
A22: =CHOOSE($U$2,'初年度 損益資金計画'!$A$22,'2年目 損益資金計画'!$A$22,'3年目 損益資金計画'!$A$22,'4年目 損益資金計画'!$A$22,'5年目 損益資金計画'!$A$22) -> 0 | B22: =CHOOSE($U$2,'初年度 損益資金計画'!$B$22,'2年目 損益資金計画'!$B$22,'3年目 損益資金計画'!$B$22,'4年目 損益資金計画'!$B$22,'5年目 損益資金計画'!$B$22) -> 0 | C22: =CHOOSE($U$2,'初年度 損益資金計画'!$C$22,'2年目 損益資金計画'!$C$22,'3年目 損益資金計画'!$C$22,'4年目 損益資金計画'!$C$22,'5年目 損益資金計画'!$C$22) -> 工賃 | D22: =CHOOSE($U$2,'初年度 損益資金計画'!$D$22,'2年目 損益資金計画'!$D$22,'3年目 損益資金計画'!$D$22,'4年目 損益資金計画'!$D$22,'5年目 損益資金計画'!$D$22) -> 500000 | E22: =CHOOSE($U$2,'初年度 損益資金計画'!$E$22,'2年目 損益資金計画'!$E$22,'3年目 損益資金計画'!$E$22,'4年目 損益資金計画'!$E$22,'5年目 損益資金計画'!$E$22) -> 500000 | F22: =CHOOSE($U$2,'初年度 損益資金計画'!$F$22,'2年目 損益資金計画'!$F$22,'3年目 損益資金計画'!$F$22,'4年目 損益資金計画'!$F$22,'5年目 損益資金計画'!$F$22) -> 500000 | G22: =CHOOSE($U$2,'初年度 損益資金計画'!$G$22,'2年目 損益資金計画'!$G$22,'3年目 損益資金計画'!$G$22,'4年目 損益資金計画'!$G$22,'5年目 損益資金計画'!$G$22) -> 500000 | H22: =CHOOSE($U$2,'初年度 損益資金計画'!$H$22,'2年目 損益資金計画'!$H$22,'3年目 損益資金計画'!$H$22,'4年目 損益資金計画'!$H$22,'5年目 損益資金計画'!$H$22) -> 500000 | I22: =CHOOSE($U$2,'初年度 損益資金計画'!$I$22,'2年目 損益資金計画'!$I$22,'3年目 損益資金計画'!$I$22,'4年目 損益資金計画'!$I$22,'5年目 損益資金計画'!$I$22) -> 500000 | J22: =CHOOSE($U$2,'初年度 損益資金計画'!$J$22,'2年目 損益資金計画'!$J$22,'3年目 損益資金計画'!$J$22,'4年目 損益資金計画'!$J$22,'5年目 損益資金計画'!$J$22) -> 500000 | K22: =CHOOSE($U$2,'初年度 損益資金計画'!$K$22,'2年目 損益資金計画'!$K$22,'3年目 損益資金計画'!$K$22,'4年目 損益資金計画'!$K$22,'5年目 損益資金計画'!$K$22) -> 500000 | L22: =CHOOSE($U$2,'初年度 損益資金計画'!$L$22,'2年目 損益資金計画'!$L$22,'3年目 損益資金計画'!$L$22,'4年目 損益資金計画'!$L$22,'5年目 損益資金計画'!$L$22) -> 500000 | M22: =CHOOSE($U$2,'初年度 損益資金計画'!$M$22,'2年目 損益資金計画'!$M$22,'3年目 損益資金計画'!$M$22,'4年目 損益資金計画'!$M$22,'5年目 損益資金計画'!$M$22) -> 500000 | N22: =CHOOSE($U$2,'初年度 損益資金計画'!$N$22,'2年目 損益資金計画'!$N$22,'3年目 損益資金計画'!$N$22,'4年目 損益資金計画'!$N$22,'5年目 損益資金計画'!$N$22) -> 500000 | O22: =CHOOSE($U$2,'初年度 損益資金計画'!$O$22,'2年目 損益資金計画'!$O$22,'3年目 損益資金計画'!$O$22,'4年目 損益資金計画'!$O$22,'5年目 損益資金計画'!$O$22) -> 500000 | P22: =CHOOSE($U$2,'初年度 損益資金計画'!$P$22,'2年目 損益資金計画'!$P$22,'3年目 損益資金計画'!$P$22,'4年目 損益資金計画'!$P$22,'5年目 損益資金計画'!$P$22) -> 6000000
A23: =CHOOSE($U$2,'初年度 損益資金計画'!$A$23,'2年目 損益資金計画'!$A$23,'3年目 損益資金計画'!$A$23,'4年目 損益資金計画'!$A$23,'5年目 損益資金計画'!$A$23) -> 0 | C23: =CHOOSE($U$2,'初年度 損益資金計画'!$C$23,'2年目 損益資金計画'!$C$23,'3年目 損益資金計画'!$C$23,'4年目 損益資金計画'!$C$23,'5年目 損益資金計画'!$C$23) -> 材料経費 | D23: =CHOOSE($U$2,'初年度 損益資金計画'!$D$23,'2年目 損益資金計画'!$D$23,'3年目 損益資金計画'!$D$23,'4年目 損益資金計画'!$D$23,'5年目 損益資金計画'!$D$23) -> 0 | E23: =CHOOSE($U$2,'初年度 損益資金計画'!$E$23,'2年目 損益資金計画'!$E$23,'3年目 損益資金計画'!$E$23,'4年目 損益資金計画'!$E$23,'5年目 損益資金計画'!$E$23) -> 0 | F23: =CHOOSE($U$2,'初年度 損益資金計画'!$F$23,'2年目 損益資金計画'!$F$23,'3年目 損益資金計画'!$F$23,'4年目 損益資金計画'!$F$23,'5年目 損益資金計画'!$F$23) -> 0 | G23: =CHOOSE($U$2,'初年度 損益資金計画'!$G$23,'2年目 損益資金計画'!$G$23,'3年目 損益資金計画'!$G$23,'4年目 損益資金計画'!$G$23,'5年目 損益資金計画'!$G$23) -> 0 | H23: =CHOOSE($U$2,'初年度 損益資金計画'!$H$23,'2年目 損益資金計画'!$H$23,'3年目 損益資金計画'!$H$23,'4年目 損益資金計画'!$H$23,'5年目 損益資金計画'!$H$23) -> 0 | I23: =CHOOSE($U$2,'初年度 損益資金計画'!$I$23,'2年目 損益資金計画'!$I$23,'3年目 損益資金計画'!$I$23,'4年目 損益資金計画'!$I$23,'5年目 損益資金計画'!$I$23) -> 0 | J23: =CHOOSE($U$2,'初年度 損益資金計画'!$J$23,'2年目 損益資金計画'!$J$23,'3年目 損益資金計画'!$J$23,'4年目 損益資金計画'!$J$23,'5年目 損益資金計画'!$J$23) -> 0 | K23: =CHOOSE($U$2,'初年度 損益資金計画'!$K$23,'2年目 損益資金計画'!$K$23,'3年目 損益資金計画'!$K$23,'4年目 損益資金計画'!$K$23,'5年目 損益資金計画'!$K$23) -> 0 | L23: =CHOOSE($U$2,'初年度 損益資金計画'!$L$23,'2年目 損益資金計画'!$L$23,'3年目 損益資金計画'!$L$23,'4年目 損益資金計画'!$L$23,'5年目 損益資金計画'!$L$23) -> 0 | M23: =CHOOSE($U$2,'初年度 損益資金計画'!$M$23,'2年目 損益資金計画'!$M$23,'3年目 損益資金計画'!$M$23,'4年目 損益資金計画'!$M$23,'5年目 損益資金計画'!$M$23) -> 0 | N23: =CHOOSE($U$2,'初年度 損益資金計画'!$N$23,'2年目 損益資金計画'!$N$23,'3年目 損益資金計画'!$N$23,'4年目 損益資金計画'!$N$23,'5年目 損益資金計画'!$N$23) -> 0 | O23: =CHOOSE($U$2,'初年度 損益資金計画'!$O$23,'2年目 損益資金計画'!$O$23,'3年目 損益資金計画'!$O$23,'4年目 損益資金計画'!$O$23,'5年目 損益資金計画'!$O$23) -> 0 | P23: =CHOOSE($U$2,'初年度 損益資金計画'!$P$23,'2年目 損益資金計画'!$P$23,'3年目 損益資金計画'!$P$23,'4年目 損益資金計画'!$P$23,'5年目 損益資金計画'!$P$23) -> 0
A24: =CHOOSE($U$2,'初年度 損益資金計画'!$A$24,'2年目 損益資金計画'!$A$24,'3年目 損益資金計画'!$A$24,'4年目 損益資金計画'!$A$24,'5年目 損益資金計画'!$A$24) -> 0 | C24: =CHOOSE($U$2,'初年度 損益資金計画'!$C$24,'2年目 損益資金計画'!$C$24,'3年目 損益資金計画'!$C$24,'4年目 損益資金計画'!$C$24,'5年目 損益資金計画'!$C$24) -> 投資的費用 | D24: =CHOOSE($U$2,'初年度 損益資金計画'!$D$24,'2年目 損益資金計画'!$D$24,'3年目 損益資金計画'!$D$24,'4年目 損益資金計画'!$D$24,'5年目 損益資金計画'!$D$24) -> 0 | E24: =CHOOSE($U$2,'初年度 損益資金計画'!$E$24,'2年目 損益資金計画'!$E$24,'3年目 損益資金計画'!$E$24,'4年目 損益資金計画'!$E$24,'5年目 損益資金計画'!$E$24) -> 0 | F24: =CHOOSE($U$2,'初年度 損益資金計画'!$F$24,'2年目 損益資金計画'!$F$24,'3年目 損益資金計画'!$F$24,'4年目 損益資金計画'!$F$24,'5年目 損益資金計画'!$F$24) -> 0 | G24: =CHOOSE($U$2,'初年度 損益資金計画'!$G$24,'2年目 損益資金計画'!$G$24,'3年目 損益資金計画'!$G$24,'4年目 損益資金計画'!$G$24,'5年目 損益資金計画'!$G$24) -> 0 | H24: =CHOOSE($U$2,'初年度 損益資金計画'!$H$24,'2年目 損益資金計画'!$H$24,'3年目 損益資金計画'!$H$24,'4年目 損益資金計画'!$H$24,'5年目 損益資金計画'!$H$24) -> 0 | I24: =CHOOSE($U$2,'初年度 損益資金計画'!$I$24,'2年目 損益資金計画'!$I$24,'3年目 損益資金計画'!$I$24,'4年目 損益資金計画'!$I$24,'5年目 損益資金計画'!$I$24) -> 0 | J24: =CHOOSE($U$2,'初年度 損益資金計画'!$J$24,'2年目 損益資金計画'!$J$24,'3年目 損益資金計画'!$J$24,'4年目 損益資金計画'!$J$24,'5年目 損益資金計画'!$J$24) -> 0 | K24: =CHOOSE($U$2,'初年度 損益資金計画'!$K$24,'2年目 損益資金計画'!$K$24,'3年目 損益資金計画'!$K$24,'4年目 損益資金計画'!$K$24,'5年目 損益資金計画'!$K$24) -> 0 | L24: =CHOOSE($U$2,'初年度 損益資金計画'!$L$24,'2年目 損益資金計画'!$L$24,'3年目 損益資金計画'!$L$24,'4年目 損益資金計画'!$L$24,'5年目 損益資金計画'!$L$24) -> 0 | M24: =CHOOSE($U$2,'初年度 損益資金計画'!$M$24,'2年目 損益資金計画'!$M$24,'3年目 損益資金計画'!$M$24,'4年目 損益資金計画'!$M$24,'5年目 損益資金計画'!$M$24) -> 0 | N24: =CHOOSE($U$2,'初年度 損益資金計画'!$N$24,'2年目 損益資金計画'!$N$24,'3年目 損益資金計画'!$N$24,'4年目 損益資金計画'!$N$24,'5年目 損益資金計画'!$N$24) -> 0 | O24: =CHOOSE($U$2,'初年度 損益資金計画'!$O$24,'2年目 損益資金計画'!$O$24,'3年目 損益資金計画'!$O$24,'4年目 損益資金計画'!$O$24,'5年目 損益資金計画'!$O$24) -> 0 | P24: =CHOOSE($U$2,'初年度 損益資金計画'!$P$24,'2年目 損益資金計画'!$P$24,'3年目 損益資金計画'!$P$24,'4年目 損益資金計画'!$P$24,'5年目 損益資金計画'!$P$24) -> 0
A25: =CHOOSE($U$2,'初年度 損益資金計画'!$A$25,'2年目 損益資金計画'!$A$25,'3年目 損益資金計画'!$A$25,'4年目 損益資金計画'!$A$25,'5年目 損益資金計画'!$A$25) -> 0 | C25: =CHOOSE($U$2,'初年度 損益資金計画'!$C$25,'2年目 損益資金計画'!$C$25,'3年目 損益資金計画'!$C$25,'4年目 損益資金計画'!$C$25,'5年目 損益資金計画'!$C$25) -> 0 | D25: =CHOOSE($U$2,'初年度 損益資金計画'!$D$25,'2年目 損益資金計画'!$D$25,'3年目 損益資金計画'!$D$25,'4年目 損益資金計画'!$D$25,'5年目 損益資金計画'!$D$25) -> 0 | E25: =CHOOSE($U$2,'初年度 損益資金計画'!$E$25,'2年目 損益資金計画'!$E$25,'3年目 損益資金計画'!$E$25,'4年目 損益資金計画'!$E$25,'5年目 損益資金計画'!$E$25) -> 0 | F25: =CHOOSE($U$2,'初年度 損益資金計画'!$F$25,'2年目 損益資金計画'!$F$25,'3年目 損益資金計画'!$F$25,'4年目 損益資金計画'!$F$25,'5年目 損益資金計画'!$F$25) -> 0 | G25: =CHOOSE($U$2,'初年度 損益資金計画'!$G$25,'2年目 損益資金計画'!$G$25,'3年目 損益資金計画'!$G$25,'4年目 損益資金計画'!$G$25,'5年目 損益資金計画'!$G$25) -> 0 | H25: =CHOOSE($U$2,'初年度 損益資金計画'!$H$25,'2年目 損益資金計画'!$H$25,'3年目 損益資金計画'!$H$25,'4年目 損益資金計画'!$H$25,'5年目 損益資金計画'!$H$25) -> 0 | I25: =CHOOSE($U$2,'初年度 損益資金計画'!$I$25,'2年目 損益資金計画'!$I$25,'3年目 損益資金計画'!$I$25,'4年目 損益資金計画'!$I$25,'5年目 損益資金計画'!$I$25) -> 0 | J25: =CHOOSE($U$2,'初年度 損益資金計画'!$J$25,'2年目 損益資金計画'!$J$25,'3年目 損益資金計画'!$J$25,'4年目 損益資金計画'!$J$25,'5年目 損益資金計画'!$J$25) -> 0 | K25: =CHOOSE($U$2,'初年度 損益資金計画'!$K$25,'2年目 損益資金計画'!$K$25,'3年目 損益資金計画'!$K$25,'4年目 損益資金計画'!$K$25,'5年目 損益資金計画'!$K$25) -> 0 | L25: =CHOOSE($U$2,'初年度 損益資金計画'!$L$25,'2年目 損益資金計画'!$L$25,'3年目 損益資金計画'!$L$25,'4年目 損益資金計画'!$L$25,'5年目 損益資金計画'!$L$25) -> 0 | M25: =CHOOSE($U$2,'初年度 損益資金計画'!$M$25,'2年目 損益資金計画'!$M$25,'3年目 損益資金計画'!$M$25,'4年目 損益資金計画'!$M$25,'5年目 損益資金計画'!$M$25) -> 0 | N25: =CHOOSE($U$2,'初年度 損益資金計画'!$N$25,'2年目 損益資金計画'!$N$25,'3年目 損益資金計画'!$N$25,'4年目 損益資金計画'!$N$25,'5年目 損益資金計画'!$N$25) -> 0 | O25: =CHOOSE($U$2,'初年度 損益資金計画'!$O$25,'2年目 損益資金計画'!$O$25,'3年目 損益資金計画'!$O$25,'4年目 損益資金計画'!$O$25,'5年目 損益資金計画'!$O$25) -> 0 | P25: =CHOOSE($U$2,'初年度 損益資金計画'!$P$25,'2年目 損益資金計画'!$P$25,'3年目 損益資金計画'!$P$25,'4年目 損益資金計画'!$P$25,'5年目 損益資金計画'!$P$25) -> 0
A26: =CHOOSE($U$2,'初年度 損益資金計画'!$A$26,'2年目 損益資金計画'!$A$26,'3年目 損益資金計画'!$A$26,'4年目 損益資金計画'!$A$26,'5年目 損益資金計画'!$A$26) -> （売上総利益） | D26: =CHOOSE($U$2,'初年度 損益資金計画'!$D$26,'2年目 損益資金計画'!$D$26,'3年目 損益資金計画'!$D$26,'4年目 損益資金計画'!$D$26,'5年目 損益資金計画'!$D$26) -> 44570 | E26: =CHOOSE($U$2,'初年度 損益資金計画'!$E$26,'2年目 損益資金計画'!$E$26,'3年目 損益資金計画'!$E$26,'4年目 損益資金計画'!$E$26,'5年目 損益資金計画'!$E$26) -> 1005970 | F26: =CHOOSE($U$2,'初年度 損益資金計画'!$F$26,'2年目 損益資金計画'!$F$26,'3年目 損益資金計画'!$F$26,'4年目 損益資金計画'!$F$26,'5年目 損益資金計画'!$F$26) -> 1453470 | G26: =CHOOSE($U$2,'初年度 損益資金計画'!$G$26,'2年目 損益資金計画'!$G$26,'3年目 損益資金計画'!$G$26,'4年目 損益資金計画'!$G$26,'5年目 損益資金計画'!$G$26) -> 1495370 | H26: =CHOOSE($U$2,'初年度 損益資金計画'!$H$26,'2年目 損益資金計画'!$H$26,'3年目 損益資金計画'!$H$26,'4年目 損益資金計画'!$H$26,'5年目 損益資金計画'!$H$26) -> 1803070 | I26: =CHOOSE($U$2,'初年度 損益資金計画'!$I$26,'2年目 損益資金計画'!$I$26,'3年目 損益資金計画'!$I$26,'4年目 損益資金計画'!$I$26,'5年目 損益資金計画'!$I$26) -> 2082670 | J26: =CHOOSE($U$2,'初年度 損益資金計画'!$J$26,'2年目 損益資金計画'!$J$26,'3年目 損益資金計画'!$J$26,'4年目 損益資金計画'!$J$26,'5年目 損益資金計画'!$J$26) -> 2229570 | K26: =CHOOSE($U$2,'初年度 損益資金計画'!$K$26,'2年目 損益資金計画'!$K$26,'3年目 損益資金計画'!$K$26,'4年目 損益資金計画'!$K$26,'5年目 損益資金計画'!$K$26) -> 2376370 | L26: =CHOOSE($U$2,'初年度 損益資金計画'!$L$26,'2年目 損益資金計画'!$L$26,'3年目 損益資金計画'!$L$26,'4年目 損益資金計画'!$L$26,'5年目 損益資金計画'!$L$26) -> 1297470 | M26: =CHOOSE($U$2,'初年度 損益資金計画'!$M$26,'2年目 損益資金計画'!$M$26,'3年目 損益資金計画'!$M$26,'4年目 損益資金計画'!$M$26,'5年目 損益資金計画'!$M$26) -> 2166570 | N26: =CHOOSE($U$2,'初年度 損益資金計画'!$N$26,'2年目 損益資金計画'!$N$26,'3年目 損益資金計画'!$N$26,'4年目 損益資金計画'!$N$26,'5年目 損益資金計画'!$N$26) -> 2642170 | O26: =CHOOSE($U$2,'初年度 損益資金計画'!$O$26,'2年目 損益資金計画'!$O$26,'3年目 損益資金計画'!$O$26,'4年目 損益資金計画'!$O$26,'5年目 損益資金計画'!$O$26) -> 3327270 | P26: =CHOOSE($U$2,'初年度 損益資金計画'!$P$26,'2年目 損益資金計画'!$P$26,'3年目 損益資金計画'!$P$26,'4年目 損益資金計画'!$P$26,'5年目 損益資金計画'!$P$26) -> 21924540
A27: =CHOOSE($U$2,'初年度 損益資金計画'!$A$27,'2年目 損益資金計画'!$A$27,'3年目 損益資金計画'!$A$27,'4年目 損益資金計画'!$A$27,'5年目 損益資金計画'!$A$27) -> （販管費） | D27: =CHOOSE($U$2,'初年度 損益資金計画'!$D$27,'2年目 損益資金計画'!$D$27,'3年目 損益資金計画'!$D$27,'4年目 損益資金計画'!$D$27,'5年目 損益資金計画'!$D$27) -> 296100 | E27: =CHOOSE($U$2,'初年度 損益資金計画'!$E$27,'2年目 損益資金計画'!$E$27,'3年目 損益資金計画'!$E$27,'4年目 損益資金計画'!$E$27,'5年目 損益資金計画'!$E$27) -> 296100 | F27: =CHOOSE($U$2,'初年度 損益資金計画'!$F$27,'2年目 損益資金計画'!$F$27,'3年目 損益資金計画'!$F$27,'4年目 損益資金計画'!$F$27,'5年目 損益資金計画'!$F$27) -> 296100 | G27: =CHOOSE($U$2,'初年度 損益資金計画'!$G$27,'2年目 損益資金計画'!$G$27,'3年目 損益資金計画'!$G$27,'4年目 損益資金計画'!$G$27,'5年目 損益資金計画'!$G$27) -> 296100 | H27: =CHOOSE($U$2,'初年度 損益資金計画'!$H$27,'2年目 損益資金計画'!$H$27,'3年目 損益資金計画'!$H$27,'4年目 損益資金計画'!$H$27,'5年目 損益資金計画'!$H$27) -> 296100 | I27: =CHOOSE($U$2,'初年度 損益資金計画'!$I$27,'2年目 損益資金計画'!$I$27,'3年目 損益資金計画'!$I$27,'4年目 損益資金計画'!$I$27,'5年目 損益資金計画'!$I$27) -> 296100 | J27: =CHOOSE($U$2,'初年度 損益資金計画'!$J$27,'2年目 損益資金計画'!$J$27,'3年目 損益資金計画'!$J$27,'4年目 損益資金計画'!$J$27,'5年目 損益資金計画'!$J$27) -> 296100 | K27: =CHOOSE($U$2,'初年度 損益資金計画'!$K$27,'2年目 損益資金計画'!$K$27,'3年目 損益資金計画'!$K$27,'4年目 損益資金計画'!$K$27,'5年目 損益資金計画'!$K$27) -> 296100 | L27: =CHOOSE($U$2,'初年度 損益資金計画'!$L$27,'2年目 損益資金計画'!$L$27,'3年目 損益資金計画'!$L$27,'4年目 損益資金計画'!$L$27,'5年目 損益資金計画'!$L$27) -> 296100 | M27: =CHOOSE($U$2,'初年度 損益資金計画'!$M$27,'2年目 損益資金計画'!$M$27,'3年目 損益資金計画'!$M$27,'4年目 損益資金計画'!$M$27,'5年目 損益資金計画'!$M$27) -> 296100 | N27: =CHOOSE($U$2,'初年度 損益資金計画'!$N$27,'2年目 損益資金計画'!$N$27,'3年目 損益資金計画'!$N$27,'4年目 損益資金計画'!$N$27,'5年目 損益資金計画'!$N$27) -> 296100 | O27: =CHOOSE($U$2,'初年度 損益資金計画'!$O$27,'2年目 損益資金計画'!$O$27,'3年目 損益資金計画'!$O$27,'4年目 損益資金計画'!$O$27,'5年目 損益資金計画'!$O$27) -> 296100 | P27: =CHOOSE($U$2,'初年度 損益資金計画'!$P$27,'2年目 損益資金計画'!$P$27,'3年目 損益資金計画'!$P$27,'4年目 損益資金計画'!$P$27,'5年目 損益資金計画'!$P$27) -> 3553200
A28: =CHOOSE($U$2,'初年度 損益資金計画'!$A$28,'2年目 損益資金計画'!$A$28,'3年目 損益資金計画'!$A$28,'4年目 損益資金計画'!$A$28,'5年目 損益資金計画'!$A$28) -> 0 | C28: =CHOOSE($U$2,'初年度 損益資金計画'!$C$28,'2年目 損益資金計画'!$C$28,'3年目 損益資金計画'!$C$28,'4年目 損益資金計画'!$C$28,'5年目 損益資金計画'!$C$28) -> 役員報酬 | D28: =CHOOSE($U$2,'初年度 損益資金計画'!$D$28,'2年目 損益資金計画'!$D$28,'3年目 損益資金計画'!$D$28,'4年目 損益資金計画'!$D$28,'5年目 損益資金計画'!$D$28) -> 180000 | E28: =CHOOSE($U$2,'初年度 損益資金計画'!$E$28,'2年目 損益資金計画'!$E$28,'3年目 損益資金計画'!$E$28,'4年目 損益資金計画'!$E$28,'5年目 損益資金計画'!$E$28) -> 180000 | F28: =CHOOSE($U$2,'初年度 損益資金計画'!$F$28,'2年目 損益資金計画'!$F$28,'3年目 損益資金計画'!$F$28,'4年目 損益資金計画'!$F$28,'5年目 損益資金計画'!$F$28) -> 180000 | G28: =CHOOSE($U$2,'初年度 損益資金計画'!$G$28,'2年目 損益資金計画'!$G$28,'3年目 損益資金計画'!$G$28,'4年目 損益資金計画'!$G$28,'5年目 損益資金計画'!$G$28) -> 180000 | H28: =CHOOSE($U$2,'初年度 損益資金計画'!$H$28,'2年目 損益資金計画'!$H$28,'3年目 損益資金計画'!$H$28,'4年目 損益資金計画'!$H$28,'5年目 損益資金計画'!$H$28) -> 180000 | I28: =CHOOSE($U$2,'初年度 損益資金計画'!$I$28,'2年目 損益資金計画'!$I$28,'3年目 損益資金計画'!$I$28,'4年目 損益資金計画'!$I$28,'5年目 損益資金計画'!$I$28) -> 180000 | J28: =CHOOSE($U$2,'初年度 損益資金計画'!$J$28,'2年目 損益資金計画'!$J$28,'3年目 損益資金計画'!$J$28,'4年目 損益資金計画'!$J$28,'5年目 損益資金計画'!$J$28) -> 180000 | K28: =CHOOSE($U$2,'初年度 損益資金計画'!$K$28,'2年目 損益資金計画'!$K$28,'3年目 損益資金計画'!$K$28,'4年目 損益資金計画'!$K$28,'5年目 損益資金計画'!$K$28) -> 180000 | L28: =CHOOSE($U$2,'初年度 損益資金計画'!$L$28,'2年目 損益資金計画'!$L$28,'3年目 損益資金計画'!$L$28,'4年目 損益資金計画'!$L$28,'5年目 損益資金計画'!$L$28) -> 180000 | M28: =CHOOSE($U$2,'初年度 損益資金計画'!$M$28,'2年目 損益資金計画'!$M$28,'3年目 損益資金計画'!$M$28,'4年目 損益資金計画'!$M$28,'5年目 損益資金計画'!$M$28) -> 180000 | N28: =CHOOSE($U$2,'初年度 損益資金計画'!$N$28,'2年目 損益資金計画'!$N$28,'3年目 損益資金計画'!$N$28,'4年目 損益資金計画'!$N$28,'5年目 損益資金計画'!$N$28) -> 180000 | O28: =CHOOSE($U$2,'初年度 損益資金計画'!$O$28,'2年目 損益資金計画'!$O$28,'3年目 損益資金計画'!$O$28,'4年目 損益資金計画'!$O$28,'5年目 損益資金計画'!$O$28) -> 180000 | P28: =CHOOSE($U$2,'初年度 損益資金計画'!$P$28,'2年目 損益資金計画'!$P$28,'3年目 損益資金計画'!$P$28,'4年目 損益資金計画'!$P$28,'5年目 損益資金計画'!$P$28) -> 2160000
