Workbook

Sheet ★入力シート
A1: 指定申請 入力統合シート（岡山市 就労継続支援B型）
A2: ※ 青色セルに入力すると各書類シートへ自動反映されます
A4: A. 法人情報
A5: 法人種別 | E5: 例：社会福祉法人、NPO法人、株式会社 等
A6: 法人名称 | E6: 登記上の正式名称
A7: 法人所在地 | E7: 登記上の住所
A8: 郵便番号 | E8: 例：700-0000
A9: 電話番号 | E9: 例：086-000-0000
A10: FAX番号
A11: 代表者氏名 | E11: 戸籍上の氏名
A12: 代表者ふりがな
A13: 代表者役職 | E13: 例：理事長、代表取締役
A15: B. 事業所情報
A16: 事業所名称 | E16: 指定を受ける事業所名
A17: 事業所所在地 | E17: 実際のサービス提供場所
A18: 郵便番号
A19: 電話番号
A20: FAX番号
A21: サービス種別 | E21: 就労継続支援B型
A22: 利用定員 | E22: 例：20
A23: 開設予定日 | E23: 例：2026/04/01
A24: 事業所面積(㎡) | E24: 例：150
A26: C. 管理者情報
A27: 管理者氏名
A28: ふりがな
A29: 住所
A30: 生年月日 | E30: 例：1980/01/01
A31: 経歴概要 | E31: 最終学歴・主な職歴
A32: 管理者兼務 | E32: 兼務あり／兼務なし
A34: D. サービス管理責任者情報
A35: サビ管氏名
A36: ふりがな
A37: 住所
A38: 生年月日 | E38: 例：1975/06/15
A39: 経歴概要 | E39: 実務経験の概要
A40: 研修修了状況 | E40: 基礎研修修了／実践研修修了
A42: E. 事前決定事項チェック
A43: 定款に障害福祉サービス事業の記載あり
A44: 事業所の賃貸借契約済み
A45: 消防署への届出済み
...

Sheet 様式第1号_指定申請書
B1: 様式第１号（第２条関係）
Q2: 受付番号
G4: 指定障害福祉サービス事業者 指定障害者支援施設 | M4: 指定（更新）申請書
Q7: =TEXT('★入力シート'!B23,"yyyy年 m月 日") -> 1899年 12月 日
A8: 岡山市長 様
K9: 申請者 | N9: 所在地 | P9: ='★入力シート'!B7 -> 0
K10: （設置者） | N10: 名 称 | P10: ='★入力シート'!B6 -> 0
N11: 代表者 | P11: ='★入力シート'!B13&" "&'★入力シート'!B11
B13: 指定障害福祉サービス事業者（指定障害者支援施設）の指定（指定の更新）を受けたいので，障害者の日常生活及び社会生活を総合的に支援するための法律（平成１７年法律第１２３号）第２９条第１項の規定により，関係書類を添えて申請します。
Q16: 事業者番号
B17: 申請者（設置者） | C17: フ リ ガ ナ | G17: ='★入力シート'!B12 -> 0
C18: 名 称 | G18: ='★入力シート'!B6 -> 0
C20: 主たる事務所 の所在地 | G20: ="（郵便番号 "&'★入力シート'!B8&" ）" -> （郵便番号 ）
G21: =" "&'★入力シート'!B7
C23: 法人の種別 | G23: ='★入力シート'!B5 -> 0 | N23: 法人所轄庁
C24: 連絡先 | E24: 電話番号 | G24: ='★入力シート'!B9 -> 0 | N24: Ｆ Ａ Ｘ 番 号 | Q24: ='★入力シート'!B10 -> 0
C25: 代表者の職・氏名・ 生年月日 | G25: 職 名 | J25: ='★入力シート'!B13 -> 0 | N25: フリガナ | Q25: ='★入力シート'!B12 -> 0
N26: 氏名 | Q26: ='★入力シート'!B11 -> 0
N27: 生年月日
C28: 代 表 者 の 住 所
B31: 指定を受けようとする事業所（施設） | C31: フ リ ガ ナ
C32: 名 称 | G32: ='★入力シート'!B16 -> 0
C34: 事業所（施設） の所在地 | G34: ="（郵便番号 "&'★入力シート'!B18&" ）" -> （郵便番号 ）
G35: =" "&'★入力シート'!B17
C37: 同一所在地において | G37: 指定申請をする事業等 | K37: 添付様式 （付表） | M37: 指定有効期間 開始年月日 | Q37: 指定有効期間 満了年月日 | U37: 備 考
C38: 行う事業等の種類 | G38: の開始の予定年月日
C39: 指定障害福祉サービス事業者 | D39: ='★入力シート'!B21 -> 0 | G39: ='★入力シート'!B23 -> 0 | K39: 付表10-1
C45: 指定障害者支援施設
B46: 既に指定を受けている事業等（他の法律含む）
B48: 備考 １ 「受付番号」欄には，記載しないでください。
B49: ２ 「法人の種別」欄には，申請者が法人である場合に，社会福祉法人，医療法人，一般社団法 人，一般財団法人，株式会社等の別を記載してください。 | Q49: 受 付 印
B50: ３ 「法人所轄庁」欄には，申請者が認可法人である場合に，その主務官庁の名称を記載してくだ さい。
B51: ４ 「同一所在地において行う事業等の種類」欄には，今回申請をするもの及び既に指定を受けて いるものについて事業の種類を記載し，該当する欄に「○」を記載してください。
B52: ５ 申請を行う都道府県において既に事業所としての指定を受け，番号が付番されている場合に は，別紙にその事業所番号をすべて記載してください。
A58: ※ 水色セルは★入力シートから自動反映

Sheet 付表10-1_記載事項
A1: 付表10-1 就労継続支援 記載事項
A3: 事業所名称 | B3: ='★入力シート'!B16 -> 0
A4: 所在地 | B4: ='★入力シート'!B17 -> 0
A5: 電話番号 | B5: ='★入力シート'!B19 -> 0
A6: FAX | B6: ='★入力シート'!B20 -> 0
A7: サービスの種類 | B7: ='★入力シート'!B21 -> 0
A8: 定員 | B8: ='★入力シート'!B22 -> 0
A9: 事業開始予定日 | B9: ='★入力シート'!B23 -> 0
A11: 【管理者】
A12: 管理者氏名 | B12: ='★入力シート'!B27 -> 0
A13: 住所 | B13: ='★入力シート'!B29 -> 0
A14: 管理者兼務 | B14: ='★入力シート'!B32 -> 0
A16: 【サービス管理責任者】
A17: サビ管氏名 | B17: ='★入力シート'!B35 -> 0
A18: 住所 | B18: ='★入力シート'!B37 -> 0
A20: 【運営方針等】（※手動入力）
A21: 運営方針
A22: 主たる対象者
A23: 営業日・営業時間
A24: サービス提供時間
A25: 通常の事業実施地域
A26: 主な生産活動の内容
A27: 工賃支払いの考え方

Sheet 役員等名簿
A1: 様式第1号別紙2付紙 役員等名簿
A2: ※ 代表者は入力シートから自動反映。他の役員は手動追加。
A4: No. | B4: 氏名 | C4: ふりがな | D4: 役職 | E4: 住所 | F4: 備考
A5: 1 | B5: ='★入力シート'!B11 -> 0 | C5: ='★入力シート'!B12 -> 0 | D5: ='★入力シート'!B13 -> 0 | E5: ='★入力シート'!B7 -> 0 | F5: 代表者（自動反映）
A6: 2
A7: 3
A8: 4
A9: 5
A10: 6
A11: 7
A12: 8
A13: 9
A14: 10

Sheet 誓約書_別紙2
A1: 様式第1号別紙2 誓約書
A2: ※ 法人名・代表者名は自動反映。印刷して押印。
A4: 障害者総合支援法第36条第3項各号の規定に該当しないことを誓約します。
A6: 法人名称 | B6: ='★入力シート'!B6 -> 0
A7: 代表者氏名 | B7: ='★入力シート'!B11 -> 0
A8: 代表者役職 | B8: ='★入力シート'!B13 -> 0

Sheet 経歴書_管理者
A1: 参考様式3 経歴書（管理者）
A3: 氏名 | B3: ='★入力シート'!B27 -> 0
A4: ふりがな | B4: ='★入力シート'!B28 -> 0
A5: 生年月日 | B5: ='★入力シート'!B30 -> 0
A6: 住所 | B6: ='★入力シート'!B29 -> 0
A8: 【学歴・職歴】（※手動入力）
A9: 年 | B9: 月 | C9: 学歴・職歴

Sheet 経歴書_サビ管
A1: 参考様式3 経歴書（サービス管理責任者）
A3: 氏名 | B3: ='★入力シート'!B35 -> 0
A4: ふりがな | B4: ='★入力シート'!B36 -> 0
A5: 生年月日 | B5: ='★入力シート'!B38 -> 0
A6: 住所 | B6: ='★入力シート'!B37 -> 0
A8: 【学歴・職歴】（※手動入力）
A9: 年 | B9: 月 | C9: 学歴・職歴

Sheet 就任承諾書
A1: 参考様式3-2 就任承諾書
A3: 下記の職に就任することを承諾します。
A5: 事業所名称 | B5: ='★入力シート'!B16 -> 0
A6: 職名 | B6: ="管理者" -> 管理者
A7: 氏名 | B7: ='★入力シート'!B27 -> 0
A8: 住所 | B8: ='★入力シート'!B29 -> 0
A9: 生年月日 | B9: ='★入力シート'!B30 -> 0

Sheet 苦情解決措置_様式6
A1: 参考様式6 苦情解決措置の概要
A3: 事業所名称 | B3: ='★入力シート'!B16 -> 0
A4: 所在地 | B4: ='★入力シート'!B17 -> 0
A5: 電話番号 | B5: ='★入力シート'!B19 -> 0
A7: 【苦情解決体制】（※手動入力）
A8: 苦情受付担当者（氏名・職名）
A9: 苦情解決責任者（氏名・職名）
A10: 第三者委員（氏名・所属）
A11: 苦情受付方法
A12: 苦情解決の流れ

Sheet 設備一覧_様式2
A1: 参考様式2 事業所の設備・備品等一覧表
A3: 事業所名称 | B3: ='★入力シート'!B16 -> 0
A4: 事業所面積 | B4: ='★入力シート'!B24 -> 0
A6: No. | B6: 設備・備品名 | C6: 数量 | D6: 用途 | E6: 設置場所 | F6: 備考
A7: 1
A8: 2
A9: 3
A10: 4
A11: 5
A12: 6
A13: 7
A14: 8
A15: 9
A16: 10
A17: 11
A18: 12
... A26: 20

Sheet 建築物協議_様式2-3
A1: 参考様式2-3 建築物関連法令協議記録
A3: 事業所名称 | B3: ='★入力シート'!B16 -> 0
A4: 所在地 | B4: ='★入力シート'!B17 -> 0
A5: 事業所面積 | B5: ='★入力シート'!B24 -> 0
A7: 【協議内容】（※手動入力）
A8: 協議先（建築指導課等）
A9: 協議日
A10: 協議結果
A11: 用途地域
A12: 建物構造・階数
A13: 消防署との協議結果

Sheet 社保確認票
A1: 社会保険及び労働保険への加入状況にかかる確認票
A3: 法人名称 | B3: ='★入力シート'!B6 -> 0
A4: 事業所名称 | B4: ='★入力シート'!B16 -> 0
A5: 所在地 | B5: ='★入力シート'!B17 -> 0
A7: 【加入状況】（※手動入力）
A8: 健康保険 | D8: 適用あり／適用なし
A9: 厚生年金保険 | D9: 適用あり／適用なし
A10: 雇用保険 | D10: 適用あり／適用なし
A11: 労災保険 | D11: 適用あり／適用なし
