Workbook

Sheet 事業評価【A案・税引前】
E1: 1 | F1: 2 | G1: 3 | H1: 4 | I1: 5 | J1: 6 | K1: 7 | L1: 8 | M1: 9
B2: 企業価値A案（税引前） | M2: 【千円】
D3: H23年度 | E3: H24年度 | F3: H25年度 | G3: H26年度 | H3: H27年度 | I3: H28年度 | J3: H29年度 | K3: H30年度 | L3: H31年度 | M3: H32年度
B4: 前年度繰越 | D4: 0 | E4: =D40 -> #REF! | F4: =E40 -> #REF! | G4: =F40 -> #REF! | H4: =G40 -> #REF! | I4: =H40 -> #REF! | J4: =I40 -> #REF! | K4: =J40 -> #REF! | L4: =K40 -> #REF! | M4: =L40 -> #REF!
B5: 経常収入 | D5: =SUM(基礎!D55:O55) -> 39760360 | E5: =SUM(基礎!V55:AG55) -> 129071704 | F5: =SUM(基礎!AM55:AX55) -> 146958399 | G5: =SUM(基礎!#REF!) -> #REF! | H5: =SUM(基礎!#REF!) -> #REF! | I5: =SUM(基礎!#REF!) -> #REF! | J5: =SUM(基礎!#REF!) -> #REF! | K5: =SUM(基礎!#REF!) -> #REF! | L5: =SUM(基礎!#REF!) -> #REF! | M5: =SUM(基礎!#REF!) -> #REF!
C6: 店舗現金売上 | D6: =SUM(基礎!D56:O56) -> 31990360 | E6: =SUM(基礎!V56:AG56) -> 107291682 | F6: =SUM(基礎!AM56:AX56) -> 122868375 | G6: =SUM(基礎!#REF!) -> #REF! | H6: =SUM(基礎!#REF!) -> #REF! | I6: =SUM(基礎!#REF!) -> #REF! | J6: =SUM(基礎!#REF!) -> #REF! | K6: =SUM(基礎!#REF!) -> #REF! | L6: =SUM(基礎!#REF!) -> #REF! | M6: =SUM(基礎!#REF!) -> #REF!
C7: 店舗催事売掛入金 | D7: =SUM(基礎!D57:O57) -> 7770000 | E7: =SUM(基礎!V57:AG57) -> 21780022 | F7: =SUM(基礎!AM57:AX57) -> 24090024 | G7: =SUM(基礎!#REF!) -> #REF! | H7: =SUM(基礎!#REF!) -> #REF! | I7: =SUM(基礎!#REF!) -> #REF! | J7: =SUM(基礎!#REF!) -> #REF! | K7: =SUM(基礎!#REF!) -> #REF! | L7: =SUM(基礎!#REF!) -> #REF! | M7: =SUM(基礎!#REF!) -> #REF!
C8: FCロイヤリティ | D8: =SUM(基礎!D58:O58) -> 0 | E8: =SUM(基礎!V58:AG58) -> 0 | F8: =SUM(基礎!AM58:AX58) -> 0 | G8: =SUM(基礎!#REF!) -> #REF! | H8: =SUM(基礎!#REF!) -> #REF! | I8: =SUM(基礎!#REF!) -> #REF! | J8: =SUM(基礎!#REF!) -> #REF! | K8: =SUM(基礎!#REF!) -> #REF! | L8: =SUM(基礎!#REF!) -> #REF! | M8: =SUM(基礎!#REF!) -> #REF!
C9: 他収入 | D9: =SUM(基礎!D59:O59) -> 0 | E9: =SUM(基礎!V59:AG59) -> 0 | F9: =SUM(基礎!AM59:AX59) -> 0 | G9: =SUM(基礎!#REF!) -> #REF! | H9: =SUM(基礎!#REF!) -> #REF! | I9: =SUM(基礎!#REF!) -> #REF! | J9: =SUM(基礎!#REF!) -> #REF! | K9: =SUM(基礎!#REF!) -> #REF! | L9: =SUM(基礎!#REF!) -> #REF! | M9: =SUM(基礎!#REF!) -> #REF!
B10: 経常支出 | D10: =SUM(基礎!D60:O60) -> 59863907 | E10: =SUM(基礎!V60:AG60) -> 1.2840054e+08 | F10: =SUM(基礎!AM60:AX60) -> 1.3755498e+08 | G10: =SUM(基礎!#REF!) -> #REF! | H10: =SUM(基礎!#REF!) -> #REF! | I10: =SUM(基礎!#REF!) -> #REF! | J10: =SUM(基礎!#REF!) -> #REF! | K10: =SUM(基礎!#REF!) -> #REF! | L10: =SUM(基礎!#REF!) -> #REF! | M10: =SUM(基礎!#REF!) -> #REF!
C11: 店舗仕入買掛 | D11: =SUM(基礎!D61:O61) -> 48137000 | E11: =SUM(基礎!V61:AG61) -> 107027000 | F11: =SUM(基礎!AM61:AX61) -> 118214000 | G11: =SUM(基礎!#REF!) -> #REF! | H11: =SUM(基礎!#REF!) -> #REF! | I11: =SUM(基礎!#REF!) -> #REF! | J11: =SUM(基礎!#REF!) -> #REF! | K11: =SUM(基礎!#REF!) -> #REF! | L11: =SUM(基礎!#REF!) -> #REF! | M11: =SUM(基礎!#REF!) -> #REF!
C12: 店舗人件費 | D12: =SUM(基礎!D62:O62) -> 5340000 | E12: =SUM(基礎!V62:AG62) -> 11780000 | F12: =SUM(基礎!AM62:AX62) -> 12100000 | G12: =SUM(基礎!#REF!) -> #REF! | H12: =SUM(基礎!#REF!) -> #REF! | I12: =SUM(基礎!#REF!) -> #REF! | J12: =SUM(基礎!#REF!) -> #REF! | K12: =SUM(基礎!#REF!) -> #REF! | L12: =SUM(基礎!#REF!) -> #REF! | M12: =SUM(基礎!#REF!) -> #REF!
C13: 販管費（ｻｲﾄ１） | D13: =SUM(基礎!D63:O63) -> 6141906.9 | E13: =SUM(基礎!V63:AG63) -> 9593542.4 | F13: =SUM(基礎!AM63:AX63) -> 7240976.5 | G13: =SUM(基礎!#REF!) -> #REF! | H13: =SUM(基礎!#REF!) -> #REF! | I13: =SUM(基礎!#REF!) -> #REF! | J13: =SUM(基礎!#REF!) -> #REF! | K13: =SUM(基礎!#REF!) -> #REF! | L13: =SUM(基礎!#REF!) -> #REF! | M13: =SUM(基礎!#REF!) -> #REF!
C14: 販管費（ｻｲﾄ２） | D14: =SUM(基礎!D64:O64) -> 0 | E14: =SUM(基礎!V64:AG64) -> 0 | F14: =SUM(基礎!AM64:AX64) -> 0 | G14: =SUM(基礎!#REF!) -> #REF! | H14: =SUM(基礎!#REF!) -> #REF! | I14: =SUM(基礎!#REF!) -> #REF! | J14: =SUM(基礎!#REF!) -> #REF! | K14: =SUM(基礎!#REF!) -> #REF! | L14: =SUM(基礎!#REF!) -> #REF! | M14: =SUM(基礎!#REF!) -> #REF!
C15: 支払利息 | D15: =SUM(基礎!D65:O65) -> 245000 | E15: =SUM(基礎!V65:AG65) -> 0 | F15: =SUM(基礎!AM65:AX65) -> 0 | G15: =SUM(基礎!#REF!) -> #REF! | H15: =SUM(基礎!#REF!) -> #REF! | I15: =SUM(基礎!#REF!) -> #REF! | J15: =SUM(基礎!#REF!) -> #REF! | K15: =SUM(基礎!#REF!) -> #REF! | L15: =SUM(基礎!#REF!) -> #REF! | M15: =SUM(基礎!#REF!) -> #REF!
C16: 固定資産購入等 | D16: =SUM(基礎!D66:O66) -> 0 | E16: =SUM(基礎!V66:AG66) -> 0 | F16: =SUM(基礎!AM66:AX66) -> 0 | G16: =SUM(基礎!#REF!) -> #REF! | H16: =SUM(基礎!#REF!) -> #REF! | I16: =SUM(基礎!#REF!) -> #REF! | J16: =SUM(基礎!#REF!) -> #REF! | K16: =SUM(基礎!#REF!) -> #REF! | L16: =SUM(基礎!#REF!) -> #REF! | M16: =SUM(基礎!#REF!) -> #REF!
C17: 他支出 | D17: =SUM(基礎!D67:O67) -> 0 | E17: =SUM(基礎!V67:AG67) -> 0 | F17: =SUM(基礎!AM67:AX67) -> 0 | G17: =SUM(基礎!#REF!) -> #REF! | H17: =SUM(基礎!#REF!) -> #REF! | I17: =SUM(基礎!#REF!) -> #REF! | J17: =SUM(基礎!#REF!) -> #REF! | K17: =SUM(基礎!#REF!) -> #REF! | L17: =SUM(基礎!#REF!) -> #REF! | M17: =SUM(基礎!#REF!) -> #REF!
B18: 経常収支差額 | D18: =SUM(基礎!D68:O68) -> -20103547 | E18: =SUM(基礎!V68:AG68) -> 671161.56 | F18: =SUM(基礎!AM68:AX68) -> 9403422.5 | G18: =SUM(基礎!#REF!) -> #REF! | H18: =SUM(基礎!#REF!) -> #REF! | I18: =SUM(基礎!#REF!) -> #REF! | J18: =SUM(基礎!#REF!) -> #REF! | K18: =SUM(基礎!#REF!) -> #REF! | L18: =SUM(基礎!#REF!) -> #REF! | M18: =SUM(基礎!#REF!) -> #REF!
B19: 財務収入 | D19: =SUM(D20:D27) -> #REF! | E19: =SUM(基礎!V69:AG69) -> 0 | F19: =SUM(基礎!AM69:AX69) -> 0 | G19: =SUM(基礎!#REF!) -> #REF! | H19: =SUM(基礎!#REF!) -> #REF! | I19: =SUM(基礎!#REF!) -> #REF! | J19: =SUM(基礎!#REF!) -> #REF! | K19: =SUM(基礎!#REF!) -> #REF! | L19: =SUM(基礎!#REF!) -> #REF! | M19: =SUM(基礎!#REF!) -> #REF!
C20: 資本金 | D20: 0 | E20: =SUM(基礎!V70:AG70) -> 0 | F20: =SUM(基礎!AM70:AX70) -> 0 | G20: =SUM(基礎!#REF!) -> #REF! | H20: =SUM(基礎!#REF!) -> #REF! | I20: =SUM(基礎!#REF!) -> #REF! | J20: =SUM(基礎!#REF!) -> #REF! | K20: =SUM(基礎!#REF!) -> #REF! | L20: =SUM(基礎!#REF!) -> #REF! | M20: =SUM(基礎!#REF!) -> #REF!
C21: 役員借入 | D21: =SUM(基礎!D71:O71) -> 8000000 | E21: =SUM(基礎!V71:AG71) -> 0 | F21: =SUM(基礎!AM71:AX71) -> 0 | G21: =SUM(基礎!#REF!) -> #REF! | H21: =SUM(基礎!#REF!) -> #REF! | I21: =SUM(基礎!#REF!) -> #REF! | J21: =SUM(基礎!#REF!) -> #REF! | K21: =SUM(基礎!#REF!) -> #REF! | L21: =SUM(基礎!#REF!) -> #REF! | M21: =SUM(基礎!#REF!) -> #REF!
C22: 金融機関借入 | D22: =SUM(基礎!D72:O72) -> 15000000 | E22: =SUM(基礎!V72:AG72) -> 0 | F22: =SUM(基礎!AM72:AX72) -> 0 | G22: =SUM(基礎!#REF!) -> #REF! | H22: =SUM(基礎!#REF!) -> #REF! | I22: =SUM(基礎!#REF!) -> #REF! | J22: =SUM(基礎!#REF!) -> #REF! | K22: =SUM(基礎!#REF!) -> #REF! | L22: =SUM(基礎!#REF!) -> #REF! | M22: =SUM(基礎!#REF!) -> #REF!
C23: 固定資産売却 | D23: =SUM(基礎!D73:O73) -> 0 | E23: =SUM(基礎!V73:AG73) -> 0 | F23: =SUM(基礎!AM73:AX73) -> 0 | G23: =SUM(基礎!#REF!) -> #REF! | H23: =SUM(基礎!#REF!) -> #REF! | I23: =SUM(基礎!#REF!) -> #REF! | J23: =SUM(基礎!#REF!) -> #REF! | K23: =SUM(基礎!#REF!) -> #REF! | L23: =SUM(基礎!#REF!) -> #REF! | M23: =SUM(基礎!#REF!) -> #REF!
C24: FC保証金 | D24: =SUM(基礎!#REF!) -> #REF! | E24: =SUM(基礎!#REF!) -> #REF! | F24: =SUM(基礎!#REF!) -> #REF! | G24: =SUM(基礎!#REF!) -> #REF! | H24: =SUM(基礎!#REF!) -> #REF! | I24: =SUM(基礎!#REF!) -> #REF! | J24: =SUM(基礎!#REF!) -> #REF! | K24: =SUM(基礎!#REF!) -> #REF! | ... M24: =SUM(基礎!#REF!) -> #REF!
C25: 地区本部保証金 | D25: =SUM(基礎!#REF!) -> #REF! | E25: =SUM(基礎!#REF!) -> #REF! | F25: =SUM(基礎!#REF!) -> #REF! | G25: =SUM(基礎!#REF!) -> #REF! | H25: =SUM(基礎!#REF!) -> #REF! | I25: =SUM(基礎!#REF!) -> #REF! | J25: =SUM(基礎!#REF!) -> #REF! | K25: =SUM(基礎!#REF!) -> #REF! | ... M25: =SUM(基礎!#REF!) -> #REF!
C26: 減価償却 | D26: =SUM(基礎!D74:O74) -> 0 | E26: =SUM(基礎!V74:AG74) -> 0 | F26: =SUM(基礎!AM74:AX74) -> 0 | G26: =SUM(基礎!#REF!) -> #REF! | H26: =SUM(基礎!#REF!) -> #REF! | I26: =SUM(基礎!#REF!) -> #REF! | J26: =SUM(基礎!#REF!) -> #REF! | K26: =SUM(基礎!#REF!) -> #REF! | L26: =SUM(基礎!#REF!) -> #REF! | M26: =SUM(基礎!#REF!) -> #REF!
C27: その他 | D27: =SUM(基礎!D76:O76) -> 0 | E27: =SUM(基礎!V76:AG76) -> 0 | F27: =SUM(基礎!AM76:AX76) -> 0 | G27: =SUM(基礎!#REF!) -> #REF! | H27: =SUM(基礎!#REF!) -> #REF! | I27: =SUM(基礎!#REF!) -> #REF! | J27: =SUM(基礎!#REF!) -> #REF! | K27: =SUM(基礎!#REF!) -> #REF! | L27: =SUM(基礎!#REF!) -> #REF! | M27: =SUM(基礎!#REF!) -> #REF!
B28: 財務支出 | D28: =SUM(D29:D35) -> #REF! | E28: =SUM(E29:E35) -> #REF! | F28: =SUM(F29:F35) -> #REF! | G28: =SUM(G29:G35) -> #REF! | H28: =SUM(H29:H35) -> #REF! | I28: =SUM(I29:I35) -> #REF! | J28: =SUM(J29:J35) -> #REF! | K28: =SUM(K29:K35) -> #REF! | ... N28: =SUM(N29:N35) -> 0
C29: 役員返済 | D29: 24000 | E29: 24000 | F29: 24000 | G29: 24000 | H29: 24000 | I29: 0 | J29: 0 | K29: 0 | L29: 0 | M29: 0
C30: 金融機関返済 | D30: =SUM(基礎!D79:O79) -> 399000 | E30: =SUM(基礎!V79:AG79) -> 684000 | F30: =SUM(基礎!AM79:AX79) -> 627000 | G30: =SUM(基礎!#REF!) -> #REF! | H30: =SUM(基礎!#REF!) -> #REF! | I30: =SUM(基礎!#REF!) -> #REF! | J30: =SUM(基礎!#REF!) -> #REF! | K30: =SUM(基礎!#REF!) -> #REF! | L30: =SUM(基礎!#REF!) -> #REF! | M30: =SUM(基礎!#REF!) -> #REF!
C31: FC保証金返却 | D31: =SUM(基礎!#REF!) -> #REF! | E31: =SUM(基礎!#REF!) -> #REF! | F31: =SUM(基礎!#REF!) -> #REF! | G31: =SUM(基礎!#REF!) -> #REF! | H31: =SUM(基礎!#REF!) -> #REF! | I31: =SUM(基礎!#REF!) -> #REF! | J31: =SUM(基礎!#REF!) -> #REF! | K31: =SUM(基礎!#REF!) -> #REF! | ... M31: =SUM(基礎!#REF!) -> #REF!
C32: 地区本部保証金返却 | D32: =SUM(基礎!#REF!) -> #REF! | E32: =SUM(基礎!#REF!) -> #REF! | F32: =SUM(基礎!#REF!) -> #REF! | G32: =SUM(基礎!#REF!) -> #REF! | H32: =SUM(基礎!#REF!) -> #REF! | I32: =SUM(基礎!#REF!) -> #REF! | J32: =SUM(基礎!#REF!) -> #REF! | K32: =SUM(基礎!#REF!) -> #REF! | ... M32: =SUM(基礎!#REF!) -> #REF!
C33: FC本部（システム等） | D33: =SUM(基礎!#REF!) -> #REF! | E33: =SUM(基礎!#REF!) -> #REF! | F33: =SUM(基礎!#REF!) -> #REF! | G33: =SUM(基礎!#REF!) -> #REF! | H33: =SUM(基礎!#REF!) -> #REF! | I33: =SUM(基礎!#REF!) -> #REF! | J33: =SUM(基礎!#REF!) -> #REF! | K33: =SUM(基礎!#REF!) -> #REF! | ... M33: =SUM(基礎!#REF!) -> #REF!
C34: 店舗出店コスト | D34: =SUM(基礎!D80:O80) -> 3000000 | E34: =SUM(基礎!V80:AG80) -> 0 | F34: =SUM(基礎!AM80:AX80) -> 0 | G34: =SUM(基礎!#REF!) -> #REF! | H34: =SUM(基礎!#REF!) -> #REF! | I34: =SUM(基礎!#REF!) -> #REF! | J34: =SUM(基礎!#REF!) -> #REF! | K34: =SUM(基礎!#REF!) -> #REF! | L34: =SUM(基礎!#REF!) -> #REF! | M34: =SUM(基礎!#REF!) -> #REF!
C35: その他 | D35: =SUM(基礎!D82:O82) -> 0 | E35: =SUM(基礎!V82:AG82) -> 0 | F35: =SUM(基礎!AM82:AX82) -> 0 | G35: =SUM(基礎!#REF!) -> #REF! | H35: =SUM(基礎!#REF!) -> #REF! | I35: =SUM(基礎!#REF!) -> #REF! | J35: =SUM(基礎!#REF!) -> #REF! | K35: =SUM(基礎!#REF!) -> #REF! | L35: =SUM(基礎!#REF!) -> #REF! | M35: =SUM(基礎!#REF!) -> #REF!
B36: 財務収支差額 | D36: =D19-D28 -> #REF! | E36: =E19-E28 -> #REF! | F36: =F19-F28 -> #REF! | G36: =G19-G28 -> #REF! | H36: =H19-H28 -> #REF! | I36: =I19-I28 -> #REF! | J36: =J19-J28 -> #REF! | K36: =K19-K28 -> #REF! | ... M36: =M19-M28 -> #REF!
B37: CF | D37: =D18+D36 -> #REF! | E37: =E18+E36 -> #REF! | F37: =F18+F36 -> #REF! | G37: =G18+G36 -> #REF! | H37: =H18+H36 -> #REF! | I37: =I18+I36 -> #REF! | J37: =J18+J36 -> #REF! | K37: =K18+K36 -> #REF! | ... M37: =M18+M36 -> #REF!
B38: 税金 | D38: =PL!D28 -> 0 | E38: =PL!E28 -> 579164.6 | F38: =PL!F28 -> 17192711 | G38: =PL!#REF! -> #REF! | H38: =PL!#REF! -> #REF! | I38: =PL!#REF! -> #REF! | J38: =PL!#REF! -> #REF! | K38: =PL!#REF! -> #REF! | L38: =PL!#REF! -> #REF! | M38: =PL!#REF! -> #REF!
B39: 税引後CF | D39: =D37-D38 -> #REF! | E39: =E37-E38 -> #REF! | F39: =F37-F38 -> #REF! | G39: =G37-G38 -> #REF! | H39: =H37-H38 -> #REF! | I39: =I37-I38 -> #REF! | J39: =J37-J38 -> #REF! | K39: =K37-K38 -> #REF! | ... M39: =M37-M38 -> #REF!
B40: 翌年度繰越 | D40: =D4+D39 -> #REF! | E40: =E4+E39 -> #REF! | F40: =F4+F39 -> #REF! | G40: =G4+G39 -> #REF! | H40: =H4+H39 -> #REF! | I40: =I4+I39 -> #REF! | J40: =J4+J39 -> #REF! | K40: =K4+K39 -> #REF! | ... M40: =M4+M39 -> #REF!
...

Sheet 事業評価【A案・税引後】
E1: 1 | F1: 2 | G1: 3 | H1: 4 | I1: 5 | J1: 6 | K1: 7 | L1: 8 | M1: 9
B2: 企業価値A案（税引後） | M2: 【千円】
D3: H23年度 | E3: H24年度 | F3: H25年度 | G3: H26年度 | H3: H27年度 | I3: H28年度 | J3: H29年度 | K3: H30年度 | L3: H31年度 | M3: H32年度
B4: 前年度繰越 | D4: 0 | E4: =D40 -> #REF! | F4: =E40 -> #REF! | G4: =F40 -> #REF! | H4: =G40 -> #REF! | I4: =H40 -> #REF! | J4: =I40 -> #REF! | K4: =J40 -> #REF! | L4: =K40 -> #REF! | M4: =L40 -> #REF!
B5: 経常収入 | D5: =SUM(基礎!D55:O55) -> 39760360 | E5: =SUM(基礎!V55:AG55) -> 129071704 | F5: =SUM(基礎!AM55:AX55) -> 146958399 | G5: =SUM(基礎!#REF!) -> #REF! | H5: =SUM(基礎!#REF!) -> #REF! | I5: =SUM(基礎!#REF!) -> #REF! | J5: =SUM(基礎!#REF!) -> #REF! | K5: =SUM(基礎!#REF!) -> #REF! | L5: =SUM(基礎!#REF!) -> #REF! | M5: =SUM(基礎!#REF!) -> #REF!
C6: 店舗現金売上 | D6: =SUM(基礎!D56:O56) -> 31990360 | E6: =SUM(基礎!V56:AG56) -> 107291682 | F6: =SUM(基礎!AM56:AX56) -> 122868375 | G6: =SUM(基礎!#REF!) -> #REF! | H6: =SUM(基礎!#REF!) -> #REF! | I6: =SUM(基礎!#REF!) -> #REF! | J6: =SUM(基礎!#REF!) -> #REF! | K6: =SUM(基礎!#REF!) -> #REF! | L6: =SUM(基礎!#REF!) -> #REF! | M6: =SUM(基礎!#REF!) -> #REF!
C7: 店舗催事売掛入金 | D7: =SUM(基礎!D57:O57) -> 7770000 | E7: =SUM(基礎!V57:AG57) -> 21780022 | F7: =SUM(基礎!AM57:AX57) -> 24090024 | G7: =SUM(基礎!#REF!) -> #REF! | H7: =SUM(基礎!#REF!) -> #REF! | I7: =SUM(基礎!#REF!) -> #REF! | J7: =SUM(基礎!#REF!) -> #REF! | K7: =SUM(基礎!#REF!) -> #REF! | L7: =SUM(基礎!#REF!) -> #REF! | M7: =SUM(基礎!#REF!) -> #REF!
C8: FCロイヤリティ | D8: =SUM(基礎!D58:O58) -> 0 | E8: =SUM(基礎!V58:AG58) -> 0 | F8: =SUM(基礎!AM58:AX58) -> 0 | G8: =SUM(基礎!#REF!) -> #REF! | H8: =SUM(基礎!#REF!) -> #REF! | I8: =SUM(基礎!#REF!) -> #REF! | J8: =SUM(基礎!#REF!) -> #REF! | K8: =SUM(基礎!#REF!) -> #REF! | L8: =SUM(基礎!#REF!) -> #REF! | M8: =SUM(基礎!#REF!) -> #REF!
C9: 他収入 | D9: =SUM(基礎!D59:O59) -> 0 | E9: =SUM(基礎!V59:AG59) -> 0 | F9: =SUM(基礎!AM59:AX59) -> 0 | G9: =SUM(基礎!#REF!) -> #REF! | H9: =SUM(基礎!#REF!) -> #REF! | I9: =SUM(基礎!#REF!) -> #REF! | J9: =SUM(基礎!#REF!) -> #REF! | K9: =SUM(基礎!#REF!) -> #REF! | L9: =SUM(基礎!#REF!) -> #REF! | M9: =SUM(基礎!#REF!) -> #REF!
B10: 経常支出 | D10: =SUM(基礎!D60:O60) -> 59863907 | E10: =SUM(基礎!V60:AG60) -> 1.2840054e+08 | F10: =SUM(基礎!AM60:AX60) -> 1.3755498e+08 | G10: =SUM(基礎!#REF!) -> #REF! | H10: =SUM(基礎!#REF!) -> #REF! | I10: =SUM(基礎!#REF!) -> #REF! | J10: =SUM(基礎!#REF!) -> #REF! | K10: =SUM(基礎!#REF!) -> #REF! | L10: =SUM(基礎!#REF!) -> #REF! | M10: =SUM(基礎!#REF!) -> #REF!
C11: 店舗仕入買掛 | D11: =SUM(基礎!D61:O61) -> 48137000 | E11: =SUM(基礎!V61:AG61) -> 107027000 | F11: =SUM(基礎!AM61:AX61) -> 118214000 | G11: =SUM(基礎!#REF!) -> #REF! | H11: =SUM(基礎!#REF!) -> #REF! | I11: =SUM(基礎!#REF!) -> #REF! | J11: =SUM(基礎!#REF!) -> #REF! | K11: =SUM(基礎!#REF!) -> #REF! | L11: =SUM(基礎!#REF!) -> #REF! | M11: =SUM(基礎!#REF!) -> #REF!
C12: 店舗人件費 | D12: =SUM(基礎!D62:O62) -> 5340000 | E12: =SUM(基礎!V62:AG62) -> 11780000 | F12: =SUM(基礎!AM62:AX62) -> 12100000 | G12: =SUM(基礎!#REF!) -> #REF! | H12: =SUM(基礎!#REF!) -> #REF! | I12: =SUM(基礎!#REF!) -> #REF! | J12: =SUM(基礎!#REF!) -> #REF! | K12: =SUM(基礎!#REF!) -> #REF! | L12: =SUM(基礎!#REF!) -> #REF! | M12: =SUM(基礎!#REF!) -> #REF!
C13: 販管費（ｻｲﾄ１） | D13: =SUM(基礎!D63:O63) -> 6141906.9 | E13: =SUM(基礎!V63:AG63) -> 9593542.4 | F13: =SUM(基礎!AM63:AX63) -> 7240976.5 | G13: =SUM(基礎!#REF!) -> #REF! | H13: =SUM(基礎!#REF!) -> #REF! | I13: =SUM(基礎!#REF!) -> #REF! | J13: =SUM(基礎!#REF!) -> #REF! | K13: =SUM(基礎!#REF!) -> #REF! | L13: =SUM(基礎!#REF!) -> #REF! | M13: =SUM(基礎!#REF!) -> #REF!
C14: 販管費（ｻｲﾄ２） | D14: =SUM(基礎!D64:O64) -> 0 | E14: =SUM(基礎!V64:AG64) -> 0 | F14: =SUM(基礎!AM64:AX64) -> 0 | G14: =SUM(基礎!#REF!) -> #REF! | H14: =SUM(基礎!#REF!) -> #REF! | I14: =SUM(基礎!#REF!) -> #REF! | J14: =SUM(基礎!#REF!) -> #REF! | K14: =SUM(基礎!#REF!) -> #REF! | L14: =SUM(基礎!#REF!) -> #REF! | M14: =SUM(基礎!#REF!) -> #REF!
C15: 支払利息 | D15: =SUM(基礎!D65:O65) -> 245000 | E15: =SUM(基礎!V65:AG65) -> 0 | F15: =SUM(基礎!AM65:AX65) -> 0 | G15: =SUM(基礎!#REF!) -> #REF! | H15: =SUM(基礎!#REF!) -> #REF! | I15: =SUM(基礎!#REF!) -> #REF! | J15: =SUM(基礎!#REF!) -> #REF! | K15: =SUM(基礎!#REF!) -> #REF! | L15: =SUM(基礎!#REF!) -> #REF! | M15: =SUM(基礎!#REF!) -> #REF!
C16: 固定資産購入等 | D16: =SUM(基礎!D66:O66) -> 0 | E16: =SUM(基礎!V66:AG66) -> 0 | F16: =SUM(基礎!AM66:AX66) -> 0 | G16: =SUM(基礎!#REF!) -> #REF! | H16: =SUM(基礎!#REF!) -> #REF! | I16: =SUM(基礎!#REF!) -> #REF! | J16: =SUM(基礎!#REF!) -> #REF! | K16: =SUM(基礎!#REF!) -> #REF! | L16: =SUM(基礎!#REF!) -> #REF! | M16: =SUM(基礎!#REF!) -> #REF!
C17: 他支出 | D17: =SUM(基礎!D67:O67) -> 0 | E17: =SUM(基礎!V67:AG67) -> 0 | F17: =SUM(基礎!AM67:AX67) -> 0 | G17: =SUM(基礎!#REF!) -> #REF! | H17: =SUM(基礎!#REF!) -> #REF! | I17: =SUM(基礎!#REF!) -> #REF! | J17: =SUM(基礎!#REF!) -> #REF! | K17: =SUM(基礎!#REF!) -> #REF! | L17: =SUM(基礎!#REF!) -> #REF! | M17: =SUM(基礎!#REF!) -> #REF!
B18: 経常収支差額 | D18: =SUM(基礎!D68:O68) -> -20103547 | E18: =SUM(基礎!V68:AG68) -> 671161.56 | F18: =SUM(基礎!AM68:AX68) -> 9403422.5 | G18: =SUM(基礎!#REF!) -> #REF! | H18: =SUM(基礎!#REF!) -> #REF! | I18: =SUM(基礎!#REF!) -> #REF! | J18: =SUM(基礎!#REF!) -> #REF! | K18: =SUM(基礎!#REF!) -> #REF! | L18: =SUM(基礎!#REF!) -> #REF! | M18: =SUM(基礎!#REF!) -> #REF!
B19: 財務収入 | D19: =SUM(D20:D27) -> #REF! | E19: =SUM(基礎!V69:AG69) -> 0 | F19: =SUM(基礎!AM69:AX69) -> 0 | G19: =SUM(基礎!#REF!) -> #REF! | H19: =SUM(基礎!#REF!) -> #REF! | I19: =SUM(基礎!#REF!) -> #REF! | J19: =SUM(基礎!#REF!) -> #REF! | K19: =SUM(基礎!#REF!) -> #REF! | L19: =SUM(基礎!#REF!) -> #REF! | M19: =SUM(基礎!#REF!) -> #REF!
C20: 資本金 | D20: 0 | E20: =SUM(基礎!V70:AG70) -> 0 | F20: =SUM(基礎!AM70:AX70) -> 0 | G20: =SUM(基礎!#REF!) -> #REF! | H20: =SUM(基礎!#REF!) -> #REF! | I20: =SUM(基礎!#REF!) -> #REF! | J20: =SUM(基礎!#REF!) -> #REF! | K20: =SUM(基礎!#REF!) -> #REF! | L20: =SUM(基礎!#REF!) -> #REF! | M20: =SUM(基礎!#REF!) -> #REF!
C21: 役員借入 | D21: =SUM(基礎!D71:O71) -> 8000000 | E21: =SUM(基礎!V71:AG71) -> 0 | F21: =SUM(基礎!AM71:AX71) -> 0 | G21: =SUM(基礎!#REF!) -> #REF! | H21: =SUM(基礎!#REF!) -> #REF! | I21: =SUM(基礎!#REF!) -> #REF! | J21: =SUM(基礎!#REF!) -> #REF! | K21: =SUM(基礎!#REF!) -> #REF! | L21: =SUM(基礎!#REF!) -> #REF! | M21: =SUM(基礎!#REF!) -> #REF!
C22: 金融機関借入 | D22: =SUM(基礎!D72:O72) -> 15000000 | E22: =SUM(基礎!V72:AG72) -> 0 | F22: =SUM(基礎!AM72:AX72) -> 0 | G22: =SUM(基礎!#REF!) -> #REF! | H22: =SUM(基礎!#REF!) -> #REF! | I22: =SUM(基礎!#REF!) -> #REF! | J22: =SUM(基礎!#REF!) -> #REF! | K22: =SUM(基礎!#REF!) -> #REF! | L22: =SUM(基礎!#REF!) -> #REF! | M22: =SUM(基礎!#REF!) -> #REF!
C23: 固定資産売却 | D23: =SUM(基礎!D73:O73) -> 0 | E23: =SUM(基礎!V73:AG73) -> 0 | F23: =SUM(基礎!AM73:AX73) -> 0 | G23: =SUM(基礎!#REF!) -> #REF! | H23: =SUM(基礎!#REF!) -> #REF! | I23: =SUM(基礎!#REF!) -> #REF! | J23: =SUM(基礎!#REF!) -> #REF! | K23: =SUM(基礎!#REF!) -> #REF! | L23: =SUM(基礎!#REF!) -> #REF! | M23: =SUM(基礎!#REF!) -> #REF!
C24: FC保証金 | D24: =SUM(基礎!#REF!) -> #REF! | E24: =SUM(基礎!#REF!) -> #REF! | F24: =SUM(基礎!#REF!) -> #REF! | G24: =SUM(基礎!#REF!) -> #REF! | H24: =SUM(基礎!#REF!) -> #REF! | I24: =SUM(基礎!#REF!) -> #REF! | J24: =SUM(基礎!#REF!) -> #REF! | K24: =SUM(基礎!#REF!) -> #REF! | ... M24: =SUM(基礎!#REF!) -> #REF!
C25: 地区本部保証金 | D25: =SUM(基礎!#REF!) -> #REF! | E25: =SUM(基礎!#REF!) -> #REF! | F25: =SUM(基礎!#REF!) -> #REF! | G25: =SUM(基礎!#REF!) -> #REF! | H25: =SUM(基礎!#REF!) -> #REF! | I25: =SUM(基礎!#REF!) -> #REF! | J25: =SUM(基礎!#REF!) -> #REF! | K25: =SUM(基礎!#REF!) -> #REF! | ... M25: =SUM(基礎!#REF!) -> #REF!
C26: 減価償却 | D26: =SUM(基礎!D74:O74) -> 0 | E26: =SUM(基礎!V74:AG74) -> 0 | F26: =SUM(基礎!AM74:AX74) -> 0 | G26: =SUM(基礎!#REF!) -> #REF! | H26: =SUM(基礎!#REF!) -> #REF! | I26: =SUM(基礎!#REF!) -> #REF! | J26: =SUM(基礎!#REF!) -> #REF! | K26: =SUM(基礎!#REF!) -> #REF! | L26: =SUM(基礎!#REF!) -> #REF! | M26: =SUM(基礎!#REF!) -> #REF!
C27: その他 | D27: =SUM(基礎!D76:O76) -> 0 | E27: =SUM(基礎!V76:AG76) -> 0 | F27: =SUM(基礎!AM76:AX76) -> 0 | G27: =SUM(基礎!#REF!) -> #REF! | H27: =SUM(基礎!#REF!) -> #REF! | I27: =SUM(基礎!#REF!) -> #REF! | J27: =SUM(基礎!#REF!) -> #REF! | K27: =SUM(基礎!#REF!) -> #REF! | L27: =SUM(基礎!#REF!) -> #REF! | M27: =SUM(基礎!#REF!) -> #REF!
B28: 財務支出 | D28: =SUM(D29:D35) -> #REF! | E28: =SUM(E29:E35) -> #REF! | F28: =SUM(F29:F35) -> #REF! | G28: =SUM(G29:G35) -> #REF! | H28: =SUM(H29:H35) -> #REF! | I28: =SUM(I29:I35) -> #REF! | J28: =SUM(J29:J35) -> #REF! | K28: =SUM(K29:K35) -> #REF! | ... N28: =SUM(N29:N35) -> 0
C29: 役員返済 | D29: 24000 | E29: 24000 | F29: 24000 | G29: 24000 | H29: 24000 | I29: 0 | J29: 0 | K29: 0 | L29: 0 | M29: 0
C30: 金融機関返済 | D30: =SUM(基礎!D79:O79) -> 399000 | E30: =SUM(基礎!V79:AG79) -> 684000 | F30: =SUM(基礎!AM79:AX79) -> 627000 | G30: =SUM(基礎!#REF!) -> #REF! | H30: =SUM(基礎!#REF!) -> #REF! | I30: =SUM(基礎!#REF!) -> #REF! | J30: =SUM(基礎!#REF!) -> #REF! | K30: =SUM(基礎!#REF!) -> #REF! | L30: =SUM(基礎!#REF!) -> #REF! | M30: =SUM(基礎!#REF!) -> #REF!
C31: FC保証金返却 | D31: =SUM(基礎!#REF!) -> #REF! | E31: =SUM(基礎!#REF!) -> #REF! | F31: =SUM(基礎!#REF!) -> #REF! | G31: =SUM(基礎!#REF!) -> #REF! | H31: =SUM(基礎!#REF!) -> #REF! | I31: =SUM(基礎!#REF!) -> #REF! | J31: =SUM(基礎!#REF!) -> #REF! | K31: =SUM(基礎!#REF!) -> #REF! | ... M31: =SUM(基礎!#REF!) -> #REF!
C32: 地区本部保証金返却 | D32: =SUM(基礎!#REF!) -> #REF! | E32: =SUM(基礎!#REF!) -> #REF! | F32: =SUM(基礎!#REF!) -> #REF! | G32: =SUM(基礎!#REF!) -> #REF! | H32: =SUM(基礎!#REF!) -> #REF! | I32: =SUM(基礎!#REF!) -> #REF! | J32: =SUM(基礎!#REF!) -> #REF! | K32: =SUM(基礎!#REF!) -> #REF! | ... M32: =SUM(基礎!#REF!) -> #REF!
C33: FC本部（システム等） | D33: =SUM(基礎!#REF!) -> #REF! | E33: =SUM(基礎!#REF!) -> #REF! | F33: =SUM(基礎!#REF!) -> #REF! | G33: =SUM(基礎!#REF!) -> #REF! | H33: =SUM(基礎!#REF!) -> #REF! | I33: =SUM(基礎!#REF!) -> #REF! | J33: =SUM(基礎!#REF!) -> #REF! | K33: =SUM(基礎!#REF!) -> #REF! | ... M33: =SUM(基礎!#REF!) -> #REF!
C34: 店舗出店コスト | D34: =SUM(基礎!D80:O80) -> 3000000 | E34: =SUM(基礎!V80:AG80) -> 0 | F34: =SUM(基礎!AM80:AX80) -> 0 | G34: =SUM(基礎!#REF!) -> #REF! | H34: =SUM(基礎!#REF!) -> #REF! | I34: =SUM(基礎!#REF!) -> #REF! | J34: =SUM(基礎!#REF!) -> #REF! | K34: =SUM(基礎!#REF!) -> #REF! | L34: =SUM(基礎!#REF!) -> #REF! | M34: =SUM(基礎!#REF!) -> #REF!
C35: その他 | D35: =SUM(基礎!D82:O82) -> 0 | E35: =SUM(基礎!V82:AG82) -> 0 | F35: =SUM(基礎!AM82:AX82) -> 0 | G35: =SUM(基礎!#REF!) -> #REF! | H35: =SUM(基礎!#REF!) -> #REF! | I35: =SUM(基礎!#REF!) -> #REF! | J35: =SUM(基礎!#REF!) -> #REF! | K35: =SUM(基礎!#REF!) -> #REF! | L35: =SUM(基礎!#REF!) -> #REF! | M35: =SUM(基礎!#REF!) -> #REF!
B36: 財務収支差額 | D36: =D19-D28 -> #REF! | E36: =E19-E28 -> #REF! | F36: =F19-F28 -> #REF! | G36: =G19-G28 -> #REF! | H36: =H19-H28 -> #REF! | I36: =I19-I28 -> #REF! | J36: =J19-J28 -> #REF! | K36: =K19-K28 -> #REF! | ... M36: =M19-M28 -> #REF!
B37: CF | D37: =D18+D36 -> #REF! | E37: =E18+E36 -> #REF! | F37: =F18+F36 -> #REF! | G37: =G18+G36 -> #REF! | H37: =H18+H36 -> #REF! | I37: =I18+I36 -> #REF! | J37: =J18+J36 -> #REF! | K37: =K18+K36 -> #REF! | ... M37: =M18+M36 -> #REF!
B38: 税金 | D38: =PL!D28 -> 0 | E38: =PL!E28 -> 579164.6 | F38: =PL!F28 -> 17192711 | G38: =PL!#REF! -> #REF! | H38: =PL!#REF! -> #REF! | I38: =PL!#REF! -> #REF! | J38: =PL!#REF! -> #REF! | K38: =PL!#REF! -> #REF! | L38: =PL!#REF! -> #REF! | M38: =PL!#REF! -> #REF!
B39: 税引後CF | D39: =D37-D38 -> #REF! | E39: =E37-E38 -> #REF! | F39: =F37-F38 -> #REF! | G39: =G37-G38 -> #REF! | H39: =H37-H38 -> #REF! | I39: =I37-I38 -> #REF! | J39: =J37-J38 -> #REF! | K39: =K37-K38 -> #REF! | ... M39: =M37-M38 -> #REF!
B40: 翌年度繰越 | D40: =D4+D39 -> #REF! | E40: =E4+E39 -> #REF! | F40: =F4+F39 -> #REF! | G40: =G4+G39 -> #REF! | H40: =H4+H39 -> #REF! | I40: =I4+I39 -> #REF! | J40: =J4+J39 -> #REF! | K40: =K4+K39 -> #REF! | ... M40: =M4+M39 -> #REF!
...

Sheet Sheet2
B2: 現在 | F2: R3 | J2: R4 | N2: R5 | R2: R6 | V2: R7
F3: 4-6 | G3: 7-9 | H3: 10-12 | I3: 1-3 | J3: 4-6 | K3: 7-9 | L3: 10-12 | M3: 1-3 | N3: 4-6 | O3: 7-9 | P3: 10-12 | Q3: 1-3 | R3: 4-6 | S3: 7-9 | T3: 10-12 | U3: 1-3 | V3: 4-6 | W3: 7-9 | X3: 10-12 | Y3: 1-3
B4: 直営(累計） | F4: =SUM(F6:F15) -> 1 | G4: =SUM(G6:G15)+F4 -> 3 | H4: =SUM(H6:H15)+G4 -> 4 | I4: =SUM(I6:I15)+H4 -> 5 | J4: =SUM(J6:J15)+I4 -> 5 | K4: =SUM(K6:K15)+J4 -> 5 | L4: =SUM(L6:L15)+K4 -> 5 | M4: =SUM(M6:M15)+L4 -> 5 | N4: =SUM(N6:N15)+M4 -> 5 | ... Y4: =SUM(Y6:Y15)+X4 -> 5
C5: 福祉
D6: 就労移行支援 | E6: 0.5 | F6: 1 | G6: 0.5 | H6: 1 | I6: 1
D7: 就労継続支援A型
D8: 就労継続支援B型 | E8: 0.5 | G8: 0.5
D9: 相談支援等 | G9: 1
C11: 教育
D12: 個別塾 | E12: 1
D13: はくし | E13: 1
D14: メディカルフィットネス
B16: FC | F16: =SUM(F17:F24) -> 0 | G16: =SUM(G17:G24)+F16 -> 1 | H16: =SUM(H17:H24)+G16 -> 1 | I16: =SUM(I17:I24)+H16 -> 1 | J16: =SUM(J17:J24)+I16 -> 1 | K16: =SUM(K17:K24)+J16 -> 1 | L16: =SUM(L17:L24)+K16 -> 1 | M16: =SUM(M17:M24)+L16 -> 1 | N16: =SUM(N17:N24)+M16 -> 1 | ... Y16: =SUM(Y17:Y24)+X16 -> 1
D17: 就労移行支援 | G17: 1
D18: 就労継続支援A型
D19: 就労継続支援B型
D20: 個別塾
D21: オンライン塾
D22: メディカルフィットネス
B23: 優先調達事業
D24: 自治体アウトソーシング
D25: DX事業
D26: メディア事業
D27: ファーム事業

Sheet 売上計画
D1: H23年度 | H1: H24年度 | L1: H25年度 | P1: H26年度 | T1: H27年度 | X1: H28年度 | AB1: H29年度 | AF1: H30年度
D2: Phase 1：基盤構築フェーズ | I2: Phase 2：高成長フェーズ（目標は100%成長） | P2: Phase3：安定成長フェーズ（目標は50%成長） | X2: Phase4：海外進出基盤構築フェーズ | AB2: Phase5：海外成長フェーズ | AF2: Phase6：海外安定成長フェーズ
C3: 月平均売上 | D3: 5 | E3: 6-8 | F3: 9-11 | G3: 12-2 | H3: 3-5 | I3: 6-8 | J3: 9-11 | K3: 12-2 | L3: 3-5 | M3: 6-8 | N3: 9-11 | O3: 12-2 | P3: 3-5 | Q3: 6-8 | R3: 9-11 | S3: 12-2 | T3: 3-5 | U3: 6-8 | V3: 9-11 | W3: 12-2 | X3: 3-5 | Y3: 6-8 | Z3: 9-11 | AA3: 12-2 | AB3: 3-5 | AC3: 6-8 | AD3: 9-11 | AE3: 12-2 | AF3: 3-5 | AG3: 6-8 | AH3: 9-11 | AI3: 12-2
A4: 直営 | B4: 都市型 | C4: 9000 | D4: 1 | E4: 1 | F4: 1 | G4: 2 | H4: 3 | I4: 3 | J4: 3 | K4: 3 | L4: 3 | M4: 4 | N4: 5 | O4: 6 | P4: 6 | Q4: 6 | R4: 7 | S4: 7 | T4: 7 | U4: 9 | V4: 9 | W4: 10 | X4: 10 | Y4: 12 | Z4: 14 | AA4: 16 | AB4: 18 | AC4: 20 | AD4: 22 | AE4: 24 | AF4: 26 | AG4: 28 | AH4: 30 | AI4: 31
B5: サテライト型 | C5: 6000 | D5: 1 | E5: 1 | F5: 1 | G5: 2 | H5: 3 | I5: 3 | J5: 3 | K5: 3 | L5: 3 | M5: 4 | N5: 5 | O5: 6 | P5: 6 | Q5: 6 | R5: 6 | S5: 7 | T5: 7 | U5: 9 | V5: 9 | W5: 10 | X5: 11 | Y5: 12 | Z5: 13 | AA5: 14 | AB5: 14 | AC5: 15 | AD5: 16 | AE5: 18 | AF5: 18 | AG5: 19 | AH5: 20 | AI5: 20
B6: 郊外型 | C6: 7500 | D6: 1 | E6: 1 | F6: 1 | G6: 2 | H6: 2 | I6: 2 | J6: 3 | K6: 3 | L6: 3 | M6: 4 | N6: 4 | O6: 5 | P6: 6 | Q6: 6 | R6: 6 | S6: 7 | T6: 7 | U6: 9 | V6: 9 | W6: 10 | X6: 10 | Y6: 10 | Z6: 10 | AA6: 10 | AB6: 10 | AC6: 10 | AD6: 10 | AE6: 12 | AF6: 12 | AG6: 12 | AH6: 13 | AI6: 13
B7: SC内 | C7: 6000 | D7: 1 | E7: 1 | F7: 1 | G7: 2 | H7: 2 | I7: 2 | J7: 2 | K7: 2 | L7: 2 | M7: 2 | N7: 2 | O7: 3 | P7: 3 | Q7: 3 | R7: 3 | S7: 4 | T7: 4 | U7: 4 | V7: 4 | W7: 5 | X7: 5 | Y7: 5 | Z7: 5 | AA7: 5 | AB7: 5 | AC7: 5 | AD7: 5 | AE7: 6 | AF7: 6 | AG7: 6 | AH7: 6 | AI7: 6
B8: 売上小計 | D8: =(($C4*D4)+($C5*D5)+($C6*D6)+($C7*D7))*1 -> 28500 | E8: =(($C4*E4)+($C5*E5)+($C6*E6)+($C7*E7))*3 -> 85500 | F8: =(($C4*F4)+($C5*F5)+($C6*F6)+($C7*F7))*3 -> 85500 | G8: =(($C4*G4)+($C5*G5)+($C6*G6)+($C7*G7))*3 -> 171000 | H8: =(($C4*H4)+($C5*H5)+($C6*H6)+($C7*H7))*3 -> 216000 | I8: =(($C4*I4)+($C5*I5)+($C6*I6)+($C7*I7))*3 -> 216000 | J8: =(($C4*J4)+($C5*J5)+($C6*J6)+($C7*J7))*3 -> 238500 | K8: =(($C4*K4)+($C5*K5)+($C6*K6)+($C7*K7))*3 -> 238500 | L8: =(($C4*L4)+($C5*L5)+($C6*L6)+($C7*L7))*3 -> 238500 | ... AI8: =(($C4*AI4)+($C5*AI5)+($C6*AI6)+($C7*AI7))*3 -> 1597500
B9: 店舗数 | D9: =SUM(D4:D7) -> 4 | E9: =SUM(E4:E7) -> 4 | F9: =SUM(F4:F7) -> 4 | G9: =SUM(G4:G7) -> 8 | H9: =SUM(H4:H7) -> 10 | I9: =SUM(I4:I7) -> 10 | J9: =SUM(J4:J7) -> 11 | K9: =SUM(K4:K7) -> 11 | ... AI9: =SUM(AI4:AI7) -> 70
A11: FC | B11: 都市型 | C11: =9000 -> 9000 | E11: 1 | F11: 2 | G11: 2 | H11: 3 | I11: 4 | J11: 4 | K11: 6 | L11: 6 | M11: 9 | N11: 9 | O11: 12 | P11: 14 | Q11: 16 | R11: 18 | S11: 20 | T11: 22 | U11: 24 | V11: 26 | W11: 28 | X11: 31 | Y11: 34 | Z11: 37 | AA11: 40 | AB11: 43 | AC11: 46 | AD11: 49 | AE11: 54 | AF11: 55 | AG11: 58 | AH11: 61 | AI11: 64
B12: サテライト型 | C12: =6000 -> 6000 | E12: 1 | F12: 1 | G12: 2 | H12: 2 | I12: 4 | J12: 4 | K12: 6 | L12: 6 | M12: 9 | N12: 9 | O12: 12 | P12: 14 | Q12: 16 | R12: 18 | S12: 20 | T12: 22 | U12: 24 | V12: 26 | W12: 28 | X12: 31 | Y12: 34 | Z12: 37 | AA12: 42 | AB12: 43 | AC12: 46 | AD12: 49 | AE12: 54 | AF12: 55 | AG12: 58 | AH12: 61 | AI12: 64
B13: 郊外型 | C13: =7500 -> 7500 | E13: 1 | F13: 1 | G13: 2 | H13: 2 | I13: 4 | J13: 4 | K13: 6 | L13: 6 | M13: 9 | N13: 9 | O13: 12 | P13: 14 | Q13: 16 | R13: 18 | S13: 20 | T13: 22 | U13: 24 | V13: 26 | W13: 28 | X13: 31 | Y13: 34 | Z13: 37 | AA13: 40 | AB13: 43 | AC13: 46 | AD13: 49 | AE13: 52 | AF13: 55 | AG13: 58 | AH13: 61 | AI13: 64
B14: SC内 | C14: =6000 -> 6000 | E14: 1 | F14: 2 | G14: 2 | H14: 2 | I14: 2 | J14: 2 | K14: 3 | L14: 3 | M14: 3 | N14: 4 | O14: 4 | P14: 4 | Q14: 4 | R14: 4 | S14: 5 | T14: 5 | U14: 5 | V14: 5 | W14: 6 | X14: 6 | Y14: 6 | Z14: 6 | AA14: 8 | AB14: 8 | AC14: 10 | AD14: 10 | AE14: 10 | AF14: 12 | AG14: 12 | AH14: 12 | AI14: 13
B15: 店舗売上小計 | D15: =(($C11*D11)+($C12*D12)+($C13*D13)+($C14*D14))*3 -> 0 | E15: =(($C11*E11)+($C12*E12)+($C13*E13)+($C14*E14))*3 -> 85500 | F15: =(($C11*F11)+($C12*F12)+($C13*F13)+($C14*F14))*3 -> 130500 | G15: =(($C11*G11)+($C12*G12)+($C13*G13)+($C14*G14))*3 -> 171000 | H15: =(($C11*H11)+($C12*H12)+($C13*H13)+($C14*H14))*3 -> 198000 | I15: =(($C11*I11)+($C12*I12)+($C13*I13)+($C14*I14))*3 -> 306000 | J15: =(($C11*J11)+($C12*J12)+($C13*J13)+($C14*J14))*3 -> 306000 | K15: =(($C11*K11)+($C12*K12)+($C13*K13)+($C14*K14))*3 -> 459000 | ... AI15: =(($C11*AI11)+($C12*AI12)+($C13*AI13)+($C14*AI14))*3 -> 4554000
B16: ロイヤルティ売上 | D16: =D15*0.06 -> 0 | E16: =E15*0.06 -> 5130 | F16: =F15*0.06 -> 7830 | G16: =G15*0.06 -> 10260 | H16: =H15*0.06 -> 11880 | I16: =I15*0.06 -> 18360 | J16: =J15*0.06 -> 18360 | K16: =K15*0.06 -> 27540 | ... AI16: =AI15*0.06 -> 273240
B17: 店舗数 | D17: =SUM(D11:D14) -> 0 | E17: =SUM(E11:E14) -> 4 | F17: =SUM(F11:F14) -> 6 | G17: =SUM(G11:G14) -> 8 | H17: =SUM(H11:H14) -> 9 | I17: =SUM(I11:I14) -> 14 | J17: =SUM(J11:J14) -> 14 | K17: =SUM(K11:K14) -> 21 | ... AI17: =SUM(AI11:AI14) -> 205
B19: 全店舗数 | D19: =D9+D17 -> 4 | E19: =E9+E17 -> 8 | F19: =F9+F17 -> 10 | G19: =G9+G17 -> 16 | H19: =H9+H17 -> 19 | I19: =I9+I17 -> 24 | J19: =J9+J17 -> 25 | K19: =K9+K17 -> 32 | ... AI19: =AI9+AI17 -> 275
B20: 直営FC合計売上 | D20: =D8+D16 -> 28500 | E20: =E8+E16 -> 90630 | F20: =F8+F16 -> 93330 | G20: =G8+G16 -> 181260 | H20: =H8+H16 -> 227880 | I20: =I8+I16 -> 234360 | J20: =J8+J16 -> 256860 | K20: =K8+K16 -> 266040 | ... AI20: =AI8+AI16 -> 1870740
B21: 年間売上 | G21: =SUM(D20:G20) -> 393720 | K21: =SUM(H20:K20) -> 985140 | O21: =SUM(L20:O20) -> 1492920 | S21: =SUM(P20:S20) -> 2242260 | W21: =SUM(T20:W20) -> 3096180 | AA21: =SUM(X20:AA20) -> 4169340 | AE21: =SUM(AB20:AE20) -> 5540940 | AI21: =SUM(AF20:AI20) -> 7064820
B22: 前年比 | K22: =K21/G21 -> 2.5021335 | O22: =O21/K21 -> 1.5154394 | S22: =S21/O21 -> 1.5019291 | W22: =W21/S21 -> 1.3808301 | AA22: =AA21/W21 -> 1.3466078 | AE22: =AE21/AA21 -> 1.3289729 | AI22: =AI21/AE21 -> 1.2750219
K23: ※２年目までに政令指定都市をカバー | O23: ※３年目までに中核市をカバー | S23: ※４年目終了で上場基準を満たして上場準備。海外進出準備 | AI23: ※５年間で展開して店舗数を３年間で達成し倍増する
W24: ※５年目終了で上場し、海外進出に向けて資金調達
U25: ■海外展開分
X26: Phase4：海外進出基盤構築フェーズ | AB26: Phase5：海外成長フェーズ
W27: 月平均売上 | X27: 3-5 | Y27: 6-8 | Z27: 9-11 | AA27: 12-2 | AB27: 3-5 | AC27: 6-8 | AD27: 9-11 | AE27: 12-2 | AF27: 3-5 | AG27: 6-8 | AH27: 9-11 | AI27: 12-2
U28: 直営 | V28: 都市型 | W28: 500 | X28: 3 | Y28: 3 | Z28: 3 | AA28: 5 | AB28: 6 | AC28: 9 | AD28: 12 | AE28: 15 | AF28: 17 | AG28: 19 | AH28: 21 | AI28: 23
V29: サテライト型 | W29: 200 | X29: 3 | Y29: 3 | Z29: 3 | AA29: 5 | AB29: 6 | AC29: 9 | AD29: 12 | AE29: 15 | AF29: 17 | AG29: 19 | AH29: 21 | AI29: 23
V30: 郊外型 | W30: 250 | X30: 3 | Y30: 3 | Z30: 3 | AA30: 5 | AB30: 6 | AC30: 9 | AD30: 12 | AE30: 15 | AF30: 17 | AG30: 19 | AH30: 21 | AI30: 23
V31: SC内 | W31: 100 | X31: 3 | Y31: 3 | Z31: 3 | AA31: 5 | AB31: 6 | AC31: 9 | AD31: 12 | AE31: 15 | AF31: 17 | AG31: 19 | AH31: 21 | AI31: 23
V32: 売上小計 | X32: =(($W28*X28)+($W29*X29)+($W30*X30)+($W31*X31))*3 -> 9450 | Y32: =(($W28*Y28)+($W29*Y29)+($W30*Y30)+($W31*Y31))*3 -> 9450 | Z32: =(($W28*Z28)+($W29*Z29)+($W30*Z30)+($W31*Z31))*3 -> 9450 | AA32: =(($W28*AA28)+($W29*AA29)+($W30*AA30)+($W31*AA31))*3 -> 15750 | AB32: =(($W28*AB28)+($W29*AB29)+($W30*AB30)+($W31*AB31))*3 -> 18900 | AC32: =(($W28*AC28)+($W29*AC29)+($W30*AC30)+($W31*AC31))*3 -> 28350 | AD32: =(($W28*AD28)+($W29*AD29)+($W30*AD30)+($W31*AD31))*3 -> 37800 | AE32: =(($W28*AE28)+($W29*AE29)+($W30*AE30)+($W31*AE31))*3 -> 47250 | ... AI32: =(($W28*AI28)+($W29*AI29)+($W30*AI30)+($W31*AI31))*3 -> 72450
V33: 店舗数 | X33: =SUM(X28:X31) -> 12 | Y33: =SUM(Y28:Y31) -> 12 | Z33: =SUM(Z28:Z31) -> 12 | AA33: =SUM(AA28:AA31) -> 20 | AB33: =SUM(AB28:AB31) -> 24 | AC33: =SUM(AC28:AC31) -> 36 | AD33: =SUM(AD28:AD31) -> 48 | AE33: =SUM(AE28:AE31) -> 60 | ... AI33: =SUM(AI28:AI31) -> 92
U35: FC | V35: 都市型 | W35: 500 | X35: 0 | Y35: 0 | Z35: 1 | AA35: 1 | AB35: 3 | AC35: 5 | AD35: 11 | AE35: 17 | AF35: 29 | AG35: 41 | AH35: 53 | AI35: 65
V36: サテライト型 | W36: 200 | X36: 0 | Y36: 0 | Z36: 1 | AA36: 1 | AB36: 3 | AC36: 5 | AD36: 11 | AE36: 17 | AF36: 29 | AG36: 41 | AH36: 53 | AI36: 65
V37: 郊外型 | W37: 250 | X37: 0 | Y37: 0 | Z37: 1 | AA37: 1 | AB37: 3 | AC37: 5 | AD37: 11 | AE37: 17 | AF37: 29 | AG37: 41 | AH37: 53 | AI37: 65
V38: SC内 | W38: 100 | X38: 0 | Y38: 0 | Z38: 1 | AA38: 1 | AB38: 3 | AC38: 5 | AD38: 11 | AE38: 17 | AF38: 29 | AG38: 41 | AH38: 53 | AI38: 65
V39: 店舗売上小計 | X39: =(($W35*X35)+($W36*X36)+($W37*X37)+($W38*X38))*3 -> 0 | Y39: =(($W35*Y35)+($W36*Y36)+($W37*Y37)+($W38*Y38))*3 -> 0 | Z39: =(($W35*Z35)+($W36*Z36)+($W37*Z37)+($W38*Z38))*3 -> 3150 | AA39: =(($W35*AA35)+($W36*AA36)+($W37*AA37)+($W38*AA38))*3 -> 3150 | AB39: =(($W35*AB35)+($W36*AB36)+($W37*AB37)+($W38*AB38))*3 -> 9450 | AC39: =(($W35*AC35)+($W36*AC36)+($W37*AC37)+($W38*AC38))*3 -> 15750 | AD39: =(($W35*AD35)+($W36*AD36)+($W37*AD37)+($W38*AD38))*3 -> 34650 | AE39: =(($W35*AE35)+($W36*AE36)+($W37*AE37)+($W38*AE38))*3 -> 53550 | ... AI39: =(($W35*AI35)+($W36*AI36)+($W37*AI37)+($W38*AI38))*3 -> 204750
V40: ロイヤルティ売上 | X40: =X39*0.06 -> 0 | Y40: =Y39*0.06 -> 0 | Z40: =Z39*0.06 -> 189 | AA40: =AA39*0.06 -> 189 | AB40: =AB39*0.06 -> 567 | AC40: =AC39*0.06 -> 945 | AD40: =AD39*0.06 -> 2079 | AE40: =AE39*0.06 -> 3213 | ... AI40: =AI39*0.06 -> 12285
V41: 店舗数 | X41: =SUM(X35:X38) -> 0 | Y41: =SUM(Y35:Y38) -> 0 | Z41: =SUM(Z35:Z38) -> 4 | AA41: =SUM(AA35:AA38) -> 4 | AB41: =SUM(AB35:AB38) -> 12 | AC41: =SUM(AC35:AC38) -> 20 | AD41: =SUM(AD35:AD38) -> 44 | AE41: =SUM(AE35:AE38) -> 68 | ... AI41: =SUM(AI35:AI38) -> 260
V43: 海外店舗数 | X43: =X33+X41 -> 12 | Y43: =Y33+Y41 -> 12 | Z43: =Z33+Z41 -> 16 | AA43: =AA33+AA41 -> 24 | AB43: =AB33+AB41 -> 36 | AC43: =AC33+AC41 -> 56 | AD43: =AD33+AD41 -> 92 | AE43: =AE33+AE41 -> 128 | ... AI43: =AI33+AI41 -> 352
V44: 直営FC合計売上 | X44: =X32+X40 -> 9450 | Y44: =Y32+Y40 -> 9450 | Z44: =Z32+Z40 -> 9639 | AA44: =AA32+AA40 -> 15939 | AB44: =AB32+AB40 -> 19467 | AC44: =AC32+AC40 -> 29295 | AD44: =AD32+AD40 -> 39879 | AE44: =AE32+AE40 -> 50463 | ... AI44: =AI32+AI40 -> 84735
...

Sheet シェル 
A1: シェル（笠岡）
D2: 令和３年 | Q2: 令和4年 | R2: 令和４年 | T2: 30000 | AD2: 令和５年 | AE2: 令和４年 | AG2: 30000 | AQ2: 令和６年 | AR2: 令和４年 | AT2: 30000 | BD2: 令和７年 | BE2: 令和４年 | BG2: 30000
E3: 1月 | F3: 2月 | G3: 3月 | H3: 4月 | I3: 5月 | J3: 6月 | K3: 7月 | L3: 8月 | M3: 9月 | N3: 10月 | O3: 11月 | P3: 12月 | R3: 1月 | S3: 2月 | T3: 3月 | U3: 4月 | V3: 5月 | W3: 6月 | X3: 7月 | Y3: 8月 | Z3: 9月 | AA3: 10月 | AB3: 11月 | AC3: 12月 | AE3: 1月 | AF3: 2月 | AG3: 3月 | AH3: 4月 | AI3: 5月 | AJ3: 6月 | AK3: 7月 | AL3: 8月 | AM3: 9月 | AN3: 10月 | AO3: 11月 | AP3: 12月 | AR3: 1月 | AS3: 2月 | AT3: 3月 | AU3: 4月 | AV3: 5月 | AW3: 6月 | AX3: 7月 | AY3: 8月 | AZ3: 9月 | BA3: 10月 | BB3: 11月 | BC3: 12月 | BE3: 1月 | BF3: 2月 | BG3: 3月 | BH3: 4月 | BI3: 5月 | BJ3: 6月 | BK3: 7月 | BL3: 8月 | BM3: 9月 | BN3: 10月 | BO3: 11月 | BP3: 12月
A4: 稼働日 | E4: 22 | F4: 20 | G4: 23 | H4: 22 | I4: 23 | J4: 22 | K4: 23 | L4: 22 | M4: 22 | N4: 23 | O4: 22 | P4: 22 | R4: 22 | S4: 20 | T4: 23 | U4: 22 | V4: 23 | W4: 22 | X4: 23 | Y4: 22 | Z4: 22 | AA4: 23 | AB4: 22 | AC4: 22 | AE4: 22 | AF4: 20 | AG4: 23 | AH4: 22 | AI4: 23 | AJ4: 22 | AK4: 23 | AL4: 22 | AM4: 22 | AN4: 23 | AO4: 22 | AP4: 22 | AR4: 22 | AS4: 20 | AT4: 23 | AU4: 22 | AV4: 23 | AW4: 22 | AX4: 23 | AY4: 22 | AZ4: 22 | BA4: 23 | BB4: 22 | BC4: 22 | BE4: 22 | BF4: 20 | BG4: 23 | BH4: 22 | BI4: 23 | BJ4: 22 | BK4: 23 | BL4: 22 | BM4: 22 | BN4: 23 | BO4: 22 | BP4: 22
A5: 稼働率 | E5: 0.8 | F5: 0.8 | G5: 0.8 | H5: 0.8 | I5: 0.8 | J5: 0.8 | K5: 0.8 | L5: 0.8 | M5: 0.8 | N5: 0.8 | O5: 0.8 | P5: 0.8 | R5: 0.8 | S5: 0.8 | T5: 0.8 | U5: 0.8 | V5: 0.8 | W5: 0.8 | X5: 0.8 | Y5: 0.8 | Z5: 0.8 | AA5: 0.8 | AB5: 0.8 | AC5: 0.8 | AE5: 0.8 | AF5: 0.8 | AG5: 0.8 | AH5: 0.8 | AI5: 0.8 | AJ5: 0.8 | AK5: 0.8 | AL5: 0.8 | AM5: 0.8 | AN5: 0.8 | AO5: 0.8 | AP5: 0.8 | AR5: 0.8 | AS5: 0.8 | AT5: 0.8 | AU5: 0.8 | AV5: 0.8 | AW5: 0.8 | AX5: 0.8 | AY5: 0.8 | AZ5: 0.8 | BA5: 0.8 | BB5: 0.8 | BC5: 0.8 | BE5: 0.8 | BF5: 0.8 | BG5: 0.8 | BH5: 0.8 | BI5: 0.8 | BJ5: 0.8 | BK5: 0.8 | BL5: 0.8 | BM5: 0.8 | BN5: 0.8 | BO5: 0.8 | BP5: 0.8
A6: 就労B利用者数 | E6: 7 | F6: 7 | G6: 10 | H6: 10 | I6: 10 | J6: 10 | K6: 10 | L6: 10 | M6: 10 | N6: 10 | O6: 10 | P6: 10 | R6: 10 | S6: 10 | T6: 10 | U6: 10 | V6: 10 | W6: 10 | X6: 10 | Y6: 10 | Z6: 10 | AA6: 10 | AB6: 10 | AC6: 10 | AE6: 10 | AF6: 10 | AG6: 10 | AH6: 10 | AI6: 10 | AJ6: 10 | AK6: 10 | AL6: 10 | AM6: 10 | AN6: 10 | AO6: 10 | AP6: 10 | AR6: 10 | AS6: 10 | AT6: 10 | AU6: 10 | AV6: 10 | AW6: 10 | AX6: 10 | AY6: 10 | AZ6: 10 | BA6: 10 | BB6: 10 | BC6: 10 | BE6: 10 | BF6: 10 | BG6: 10 | BH6: 10 | BI6: 10 | BJ6: 10 | BK6: 10 | BL6: 10 | BM6: 10 | BN6: 10 | BO6: 10 | BP6: 10
A7: 就労B施設外利用者数 | K7: 2 | L7: 3 | M7: 4 | N7: 5 | O7: 6 | P7: 7 | R7: 8 | S7: 9 | T7: 10 | U7: 10 | V7: 10 | W7: 10 | X7: 10 | Y7: 10 | Z7: 10 | AA7: 10 | AB7: 10 | AC7: 10 | AE7: 10 | AF7: 10 | AG7: 10 | AH7: 10 | AI7: 10 | AJ7: 10 | AK7: 10 | AL7: 10 | AM7: 10 | AN7: 10 | AO7: 10 | AP7: 10 | AR7: 10 | AS7: 10 | AT7: 10 | AU7: 10 | AV7: 10 | AW7: 10 | AX7: 10 | AY7: 10 | AZ7: 10 | BA7: 10 | BB7: 10 | BC7: 10 | BE7: 10 | BF7: 10 | BG7: 10 | BH7: 10 | BI7: 10 | BJ7: 10 | BK7: 10 | BL7: 10 | BM7: 10 | BN7: 10 | BO7: 10 | BP7: 10
A8: B合計 | E8: =SUM(E6:E7) -> 7 | F8: =SUM(F6:F7) -> 7 | G8: =SUM(G6:G7) -> 10 | H8: =SUM(H6:H7) -> 10 | I8: =SUM(I6:I7) -> 10 | J8: =SUM(J6:J7) -> 10 | K8: =SUM(K6:K7) -> 12 | L8: =SUM(L6:L7) -> 13 | ... P8: =SUM(P6:P7) -> 17 | R8: =SUM(R6:R7) -> 18 | S8: =SUM(S6:S7) -> 19 | T8: =SUM(T6:T7) -> 20 | U8: =SUM(U6:U7) -> 20 | V8: =SUM(V6:V7) -> 20 | W8: =SUM(W6:W7) -> 20 | X8: =SUM(X6:X7) -> 20 | Y8: =SUM(Y6:Y7) -> 20 | ... AC8: =SUM(AC6:AC7) -> 20 | AE8: =SUM(AE6:AE7) -> 20 | AF8: =SUM(AF6:AF7) -> 20 | AG8: =SUM(AG6:AG7) -> 20 | AH8: =SUM(AH6:AH7) -> 20 | AI8: =SUM(AI6:AI7) -> 20 | AJ8: =SUM(AJ6:AJ7) -> 20 | AK8: =SUM(AK6:AK7) -> 20 | AL8: =SUM(AL6:AL7) -> 20 | ... AP8: =SUM(AP6:AP7) -> 20 | AR8: =SUM(AR6:AR7) -> 20 | AS8: =SUM(AS6:AS7) -> 20 | AT8: =SUM(AT6:AT7) -> 20 | AU8: =SUM(AU6:AU7) -> 20 | AV8: =SUM(AV6:AV7) -> 20 | AW8: =SUM(AW6:AW7) -> 20 | AX8: =SUM(AX6:AX7) -> 20 | AY8: =SUM(AY6:AY7) -> 20 | ... BC8: =SUM(BC6:BC7) -> 20 | BE8: =SUM(BE6:BE7) -> 20 | BF8: =SUM(BF6:BF7) -> 20 | BG8: =SUM(BG6:BG7) -> 20 | BH8: =SUM(BH6:BH7) -> 20 | BI8: =SUM(BI6:BI7) -> 20 | BJ8: =SUM(BJ6:BJ7) -> 20 | BK8: =SUM(BK6:BK7) -> 20 | BL8: =SUM(BL6:BL7) -> 20 | ... BP8: =SUM(BP6:BP7) -> 20
A9: 就労移行利用者数 | E9: 4 | F9: 5 | G9: 5 | H9: 6 | I9: 6 | J9: 4 | K9: 5 | L9: 6 | M9: 6 | N9: 7 | O9: 8 | P9: 9 | R9: 10 | S9: 10 | T9: 10 | U9: 10 | V9: 10 | W9: 10 | X9: 10 | Y9: 10 | Z9: 10 | AA9: 10 | AB9: 10 | AC9: 10 | AE9: 10 | AF9: 10 | AG9: 10 | AH9: 10 | AI9: 10 | AJ9: 10 | AK9: 10 | AL9: 10 | AM9: 10 | AN9: 10 | AO9: 10 | AP9: 10 | AR9: 10 | AS9: 10 | AT9: 10 | AU9: 10 | AV9: 10 | AW9: 10 | AX9: 10 | AY9: 10 | AZ9: 10 | BA9: 10 | BB9: 10 | BC9: 10 | BE9: 10 | BF9: 10 | BG9: 10 | BH9: 10 | BI9: 10 | BJ9: 10 | BK9: 10 | BL9: 10 | BM9: 10 | BN9: 10 | BO9: 10 | BP9: 10
A10: 就労移行施設外利用者数 | M10: 2 | N10: 4 | O10: 6 | P10: 8 | R10: 10 | S10: 10 | T10: 10 | U10: 10 | V10: 10 | W10: 10 | X10: 10 | Y10: 10 | Z10: 10 | AA10: 10 | AB10: 10 | AC10: 10 | AE10: 10 | AF10: 10 | AG10: 10 | AH10: 10 | AI10: 10 | AJ10: 10 | AK10: 10 | AL10: 10 | AM10: 10 | AN10: 10 | AO10: 10 | AP10: 10 | AR10: 10 | AS10: 10 | AT10: 10 | AU10: 10 | AV10: 10 | AW10: 10 | AX10: 10 | AY10: 10 | AZ10: 10 | BA10: 10 | BB10: 10 | BC10: 10 | BE10: 10 | BF10: 10 | BG10: 10 | BH10: 10 | BI10: 10 | BJ10: 10 | BK10: 10 | BL10: 10 | BM10: 10 | BN10: 10 | BO10: 10 | BP10: 10
A11: 移行合計 | E11: =SUM(E9:E10) -> 4 | F11: =SUM(F9:F10) -> 5 | G11: =SUM(G9:G10) -> 5 | H11: =SUM(H9:H10) -> 6 | I11: =SUM(I9:I10) -> 6 | J11: =SUM(J9:J10) -> 4 | K11: =SUM(K9:K10) -> 5 | L11: =SUM(L9:L10) -> 6 | ... P11: =SUM(P9:P10) -> 17 | R11: =SUM(R9:R10) -> 20 | S11: =SUM(S9:S10) -> 20 | T11: =SUM(T9:T10) -> 20 | U11: =SUM(U9:U10) -> 20 | V11: =SUM(V9:V10) -> 20 | W11: =SUM(W9:W10) -> 20 | X11: =SUM(X9:X10) -> 20 | Y11: =SUM(Y9:Y10) -> 20 | ... AC11: =SUM(AC9:AC10) -> 20 | AE11: =SUM(AE9:AE10) -> 20 | AF11: =SUM(AF9:AF10) -> 20 | AG11: =SUM(AG9:AG10) -> 20 | AH11: =SUM(AH9:AH10) -> 20 | AI11: =SUM(AI9:AI10) -> 20 | AJ11: =SUM(AJ9:AJ10) -> 20 | AK11: =SUM(AK9:AK10) -> 20 | AL11: =SUM(AL9:AL10) -> 20 | ... AP11: =SUM(AP9:AP10) -> 20 | AR11: =SUM(AR9:AR10) -> 20 | AS11: =SUM(AS9:AS10) -> 20 | AT11: =SUM(AT9:AT10) -> 20 | AU11: =SUM(AU9:AU10) -> 20 | AV11: =SUM(AV9:AV10) -> 20 | AW11: =SUM(AW9:AW10) -> 20 | AX11: =SUM(AX9:AX10) -> 20 | AY11: =SUM(AY9:AY10) -> 20 | ... BC11: =SUM(BC9:BC10) -> 20 | BE11: =SUM(BE9:BE10) -> 20 | BF11: =SUM(BF9:BF10) -> 20 | BG11: =SUM(BG9:BG10) -> 20 | BH11: =SUM(BH9:BH10) -> 20 | BI11: =SUM(BI9:BI10) -> 20 | BJ11: =SUM(BJ9:BJ10) -> 20 | BK11: =SUM(BK9:BK10) -> 20 | BL11: =SUM(BL9:BL10) -> 20 | ... BP11: =SUM(BP9:BP10) -> 20
A12: 合計人数 | E12: =E8:F8+E11 -> 11 | F12: =F8:G8+F11 -> 12 | G12: =G8:H8+G11 -> 15 | H12: =H8:I8+H11 -> 16 | I12: =I8:J8+I11 -> 16 | J12: =J8:K8+J11 -> 14 | K12: =K8:L8+K11 -> 17 | L12: =L8:M8+L11 -> 19 | ... P12: =P8:Q8+P11 -> 34 | R12: =R8:S8+R11 -> 38 | S12: =S8:T8+S11 -> 39 | T12: =T8:U8+T11 -> 40 | U12: =U8:V8+U11 -> 40 | V12: =V8:W8+V11 -> 40 | W12: =W8:X8+W11 -> 40 | X12: =X8:Y8+X11 -> 40 | Y12: =Y8:Z8+Y11 -> 40 | ... AC12: =AC8:AD8+AC11 -> 40 | AE12: =AE8:AF8+AE11 -> 40 | AF12: =AF8:AG8+AF11 -> 40 | AG12: =AG8:AH8+AG11 -> 40 | AH12: =AH8:AI8+AH11 -> 40 | AI12: =AI8:AJ8+AI11 -> 40 | AJ12: =AJ8:AK8+AJ11 -> 40 | AK12: =AK8:AL8+AK11 -> 40 | AL12: =AL8:AM8+AL11 -> 40 | ... AO12: =AO8:AP8+AO11 -> 40 | AP12: =AP8:AP8+AP11 -> 40 | AR12: =AR8:AS8+AR11 -> 40 | AS12: =AS8:AT8+AS11 -> 40 | AT12: =AT8:AU8+AT11 -> 40 | AU12: =AU8:AV8+AU11 -> 40 | AV12: =AV8:AW8+AV11 -> 40 | AW12: =AW8:AX8+AW11 -> 40 | AX12: =AX8:AY8+AX11 -> 40 | AY12: =AY8:AZ8+AY11 -> 40 | ... BB12: =BB8:BC8+BB11 -> 40 | BC12: =BC8:BC8+BC11 -> 40 | BE12: =BE8:BF8+BE11 -> 40 | BF12: =BF8:BG8+BF11 -> 40 | BG12: =BG8:BH8+BG11 -> 40 | BH12: =BH8:BI8+BH11 -> 40 | BI12: =BI8:BJ8+BI11 -> 40 | BJ12: =BJ8:BK8+BJ11 -> 40 | BK12: =BK8:BL8+BK11 -> 40 | BL12: =BL8:BM8+BL11 -> 40 | ... BO12: =BO8:BP8+BO11 -> 40 | BP12: =BP8:BP8+BP11 -> 40
A14: B通常給付金 | E14: =ROUNDDOWN(E6*E23*E4*E5,-2) -> 725600 | F14: =ROUNDDOWN(F6*F23*F4*F5,-2) -> 659600 | G14: =ROUNDDOWN(G6*G23*G4*G5,-2) -> 1083700 | H14: =ROUNDDOWN(H6*H23*H4*H5,-2) -> 1036600 | I14: =ROUNDDOWN(I6*I23*I4*I5,-2) -> 1083700 | J14: =ROUNDDOWN(J6*J23*J4*J5,-2) -> 1036600 | K14: =ROUNDDOWN(K6*K23*K4*K5,-2) -> 1083700 | L14: =ROUNDDOWN(L6*L23*L4*L5,-2) -> 1036600 | ... P14: =ROUNDDOWN(P6*P23*P4*P5,-2) -> 1036600 | R14: =ROUNDDOWN(R6*R23*R4*R5,-2) -> 1036600 | S14: =ROUNDDOWN(S6*S23*S4*S5,-2) -> 942400 | T14: =ROUNDDOWN(T6*T23*T4*T5,-2) -> 1083700 | U14: =ROUNDDOWN(U6*U23*U4*U5,-2) -> 1036600 | V14: =ROUNDDOWN(V6*V23*V4*V5,-2) -> 1083700 | W14: =ROUNDDOWN(W6*W23*W4*W5,-2) -> 1036600 | X14: =ROUNDDOWN(X6*X23*X4*X5,-2) -> 1083700 | Y14: =ROUNDDOWN(Y6*Y23*Y4*Y5,-2) -> 1036600 | ... AC14: =ROUNDDOWN(AC6*AC23*AC4*AC5,-2) -> 1036600 | AE14: =ROUNDDOWN(AE6*AE23*AE4*AE5,-2) -> 1036600 | AF14: =ROUNDDOWN(AF6*AF23*AF4*AF5,-2) -> 942400 | AG14: =ROUNDDOWN(AG6*AG23*AG4*AG5,-2) -> 1083700 | AH14: =ROUNDDOWN(AH6*AH23*AH4*AH5,-2) -> 1036600 | AI14: =ROUNDDOWN(AI6*AI23*AI4*AI5,-2) -> 1083700 | AJ14: =ROUNDDOWN(AJ6*AJ23*AJ4*AJ5,-2) -> 1036600 | AK14: =ROUNDDOWN(AK6*AK23*AK4*AK5,-2) -> 1083700 | AL14: =ROUNDDOWN(AL6*AL23*AL4*AL5,-2) -> 1036600 | ... AP14: =ROUNDDOWN(AP6*AP23*AP4*AP5,-2) -> 1036600 | AR14: =ROUNDDOWN(AR6*AR23*AR4*AR5,-2) -> 1036600 | AS14: =ROUNDDOWN(AS6*AS23*AS4*AS5,-2) -> 942400 | AT14: =ROUNDDOWN(AT6*AT23*AT4*AT5,-2) -> 1083700 | AU14: =ROUNDDOWN(AU6*AU23*AU4*AU5,-2) -> 1036600 | AV14: =ROUNDDOWN(AV6*AV23*AV4*AV5,-2) -> 1083700 | AW14: =ROUNDDOWN(AW6*AW23*AW4*AW5,-2) -> 1036600 | AX14: =ROUNDDOWN(AX6*AX23*AX4*AX5,-2) -> 1083700 | AY14: =ROUNDDOWN(AY6*AY23*AY4*AY5,-2) -> 1036600 | ... BC14: =ROUNDDOWN(BC6*BC23*BC4*BC5,-2) -> 1036600 | BE14: =ROUNDDOWN(BE6*BE23*BE4*BE5,-2) -> 1036600 | BF14: =ROUNDDOWN(BF6*BF23*BF4*BF5,-2) -> 942400 | BG14: =ROUNDDOWN(BG6*BG23*BG4*BG5,-2) -> 1083700 | BH14: =ROUNDDOWN(BH6*BH23*BH4*BH5,-2) -> 1036600 | BI14: =ROUNDDOWN(BI6*BI23*BI4*BI5,-2) -> 1083700 | BJ14: =ROUNDDOWN(BJ6*BJ23*BJ4*BJ5,-2) -> 1036600 | BK14: =ROUNDDOWN(BK6*BK23*BK4*BK5,-2) -> 1083700 | BL14: =ROUNDDOWN(BL6*BL23*BL4*BL5,-2) -> 1036600 | ... BP14: =ROUNDDOWN(BP6*BP23*BP4*BP5,-2) -> 1036600
A15: B施設外給付金 | E15: =ROUNDDOWN(E7*E24*E4*E29,-2) -> 0 | F15: =F7*F24*F4*F29 -> 0 | G15: =G7*G24*G4*G29 -> 0 | H15: =H7*H24*H4*H29 -> 0 | I15: =I7*I24*I4*I29 -> 0 | J15: =J7*J24*J4*J29 -> 0 | K15: =K7*K24*K4*K29 -> 253552 | L15: =L7*L24*L4*L29 -> 363792 | M15: =M7*M24*M4*M29 -> 485056 | ... P15: =P7*P24*P4*P29 -> 848848 | R15: =ROUNDDOWN(R7*R24*R4*R29,-2) -> 909400 | S15: =S7*S24*S4*S29 -> 930150 | T15: =T7*T24*T4*T29 -> 1188525 | U15: =U7*U24*U4*U29 -> 1136850 | V15: =V7*V24*V4*V29 -> 1188525 | W15: =W7*W24*W4*W29 -> 1136850 | X15: =X7*X24*X4*X29 -> 1188525 | Y15: =Y7*Y24*Y4*Y29 -> 1136850 | Z15: =Z7*Z24*Z4*Z29 -> 1136850 | ... AC15: =AC7*AC24*AC4*AC29 -> 1136850 | AE15: =ROUNDDOWN(AE7*AE24*AE4*AE29,-2) -> 1136800 | AF15: =AF7*AF24*AF4*AF29 -> 1033500 | AG15: =AG7*AG24*AG4*AG29 -> 1188525 | AH15: =AH7*AH24*AH4*AH29 -> 1136850 | AI15: =AI7*AI24*AI4*AI29 -> 1188525 | AJ15: =AJ7*AJ24*AJ4*AJ29 -> 1136850 | AK15: =AK7*AK24*AK4*AK29 -> 1188525 | AL15: =AL7*AL24*AL4*AL29 -> 1136850 | AM15: =AM7*AM24*AM4*AM29 -> 1136850 | ... AP15: =AP7*AP24*AP4*AP29 -> 1136850 | AR15: =ROUNDDOWN(AR7*AR24*AR4*AR29,-2) -> 1136800 | AS15: =AS7*AS24*AS4*AS29 -> 1033500 | AT15: =AT7*AT24*AT4*AT29 -> 1188525 | AU15: =AU7*AU24*AU4*AU29 -> 1136850 | AV15: =AV7*AV24*AV4*AV29 -> 1188525 | AW15: =AW7*AW24*AW4*AW29 -> 1136850 | AX15: =AX7*AX24*AX4*AX29 -> 1188525 | AY15: =AY7*AY24*AY4*AY29 -> 1136850 | AZ15: =AZ7*AZ24*AZ4*AZ29 -> 1136850 | ... BC15: =BC7*BC24*BC4*BC29 -> 1136850 | BE15: =ROUNDDOWN(BE7*BE24*BE4*BE29,-2) -> 1136800 | BF15: =BF7*BF24*BF4*BF29 -> 1033500 | BG15: =BG7*BG24*BG4*BG29 -> 1188525 | BH15: =BH7*BH24*BH4*BH29 -> 1136850 | BI15: =BI7*BI24*BI4*BI29 -> 1188525 | BJ15: =BJ7*BJ24*BJ4*BJ29 -> 1136850 | BK15: =BK7*BK24*BK4*BK29 -> 1188525 | BL15: =BL7*BL24*BL4*BL29 -> 1136850 | BM15: =BM7*BM24*BM4*BM29 -> 1136850 | ... BP15: =BP7*BP24*BP4*BP29 -> 1136850
A16: B加算 | E16: =ROUNDDOWN(((E6+E7)*(E27+E28*0.8))*E4,-2) -> 203500 | F16: =ROUNDDOWN(((F6+F7)*(F27+F28*0.8))*F4,-2) -> 185000 | G16: =ROUNDDOWN(((G6+G7)*(G27+G28*0.8))*G4,-2) -> 304000 | H16: =ROUNDDOWN(((H6+H7)*(H27+H28*0.8))*H4,-2) -> 290800 | I16: =ROUNDDOWN(((I6+I7)*(I27+I28*0.8))*I4,-2) -> 304000 | J16: =ROUNDDOWN(((J6+J7)*(J27+J28*0.8))*J4,-2) -> 290800 | K16: =ROUNDDOWN(((K6+K7)*(K27+K28*0.8))*K4,-2) -> 364800 | L16: =ROUNDDOWN(((L6+L7)*(L27+L28*0.8))*L4,-2) -> 378000 | ... P16: =ROUNDDOWN(((P6+P7)*(P27+P28*0.8))*P4,-2) -> 494400 | R16: =ROUNDDOWN(((R6+R7)*(R27+R28*0.8))*R4,-2) -> 523500 | S16: =ROUNDDOWN(((S6+S7)*(S27+S28*0.8))*S4,-2) -> 502300 | T16: =ROUNDDOWN(((T6+T7)*(T27+T28*0.8))*T4,-2) -> 608100 | U16: =ROUNDDOWN(((U6+U7)*(U27+U28*0.8))*U4,-2) -> 581600 | V16: =ROUNDDOWN(((V6+V7)*(V27+V28*0.8))*V4,-2) -> 608100 | W16: =ROUNDDOWN(((W6+W7)*(W27+W28*0.8))*W4,-2) -> 581600 | X16: =ROUNDDOWN(((X6+X7)*(X27+X28*0.8))*X4,-2) -> 608100 | Y16: =ROUNDDOWN(((Y6+Y7)*(Y27+Y28*0.8))*Y4,-2) -> 581600 | ... AC16: =ROUNDDOWN(((AC6+AC7)*(AC27+AC28*0.8))*AC4,-2) -> 581600 | AE16: =ROUNDDOWN(((AE6+AE7)*(AE27+AE28*0.8))*AE4,-2) -> 581600 | AF16: =ROUNDDOWN(((AF6+AF7)*(AF27+AF28*0.8))*AF4,-2) -> 528800 | AG16: =ROUNDDOWN(((AG6+AG7)*(AG27+AG28*0.8))*AG4,-2) -> 608100 | AH16: =ROUNDDOWN(((AH6+AH7)*(AH27+AH28*0.8))*AH4,-2) -> 581600 | AI16: =ROUNDDOWN(((AI6+AI7)*(AI27+AI28*0.8))*AI4,-2) -> 608100 | AJ16: =ROUNDDOWN(((AJ6+AJ7)*(AJ27+AJ28*0.8))*AJ4,-2) -> 581600 | AK16: =ROUNDDOWN(((AK6+AK7)*(AK27+AK28*0.8))*AK4,-2) -> 608100 | AL16: =ROUNDDOWN(((AL6+AL7)*(AL27+AL28*0.8))*AL4,-2) -> 581600 | ... AP16: =ROUNDDOWN(((AP6+AP7)*(AP27+AP28*0.8))*AP4,-2) -> 581600 | AR16: =ROUNDDOWN(((AR6+AR7)*(AR27+AR28*0.8))*AR4,-2) -> 581600 | AS16: =ROUNDDOWN(((AS6+AS7)*(AS27+AS28*0.8))*AS4,-2) -> 528800 | AT16: =ROUNDDOWN(((AT6+AT7)*(AT27+AT28*0.8))*AT4,-2) -> 608100 | AU16: =ROUNDDOWN(((AU6+AU7)*(AU27+AU28*0.8))*AU4,-2) -> 581600 | AV16: =ROUNDDOWN(((AV6+AV7)*(AV27+AV28*0.8))*AV4,-2) -> 608100 | AW16: =ROUNDDOWN(((AW6+AW7)*(AW27+AW28*0.8))*AW4,-2) -> 581600 | AX16: =ROUNDDOWN(((AX6+AX7)*(AX27+AX28*0.8))*AX4,-2) -> 608100 | AY16: =ROUNDDOWN(((AY6+AY7)*(AY27+AY28*0.8))*AY4,-2) -> 581600 | ... BC16: =ROUNDDOWN(((BC6+BC7)*(BC27+BC28*0.8))*BC4,-2) -> 581600 | BE16: =ROUNDDOWN(((BE6+BE7)*(BE27+BE28*0.8))*BE4,-2) -> 581600 | BF16: =ROUNDDOWN(((BF6+BF7)*(BF27+BF28*0.8))*BF4,-2) -> 528800 | BG16: =ROUNDDOWN(((BG6+BG7)*(BG27+BG28*0.8))*BG4,-2) -> 608100 | BH16: =ROUNDDOWN(((BH6+BH7)*(BH27+BH28*0.8))*BH4,-2) -> 581600 | BI16: =ROUNDDOWN(((BI6+BI7)*(BI27+BI28*0.8))*BI4,-2) -> 608100 | BJ16: =ROUNDDOWN(((BJ6+BJ7)*(BJ27+BJ28*0.8))*BJ4,-2) -> 581600 | BK16: =ROUNDDOWN(((BK6+BK7)*(BK27+BK28*0.8))*BK4,-2) -> 608100 | BL16: =ROUNDDOWN(((BL6+BL7)*(BL27+BL28*0.8))*BL4,-2) -> 581600 | ... BP16: =ROUNDDOWN(((BP6+BP7)*(BP27+BP28*0.8))*BP4,-2) -> 581600
A17: 移行通常給付金 | E17: =ROUNDDOWN(E9*E25*E4*E5,-2) -> 568800 | F17: =ROUNDDOWN(F9*F25*F4*F5,-2) -> 646400 | G17: =ROUNDDOWN(G9*G25*G4*G5,-2) -> 743300 | H17: =ROUNDDOWN(H9*H25*H4*H5,-2) -> 853200 | I17: =ROUNDDOWN(I9*I25*I4*I5,-2) -> 892000 | J17: =ROUNDDOWN(J9*J25*J4*J5,-2) -> 568800 | K17: =ROUNDDOWN(K9*K25*K4*K5,-2) -> 743300 | L17: =ROUNDDOWN(L9*L25*L4*L5,-2) -> 853200 | ... P17: =ROUNDDOWN(P9*P25*P4*P5,-2) -> 1279800 | R17: =ROUNDDOWN(R9*R25*R4*R5,-2) -> 1422000 | S17: =ROUNDDOWN(S9*S25*S4*S5,-2) -> 1292800 | T17: =ROUNDDOWN(T9*T25*T4*T5,-2) -> 1486700 | U17: =ROUNDDOWN(U9*U25*U4*U5,-2) -> 1422000 | V17: =ROUNDDOWN(V9*V25*V4*V5,-2) -> 1486700 | W17: =ROUNDDOWN(W9*W25*W4*W5,-2) -> 1422000 | X17: =ROUNDDOWN(X9*X25*X4*X5,-2) -> 1486700 | Y17: =ROUNDDOWN(Y9*Y25*Y4*Y5,-2) -> 1422000 | ... AC17: =ROUNDDOWN(AC9*AC25*AC4*AC5,-2) -> 1422000 | AE17: =ROUNDDOWN(AE9*AE25*AE4*AE5,-2) -> 1422000 | AF17: =ROUNDDOWN(AF9*AF25*AF4*AF5,-2) -> 1292800 | AG17: =ROUNDDOWN(AG9*AG25*AG4*AG5,-2) -> 1486700 | AH17: =ROUNDDOWN(AH9*AH25*AH4*AH5,-2) -> 1422000 | AI17: =ROUNDDOWN(AI9*AI25*AI4*AI5,-2) -> 1486700 | AJ17: =ROUNDDOWN(AJ9*AJ25*AJ4*AJ5,-2) -> 1422000 | AK17: =ROUNDDOWN(AK9*AK25*AK4*AK5,-2) -> 1486700 | AL17: =ROUNDDOWN(AL9*AL25*AL4*AL5,-2) -> 1422000 | ... AP17: =ROUNDDOWN(AP9*AP25*AP4*AP5,-2) -> 1422000 | AR17: =ROUNDDOWN(AR9*AR25*AR4*AR5,-2) -> 1422000 | AS17: =ROUNDDOWN(AS9*AS25*AS4*AS5,-2) -> 1292800 | AT17: =ROUNDDOWN(AT9*AT25*AT4*AT5,-2) -> 1486700 | AU17: =ROUNDDOWN(AU9*AU25*AU4*AU5,-2) -> 1422000 | AV17: =ROUNDDOWN(AV9*AV25*AV4*AV5,-2) -> 1486700 | AW17: =ROUNDDOWN(AW9*AW25*AW4*AW5,-2) -> 1422000 | AX17: =ROUNDDOWN(AX9*AX25*AX4*AX5,-2) -> 1486700 | AY17: =ROUNDDOWN(AY9*AY25*AY4*AY5,-2) -> 1422000 | ... BC17: =ROUNDDOWN(BC9*BC25*BC4*BC5,-2) -> 1422000 | BE17: =ROUNDDOWN(BE9*BE25*BE4*BE5,-2) -> 1422000 | BF17: =ROUNDDOWN(BF9*BF25*BF4*BF5,-2) -> 1292800 | BG17: =ROUNDDOWN(BG9*BG25*BG4*BG5,-2) -> 1486700 | BH17: =ROUNDDOWN(BH9*BH25*BH4*BH5,-2) -> 1422000 | BI17: =ROUNDDOWN(BI9*BI25*BI4*BI5,-2) -> 1486700 | BJ17: =ROUNDDOWN(BJ9*BJ25*BJ4*BJ5,-2) -> 1422000 | BK17: =ROUNDDOWN(BK9*BK25*BK4*BK5,-2) -> 1486700 | BL17: =ROUNDDOWN(BL9*BL25*BL4*BL5,-2) -> 1422000 | ... BP17: =ROUNDDOWN(BP9*BP25*BP4*BP5,-2) -> 1422000
A18: 移行施設外給付金 | E18: =ROUNDDOWN(E10*E26*E4*E5,-2) -> 0 | F18: =ROUNDDOWN(F10*F26*F4*F5,-2) -> 0 | G18: =ROUNDDOWN(G10*G26*G4*G5,-2) -> 0 | H18: =ROUNDDOWN(H10*H26*H4*H5,-2) -> 0 | I18: =ROUNDDOWN(I10*I26*I4*I5,-2) -> 0 | J18: =ROUNDDOWN(J10*J26*J4*J5,-2) -> 0 | K18: =ROUNDDOWN(K10*K26*K4*K5,-2) -> 0 | L18: =ROUNDDOWN(L10*L26*L4*L5,-2) -> 0 | ... P18: =ROUNDDOWN(P10*P26*P4*P5,-2) -> 1278400 | R18: =ROUNDDOWN(R10*R26*R4*R5,-2) -> 1598000 | S18: =ROUNDDOWN(S10*S26*S4*S5,-2) -> 1452800 | T18: =ROUNDDOWN(T10*T26*T4*T5,-2) -> 1670700 | U18: =ROUNDDOWN(U10*U26*U4*U5,-2) -> 1598000 | V18: =ROUNDDOWN(V10*V26*V4*V5,-2) -> 1670700 | W18: =ROUNDDOWN(W10*W26*W4*W5,-2) -> 1598000 | X18: =ROUNDDOWN(X10*X26*X4*X5,-2) -> 1670700 | Y18: =ROUNDDOWN(Y10*Y26*Y4*Y5,-2) -> 1598000 | ... AC18: =ROUNDDOWN(AC10*AC26*AC4*AC5,-2) -> 1598000 | AE18: =ROUNDDOWN(AE10*AE26*AE4*AE5,-2) -> 1598000 | AF18: =ROUNDDOWN(AF10*AF26*AF4*AF5,-2) -> 1452800 | AG18: =ROUNDDOWN(AG10*AG26*AG4*AG5,-2) -> 1670700 | AH18: =ROUNDDOWN(AH10*AH26*AH4*AH5,-2) -> 1598000 | AI18: =ROUNDDOWN(AI10*AI26*AI4*AI5,-2) -> 1670700 | AJ18: =ROUNDDOWN(AJ10*AJ26*AJ4*AJ5,-2) -> 1598000 | AK18: =ROUNDDOWN(AK10*AK26*AK4*AK5,-2) -> 1670700 | AL18: =ROUNDDOWN(AL10*AL26*AL4*AL5,-2) -> 1598000 | ... AP18: =ROUNDDOWN(AP10*AP26*AP4*AP5,-2) -> 1598000 | AR18: =ROUNDDOWN(AR10*AR26*AR4*AR5,-2) -> 1598000 | AS18: =ROUNDDOWN(AS10*AS26*AS4*AS5,-2) -> 1452800 | AT18: =ROUNDDOWN(AT10*AT26*AT4*AT5,-2) -> 1670700 | AU18: =ROUNDDOWN(AU10*AU26*AU4*AU5,-2) -> 1598000 | AV18: =ROUNDDOWN(AV10*AV26*AV4*AV5,-2) -> 1670700 | AW18: =ROUNDDOWN(AW10*AW26*AW4*AW5,-2) -> 1598000 | AX18: =ROUNDDOWN(AX10*AX26*AX4*AX5,-2) -> 1670700 | AY18: =ROUNDDOWN(AY10*AY26*AY4*AY5,-2) -> 1598000 | ... BC18: =ROUNDDOWN(BC10*BC26*BC4*BC5,-2) -> 1598000 | BE18: =ROUNDDOWN(BE10*BE26*BE4*BE5,-2) -> 1598000 | BF18: =ROUNDDOWN(BF10*BF26*BF4*BF5,-2) -> 1452800 | BG18: =ROUNDDOWN(BG10*BG26*BG4*BG5,-2) -> 1670700 | BH18: =ROUNDDOWN(BH10*BH26*BH4*BH5,-2) -> 1598000 | BI18: =ROUNDDOWN(BI10*BI26*BI4*BI5,-2) -> 1670700 | BJ18: =ROUNDDOWN(BJ10*BJ26*BJ4*BJ5,-2) -> 1598000 | BK18: =ROUNDDOWN(BK10*BK26*BK4*BK5,-2) -> 1670700 | BL18: =ROUNDDOWN(BL10*BL26*BL4*BL5,-2) -> 1598000 | ... BP18: =ROUNDDOWN(BP10*BP26*BP4*BP5,-2) -> 1598000
A19: 移行加算 | E19: =ROUNDDOWN((E9+E10)*E4*E5*E28,-2) -> 38000 | F19: =ROUNDDOWN((F9+F10)*F4*F5*F28,-2) -> 43200 | G19: =ROUNDDOWN((G9+G10)*G4*G5*G28,-2) -> 49600 | H19: =ROUNDDOWN((H9+H10)*H4*H5*H28,-2) -> 57000 | I19: =ROUNDDOWN((I9+I10)*I4*I5*I28,-2) -> 59600 | J19: =ROUNDDOWN((J9+J10)*J4*J5*J28,-2) -> 38000 | K19: =ROUNDDOWN((K9+K10)*K4*K5*K28,-2) -> 49600 | L19: =ROUNDDOWN((L9+L10)*L4*L5*L28,-2) -> 57000 | ... P19: =ROUNDDOWN((P9+P10)*P4*P5*P28,-2) -> 161500 | R19: =ROUNDDOWN((R9+R10)*R4*R5*R28,-2) -> 190000 | S19: =ROUNDDOWN((S9+S10)*S4*S5*S28,-2) -> 172800 | T19: =ROUNDDOWN((T9+T10)*T4*T5*T28,-2) -> 198700 | U19: =ROUNDDOWN((U9+U10)*U4*U5*U28,-2) -> 190000 | V19: =ROUNDDOWN((V9+V10)*V4*V5*V28,-2) -> 198700 | W19: =ROUNDDOWN((W9+W10)*W4*W5*W28,-2) -> 190000 | X19: =ROUNDDOWN((X9+X10)*X4*X5*X28,-2) -> 198700 | Y19: =ROUNDDOWN((Y9+Y10)*Y4*Y5*Y28,-2) -> 190000 | ... AC19: =ROUNDDOWN((AC9+AC10)*AC4*AC5*AC28,-2) -> 190000 | AE19: =ROUNDDOWN((AE9+AE10)*AE4*AE5*AE28,-2) -> 190000 | AF19: =ROUNDDOWN((AF9+AF10)*AF4*AF5*AF28,-2) -> 172800 | AG19: =ROUNDDOWN((AG9+AG10)*AG4*AG5*AG28,-2) -> 198700 | AH19: =ROUNDDOWN((AH9+AH10)*AH4*AH5*AH28,-2) -> 190000 | AI19: =ROUNDDOWN((AI9+AI10)*AI4*AI5*AI28,-2) -> 198700 | AJ19: =ROUNDDOWN((AJ9+AJ10)*AJ4*AJ5*AJ28,-2) -> 190000 | AK19: =ROUNDDOWN((AK9+AK10)*AK4*AK5*AK28,-2) -> 198700 | AL19: =ROUNDDOWN((AL9+AL10)*AL4*AL5*AL28,-2) -> 190000 | ... AP19: =ROUNDDOWN((AP9+AP10)*AP4*AP5*AP28,-2) -> 190000 | AR19: =ROUNDDOWN((AR9+AR10)*AR4*AR5*AR28,-2) -> 190000 | AS19: =ROUNDDOWN((AS9+AS10)*AS4*AS5*AS28,-2) -> 172800 | AT19: =ROUNDDOWN((AT9+AT10)*AT4*AT5*AT28,-2) -> 198700 | AU19: =ROUNDDOWN((AU9+AU10)*AU4*AU5*AU28,-2) -> 190000 | AV19: =ROUNDDOWN((AV9+AV10)*AV4*AV5*AV28,-2) -> 198700 | AW19: =ROUNDDOWN((AW9+AW10)*AW4*AW5*AW28,-2) -> 190000 | AX19: =ROUNDDOWN((AX9+AX10)*AX4*AX5*AX28,-2) -> 198700 | AY19: =ROUNDDOWN((AY9+AY10)*AY4*AY5*AY28,-2) -> 190000 | ... BC19: =ROUNDDOWN((BC9+BC10)*BC4*BC5*BC28,-2) -> 190000 | BE19: =ROUNDDOWN((BE9+BE10)*BE4*BE5*BE28,-2) -> 190000 | BF19: =ROUNDDOWN((BF9+BF10)*BF4*BF5*BF28,-2) -> 172800 | BG19: =ROUNDDOWN((BG9+BG10)*BG4*BG5*BG28,-2) -> 198700 | BH19: =ROUNDDOWN((BH9+BH10)*BH4*BH5*BH28,-2) -> 190000 | BI19: =ROUNDDOWN((BI9+BI10)*BI4*BI5*BI28,-2) -> 198700 | BJ19: =ROUNDDOWN((BJ9+BJ10)*BJ4*BJ5*BJ28,-2) -> 190000 | BK19: =ROUNDDOWN((BK9+BK10)*BK4*BK5*BK28,-2) -> 198700 | BL19: =ROUNDDOWN((BL9+BL10)*BL4*BL5*BL28,-2) -> 190000 | ... BP19: =ROUNDDOWN((BP9+BP10)*BP4*BP5*BP28,-2) -> 190000
A20: 給付費合計 | E20: =SUM(E14:E19) -> 1535900 | F20: =SUM(F14:F19) -> 1534200 | G20: =SUM(G14:G19) -> 2180600 | H20: =SUM(H14:H19) -> 2237600 | I20: =SUM(I14:I19) -> 2339300 | J20: =SUM(J14:J19) -> 1934200 | K20: =SUM(K14:K19) -> 2494952 | L20: =SUM(L14:L19) -> 2688592 | ... P20: =SUM(P14:P19) -> 5099548 | R20: =SUM(R14:R19) -> 5679500 | S20: =SUM(S14:S19) -> 5293250 | T20: =SUM(T14:T19) -> 6236425 | U20: =SUM(U14:U19) -> 5965050 | V20: =SUM(V14:V19) -> 6236425 | W20: =SUM(W14:W19) -> 5965050 | X20: =SUM(X14:X19) -> 6236425 | Y20: =SUM(Y14:Y19) -> 5965050 | ... AC20: =SUM(AC14:AC19) -> 5965050 | AE20: =SUM(AE14:AE19) -> 5965000 | AF20: =SUM(AF14:AF19) -> 5423100 | AG20: =SUM(AG14:AG19) -> 6236425 | AH20: =SUM(AH14:AH19) -> 5965050 | AI20: =SUM(AI14:AI19) -> 6236425 | AJ20: =SUM(AJ14:AJ19) -> 5965050 | AK20: =SUM(AK14:AK19) -> 6236425 | AL20: =SUM(AL14:AL19) -> 5965050 | ... AP20: =SUM(AP14:AP19) -> 5965050 | AR20: =SUM(AR14:AR19) -> 5965000 | AS20: =SUM(AS14:AS19) -> 5423100 | AT20: =SUM(AT14:AT19) -> 6236425 | AU20: =SUM(AU14:AU19) -> 5965050 | AV20: =SUM(AV14:AV19) -> 6236425 | AW20: =SUM(AW14:AW19) -> 5965050 | AX20: =SUM(AX14:AX19) -> 6236425 | AY20: =SUM(AY14:AY19) -> 5965050 | ... BC20: =SUM(BC14:BC19) -> 5965050 | BE20: =SUM(BE14:BE19) -> 5965000 | BF20: =SUM(BF14:BF19) -> 5423100 | BG20: =SUM(BG14:BG19) -> 6236425 | BH20: =SUM(BH14:BH19) -> 5965050 | BI20: =SUM(BI14:BI19) -> 6236425 | BJ20: =SUM(BJ14:BJ19) -> 5965050 | BK20: =SUM(BK14:BK19) -> 6236425 | BL20: =SUM(BL14:BL19) -> 5965050 | ... BP20: =SUM(BP14:BP19) -> 5965050
A21: 給付費合計（千円） | E21: =E20/1000 -> 1535.9 | F21: =F20/1000 -> 1534.2 | G21: =G20/1000 -> 2180.6 | H21: =H20/1000 -> 2237.6 | I21: =I20/1000 -> 2339.3 | J21: =J20/1000 -> 1934.2 | K21: =K20/1000 -> 2494.952 | L21: =L20/1000 -> 2688.592 | ... P21: =P20/1000 -> 5099.548 | R21: =R20/1000 -> 5679.5 | S21: =S20/1000 -> 5293.25 | T21: =T20/1000 -> 6236.425 | U21: =U20/1000 -> 5965.05 | V21: =V20/1000 -> 6236.425 | W21: =W20/1000 -> 5965.05 | X21: =X20/1000 -> 6236.425 | Y21: =Y20/1000 -> 5965.05 | ... AC21: =AC20/1000 -> 5965.05 | AE21: =AE20/1000 -> 5965 | AF21: =AF20/1000 -> 5423.1 | AG21: =AG20/1000 -> 6236.425 | AH21: =AH20/1000 -> 5965.05 | AI21: =AI20/1000 -> 6236.425 | AJ21: =AJ20/1000 -> 5965.05 | AK21: =AK20/1000 -> 6236.425 | AL21: =AL20/1000 -> 5965.05 | ... AP21: =AP20/1000 -> 5965.05 | AR21: =AR20/1000 -> 5965 | AS21: =AS20/1000 -> 5423.1 | AT21: =AT20/1000 -> 6236.425 | AU21: =AU20/1000 -> 5965.05 | AV21: =AV20/1000 -> 6236.425 | AW21: =AW20/1000 -> 5965.05 | AX21: =AX20/1000 -> 6236.425 | AY21: =AY20/1000 -> 5965.05 | ... BC21: =BC20/1000 -> 5965.05 | BE21: =BE20/1000 -> 5965 | BF21: =BF20/1000 -> 5423.1 | BG21: =BG20/1000 -> 6236.425 | BH21: =BH20/1000 -> 5965.05 | BI21: =BI20/1000 -> 6236.425 | BJ21: =BJ20/1000 -> 5965.05 | BK21: =BK20/1000 -> 6236.425 | BL21: =BL20/1000 -> 5965.05 | ... BP21: =BP20/1000 -> 5965.05
A23: B基本報酬 | E23: 5890 | F23: 5890 | G23: 5890 | H23: 5890 | I23: 5890 | J23: 5890 | K23: 5890 | L23: 5890 | M23: 5890 | N23: 5890 | O23: 5890 | P23: 5890 | R23: 5890 | S23: 5890 | T23: 5890 | U23: 5890 | V23: 5890 | W23: 5890 | X23: 5890 | Y23: 5890 | Z23: 5890 | AA23: 5890 | AB23: 5890 | AC23: 5890 | AE23: 5890 | AF23: 5890 | AG23: 5890 | AH23: 5890 | AI23: 5890 | AJ23: 5890 | AK23: 5890 | AL23: 5890 | AM23: 5890 | AN23: 5890 | AO23: 5890 | AP23: 5890 | AR23: 5890 | AS23: 5890 | AT23: 5890 | AU23: 5890 | AV23: 5890 | AW23: 5890 | AX23: 5890 | AY23: 5890 | AZ23: 5890 | BA23: 5890 | BB23: 5890 | BC23: 5890 | BE23: 5890 | BF23: 5890 | BG23: 5890 | BH23: 5890 | BI23: 5890 | BJ23: 5890 | BK23: 5890 | BL23: 5890 | BM23: 5890 | BN23: 5890 | BO23: 5890 | BP23: 5890
