Workbook

Sheet 調査票（１）
A2: 令和３年度 就職者数等業務報告調査票（１）
B12: 問１ 法人名、施設名称、指定年月日を記入してください。
B13: 法人名 | E13: 合同会社DUG研究所
B14: 施設名称 | E14: コーリングサポ笠岡
B15: 指定年月日 | E15: 44531
B16: 施設の所在市町村 | E16: 5笠岡市 | L16: ←プルダウンリスト
L17: から選択
B18: 問２ 事業種類を下欄より選択し、番号を記入してください。
B19: 事業実施の種類 | E19: 1
B21: １ 就労移行支援 ２ 就労継続支援Ａ型 ３ 就労継続支援Ｂ型
B22: ４ 生活介護 ５ 自立訓練(機能訓練) 6 自立訓練(生活訓練)
B24: 問３ 令和４年３月31日時点で、利用者数（利用契約を締結している者の人数の合計）を記入してください。
D25: 令和４年３月31日時点
B26: 利用者数 | D26: 3 | F26: 人 | H26: 調査票２に支給決定市町村別の内訳を記入してください。
B28: 問４ 令和４年４月１日時点で、利用者数（利用契約を締結している者の人数の合計）を記入してください。
D29: 令和４年４月１日時点
B30: 利用者数 | D30: 3 | F30: 人
B32: 問５ 令和３年度（令和３年4月1日～令和４年3月31日まで）に利用を終了した者のうち就職した者の数
B33: （A型での就労を除く）を記入してください。
D34: 令和３年度中に就職した者の数 （令和3年4月1日～令和4年3月31日） | J34: 調査票２に支給決定市町村別
B35: 就職者数 | D35: 0 | H35: 人 | J35: の内訳を記入してください。
B37: 問６ 令和４年３月３１日時点で、問５の就職者のうち６か月以上経過している者の数を記入してください。
D38: 令和３年度就職者のうち令和4年3月31日時点で 一般就労して６か月を経過した者の数 | J38: 調査票２に支給決定市町村別
B39: 利用者数 | D39: 0 | H39: 人 | J39: の内訳を記入してください。
B41: 問７ 令和４年３月３１日時点で、問６の就職者のうち就労定着支援事業の利用者数を記入してください。
D42: 令和３年度就職者のうち令和4年3月31日時点で 就労定着支援事業を利用している者の数 | J42: 調査票２に支給決定市町村別
B43: 利用者数 | D43: 0 | H43: 人 | J43: の内訳を記入してください。
H45: 調査票（２）〔内訳表〕に続きます→
B56: 1 | C56: 1岡山市
B57: 2 | C57: 2倉敷市
B58: 3 | C58: 3津山市
B59: 4 | C59: 4玉野市
B60: 5 | C60: 5笠岡市
B61: 6 | C61: 6井原市
C62: 7総社市
C63: 8高梁市
C64: 9新見市
C65: 10備前市
C66: 11瀬戸内市
C67: 12赤磐市
...

Sheet 調査票 (2)
A2: 令和３年度 就職者数等業務報告調査票（２）〔内訳票〕
B4: ＊調査票（１）の人数の内訳（支給決定市町村別）を記入してください。
H5: （単位：人）
B6: 利用者の住所 | D6: 問３ | E6: 問４ | F6: 問５ | G6: 問６ | H6: 問７
B7: 1 | C7: 岡山市 | E7: 不要
B8: 2 | C8: 倉敷市
B9: 3 | C9: 津山市
B10: 4 | C10: 玉野市
B11: 5 | C11: 笠岡市 | D11: 1 | F11: 0 | G11: 0 | H11: 0
B12: 6 | C12: 井原市
B13: 7 | C13: 総社市
B14: 8 | C14: 高梁市
B15: 9 | C15: 新見市
B16: 10 | C16: 備前市
B17: 11 | C17: 瀬戸内市
B18: 12 | C18: 赤磐市
B19: 13 | C19: 真庭市
B20: 14 | C20: 美作市
B21: 15 | C21: 浅口市
B22: 16 | C22: 和気町
B23: 17 | C23: 早島町
... B33: 27 | C33: 吉備中央町
B34: 28 | C34: 県外 福山市 | D34: 2 | F34: 0 | G34: 0 | H34: 0
B35: 計 | D35: =SUM(D7:D34) -> 3 | F35: =SUM(F7:F34) -> 0 | G35: =SUM(G7:G34) -> 0 | H35: =SUM(H7:H34) -> 0 | J35: 同じ数字が入っていることを確認してください
B37: 調査票（１）の人数 〔自動で入ります〕 | D37: ='自動編集用【入力しないでください】'!F4 -> 3 | E37: ='自動編集用【入力しないでください】'!G4 -> 3 | F37: ='自動編集用【入力しないでください】'!H4 -> 0 | G37: ='自動編集用【入力しないでください】'!I4 -> 0 | H37: ='自動編集用【入力しないでください】'!J4 -> 0

Sheet 自動編集用【入力しないでください】
F1: 問３ | G1: 問４ | H1: 問５ | I1: 問６ | J1: 問７
A2: 法人名 | B2: 施設名称 | C2: 指定年月日 | D2: 施設所在市町村 | E2: 事業種類 | F2: R4年3月31日 | G2: R4年4月1日 | H2: 令和3年度 中の就職者数 | I2: うち６か月以上経過した者 | J2: うち 定着支援利用者数 | K2: 問３の内訳 | AM2: 問５の内訳 | BO2: 問６の内訳 | CQ2: 問７の内訳
F3: 利用者数 | G3: 利用者数 | K3: 1岡山市 | L3: 2倉敷市 | M3: 3津山市 | N3: 4玉野市 | O3: 5笠岡市 | P3: 6井原市 | Q3: 7総社市 | R3: 8高梁市 | S3: 9新見市 | T3: 10備前市 | U3: 11瀬戸内市 | V3: 12赤磐市 | W3: 13真庭市 | X3: 14美作市 | Y3: 15浅口市 | Z3: 16和気町 | AA3: 17早島町 | AB3: 18里庄町 | AC3: 19矢掛町 | AD3: 20新庄村 | AE3: 21鏡野町 | AF3: 22勝央町 | AG3: 23奈義町 | AH3: 24西粟倉村 | AI3: 25久米南町 | AJ3: 26美咲町 | AK3: 27吉備中央町 | AL3: 28県外 | AM3: 1岡山市 | AN3: 2倉敷市 | AO3: 3津山市 | AP3: 4玉野市 | AQ3: 5笠岡市 | AR3: 6井原市 | AS3: 7総社市 | AT3: 8高梁市 | AU3: 9新見市 | AV3: 10備前市 | AW3: 11瀬戸内市 | AX3: 12赤磐市 | AY3: 13真庭市 | AZ3: 14美作市 | BA3: 15浅口市 | BB3: 16和気町 | BC3: 17早島町 | BD3: 18里庄町 | BE3: 19矢掛町 | BF3: 20新庄村 | BG3: 21鏡野町 | BH3: 22勝央町 | BI3: 23奈義町 | BJ3: 24西粟倉村 | BK3: 25久米南町 | BL3: 26美咲町 | BM3: 27吉備中央町 | BN3: 28県外 | BO3: 1岡山市 | BP3: 2倉敷市 | BQ3: 3津山市 | BR3: 4玉野市 | BS3: 5笠岡市 | BT3: 6井原市 | BU3: 7総社市 | BV3: 8高梁市 | BW3: 9新見市 | BX3: 10備前市 | BY3: 11瀬戸内市 | BZ3: 12赤磐市 | CA3: 13真庭市 | CB3: 14美作市 | CC3: 15浅口市 | CD3: 16和気町 | CE3: 17早島町 | CF3: 18里庄町 | CG3: 19矢掛町 | CH3: 20新庄村 | CI3: 21鏡野町 | CJ3: 22勝央町 | CK3: 23奈義町 | CL3: 24西粟倉村 | CM3: 25久米南町 | CN3: 26美咲町 | CO3: 27吉備中央町 | CP3: 28県外 | CQ3: 1岡山市 | CR3: 2倉敷市 | CS3: 3津山市 | CT3: 4玉野市 | CU3: 5笠岡市 | CV3: 6井原市 | CW3: 7総社市 | CX3: 8高梁市 | CY3: 9新見市 | CZ3: 10備前市 | DA3: 11瀬戸内市 | DB3: 12赤磐市 | DC3: 13真庭市 | DD3: 14美作市 | DE3: 15浅口市 | DF3: 16和気町 | DG3: 17早島町 | DH3: 18里庄町 | DI3: 19矢掛町 | DJ3: 20新庄村 | DK3: 21鏡野町 | DL3: 22勝央町 | DM3: 23奈義町 | DN3: 24西粟倉村 | DO3: 25久米南町 | DP3: 26美咲町 | DQ3: 27吉備中央町 | DR3: 28県外
A4: ='調査票（１）'!$E$13 -> 合同会社DUG研究所 | B4: ='調査票（１）'!$E$14 -> コーリングサポ笠岡 | C4: ='調査票（１）'!$E$15 -> 44531 | D4: ='調査票（１）'!$E$16 -> 5笠岡市 | E4: ='調査票（１）'!$E$19 -> 1 | F4: ='調査票（１）'!$D$26 -> 3 | G4: ='調査票（１）'!$D$30 -> 3 | H4: ='調査票（１）'!$D$35 -> 0 | I4: ='調査票（１）'!$D$39 -> 0 | J4: ='調査票（１）'!$D$43 -> 0 | K4: ='調査票 (2)'!$D7 | L4: ='調査票 (2)'!$D8 | M4: ='調査票 (2)'!$D9 | N4: ='調査票 (2)'!$D10 | O4: ='調査票 (2)'!$D11 -> 1 | P4: ='調査票 (2)'!$D12 | Q4: ='調査票 (2)'!$D13 | R4: ='調査票 (2)'!$D14 | S4: ='調査票 (2)'!$D15 | T4: ='調査票 (2)'!$D16 | U4: ='調査票 (2)'!$D17 | V4: ='調査票 (2)'!$D18 | W4: ='調査票 (2)'!$D19 | X4: ='調査票 (2)'!$D20 | Y4: ='調査票 (2)'!$D21 | Z4: ='調査票 (2)'!$D22 | AA4: ='調査票 (2)'!$D23 | AB4: ='調査票 (2)'!$D24 | AC4: ='調査票 (2)'!$D25 | AD4: ='調査票 (2)'!$D26 | AE4: ='調査票 (2)'!$D27 | AF4: ='調査票 (2)'!$D28 | AG4: ='調査票 (2)'!$D29 | AH4: ='調査票 (2)'!$D30 | AI4: ='調査票 (2)'!$D31 | AJ4: ='調査票 (2)'!$D32 | AK4: ='調査票 (2)'!$D33 | AL4: ='調査票 (2)'!$D34 -> 2 | AM4: ='調査票 (2)'!$F7 | AN4: ='調査票 (2)'!$F8 | AO4: ='調査票 (2)'!$F9 | AP4: ='調査票 (2)'!$F10 | AQ4: ='調査票 (2)'!$F11 -> 0 | AR4: ='調査票 (2)'!$F12 | AS4: ='調査票 (2)'!$F13 | AT4: ='調査票 (2)'!$F14 | AU4: ='調査票 (2)'!$F15 | AV4: ='調査票 (2)'!$F16 | AW4: ='調査票 (2)'!$F17 | AX4: ='調査票 (2)'!$F18 | AY4: ='調査票 (2)'!$F19 | AZ4: ='調査票 (2)'!$F20 | BA4: ='調査票 (2)'!$F21 | BB4: ='調査票 (2)'!$F22 | BC4: ='調査票 (2)'!$F23 | BD4: ='調査票 (2)'!$F24 | BE4: ='調査票 (2)'!$F25 | BF4: ='調査票 (2)'!$F26 | BG4: ='調査票 (2)'!$F27 | BH4: ='調査票 (2)'!$F28 | BI4: ='調査票 (2)'!$F29 | BJ4: ='調査票 (2)'!$F30 | BK4: ='調査票 (2)'!$F31 | BL4: ='調査票 (2)'!$F32 | BM4: ='調査票 (2)'!$F33 | BN4: ='調査票 (2)'!$F34 -> 0 | BO4: ='調査票 (2)'!$G7 | BP4: ='調査票 (2)'!$G8 | BQ4: ='調査票 (2)'!$G9 | BR4: ='調査票 (2)'!$G10 | BS4: ='調査票 (2)'!$G11 -> 0 | BT4: ='調査票 (2)'!$G12 | BU4: ='調査票 (2)'!$G13 | BV4: ='調査票 (2)'!$G14 | BW4: ='調査票 (2)'!$G15 | BX4: ='調査票 (2)'!$G16 | BY4: ='調査票 (2)'!$G17 | BZ4: ='調査票 (2)'!$G18 | CA4: ='調査票 (2)'!$G19 | CB4: ='調査票 (2)'!$G20 | CC4: ='調査票 (2)'!$G21 | CD4: ='調査票 (2)'!$G22 | CE4: ='調査票 (2)'!$G23 | CF4: ='調査票 (2)'!$G24 | CG4: ='調査票 (2)'!$G25 | CH4: ='調査票 (2)'!$G26 | CI4: ='調査票 (2)'!$G27 | CJ4: ='調査票 (2)'!$G28 | CK4: ='調査票 (2)'!$G29 | CL4: ='調査票 (2)'!$G30 | CM4: ='調査票 (2)'!$G31 | CN4: ='調査票 (2)'!$G32 | CO4: ='調査票 (2)'!$G33 | CP4: ='調査票 (2)'!$G34 -> 0 | CQ4: ='調査票 (2)'!$H7 | CR4: ='調査票 (2)'!$H8 | CS4: ='調査票 (2)'!$H9 | CT4: ='調査票 (2)'!$H10 | CU4: ='調査票 (2)'!$H11 -> 0 | CV4: ='調査票 (2)'!$H12 | CW4: ='調査票 (2)'!$H13 | CX4: ='調査票 (2)'!$H14 | CY4: ='調査票 (2)'!$H15 | CZ4: ='調査票 (2)'!$H16 | DA4: ='調査票 (2)'!$H17 | DB4: ='調査票 (2)'!$H18 | DC4: ='調査票 (2)'!$H19 | DD4: ='調査票 (2)'!$H20 | DE4: ='調査票 (2)'!$H21 | DF4: ='調査票 (2)'!$H22 | DG4: ='調査票 (2)'!$H23 | DH4: ='調査票 (2)'!$H24 | DI4: ='調査票 (2)'!$H25 | DJ4: ='調査票 (2)'!$H26 | DK4: ='調査票 (2)'!$H27 | DL4: ='調査票 (2)'!$H28 | DM4: ='調査票 (2)'!$H29 | DN4: ='調査票 (2)'!$H30 | DO4: ='調査票 (2)'!$H31 | DP4: ='調査票 (2)'!$H32 | DQ4: ='調査票 (2)'!$H33 | DR4: ='調査票 (2)'!$H34 -> 0
