Workbook

Sheet 8月分
A1: 平成 27年 8月度 | Q1: 出 勤 簿
B3: 日 | C3: 1 | D3: 2 | E3: 3 | F3: 4 | G3: 5 | H3: 6 | I3: 7 | J3: 8 | K3: 9 | L3: 10 | M3: 11 | N3: 12 | O3: 13 | P3: 14 | Q3: 15 | R3: 16 | S3: 17 | T3: 18 | U3: 19 | V3: 20 | W3: 21 | X3: 22 | Y3: 23 | Z3: 24 | AA3: 25 | AB3: 26 | AC3: 27 | AD3: 28 | AE3: 29 | AF3: 30 | AG3: 31 | AH3: 出勤日数 | AI3: 労働時間 | AJ3: 休日出勤日数 | AK3: 欠勤日数 | AL3: 遅刻早引時間 | AM3: 時間外労働
B4: 氏 名 曜 | C4: 土 | D4: 日 | E4: 月 | F4: 火 | G4: 水 | H4: 木 | I4: 金 | J4: 土 | K4: 日 | L4: 月 | M4: 火 | N4: 水 | O4: 木 | P4: 金 | Q4: 土 | R4: 日 | S4: 月 | T4: 火 | U4: 水 | V4: 木 | W4: 金 | X4: 土 | Y4: 日 | Z4: 月 | AA4: 火 | AB4: 水 | AC4: 木 | AD4: 金 | AE4: 土 | AF4: 日 | AG4: 月 | AM4: 早出残業 | AN4: 深夜 | AO4: 休日
A5: 1 | B5: 岡﨑 峻喬 | C5: 休 | D5: 休 | J5: 休 | K5: 休 | P5: 休 | Q5: 休 | R5: 休 | Y5: 休 | AE5: 休 | AF5: 休 | AH5: 21 | AQ5: 280000 | AR5: 10000
A6: 2 | B6: 山内 雄司 | C6: 休 | D6: 休 | J6: 休 | K6: 休 | P6: 休 | Q6: 休 | R6: 休 | Y6: 休 | AE6: 休 | AF6: 休 | AH6: 21 | AQ6: 200000
A7: 3
A8: 4 | B8: 大元 照美 | D8: 休 | K8: 休 | Q8: 休 | R8: 休 | Y8: 休 | AF8: 休 | AH8: 25 | AI8: =時給計算書!F35 -> 7.1229167 | AQ8: 6000 | AS8: 858
A9: 5 | B9: 瀬戸 光代 | C9: 休 | D9: 休 | J9: 休 | K9: 休 | P9: 休 | Q9: 休 | R9: 休 | Y9: 休 | AE9: 休 | AF9: 休 | AH9: 21 | AI9: =時給計算書!F71 -> 6.1923611 | AQ9: 800 | AR9: 5000
A10: 6 | AQ10: 800
A11: 7
A12: 8 | B12: 山内 龍一 | C12: 休 | D12: 休 | J12: 休 | K12: 休 | O12: 休 | P12: 休 | Q12: 休 | R12: 休 | X12: 休 | Y12: 休 | AE12: 休 | AF12: 休 | AH12: 19 | AQ12: 1000
A13: 9 | B13: 山下恵美子 | C13: 休 | D13: 休 | H13: 休 | J13: 休 | K13: 休 | P13: 休 | Q13: 休 | R13: 休 | X13: 休 | Y13: 休 | AE13: 休 | AF13: 休 | AH13: 19 | AQ13: 1000
A14: 10 | B14: 川上 智樹 | C14: 休 | D14: 休 | J14: 休 | K14: 休 | P14: 休 | Q14: 休 | R14: 休 | Y14: 休 | AB14: 休 | AE14: 休 | AF14: 休 | AH14: 20 | AQ14: 1500
A15: 11 | B15: 上松 正和 | D15: 休 | J15: 休 | K15: 休 | P15: 休 | Q15: 休 | R15: 休 | V15: 休 | W15: 休 | Y15: 休 | AE15: 休 | AF15: 休 | AH15: 19 | AQ15: 1500
A16: 12 | B16: 上松 浩二 | D16: 休 | J16: 休 | K16: 休 | P16: 休 | Q16: 休 | R16: 休 | Y16: 休 | AF16: 休 | AH16: 22 | AQ16: 1500
A17: 13 | B17: 若林 哲也 | C17: 休 | D17: 休 | E17: 休 | F17: 休 | G17: 休 | H17: 休 | I17: 休 | J17: 休 | K17: 休 | L17: 休 | M17: 休 | N17: 休 | O17: 休 | P17: 休 | Q17: 休 | R17: 休 | S17: 休 | T17: 休 | U17: 休 | V17: 休 | W17: 休 | X17: 休 | Y17: 休 | Z17: 休 | AA17: 休 | AB17: 休 | AC17: 休 | AD17: 休 | AE17: 休 | AF17: 休 | AG17: 休 | AH17: 0 | AQ17: 1000
A18: 14 | B18: 柏木 憲太 | C18: 休 | D18: 休 | J18: 休 | K18: 休 | P18: 休 | Q18: 休 | R18: 休 | Y18: 休 | AE18: 休 | AF18: 休 | AH18: 21 | AQ18: 1500 | AR18: 5000
A19: 15 | B19: 大元裕美子 | C19: 休 | D19: 休 | F19: 休 | H19: 休 | J19: 休 | K19: 休 | M19: 休 | P19: 休 | Q19: 休 | R19: 休 | T19: 休 | V19: 休 | X19: 休 | Y19: 休 | AA19: 休 | AC19: 休 | AE19: 休 | AF19: 休 | AH19: 13 | AQ19: 1000
A20: 16 | B20: 倉谷 円 | C20: 休 | D20: 休 | J20: 休 | K20: 休 | P20: 休 | Q20: 休 | R20: 休 | Y20: 休 | AA20: 休 | AE20: 休 | AF20: 休 | AG20: 休 | AH20: 19 | AQ20: 1000
A21: 17 | B21: 葛籠 沙葵 | C21: 休 | D21: 休 | F21: 休 | G21: 休 | J21: 休 | K21: 休 | P21: 休 | Q21: 休 | R21: 休 | T21: 休 | X21: 休 | Y21: 休 | AE21: 休 | AF21: 休 | AH21: 17 | AQ21: 1000
A22: 18 | B22: 岡田 直明 | C22: 休 | D22: 休 | F22: 休 | G22: 休 | H22: 休 | I22: 休 | J22: 休 | K22: 休 | L22: 休 | M22: 休 | N22: 休 | O22: 休 | P22: 休 | Q22: 休 | R22: 休 | S22: 休 | T22: 休 | U22: 休 | V22: 休 | W22: 休 | X22: 休 | Y22: 休 | Z22: 休 | AA22: 休 | AB22: 休 | AC22: 休 | AD22: 休 | AE22: 休 | AF22: 休 | AG22: 休 | AH22: 1 | AQ22: 1000
A23: 19 | B23: 神田 幸弘 | C23: 休 | D23: 休 | E23: 休 | G23: 休 | H23: 休 | J23: 休 | K23: 休 | N23: 休 | P23: 休 | Q23: 休 | R23: 休 | U23: 休 | V23: 休 | Y23: 休 | AB23: 休 | AE23: 休 | AF23: 休 | AH23: 14 | AQ23: 1000
A24: 20 | B24: 鹿室 泰洋 | C24: 休 | D24: 休 | E24: 休 | F24: 休 | H24: 休 | I24: 休 | J24: 休 | K24: 休 | M24: 休 | N24: 休 | O24: 休 | P24: 休 | Q24: 休 | R24: 休 | S24: 休 | T24: 休 | U24: 休 | V24: 休 | X24: 休 | Y24: 休 | AA24: 休 | AC24: 休 | AE24: 休 | AF24: 休 | AH24: 7 | AQ24: 1000
A25: 21 | B25: 吉岡 一夫 | C25: 休 | D25: 休 | H25: 休 | I25: 休 | J25: 休 | K25: 休 | P25: 休 | Q25: 休 | R25: 休 | Y25: 休 | AC25: 休 | AE25: 休 | AF25: 休 | AH25: 18 | AQ25: 1000
A26: 22 | B26: 宇江 寿江 | C26: 休 | D26: 休 | F26: 休 | J26: 休 | K26: 休 | N26: 休 | P26: 休 | Q26: 休 | R26: 休 | V26: 休 | Y26: 休 | AA26: 休 | AE26: 休 | AF26: 休 | AG26: 休 | AH26: 16 | AQ26: 1000
A27: 23 | B27: 吉原 祐平 | C27: 休 | D27: 休 | J27: 休 | K27: 休 | P27: 休 | Q27: 休 | R27: 休 | Y27: 休 | AE27: 休 | AF27: 休 | AH27: 21 | AQ27: 1000
A28: 24 | B28: 櫻武 隆一 | C28: 休 | D28: 休 | I28: 休 | J28: 休 | K28: 休 | M28: 休 | O28: 休 | P28: 休 | Q28: 休 | R28: 休 | V28: 休 | Y28: 休 | Z28: 休 | AD28: 休 | AE28: 休 | AF28: 休 | AH28: 15 | AQ28: 1000
A29: 25 | B29: 志並 智美 | C29: 休 | D29: 休 | F29: 休 | G29: 休 | I29: 休 | J29: 休 | K29: 休 | M29: 休 | N29: 休 | O29: 休 | P29: 休 | Q29: 休 | R29: 休 | T29: 休 | U29: 休 | V29: 休 | W29: 休 | X29: 休 | Y29: 休 | Z29: 休 | AA29: 休 | AB29: 休 | AC29: 休 | AD29: 休 | AE29: 休 | AF29: 休 | AH29: 5 | AQ29: 1000
A30: 26 | B30: 仁井 諭 | C30: 休 | D30: 休 | J30: 休 | K30: 休 | P30: 休 | Q30: 休 | R30: 休 | Y30: 休 | AE30: 休 | AF30: 休 | AH30: 21 | AQ30: 1000
A31: 27 | B31: 林 命 | C31: 休 | D31: 休 | E31: 休 | I31: 休 | J31: 休 | K31: 休 | M31: 休 | N31: 休 | O31: 休 | P31: 休 | Q31: 休 | R31: 休 | V31: 休 | W31: 休 | Y31: 休 | Z31: 休 | AA31: 休 | AC31: 休 | AE31: 休 | AF31: 休 | AG31: 休 | AH31: 10 | AQ31: 1000
A32: 28
A33: 29
A34: 30

Sheet 賃金集計表
A1: 賃 金 集 計 表
A2: 平成27年8月分
A4: 氏名 | B4: 労働日数 | C4: 給料体系 | D4: 労働時間数 | E4: 休日労働時間数 | F4: 早出残業時間数 | G4: 深夜労働時間数 | H4: 基本賃金 | I4: 家族手当 | J4: 住宅手当 | K4: 通勤手当 | L4: 精勤手当 | M4: 資格手当 | N4: 手当 | O4: 小計 | P4: 健康保険 | Q4: 厚生年金 | R4: 雇用保険 | S4: 所得税 | T4: 市民税 | V4: 弁当代 | W4: 小計 | X4: 差引支払金
A5: ='8月分'!B5 -> 岡﨑 峻喬 | B5: 21 | C5: 280000 | H5: 280000 | M5: 10000 | O5: =SUM(H5:N5) -> 290000 | P5: 14042 | Q5: 24464 | R5: =O5*5/1000 -> 1450 | S5: 4920 | W5: =SUM(P5:V5) -> 44876 | X5: =O5-W5 -> 245124
A6: 山内 雄司 | B6: ='8月分'!AH6 -> 21 | C6: 200000 | H6: 200000 | O6: =SUM(H6:N6) -> 200000 | S6: 3140 | W6: =SUM(P6:V6) -> 3140 | X6: =O6-W6 -> 196860
A8: 給料手当 | H8: =SUM(H5:H7) -> 480000 | L8: =SUM(L5:L7) -> 0 | M8: =SUM(M5:M7) -> 10000 | O8: =SUM(O5:O7) -> 490000 | P8: =SUM(P5:P7) -> 14042 | Q8: =SUM(Q5:Q7) -> 24464 | R8: =SUM(R5:R7) -> 1450 | S8: =SUM(S5:S7) -> 8060 | V8: =SUM(V5:V7) -> 0 | W8: =SUM(W5:W7) -> 48016 | X8: =SUM(X5:X7) -> 441984
A10: 大元 照美 | B10: ='8月分'!AH8 -> 25 | C10: 6000 | D10: =時給計算書!F35 -> 7.1229167 | E10: 1157 | F10: 1071 | G10: 1288 | H10: =B10*C10 -> 150000 | O10: =SUM(H10:N10) -> 150000 | P10: 8708 | Q10: 13106 | R10: =O10*5/1000 -> 750 | S10: 2150 | W10: =SUM(P10:V10) -> 24714 | X10: =O10-W10 -> 125286 | Z10: 25日/7Ｈ | AA10: 6000円 | AB10: 1H/858
A11: 瀬戸 光代 | B11: ='8月分'!AH9 -> 21 | C11: 800 | D11: ='8月分'!AI9 -> 6.1923611 | F11: 1000 | H11: =D11*24*C11 -> 118893.33 | K11: 5000 | O11: =SUM(H11:N11) -> 123893.33 | R11: =O11*5/1000 -> 619.46667 | S11: 1950 | W11: =SUM(P11:V11) -> 2569.4667 | X11: =O11-W11 -> 121323.87
H12: =D12*24*C12 -> 0 | O12: =SUM(H12:N12) -> 0 | W12: =SUM(P12:V12) -> 0 | X12: =O12-W12 -> 0
A14: 原 賃金 | H14: =SUM(H10:H13) -> 268893.33 | K14: =SUM(K10:K12) -> 5000 | L14: =SUM(L9:L13) -> 0 | M14: =SUM(M10:M13) -> 0 | O14: =SUM(O10:O13) -> 273893.33 | P14: =SUM(P10:P12) -> 8708 | Q14: =SUM(Q10:Q13) -> 13106 | R14: =SUM(R10:R13) -> 1369.4667 | S14: =SUM(S10:S13) -> 4100 | V14: =SUM(V9:V13) -> 0 | W14: =SUM(W10:W13) -> 27283.467 | X14: =O14-P14-Q14-R14-S14-V14 -> 246609.87
A16: 山内 龍一 | B16: ='8月分'!AH12 -> 19 | C16: 1000 | H16: =B16*C16 -> 19000 | O16: =SUM(H16:N16) -> 19000 | V16: 6300 | W16: =SUM(P16:V16) -> 6300 | X16: =O16-W16 -> 12700
A17: 山下恵美子 | B17: ='8月分'!AH13 -> 19 | C17: 1000 | H17: =B17*C17 -> 19000 | O17: =SUM(H17:N17) -> 19000 | V17: 6300 | W17: =SUM(P17:V17) -> 6300 | X17: =O17-W17 -> 12700
A18: 川上 智樹 | B18: ='8月分'!AH14 -> 20 | C18: 1500 | H18: =B18*C18 -> 30000 | O18: =SUM(H18:N18) -> 30000 | W18: =SUM(P18:V18) -> 0 | X18: =O18-W18 -> 30000
A19: 上松 正和 | B19: 20 | C19: 1500 | H19: =B19*C19 -> 30000 | O19: =SUM(H19:N19) -> 30000 | W19: =SUM(P19:V19) -> 0 | X19: =O19-W19 -> 30000
A20: 上松 浩二 | B20: 23 | C20: 1500 | H20: =B20*C20 -> 34500 | O20: =SUM(H20:N20) -> 34500 | W20: =SUM(P20:V20) -> 0 | X20: =O20-W20 -> 34500
A21: 若林 哲也 | B21: ='8月分'!AH17 -> 0 | C21: 1000 | H21: =B21*C21 -> 0 | O21: =SUM(H21:N21) -> 0 | W21: =SUM(P21:V21) -> 0 | X21: =O21-W21 -> 0
A22: 柏木 憲太 | B22: ='8月分'!AH18 -> 21 | C22: 1500 | H22: =B22*C22 -> 31500 | N22: 5000 | O22: =SUM(H22:N22) -> 36500 | V22: 7000 | W22: =SUM(P22:V22) -> 7000 | X22: =O22-W22 -> 29500
A23: 大元裕美子 | B23: ='8月分'!AH19 -> 13 | C23: 1000 | H23: =B23*C23 -> 13000 | O23: =SUM(H23:N23) -> 13000 | V23: 3150 | W23: =SUM(P23:V23) -> 3150 | X23: =O23-W23 -> 9850
A24: 倉谷 円 | B24: ='8月分'!AH20 -> 19 | C24: 1000 | H24: =B24*C24 -> 19000 | O24: =SUM(H24:N24) -> 19000 | W24: =SUM(P24:V24) -> 0 | X24: =O24-W24 -> 19000
A25: 葛籠 沙葵 | B25: ='8月分'!AH21 -> 17 | C25: 1000 | H25: =B25*C25 -> 17000 | L25: 5600 | O25: =SUM(H25:N25) -> 22600 | V25: 5600 | W25: =SUM(P25:V25) -> 5600 | X25: =O25-W25 -> 17000
A26: ='8月分'!B22 -> 岡田 直明 | B26: ='8月分'!AH22 -> 1 | C26: 1000 | H26: =B26*C26 -> 1000 | O26: =SUM(H26:N26) -> 1000 | W26: =SUM(P26:V26) -> 0 | X26: =O26-W26 -> 1000
A27: ='8月分'!B23 -> 神田 幸弘 | B27: ='8月分'!AH23 -> 14 | C27: 1000 | H27: =B27*C27 -> 14000 | O27: =SUM(H27:N27) -> 14000 | W27: =SUM(P27:V27) -> 0 | X27: =O27-W27 -> 14000
A28: 鹿室 泰洋 | B28: ='8月分'!AH24 -> 7 | C28: 1000 | H28: =B28*C28 -> 7000 | O28: =SUM(H28:N28) -> 7000 | W28: =SUM(P28:V28) -> 0 | X28: =O28-W28 -> 7000
A29: 吉岡 一夫 | B29: ='8月分'!AH25 -> 18 | C29: 1000 | H29: =B29*C29 -> 18000 | O29: =SUM(H29:N29) -> 18000 | W29: =SUM(P29:V29) -> 0 | X29: =O29-W29 -> 18000
A30: 宇江 寿江 | B30: ='8月分'!AH26 -> 16 | C30: 1000 | H30: =B30*C30 -> 16000 | O30: =SUM(H30:N30) -> 16000 | W30: =SUM(P30:V30) -> 0 | X30: =O30-W30 -> 16000
A31: 吉原 祐平 | B31: ='8月分'!AH27 -> 21 | C31: 1000 | H31: =B31*C31 -> 21000 | L31: 7000 | O31: =SUM(H31:N31) -> 28000 | V31: 7000 | W31: =SUM(P31:V31) -> 7000 | X31: =O31-W31 -> 21000
A32: 櫻武 隆一 | B32: ='8月分'!AH28 -> 15 | C32: 1000 | H32: =B32*C32 -> 15000 | L32: 5250 | O32: =SUM(H32:N32) -> 20250 | V32: 5250 | W32: =SUM(P32:V32) -> 5250 | X32: =O32-W32 -> 15000
A33: 志並 智美 | B33: ='8月分'!AH29 -> 5 | C33: 1000 | H33: =B33*C33 -> 5000 | O33: =SUM(H33:N33) -> 5000 | W33: =SUM(P33:V33) -> 0 | X33: =O33-W33 -> 5000
A34: 仁井 諭 | B34: ='8月分'!AH30 -> 21 | C34: 1000 | H34: =B34*C34 -> 21000 | O34: =SUM(H34:N34) -> 21000 | V34: 6300 | W34: =SUM(P34:V34) -> 6300 | X34: =O34-W34 -> 14700
A35: 林 命 | B35: ='8月分'!AH31 -> 10 | C35: 1000 | H35: =B35*C35 -> 10000 | L35: 3500 | O35: =SUM(H35:N35) -> 13500 | V35: 3500 | W35: =SUM(P35:V35) -> 3500 | X35: =O35-W35 -> 10000
A36: 訓練等給付費 | H36: =SUM(H16:H35) -> 341000 | K36: =SUM(K16:K35) -> 0 | L36: =SUM(L15:L35) -> 21350 | M36: =SUM(M16:M25) -> 0 | N36: =SUM(N15:N35) -> 5000 | O36: =SUM(O16:O35) -> 367350 | V36: =SUM(V16:V35) -> 50400 | W36: =SUM(W16:W35) -> 50400 | X36: =SUM(X16:X35) -> 316950
H38: =B38*C38 -> 0 | O38: =SUM(H38:N38) -> 0 | W38: =SUM(P38:V38) -> 0 | X38: =O38-W38 -> 0
H39: =B39*C39 -> 0 | O39: =SUM(H39:N39) -> 0 | W39: =SUM(P39:V39) -> 0 | X39: =O39-W39 -> 0
H40: =B40*C40 -> 0 | O40: =SUM(H40:N40) -> 0 | W40: =SUM(P40:V40) -> 0 | X40: =O40-W40 -> 0
H41: =B41*C41 -> 0 | O41: =SUM(H41:N41) -> 0 | V41: 0 | W41: =SUM(P41:V41) -> 0 | X41: =O41-W41 -> 0
H42: =B42*C42 -> 0 | O42: =SUM(H42:N42) -> 0 | V42: 0 | W42: =SUM(P42:V42) -> 0 | X42: =O42-W42 -> 0
A44: 謝金 | H44: =SUM(H38:H43) -> 0 | L44: =SUM(L38:L43) -> 0 | M44: =SUM(M38:M42) -> 0 | O44: =SUM(O38:O43) -> 0 | V44: =SUM(V38:V43) -> 0 | W44: =SUM(W38:W43) -> 0 | X44: =SUM(X38:X43) -> 0
A45: 合計 | H45: =H8+H14+H36+H44 -> 1089893.3 | I45: =I8+I14+I36+I44 -> 0 | J45: =J8+J14+J36+J44 -> 0 | K45: =K8+K14+K36+K44 -> 5000 | L45: =L8+L14+L36+L44 -> 21350 | M45: =M8+M14+M36+M44 -> 10000 | N45: =N8+N14+N36+N44 -> 5000 | O45: =O8+O14+O36+O44 -> 1131243.3 | P45: =P8+P14+P36+P42 -> 22750 | Q45: =Q8+Q14+Q36+Q42 -> 37570 | R45: =R8+R14+R36+R42 -> 2819.4667 | S45: =S8+S14+S36+S42 -> 12160 | T45: =T8+T14+T36+T42 -> 0 | U45: =U8+U14+U36+U42 -> 0 | V45: =V8+V14+V36+V44 -> 50400 | W45: =W8+W14+W36+W44 -> 125699.47 | X45: =O45-P45-Q45-R45-S45-V45 -> 1005543.9
O47: =H45+I45+J45+K45+L45+M45+N45 -> 1131243.3

Sheet 給料支払明細書
A1: 給料支払明細書 | M1: 平成27年8月分
A3: 氏名 | C3: =賃金集計表!A5 -> 岡﨑 峻喬 | G3: 殿 | H3: 労働日数 | K3: 労働時間 | N3: 時間外労働時間
H4: =賃金集計表!B5 -> 21
A6: 基本給 | C6: 時間外労働時間 | I6: 手当
A7: =賃金集計表!H5 -> 280000 | I7: =賃金集計表!M5 -> 10000
A9: 社会保険料 | C9: 厚生年金 | E9: 雇用保険料 | G9: 市民税 | I9: 所得税 | O9: 弁当代
A10: =賃金集計表!P5 -> 14042 | C10: =賃金集計表!Q5 -> 24464 | E10: =賃金集計表!R5 -> 1450 | G10: =賃金集計表!T5 -> 0 | I10: =賃金集計表!S5 -> 4920 | O10: =賃金集計表!V5 -> 0
A12: 総支給額 | D12: 控除額 | G12: 差引支給額 | K12: 一般社団法人 チャレンジド尾道
A13: =SUM(A7:P7) -> 290000 | D13: =SUM(A10:P10) -> 44876 | G13: =A13-D13 -> 245124 | K13: 就労継続支援（Ｂ型）施設 カイト御調
A16: 給料支払明細書 | M16: 平成27年8月分
A18: 氏名 | C18: =賃金集計表!A6 -> 山内 雄司 | G18: 殿 | H18: 労働日数 | K18: 労働時間 | N18: 時間外労働時間
H19: =賃金集計表!B6 -> 21
A21: 基本給 | C21: 時間外労働時間 | I21: 手当
A22: =賃金集計表!H6 -> 200000
A24: 社会保険料 | C24: 厚生年金 | E24: 雇用保険料 | G24: 市民税 | I24: 所得税 | M24: ガソリン代 | O24: 弁当代
I25: =賃金集計表!S6 -> 3140 | M25: 46555 | O25: =賃金集計表!V6 -> 0
A27: 総支給額 | D27: 控除額 | G27: 差引支給額 | K27: 一般社団法人 チャレンジド尾道
A28: =SUM(A22:P22) -> 200000 | D28: =SUM(A25:P25) -> 49695 | G28: =A28-D28 -> 150305 | K28: 就労継続支援（Ｂ型）施設 カイト御調
A31: 給料支払明細書 | M31: 平成27年8月分
A33: 氏名 | G33: 殿 | H33: 労働日数 | K33: 労働時間 | N33: 時間外労働時間
A36: 基本給 | C36: 時間外労働時間 | I36: 手当
A39: 社会保険料 | C39: 厚生年金 | E39: 雇用保険料 | G39: 市民税 | I39: 所得税 | O39: 弁当代
A42: 総支給額 | D42: 控除額 | G42: 差引支給額 | K42: 一般社団法人 チャレンジド尾道
A43: =SUM(A37:P37) -> 0 | D43: =SUM(A40:P40) -> 0 | G43: =A43-D43 -> 0 | K43: 就労継続支援（Ｂ型）施設 カイト御調
A46: 給料支払明細書 | M46: 平成27年8月分
A48: 氏名 | C48: =賃金集計表!A10 -> 大元 照美 | G48: 殿 | H48: 労働日数 | K48: 労働時間 | N48: 時間外労働時間
H49: =賃金集計表!B10 -> 25 | R49: 1日＝6000
A51: 基本給 | C51: 時間外労働時間 | I51: 手当
A52: =賃金集計表!H10 -> 150000 | I52: =賃金集計表!M10 -> 0
A54: 社会保険料 | C54: 厚生年金 | E54: 雇用保険料 | G54: 市民税 | I54: 所得税 | O54: 弁当代
A55: =賃金集計表!P10 -> 8708 | C55: =賃金集計表!Q10 -> 13106 | E55: =賃金集計表!R10 -> 750 | G55: =賃金集計表!T10 -> 0 | I55: =賃金集計表!S10 -> 2150 | O55: =賃金集計表!V10 -> 0
A57: 総支給額 | D57: 控除額 | G57: 差引支給額 | K57: 一般社団法人 チャレンジド尾道
A58: =SUM(A52:P52) -> 150000 | D58: =SUM(A55:P55) -> 24714 | G58: =A58-D58 -> 125286 | K58: 就労継続支援（Ｂ型）施設 カイト御調
A61: 給料支払明細書 | M61: 平成27年8月分
A63: 氏名 | C63: =賃金集計表!A11 -> 瀬戸 光代 | G63: 殿 | H63: 労働日数 | K63: 労働時間 | N63: 時間外労働時間
H64: =賃金集計表!B11 -> 21 | K64: =賃金集計表!D11 -> 6.1923611 | N64: ='8月分'!AM22 -> 0 | R64: 4.2263889 | S64: 800 | T64: =R64*S64 -> 3381.1111
A66: 基本給 | C66: 時間外労働時間 | I66: 手当
A67: =賃金集計表!H11 -> 118893.33 | I67: =賃金集計表!K11 -> 5000
A69: 社会保険料 | C69: 厚生年金 | E69: 雇用保険料 | G69: 市民税 | I69: 所得税 | O69: 弁当代
E70: =賃金集計表!R11 -> 619.46667 | I70: =賃金集計表!S11 -> 1950 | O70: =賃金集計表!V11 -> 0
...

Sheet 時給計算書
C1: 氏名 | D1: 大元 照美
C2: 計算年月 | D2: 平成27年 | E2: 8月
A3: 日 | B3: 曜日 | C3: 出社時間 | D3: 退社時間 | E3: 休憩時間 | F3: 勤務時間
A4: 1 | B4: 土 | C4: 0.375 | D4: 0.62361111 | E4: 0.041666667 | F4: =D4-C4-E4 -> 0.20694444
A5: 2 | B5: 日 | F5: =D5-C5-E5 -> 0
A6: 3 | B6: 月 | C6: 0.37291667 | D6: 0.73333333 | E6: 0.041666667 | F6: =D6-C6-E6 -> 0.31875
A7: 4 | B7: 火 | C7: 0.39375 | D7: 0.73611111 | E7: 0.041666667 | F7: =D7-C7-E7 -> 0.30069444
A8: 5 | B8: 水 | C8: 0.36736111 | D8: 0.71180556 | E8: 0.041666667 | F8: =D8-C8-E8 -> 0.30277778
A9: 6 | B9: 木 | C9: 0.39166667 | D9: 0.73680556 | E9: 0.041666667 | F9: =D9-C9-E9 -> 0.30347222
A10: 7 | B10: 金 | C10: 0.37986111 | D10: 0.72013889 | E10: 0.041666667 | F10: =D10-C10-E10 -> 0.29861111
A11: 8 | B11: 土 | C11: 0.38680556 | D11: 0.63125 | F11: =D11-C11-E11 -> 0.24444444
A12: 9 | B12: 日 | F12: =D12-C12-E12 -> 0
A13: 10 | B13: 月 | C13: 0.36736111 | D13: 0.70902778 | E13: 0.041666667 | F13: =D13-C13-E13 -> 0.3
A14: 11 | B14: 火 | C14: 0.3875 | D14: 0.73819444 | E14: 0.041666667 | F14: =D14-C14-E14 -> 0.30902778
A15: 12 | B15: 水 | C15: 0.37083333 | D15: 0.71458333 | E15: 0.041666667 | F15: =D15-C15-E15 -> 0.30208333
A16: 13 | B16: 木 | C16: 0.3625 | D16: 0.70972222 | E16: 0.041666667 | F16: =D16-C16-E16 -> 0.30555556
A17: 14 | B17: 金 | C17: 0.38819444 | D17: 0.62083333 | F17: =D17-C17-E17 -> 0.23263889
A18: 15 | B18: 土 | F18: =D18-C18-E18 -> 0
A19: 16 | B19: 日 | F19: =D19-C19-E19 -> 0
A20: 17 | B20: 月 | C20: 0.37083333 | D20: 0.725 | E20: 0.041666667 | F20: =D20-C20-E20 -> 0.3125
A21: 18 | B21: 火 | C21: 0.39097222 | D21: 0.73194444 | E21: 0.041666667 | F21: =D21-C21-E21 -> 0.29930556
A22: 19 | B22: 水 | C22: 0.36597222 | D22: 0.71111111 | E22: 0.041666667 | F22: =D22-C22-E22 -> 0.30347222
A23: 20 | B23: 木 | C23: 0.39375 | D23: 0.72916667 | E23: 0.041666667 | F23: =D23-C23-E23 -> 0.29375
A24: 21 | B24: 金 | C24: 0.375 | D24: 0.71666667 | E24: 0.041666667 | F24: =D24-C24-E24 -> 0.3
A25: 22 | B25: 土 | C25: 0.39236111 | D25: 0.72569444 | E25: 0.041666667 | F25: =D25-C25-E25 -> 0.29166667
A26: 23 | B26: 日 | F26: =D26-C26-E26 -> 0
A27: 24 | B27: 月 | C27: 0.36319444 | D27: 0.72430556 | E27: 0.041666667 | F27: =D27-C27-E27 -> 0.31944444
A28: 25 | B28: 火 | C28: 0.38888889 | D28: 0.52569444 | F28: =D28-C28-E28 -> 0.13680556
A29: 26 | B29: 水 | C29: 0.37152778 | D29: 0.71458333 | E29: 0.041666667 | F29: =D29-C29-E29 -> 0.30138889
A30: 27 | B30: 木 | C30: 0.38888889 | D30: 0.72222222 | E30: 0.041666667 | F30: =D30-C30-E30 -> 0.29166667
A31: 28 | B31: 金 | C31: 0.36944444 | D31: 0.70833333 | E31: 0.041666667 | F31: =D31-C31-E31 -> 0.29722222
A32: 29 | B32: 土 | C32: 0.39375 | D32: 0.63958333 | F32: =D32-C32-E32 -> 0.24583333
A33: 30 | B33: 日 | F33: =D33-C33-E33 -> 0
A34: 31 | B34: 月 | C34: 0.37291667 | D34: 0.71944444 | E34: 0.041666667 | F34: =D34-C34-E34 -> 0.30486111
E35: 合計 | F35: =SUM(F4:F34) -> 7.1229167 | G35: =SUM(G4:G34) -> 0 | H35: =SUM(H4:H34) -> 0
C37: 氏名 | D37: 瀬戸 光代
C38: 計算年月 | D38: 平成27年 | E38: 8月
A39: 日 | B39: 曜日 | C39: 出社時間 | D39: 退社時間 | E39: 休憩時間 | F39: 勤務時間
A40: 1 | B40: 土 | F40: =D40-C40-E40 -> 0
A41: 2 | B41: 日 | F41: =D41-C41-E41 -> 0
...

Sheet 8月集計表
A1: 8月集計表
A2: 支払先 | C2: 内容 | G2: 支払予定 | H2: 金額 | I2: 支払方法
A3: ゴトウ石油㈱ | C3: ガソリン代 | G3: 42264 | H3: 145230 | I3: 振込み
A4: こさこ電気 | G4: 42264 | H4: 8640 | I4: 振込み
A5: ミール | C5: 弁当代 | G5: 42264 | H5: 50400 | I5: 現金
A9: 従業員 | C9: 8月分給料 | G9: 42264 | H9: 688594 | I9: 現金
A10: 利用者 | C10: 8月分工賃 | G10: 42264 | H10: 316950 | I10: 現金
G12: 合計 | H12: =SUM(H3:H11) -> 1209814
A14: 請求先 | C14: 内容 | G14: 入金予定 | H14: 金額
A15: 広島県国保連 | C15: 訓練給付金(8月請求金額） | G15: 42292 | H15: 2051600
A16: 藤鳶工業(株) | C16: パチンコ台解体費（8月分） | G16: 42262 | H16: 257040
G19: 合計 | H19: =SUM(H15:H18) -> 2308640
A21: 未払金 | C21: 内容 | H21: 金額
A22: 藤鳶工業(株) | C22: 8月分家賃 | H22: 324000
A23: 藤鳶工業(株) | C23: 8月分技術指導料 | H23: 270000
G26: 合計 | H26: =SUM(H22:H25) -> 594000
A28: 国保9月15日入金予定額 | G28: 給料支払い金種表
A29: 尾道市 | C29: 949390 | G29: 10000 | H29: 90 | I29: 900000 | K29: 1005544 | L29: 支払金
A30: 笠岡市 | G30: 5000 | H30: 12 | I30: 60000 | K30: 50400 | L30: 支払金
A31: 今治市 | C31: 238740 | G31: 1000 | H31: 40 | I31: 40000 | K31: 153870 | L31: 振込み
A32: 福山市 | C32: 383660 | G32: 500 | H32: 7 | I32: 3500 | K32: 90186 | L32: 手持ち金
A33: 三原市 | C33: 238960 | G33: 100 | H33: 18 | I33: 1800
A34: 世羅町 | C34: 106900 | G34: 50 | H34: 3 | I34: 150 | K34: =SUM(K29:K33) -> 1300000 | L34: 御調へ渡す金額
A35: (4月）福山市 | C35: 127300 | G35: 10 | H35: 8 | I35: 80
A36: (5月）今治市 | G36: 5 | H36: 1 | I36: 5
A37: (5月）福山市 | G37: 1 | H37: 9 | I37: 9
A38: 合計 | C38: =SUM(C29:F37) -> 2044950 | G38: 合計 | H38: =SUM(H29:H37) -> 188 | I38: =SUM(I29:I37) -> 1005544

Sheet Sheet2
