Workbook

Sheet 3月分
A1: 平成 27年 3月度 | Q1: 出 勤 簿
B3: 日 | C3: 1 | D3: 2 | E3: 3 | F3: 4 | G3: 5 | H3: 6 | I3: 7 | J3: 8 | K3: 9 | L3: 10 | M3: 11 | N3: 12 | O3: 13 | P3: 14 | Q3: 15 | R3: 16 | S3: 17 | T3: 18 | U3: 19 | V3: 20 | W3: 21 | X3: 22 | Y3: 23 | Z3: 24 | AA3: 25 | AB3: 26 | AC3: 27 | AD3: 28 | AE3: 29 | AF3: 30 | AG3: 31 | AH3: 出勤日数 | AI3: 労働時間 | AJ3: 休日出勤日数 | AK3: 欠勤日数 | AL3: 遅刻早引時間 | AM3: 時間外労働
B4: 氏 名 曜 | C4: 日 | D4: 月 | E4: 火 | F4: 水 | G4: 木 | H4: 金 | I4: 土 | J4: 日 | K4: 月 | L4: 火 | M4: 水 | N4: 木 | O4: 金 | P4: 土 | Q4: 日 | R4: 月 | S4: 火 | T4: 水 | U4: 木 | V4: 金 | W4: 土 | X4: 日 | Y4: 月 | Z4: 火 | AA4: 水 | AB4: 木 | AC4: 金 | AD4: 土 | AE4: 日 | AF4: 月 | AG4: 火 | AM4: 早出残業 | AN4: 深夜 | AO4: 休日
A5: 1 | B5: 岡崎 峻喬 | C5: 休 | D5: 出 | E5: 出 | F5: 出 | G5: 出 | H5: 出 | I5: 休 | J5: 休 | K5: 出 | L5: 出 | M5: 出 | N5: 出 | O5: 出 | P5: 休 | Q5: 休 | R5: 出 | S5: 出 | T5: 出 | U5: 出 | V5: 出 | W5: 休 | X5: 休 | Y5: 出 | Z5: 出 | AA5: 出 | AB5: 出 | AC5: 出 | AD5: 休 | AE5: 休 | AF5: 出 | AG5: 出 | AH5: 22
A6: 2
A7: 3 | B7: 山内 雄司 | C7: 休 | D7: 出 | E7: 出 | F7: 出 | G7: 出 | H7: 出 | I7: 休 | J7: 休 | K7: 出 | L7: 出 | M7: 出 | N7: 出 | O7: 出 | P7: 出 | Q7: 休 | R7: 出 | S7: 出 | T7: 出 | U7: 出 | V7: 出 | W7: 出 | X7: 休 | Y7: 出 | Z7: 出 | AA7: 休 | AB7: 出 | AC7: 休 | AD7: 休 | AE7: 休 | AF7: 出 | AG7: 出 | AH7: 22
A8: 4
A9: 5 | B9: 大元 照美 | C9: 休 | D9: 出 | E9: 出 | F9: 出 | G9: 出 | H9: 出 | I9: 休 | J9: 休 | K9: 出 | L9: 出 | M9: 出 | N9: 4Ｈ | O9: 出 | P9: 4Ｈ | Q9: 休 | R9: 出 | S9: 出 | T9: 出 | U9: 出 | V9: 出 | W9: 休 | X9: 休 | Y9: 出 | Z9: 出 | AA9: 出 | AB9: 出 | AC9: 出 | AD9: 休 | AE9: 休 | AF9: 出 | AG9: 出 | AH9: 23 | AQ9: 800
A10: 6
A11: 7 | B11: 山内 ノリ子 | C11: 休 | D11: 0.19236111 | E11: 0.19444444 | F11: 0.19236111 | G11: 0.19930556 | H11: 0.19444444 | I11: 休 | J11: 休 | K11: 0.18055556 | L11: 0.20208333 | M11: 0.19791667 | N11: 0.19027778 | O11: 0.19791667 | P11: 0.12847222 | Q11: 休 | R11: 0.19791667 | S11: 0.2 | T11: 0.073611111 | U11: 0.18819444 | V11: 0.19305556 | W11: 休 | X11: 休 | Y11: 0.18888889 | Z11: 0.19305556 | AA11: 0.19930556 | AB11: 0.15555556 | AC11: 0.18611111 | AD11: 休 | AE11: 休 | AF11: 0.19236111 | AG11: 0.18819444 | AH11: 23 | AI11: 4.2263889 | AQ11: 800
A12: 8
A13: 9 | B13: 瀬戸 光代 | AF13: 0.21805556 | AG13: 0.225 | AH13: 2 | AI13: 0.44305556 | AQ13: 800
A14: 10
A15: 11
A16: 12
A17: 13
A18: 14
A19: 15
A20: 16
A21: 17
A22: 18
A23: 19
A24: 20

Sheet Sheet2
A1: 給料支払明細書 | M1: 平成27年3月分
A3: 氏名 | C3: 岡崎 峻喬 殿 | H3: 労働日数 | K3: 労働時間 | N3: 時間外労働時間
H4: ='3月分'!AH5 -> 22
A6: 基本給 | C6: 時間外労働時間 | I6: 手当
A7: 280000 | I7: 10000
A9: 社会保険料 | C9: 厚生年金 | E9: 雇用保険料 | G9: 市民税 | I9: 所得税
A10: 14042 | C10: 24464 | E10: 1450 | I10: 4920
A12: 総支給額 | D12: 控除額 | G12: 差引支給額 | K12: 一般社団法人 チャレンジド尾道
A13: =SUM(A7:P7) -> 290000 | D13: =SUM(A10:P10) -> 44876 | G13: =A13-D13 -> 245124 | K13: 就労継続支援（Ｂ型）施設 カイト御調
A16: 給料支払明細書 | M16: 平成27年3月分
A18: 氏名 | C18: 山内 雄司 殿 | H18: 労働日数 | K18: 労働時間 | N18: 時間外労働時間
H19: ='3月分'!AH7 -> 22
A21: 基本給 | C21: 時間外労働時間 | I21: 手当
A22: 200000
A24: 社会保険料 | C24: 厚生年金 | E24: 雇用保険料 | G24: 市民税 | I24: 所得税
I25: 3140
A27: 総支給額 | D27: 控除額 | G27: 差引支給額 | K27: 一般社団法人 チャレンジド尾道
A28: =SUM(A22:P22) -> 200000 | D28: =SUM(A25:P25) -> 3140 | G28: =A28-D28 -> 196860 | K28: 就労継続支援（Ｂ型）施設 カイト御調
A31: 給料支払明細書 | M31: 平成27年3月分
A33: 氏名 | C33: 大元 照美 殿 | H33: 労働日数 | K33: 労働時間 | N33: 時間外労働時間
H34: ='3月分'!AH9 -> 23 | K34: ='3月分'!AI9 -> 0 | N34: ='3月分'!AM9 -> 0 | R34: 6400 | S34: 1000
A36: 基本給 | C36: 時間外労働時間 | I36: 手当
A37: =H34*R34 -> 147200 | C37: =K34*S34 -> 0
A39: 社会保険料 | C39: 厚生年金 | E39: 雇用保険料 | G39: 市民税 | I39: 所得税
E40: =A43*5/1000 -> 736
A42: 総支給額 | D42: 控除額 | G42: 差引支給額 | K42: 一般社団法人 チャレンジド尾道
A43: =SUM(A37:P37) -> 147200 | D43: =SUM(A40:P40) -> 736 | G43: =A43-D43 -> 146464 | K43: 就労継続支援（Ｂ型）施設 カイト御調
A46: 給料支払明細書 | M46: 平成27年3月分
A48: 氏名 | C48: 山内 ノリ子 殿 | H48: 労働日数 | K48: 労働時間 | N48: 時間外労働時間
H49: ='3月分'!AH11 -> 23 | K49: ='3月分'!AI11 -> 4.2263889 | N49: ='3月分'!AM11 -> 0 | R49: 800
A51: 基本給 | C51: 時間外労働時間 | I51: 手当
A52: 81147
A54: 社会保険料 | C54: 厚生年金 | E54: 雇用保険料 | G54: 市民税 | I54: 所得税
A57: 総支給額 | D57: 控除額 | G57: 差引支給額 | K57: 一般社団法人 チャレンジド尾道
A58: =SUM(A52:P52) -> 81147 | D58: =SUM(A55:P55) -> 0 | G58: =A58-D58 -> 81147 | K58: 就労継続支援（Ｂ型）施設 カイト御調
A61: 給料支払明細書 | M61: 平成27年3月分
A63: 氏名 | C63: 瀬戸 光代 殿 | H63: 労働日数 | K63: 労働時間 | N63: 時間外労働時間
H64: ='3月分'!AH13 -> 2 | K64: 0.44305556 | N64: ='3月分'!AM13 -> 0 | R64: 800
A66: 基本給 | C66: 時間外労働時間 | I66: 手当
A67: 8507
...
