Workbook

Sheet 3月分
A1: 平成 27年 3月度 | Q1: 出 勤 簿
B3: 日 | C3: 1 | D3: 2 | E3: 3 | F3: 4 | G3: 5 | H3: 6 | I3: 7 | J3: 8 | K3: 9 | L3: 10 | M3: 11 | N3: 12 | O3: 13 | P3: 14 | Q3: 15 | R3: 16 | S3: 17 | T3: 18 | U3: 19 | V3: 20 | W3: 21 | X3: 22 | Y3: 23 | Z3: 24 | AA3: 25 | AB3: 26 | AC3: 27 | AD3: 28 | AE3: 29 | AF3: 30 | AG3: 31 | AH3: 出勤日数 | AI3: 労働時間 | AJ3: 休日出勤日数 | AK3: 欠勤日数 | AL3: 遅刻早引時間 | AM3: 時間外労働
B4: 氏 名 曜 | C4: 日 | D4: 月 | E4: 火 | F4: 水 | G4: 木 | H4: 金 | I4: 土 | J4: 日 | K4: 月 | L4: 火 | M4: 水 | N4: 木 | O4: 金 | P4: 土 | Q4: 日 | R4: 月 | S4: 火 | T4: 水 | U4: 木 | V4: 金 | W4: 土 | X4: 日 | Y4: 月 | Z4: 火 | AA4: 水 | AB4: 木 | AC4: 金 | AD4: 土 | AE4: 日 | AF4: 月 | AG4: 火 | AM4: 早出残業 | AN4: 深夜 | AO4: 休日
A5: 1 | B5: 岡崎 峻喬 | C5: 休 | D5: 出 | E5: 出 | F5: 出 | G5: 出 | H5: 出 | I5: 休 | J5: 休 | K5: 出 | L5: 出 | M5: 出 | N5: 出 | O5: 出 | P5: 休 | Q5: 休 | R5: 出 | S5: 出 | T5: 出 | U5: 出 | V5: 出 | W5: 休 | X5: 休 | Y5: 出 | Z5: 出 | AA5: 出 | AB5: 出 | AC5: 出 | AD5: 休 | AE5: 休 | AF5: 出 | AG5: 出 | AH5: 22 | AQ5: 280000 | AR5: 10000
A6: 2 | B6: 山内 雄司 | C6: 休 | D6: 出 | E6: 出 | F6: 出 | G6: 出 | H6: 出 | I6: 休 | J6: 休 | K6: 出 | L6: 出 | M6: 出 | N6: 出 | O6: 出 | P6: 出 | Q6: 休 | R6: 出 | S6: 出 | T6: 出 | U6: 出 | V6: 出 | W6: 出 | X6: 休 | Y6: 出 | Z6: 出 | AA6: 休 | AB6: 出 | AC6: 休 | AD6: 休 | AE6: 休 | AF6: 出 | AG6: 出 | AH6: 22 | AQ6: 200000
A7: 3
A8: 4 | B8: 大元 照美 | C8: 休 | D8: 出 | E8: 出 | F8: 出 | G8: 出 | H8: 出 | I8: 休 | J8: 休 | K8: 出 | L8: 出 | M8: 出 | N8: 4Ｈ | O8: 出 | P8: 4Ｈ | Q8: 休 | R8: 出 | S8: 出 | T8: 出 | U8: 出 | V8: 出 | W8: 休 | X8: 休 | Y8: 出 | Z8: 出 | AA8: 出 | AB8: 出 | AC8: 出 | AD8: 休 | AE8: 休 | AF8: 出 | AG8: 出 | AH8: 23 | AQ8: 150000 | AR8: 10000
A9: 5 | B9: 山内ノリ子 | C9: 休 | D9: 0.19236111 | E9: 0.19444444 | F9: 0.19236111 | G9: 0.19930556 | H9: 0.19444444 | I9: 休 | J9: 休 | K9: 0.18055556 | L9: 0.20208333 | M9: 0.19791667 | N9: 0.19027778 | O9: 0.19791667 | P9: 0.12847222 | Q9: 休 | R9: 0.19791667 | S9: 0.2 | T9: 0.073611111 | U9: 0.18819444 | V9: 0.19305556 | W9: 休 | X9: 休 | Y9: 0.18888889 | Z9: 0.19305556 | AA9: 0.19930556 | AB9: 0.15555556 | AC9: 0.18611111 | AD9: 休 | AE9: 休 | AF9: 0.19236111 | AG9: 0.18819444 | AH9: 23 | AI9: 4.2263889 | AQ9: 800
A10: 6 | B10: 瀬戸 光代 | AF10: 0.21805556 | AG10: 0.225 | AH10: 2 | AI10: 0.44305556 | AQ10: 800
A11: 7
A12: 8 | B12: 山内 龍一 | C12: 休 | I12: 休 | J12: 休 | Q12: 休 | W12: 休 | X12: 休 | AD12: 休 | AE12: 休 | AH12: 21
A13: 9 | B13: 山下恵美子 | C13: 休 | I13: 休 | J13: 休 | Q13: 休 | W13: 休 | X13: 休 | AD13: 休 | AE13: 休 | AH13: 20
A14: 10 | B14: 川上 智樹 | C14: 休 | I14: 休 | J14: 休 | Q14: 休 | W14: 休 | X14: 休 | AD14: 休 | AE14: 休 | AH14: 16
A15: 11 | B15: 上松 正和 | C15: 休 | I15: 休 | J15: 休 | Q15: 休 | W15: 休 | X15: 休 | AD15: 休 | AE15: 休 | AH15: 21
A16: 12 | B16: 上松 浩二 | C16: 休 | D16: 出 | E16: 出 | F16: 出 | G16: 出 | H16: 出 | I16: 休 | J16: 休 | K16: 出 | L16: 出 | M16: 出 | N16: 出 | O16: 出 | P16: 出 | Q16: 休 | R16: 出 | S16: 出 | T16: 出 | U16: 出 | V16: 出 | W16: 休 | X16: 休 | Y16: 出 | Z16: 出 | AA16: 出 | AB16: 出 | AC16: 出 | AD16: 休 | AE16: 休 | AF16: 出 | AG16: 出 | AH16: 23
A17: 13 | B17: 若林 哲也 | C17: 休 | I17: 休 | J17: 休 | Q17: 休 | W17: 休 | X17: 休 | AD17: 休 | AE17: 休 | AH17: 16
A18: 14 | B18: 柏木 憲太 | C18: 休 | D18: 出 | E18: 出 | F18: 出 | G18: 出 | H18: 出 | I18: 休 | J18: 休 | K18: 出 | L18: 出 | M18: 出 | N18: 出 | O18: 出 | P18: 出 | Q18: 休 | R18: 出 | S18: 出 | T18: 出 | U18: 出 | V18: 出 | W18: 休 | X18: 休 | Y18: 出 | Z18: 出 | AA18: 出 | AB18: 出 | AC18: 出 | AD18: 休 | AE18: 休 | AF18: 出 | AG18: 出 | AH18: 23
A19: 15 | B19: 大元裕美子 | C19: 休 | D19: 出 | E19: 出 | F19: 出 | G19: 出 | H19: 出 | I19: 休 | J19: 休 | K19: 出 | L19: 出 | M19: 出 | N19: 出 | O19: 出 | P19: 出 | Q19: 休 | R19: 出 | S19: 出 | T19: 出 | U19: 出 | V19: 出 | W19: 休 | X19: 休 | Y19: 出 | Z19: 出 | AA19: 出 | AB19: 出 | AC19: 出 | AD19: 休 | AE19: 休 | AF19: 出 | AG19: 出 | AH19: 23
A20: 16 | B20: 倉谷 円 | C20: 休 | I20: 休 | J20: 休 | Q20: 休 | W20: 休 | X20: 休 | AD20: 休 | AE20: 休 | AH20: 13
A21: 17 | B21: 葛籠 沙葵 | C21: 休 | I21: 休 | J21: 休 | Q21: 休 | W21: 休 | X21: 休 | AD21: 休 | AE21: 休 | AH21: 13
A22: 18 | AQ22: 800
A23: 19 | B23: 吉原 祐平 | C23: 休 | I23: 休 | J23: 休 | Q23: 休 | W23: 休 | X23: 休 | AD23: 休 | AE23: 休 | AH23: 15
A24: 20 | B24: 櫻武 隆一 | C24: 休 | I24: 休 | J24: 休 | Q24: 休 | W24: 休 | X24: 休 | AD24: 休 | AE24: 休 | AH24: 13
A25: 21 | B25: 佐藤 皓喜 | C25: 休 | I25: 休 | J25: 休 | Q25: 休 | W25: 休 | X25: 休 | AD25: 休 | AE25: 休 | AH25: 10
A26: 22
A27: 23
A28: 24
A29: 25
A30: 26
A31: 27
A32: 28
A33: 29
A34: 30

Sheet 賃金集計表
A1: 賃 金 集 計 表
A2: 平成27年3月分
A4: 氏名 | B4: 労働日数 | C4: 給料体系 | D4: 労働時間数 | E4: 休日労働時間数 | F4: 早出残業時間数 | G4: 深夜労働時間数 | H4: 基本賃金 | I4: 家族手当 | J4: 住宅手当 | K4: 通勤手当 | L4: 精勤手当 | M4: 資格手当 | O4: 小計 | P4: 健康保険 | Q4: 厚生年金 | R4: 雇用保険 | S4: 所得税 | T4: 市民税 | V4: 弁当代 | W4: 小計 | X4: 差引支払金
A5: 岡崎 峻喬 | B5: ='3月分'!AH5 -> 22 | C5: 280000 | H5: 280000 | M5: 10000 | O5: =SUM(H5:N5) -> 290000 | P5: 14042 | Q5: 24464 | R5: 1450 | S5: 4920 | W5: =SUM(P5:V5) -> 44876 | X5: =O5-W5 -> 245124
A6: 山内 雄司 | B6: ='3月分'!AH6 -> 22 | C6: 200000 | H6: 200000 | O6: =SUM(H6:N6) -> 200000 | S6: 3140 | W6: =SUM(P6:V6) -> 3140 | X6: =O6-W6 -> 196860
A8: 給料手当 | H8: =SUM(H5:H7) -> 480000 | M8: =SUM(M5:M7) -> 10000 | O8: =SUM(O5:O7) -> 490000 | P8: =SUM(P5:P7) -> 14042 | Q8: =SUM(Q5:Q7) -> 24464 | R8: =SUM(R5:R7) -> 1450 | S8: =SUM(S5:S7) -> 8060 | W8: =SUM(W5:W7) -> 48016 | X8: =SUM(X5:X7) -> 441984
A10: 大元 照美 | B10: ='3月分'!AH8 -> 23 | C10: 150000 | H10: 150000 | M10: 10000 | O10: =SUM(H10:N10) -> 160000 | R10: 800 | S10: 3340 | V10: 2100 | W10: =SUM(P10:V10) -> 6240 | X10: =O10-W10 -> 153760
A11: 山内ノリ子 | B11: ='3月分'!AH9 -> 23 | C11: 800 | D11: 101;26 | H11: 81147 | O11: =SUM(H11:N11) -> 81147 | V11: 8050 | W11: =SUM(P11:V11) -> 8050 | X11: =O11-W11 -> 73097
A12: 瀬戸 光代 | B12: ='3月分'!AH10 -> 2 | C12: 800 | D12: 0.44305556 | H12: 8507 | O12: =SUM(H12:N12) -> 8507 | W12: =SUM(P12:V12) -> 0 | X12: =O12-W12 -> 8507
A14: 原 賃金 | H14: =SUM(H10:H13) -> 239654 | M14: =SUM(M10:M13) -> 10000 | O14: =SUM(O10:O13) -> 249654 | R14: =SUM(R10:R13) -> 800 | S14: =SUM(S10:S13) -> 3340 | V14: =SUM(V10:V13) -> 10150 | W14: =SUM(W10:W13) -> 14290 | X14: =SUM(X10:X13) -> 235364
A16: 山内 龍一 | B16: ='3月分'!AH12 -> 21 | C16: 1000 | H16: =B16*C16 -> 21000 | O16: =SUM(H16:N16) -> 21000 | V16: 7350 | W16: =SUM(P16:V16) -> 7350 | X16: =O16-W16 -> 13650
A17: 山下恵美子 | B17: ='3月分'!AH13 -> 20 | C17: 1000 | H17: =B17*C17 -> 20000 | O17: =SUM(H17:N17) -> 20000 | V17: 7000 | W17: =SUM(P17:V17) -> 7000 | X17: =O17-W17 -> 13000
A18: 川上 智樹 | B18: ='3月分'!AH14 -> 16 | C18: 1500 | H18: =B18*C18 -> 24000 | O18: =SUM(H18:N18) -> 24000 | W18: =SUM(P18:V18) -> 0 | X18: =O18-W18 -> 24000
A19: 上松 正和 | B19: ='3月分'!AH15 -> 21 | C19: 1500 | H19: =B19*C19 -> 31500 | O19: =SUM(H19:N19) -> 31500 | V19: 7000 | W19: =SUM(P19:V19) -> 7000 | X19: =O19-W19 -> 24500
A20: 上松 浩二 | B20: ='3月分'!AH16 -> 23 | C20: 1500 | H20: =B20*C20 -> 34500 | O20: =SUM(H20:N20) -> 34500 | V20: 7350 | W20: =SUM(P20:V20) -> 7350 | X20: =O20-W20 -> 27150
A21: 若林 哲也 | B21: ='3月分'!AH17 -> 16 | C21: 1000 | H21: =B21*C21 -> 16000 | O21: =SUM(H21:N21) -> 16000 | W21: =SUM(P21:V21) -> 0 | X21: =O21-W21 -> 16000
A22: 柏木 憲太 | B22: ='3月分'!AH18 -> 23 | C22: 1500 | H22: =B22*C22 -> 34500 | L22: 5000 | O22: =SUM(H22:N22) -> 39500 | V22: 8050 | W22: =SUM(P22:V22) -> 8050 | X22: =O22-W22 -> 31450
A23: 大元裕美子 | B23: ='3月分'!AH19 -> 23 | C23: 1000 | H23: =B23*C23 -> 23000 | O23: =SUM(H23:N23) -> 23000 | V23: 350 | W23: =SUM(P23:V23) -> 350 | X23: =O23-W23 -> 22650
A24: 倉谷 円 | B24: ='3月分'!AH20 -> 13 | C24: 1000 | H24: =B24*C24 -> 13000 | O24: =SUM(H24:N24) -> 13000 | W24: =SUM(P24:V24) -> 0 | X24: =O24-W24 -> 13000
A25: 葛籠 沙葵 | B25: ='3月分'!AH21 -> 13 | C25: 1000 | H25: =B25*C25 -> 13000 | O25: =SUM(H25:N25) -> 13000 | W25: =SUM(P25:V25) -> 0 | X25: =O25-W25 -> 13000
A27: 訓練等給付費 | H27: =SUM(H16:H26) -> 230500 | L27: =SUM(L16:L25) -> 5000 | O27: =SUM(O16:O26) -> 235500 | V27: =SUM(V16:V25) -> 37100 | W27: =SUM(W16:W26) -> 37100 | X27: =SUM(X16:X26) -> 198400
A29: 吉原 祐平 | B29: ='3月分'!AH23 -> 15 | C29: 1000 | H29: =B29*C29 -> 15000 | O29: =SUM(H29:N29) -> 15000 | W29: =SUM(P25:V25) -> 0 | X29: =O29-W29 -> 15000
A30: 櫻武 隆一 | B30: ='3月分'!AH24 -> 13 | C30: 1000 | H30: =B30*C30 -> 13000 | O30: =SUM(H30:N30) -> 13000 | W30: =SUM(P28:V28) -> 0 | X30: =O30-W30 -> 13000
A31: 佐藤 皓喜 | B31: ='3月分'!AH25 -> 10 | C31: 1000 | H31: =B31*C31 -> 10000 | O31: =SUM(H31:N31) -> 10000 | W31: =SUM(P29:V29) -> 0 | X31: =O31-W31 -> 10000
A33: 謝金 | H33: =SUM(H29:H32) -> 38000 | O33: =SUM(O29:O32) -> 38000 | W33: =SUM(W31) -> 0 | X33: =SUM(X29:X32) -> 38000
A36: 合計 | H36: =H8+H14+H27+H33 -> 988154 | I36: =I8+I14+I27+I33 -> 0 | J36: =J8+J14+J27+J33 -> 0 | K36: =K8+K14+K27+K33 -> 0 | L36: =L8+L14+L27+L33 -> 5000 | M36: =M8+M14+M27+M33 -> 20000 | N36: =N8+N14+N27+N33 -> 0 | O36: =O8+O14+O27+O33 -> 1013154 | ... X36: =X8+X14+X27+X33 -> 913748

Sheet 給料支払明細書
A1: 給料支払明細書 | M1: 平成27年3月分
A3: 氏名 | C3: =賃金集計表!A5 -> 岡崎 峻喬 | G3: 殿 | H3: 労働日数 | K3: 労働時間 | N3: 時間外労働時間
H4: =賃金集計表!B5 -> 22
A6: 基本給 | C6: 時間外労働時間 | I6: 手当
A7: =賃金集計表!H5 -> 280000 | I7: =賃金集計表!M5 -> 10000
A9: 社会保険料 | C9: 厚生年金 | E9: 雇用保険料 | G9: 市民税 | I9: 所得税 | O9: 弁当代
A10: =賃金集計表!P5 -> 14042 | C10: =賃金集計表!Q5 -> 24464 | E10: =賃金集計表!R5 -> 1450 | G10: =賃金集計表!T5 -> 0 | I10: =賃金集計表!S5 -> 4920 | O10: =賃金集計表!V5 -> 0
A12: 総支給額 | D12: 控除額 | G12: 差引支給額 | K12: 一般社団法人 チャレンジド尾道
A13: =SUM(A7:P7) -> 290000 | D13: =SUM(A10:P10) -> 44876 | G13: =A13-D13 -> 245124 | K13: 就労継続支援（Ｂ型）施設 カイト御調
A16: 給料支払明細書 | M16: 平成27年3月分
A18: 氏名 | C18: =賃金集計表!A6 -> 山内 雄司 | G18: 殿 | H18: 労働日数 | K18: 労働時間 | N18: 時間外労働時間
H19: =賃金集計表!B6 -> 22
A21: 基本給 | C21: 時間外労働時間 | I21: 手当
A22: =賃金集計表!H6 -> 200000
A24: 社会保険料 | C24: 厚生年金 | E24: 雇用保険料 | G24: 市民税 | I24: 所得税 | O24: 弁当代
I25: =賃金集計表!S6 -> 3140 | O25: =賃金集計表!V6 -> 0
A27: 総支給額 | D27: 控除額 | G27: 差引支給額 | K27: 一般社団法人 チャレンジド尾道
A28: =SUM(A22:P22) -> 200000 | D28: =SUM(A25:P25) -> 3140 | G28: =A28-D28 -> 196860 | K28: 就労継続支援（Ｂ型）施設 カイト御調
A31: 給料支払明細書 | M31: 平成27年3月分
A33: 氏名 | G33: 殿 | H33: 労働日数 | K33: 労働時間 | N33: 時間外労働時間
A36: 基本給 | C36: 時間外労働時間 | I36: 手当
A39: 社会保険料 | C39: 厚生年金 | E39: 雇用保険料 | G39: 市民税 | I39: 所得税 | O39: 弁当代
A42: 総支給額 | D42: 控除額 | G42: 差引支給額 | K42: 一般社団法人 チャレンジド尾道
A43: =SUM(A37:P37) -> 0 | D43: =SUM(A40:P40) -> 0 | G43: =A43-D43 -> 0 | K43: 就労継続支援（Ｂ型）施設 カイト御調
A46: 給料支払明細書 | M46: 平成27年3月分
A48: 氏名 | C48: =賃金集計表!A10 -> 大元 照美 | G48: 殿 | H48: 労働日数 | K48: 労働時間 | N48: 時間外労働時間
H49: =賃金集計表!B10 -> 23 | N49: ='3月分'!AM11 -> 0
A51: 基本給 | C51: 時間外労働時間 | I51: 手当
A52: =賃金集計表!H10 -> 150000 | I52: =賃金集計表!M10 -> 10000
A54: 社会保険料 | C54: 厚生年金 | E54: 雇用保険料 | G54: 市民税 | I54: 所得税 | O54: 弁当代
A55: =賃金集計表!P10 -> 0 | C55: =賃金集計表!Q10 -> 0 | E55: =賃金集計表!R10 -> 800 | G55: =賃金集計表!T10 -> 0 | I55: =賃金集計表!S10 -> 3340 | O55: =賃金集計表!V10 -> 2100
A57: 総支給額 | D57: 控除額 | G57: 差引支給額 | K57: 一般社団法人 チャレンジド尾道
A58: =SUM(A52:P52) -> 160000 | D58: =SUM(A55:P55) -> 6240 | G58: =A58-D58 -> 153760 | K58: 就労継続支援（Ｂ型）施設 カイト御調
A61: 給料支払明細書 | M61: 平成27年3月分
A63: 氏名 | C63: =賃金集計表!A11 -> 山内ノリ子 | G63: 殿 | H63: 労働日数 | K63: 労働時間 | N63: 時間外労働時間
H64: =賃金集計表!B11 -> 23 | K64: =賃金集計表!D11 -> 101;26 | N64: ='3月分'!AM22 -> 0 | R64: 4.2263889 | S64: 800 | T64: =R64*S64 -> 3381.1111
A66: 基本給 | C66: 時間外労働時間 | I66: 手当
A67: 81147
A69: 社会保険料 | C69: 厚生年金 | E69: 雇用保険料 | G69: 市民税 | I69: 所得税 | O69: 弁当代
O70: =賃金集計表!V11 -> 8050
...

Sheet 給料支払明細書（2）
A1: 給料支払明細書 | J1: 給料支払明細書 | S1: 給料支払明細書 | AB1: 給料支払明細書
C3: 平成 | D3: 27 | E3: 年 | F3: 3 | G3: 月分 | L3: 平成 | M3: 27 | N3: 年 | O3: 3 | P3: 月分 | U3: 平成 | V3: 27 | W3: 年 | X3: 3 | Y3: 月分 | AD3: 平成 | AE3: 27 | AF3: 年 | AG3: 3 | AH3: 月分
A4: 所属 | B4: ： | C4: カイト御調 | J4: 所属 | K4: ： | L4: カイト御調 | S4: 所属 | T4: ： | U4: カイト御調 | AB4: 所属 | AC4: ： | AD4: カイト御調
A5: ='3月分'!B5 -> 岡崎 峻喬 | J5: ='3月分'!B7 -> 0 | S5: ='3月分'!B9 -> 山内ノリ子 | AB5: ='3月分'!B11 -> 0
H6: 殿 | Q6: 殿 | Z6: 殿 | AI6: 殿
A8: 賃金計算期間 | E8: 3月1日～3月31日 | J8: 賃金計算期間 | N8: 3月1日～3月31日 | S8: 賃金計算期間 | W8: 3月1日～3月31日 | AB8: 賃金計算期間 | AF8: 3月1日～3月31日
A9: 労働日数 | G9: ='3月分'!AH5 -> 22 | H9: 日 | J9: 労働日数 | P9: ='3月分'!AH7 -> 0 | Q9: 日 | S9: 労働日数 | Y9: ='3月分'!AH9 -> 23 | Z9: 日 | AB9: 労働日数 | AH9: ='3月分'!AH11 -> 0 | AI9: 日
A10: 労働時間数 | F10: 時間 | H10: 分 | J10: 労働時間数 | O10: 時間 | Q10: 分 | S10: 労働時間数 | X10: 時間 | Z10: 分 | AB10: 労働時間数 | AF10: 101 | AG10: 時間 | AH10: 23 | AI10: 分
A11: 休日労働時間数 | F11: 時間 | H11: 分 | J11: 休日労働時間数 | O11: 時間 | Q11: 分 | S11: 休日労働時間数 | X11: 時間 | Z11: 分 | AB11: 休日労働時間数 | AG11: 時間 | AI11: 分
A12: 早出残業時間数 | F12: 時間 | H12: 分 | J12: 早出残業時間数 | O12: 時間 | Q12: 分 | S12: 早出残業時間数 | X12: 時間 | Z12: 分 | AB12: 早出残業時間数 | AG12: 時間 | AI12: 分
A13: 深夜労働時間数 | F13: 時間 | H13: 分 | J13: 深夜労働時間数 | O13: 時間 | Q13: 分 | S13: 深夜労働時間数 | X13: 時間 | Z13: 分 | AB13: 深夜労働時間数 | AG13: 時間 | AI13: 分
A14: 基本賃金 | E14: =賃金集計表!H5 -> 280000 | J14: 基本賃金 | N14: =賃金集計表!H6 -> 200000 | S14: 基本賃金 | W14: =賃金集計表!H10 -> 150000 | AB14: 基本賃金 | AF14: 81107
A15: 所定時間外割増賃金 | J15: 所定時間外割増賃金 | S15: 所定時間外割増賃金 | AB15: 所定時間外割増賃金
A16: 手当 | B16: 家族手当 | J16: 手当 | K16: 家族手当 | S16: 手当 | T16: 家族手当 | AB16: 手当 | AC16: 家族手当
B17: 住宅手当 | K17: 住宅手当 | T17: 住宅手当 | AC17: 住宅手当
B18: 通勤手当 | K18: 通勤手当 | T18: 通勤手当 | AC18: 通勤手当
B19: 精勤手当 | K19: 精勤手当 | T19: 精勤手当 | AC19: 精勤手当
B20: 資格手当 | E20: =賃金集計表!M5 -> 10000 | K20: 資格手当 | T20: 資格手当 | W20: =賃金集計表!M10 -> 10000 | AC20: 資格手当
A22: 小計 | E22: =賃金集計表!O5 -> 290000 | J22: 小計 | N22: =賃金集計表!O6 -> 200000 | S22: 小計 | W22: =賃金集計表!O10 -> 160000 | AB22: 小計 | AF22: =賃金集計表!O11 -> 81147
A23: 控除額 | B23: 健康保険 | E23: =賃金集計表!P5 -> 14042 | J23: 控除額 | K23: 健康保険 | S23: 控除額 | T23: 健康保険 | AB23: 控除額 | AC23: 健康保険
B24: 厚生年金 | E24: =賃金集計表!Q5 -> 24464 | K24: 厚生年金 | T24: 厚生年金 | AC24: 厚生年金
B25: 雇用保険 | E25: =賃金集計表!R5 -> 1450 | K25: 雇用保険 | T25: 雇用保険 | AC25: 雇用保険
B26: 所得税 | E26: =賃金集計表!S5 -> 4920 | K26: 所得税 | N26: =賃金集計表!S6 -> 3140 | T26: 所得税 | W26: =賃金集計表!S10 -> 3340 | AC26: 所得税
B27: 市民税 | E27: =賃金集計表!T5 -> 0 | K27: 市民税 | T27: 市民税 | AC27: 市民税
T29: 弁当代 | W29: =賃金集計表!V10 -> 2100 | AC29: 弁当代 | AF29: =賃金集計表!V11 -> 8050
B30: 小計 | E30: =賃金集計表!W5 -> 44876 | K30: 小計 | N30: =賃金集計表!W6 -> 3140 | T30: 小計 | W30: =賃金集計表!W10 -> 6240 | AC30: 小計 | AF30: =賃金集計表!W11 -> 8050
A31: 差引支払額 | E31: =賃金集計表!X5 -> 245124 | J31: 差引支払額 | N31: =賃金集計表!X6 -> 196860 | S31: 差引支払額 | W31: =賃金集計表!X10 -> 153760 | AB31: 差引支払額 | AF31: =賃金集計表!X11 -> 73097
A32: （事業所名） | G32: 印 | J32: （事業所名） | P32: 印 | S32: （事業所名） | Y32: 印 | AB32: （事業所名） | AH32: 印
A33: 一般社団法人 チャレンジド尾道 | J33: 一般社団法人 チャレンジド尾道 | S33: 一般社団法人 チャレンジド尾道 | AB33: 一般社団法人 チャレンジド尾道
A34: カイト 御調 | J34: カイト 御調 | S34: カイト 御調 | AB34: カイト 御調
A35: 給料支払明細書 | J35: 給料支払明細書 | S35: 給料支払明細書 | AB35: 給料支払明細書
C37: 平成 | D37: 27 | E37: 年 | F37: 3 | G37: 月分 | L37: 平成 | N37: 年 | P37: 月分 | U37: 平成 | W37: 年 | Y37: 月分 | AD37: 平成 | AF37: 年 | AH37: 月分
A38: 所属 | B38: ： | C38: カイト御調 | J38: 所属 | K38: ： | L38: カイト御調 | S38: 所属 | T38: ： | U38: カイト御調 | AB38: 所属 | AC38: ： | AD38: カイト御調
A39: ='3月分'!B22 -> 0
H40: 殿 | Q40: 殿 | Z40: 殿 | AI40: 殿
A42: 賃金計算期間 | E42: 3月1日～3月31日 | J42: 賃金計算期間 | S42: 賃金計算期間 | AB42: 賃金計算期間
A43: 労働日数 | G43: ='3月分'!AH22 -> 0 | H43: 日 | J43: 労働日数 | Q43: 日 | S43: 労働日数 | Z43: 日 | AB43: 労働日数 | AI43: 日
A44: 労働時間数 | E44: 10 | F44: 時間 | G44: 38 | H44: 分 | J44: 労働時間数 | O44: 時間 | Q44: 分 | S44: 労働時間数 | X44: 時間 | Z44: 分 | AB44: 労働時間数 | AG44: 時間 | AI44: 分
A45: 休日労働時間数 | F45: 時間 | H45: 分 | J45: 休日労働時間数 | O45: 時間 | Q45: 分 | S45: 休日労働時間数 | X45: 時間 | Z45: 分 | AB45: 休日労働時間数 | AG45: 時間 | AI45: 分
A46: 早出残業時間数 | F46: 時間 | H46: 分 | J46: 早出残業時間数 | O46: 時間 | Q46: 分 | S46: 早出残業時間数 | X46: 時間 | Z46: 分 | AB46: 早出残業時間数 | AG46: 時間 | AI46: 分
...

Sheet Sheet1
C1: 氏名
C2: 計算年月 | D2: 平成27年 | E2: 3月
A3: 日 | B3: 曜日 | C3: 出社時間 | D3: 退社時間 | E3: 休憩時間 | F3: 勤務時間
A4: 1 | B4: 日
A5: 2 | B5: 月 | C5: 0.39583333 | D5: 0.62986111 | E5: 0.041666667 | F5: =D5-C5-E5 -> 0.19236111
A6: 3 | B6: 火 | C6: 0.39236111 | D6: 0.62847222 | E6: 0.041666667 | F6: =D6-C6-E6 -> 0.19444444
A7: 4 | B7: 水 | C7: 0.39305556 | D7: 0.62708333 | E7: 0.041666667 | F7: =D7-C7-E7 -> 0.19236111
A8: 5 | B8: 木 | C8: 0.38680556 | D8: 0.62777778 | E8: 0.041666667 | F8: =D8-C8-E8 -> 0.19930556
A9: 6 | B9: 金 | C9: 0.38888889 | D9: 0.625 | E9: 0.041666667 | F9: =D9-C9-E9 -> 0.19444444
A10: 7 | B10: 土
A11: 8 | B11: 日
A12: 9 | B12: 月 | C12: 0.40555556 | D12: 0.62777778 | E12: 0.041666667 | F12: =D12-C12-E12 -> 0.18055556
A13: 10 | B13: 火 | C13: 0.44305556 | D13: 0.68680556 | E13: 0.041666667 | F13: =D13-C13-E13 -> 0.20208333
A14: 11 | B14: 水 | C14: 0.38819444 | D14: 0.62777778 | E14: 0.041666667 | F14: =D14-C14-E14 -> 0.19791667
A15: 12 | B15: 木 | C15: 0.39513889 | D15: 0.62708333 | E15: 0.041666667 | F15: =D15-C15-E15 -> 0.19027778
A16: 13 | B16: 金 | C16: 0.3875 | D16: 0.62708333 | E16: 0.041666667 | F16: =D16-C16-E16 -> 0.19791667
A17: 14 | B17: 土 | C17: 0.39791667 | D17: 0.52638889 | F17: =D17-C17-E17 -> 0.12847222
A18: 15 | B18: 日
A19: 16 | B19: 月 | C19: 0.38819444 | D19: 0.62777778 | E19: 0.041666667 | F19: =D19-C19-E19 -> 0.19791667
A20: 17 | B20: 火 | C20: 0.38611111 | D20: 0.62777778 | E20: 0.041666667 | F20: =D20-C20-E20 -> 0.2
A21: 18 | B21: 水 | C21: 0.51388889 | D21: 0.62916667 | E21: 0.041666667 | F21: =D21-C21-E21 -> 0.073611111
A22: 19 | B22: 木 | C22: 0.39583333 | D22: 0.62569444 | E22: 0.041666667 | F22: =D22-C22-E22 -> 0.18819444
A23: 20 | B23: 金 | C23: 0.39236111 | D23: 0.62708333 | E23: 0.041666667 | F23: =D23-C23-E23 -> 0.19305556
A24: 21 | B24: 土
A25: 22 | B25: 日
A26: 23 | B26: 月 | C26: 0.39583333 | D26: 0.62638889 | E26: 0.041666667 | F26: =D26-C26-E26 -> 0.18888889
A27: 24 | B27: 火 | C27: 0.39236111 | D27: 0.62708333 | E27: 0.041666667 | F27: =D27-C27-E27 -> 0.19305556
A28: 25 | B28: 水 | C28: 0.38680556 | D28: 0.62777778 | E28: 0.041666667 | F28: =D28-C28-E28 -> 0.19930556
A29: 26 | B29: 木 | C29: 0.39444444 | D29: 0.59236111 | E29: 0.041666667 | F29: =D29-C29-E29 -> 0.15625
A30: 27 | B30: 金 | C30: 0.39930556 | D30: 0.62708333 | E30: 0.041666667 | F30: =D30-C30-E30 -> 0.18611111
A31: 28 | B31: 土
A32: 29 | B32: 日
A33: 30 | B33: 月 | C33: 0.39166667 | D33: 0.62569444 | E33: 0.041666667 | F33: =D33-C33-E33 -> 0.19236111
A34: 31 | B34: 火 | C34: 0.39652778 | D34: 0.62638889 | E34: 0.041666667 | F34: =D34-C34-E34 -> 0.18819444
E35: 合計 | F35: =SUM(F4:F34) -> 4.2270833
