Workbook
Name ___________kk29: #REF!
Name ___________kk29: #REF!
Name ___________kk29: #REF!
Name ___________kk29: #REF!
Name ___________kk29: #REF!
Name ___________kk29: #REF!
Name ___________kk29: #REF!
Name ___________kk29: #REF!
Name __________kk06: #REF!
Name __________kk06: #REF!
Name __________kk06: #REF!
Name __________kk06: #REF!
Name __________kk06: #REF!
Name __________kk06: #REF!
Name __________kk06: #REF!
Name __________kk06: #REF!
Name __________kk29: #REF!
Name __________kk29: #REF!
Name __________kk29: #REF!
Name __________kk29: #REF!
Name __________kk29: #REF!
Name __________kk29: #REF!
Name __________kk29: #REF!
Name __________kk29: #REF!
Name _________kk06: #REF!
Name _________kk06: #REF!
Name _________kk06: #REF!
Name _________kk06: #REF!
Name _________kk06: #REF!
Name _________kk06: #REF!
Name _________kk06: #REF!
Name _________kk06: #REF!
Name _________kk29: #REF!
Name _________kk29: #REF!
Name _________kk29: #REF!
Name _________kk29: #REF!
Name _________kk29: #REF!
Name _________kk29: #REF!
Name _________kk29: #REF!
Name _________kk29: #REF!
Name ________kk06: #REF!
Name ________kk06: #REF!
Name ________kk06: #REF!
Name ________kk06: #REF!
Name ________kk06: #REF!
Name ________kk06: #REF!
Name ________kk06: #REF!
Name ________kk06: #REF!
Name ________kk29: #REF!
Name ________kk29: #REF!
Name ________kk29: #REF!
Name ________kk29: #REF!
Name ________kk29: #REF!
Name ________kk29: #REF!
Name ________kk29: #REF!
Name ________kk29: #REF!
Name _______kk06: #REF!
Name _______kk06: #REF!
Name _______kk06: #REF!
Name _______kk06: #REF!

Sheet 別紙１（他の法律において既に指定を受けている事業等）
A1: （別紙１）
G3: 他の法律において既に指定を受けている事業等について
A5: 法律の名称 | G5: サービスの種類 | K5: 事業所・施設名称 | O5: 指定年月日 | T5: 指定事業所番号
A7: 障害者総合支援法 | G7: 多機能型（就労継続支援B型・就労移行支援） | K7: シェル | O7: 42917 | X7: 3 | Y7: 3 | Z7: 1 | AA7: 0 | AB7: 5 | AC7: 0 | AD7: 0 | AE7: 3 | AF7: 9 | AG7: 6

Sheet 別紙１【記載例】
A9: （別紙１）
G11: 他の法律において既に指定を受けている事業等について
A13: 法律の名称 | G13: サービスの種類 | K13: 事業所・施設名称 | O13: 指定年月日 | T13: 指定事業所番号
A15: 介護保険法 | G15: 訪問介護 | K15: ○△ホームヘルプ | O15: 38899 | T15: ＊ | U15: ＊ | V15: ＊ | W15: ＊ | X15: ＊ | Y15: ＊ | Z15: ＊ | AA15: ＊ | AB15: ＊ | AC15: ＊

Sheet 別紙2-2勤務体制一覧表（訪問・相談系以外）
AU2: （訪問系サービスを除くすべてのサービス） | BP2: ▼選択してください。
B3: 別紙２－２ | BP3: 療養介護
B4: 従業者の勤務の体制及び勤務形態一覧表 | BP4: 生活介護
BP5: 短期入所
B6: 事業所名 | K6: ='参考様式７（組織体制図）'!D5 -> コーリングサポ笠岡 | BP6: 共同生活援助
B7: サービス種類 | K7: 就労移行支援（一般型） | BP7: 施設入所支援
BP8: 自立訓練（生活訓練）宿泊型
B9: 職種 | H9: 勤務 形態 | K9: 氏名 | R9: 第１週 | Y9: 第２週 | AF9: 第３週 | AM9: 第４週 | AT9: 4週の合計 | AW9: 週平均の勤務時間 | AZ9: 常勤換算後の人数 | BA9: 加算等に係る資格 （実務経験） ・ 兼務先 | BP9: 自立訓練（生活訓練）
P10: 日付 | R10: 1 | S10: 2 | T10: 3 | U10: 4 | V10: 5 | W10: 6 | X10: 7 | Y10: 8 | Z10: 9 | AA10: 10 | AB10: 11 | AC10: 12 | AD10: 13 | AE10: 14 | AF10: 15 | AG10: 16 | AH10: 17 | AI10: 18 | AJ10: 19 | AK10: 20 | AL10: 21 | AM10: 22 | AN10: 23 | AO10: 24 | AP10: 25 | AQ10: 26 | AR10: 27 | AS10: 28 | BP10: 自立訓練（機能訓練）
P11: 曜日 | R11: 木 | S11: 金 | T11: 土 | U11: 日 | V11: 月 | W11: 火 | X11: 水 | Y11: 木 | Z11: 金 | AA11: 土 | AB11: 日 | AC11: 月 | AD11: 火 | AE11: 水 | AF11: 木 | AG11: 金 | AH11: 土 | AI11: 日 | AJ11: 月 | AK11: 火 | AL11: 水 | AM11: 木 | AN11: 金 | AO11: 土 | AP11: 日 | AQ11: 月 | AR11: 火 | AS11: 水 | BP11: 就労移行支援（一般型）
P12: 開所日 | R12: ● | S12: ● | V12: ● | W12: ● | X12: ● | Y12: ● | Z12: ● | AC12: ● | AD12: ● | AE12: ● | AF12: ● | AG12: ● | AJ12: ● | AK12: ● | AL12: ● | AM12: ● | AN12: ● | AQ12: ● | AR12: ● | AS12: ● | BP12: 就労移行支援（養成施設）
B13: 管理者 | H13: 常勤・兼務 | K13: ='参考様式４（管理者等経歴書）'!C14 -> 貝畑明典 | R13: 7 | S13: 7 | V13: 7 | W13: 7 | X13: 7 | Y13: 7 | Z13: 7 | AC13: 7 | AD13: 7 | AE13: 7 | AF13: 7 | AG13: 7 | AJ13: 7 | AK13: 7 | AL13: 7 | AM13: 7 | AN13: 7 | AQ13: 7 | AR13: 7 | AS13: 7 | AT13: =SUM(R13:AS13) -> 140 | AW13: =AT13/4 -> 35 | AZ13: =ROUNDDOWN(AW13/AT33,1) -> 1 | BP13: 就労継続支援Ａ型
B14: サービス管理責任者 | H14: 常勤・専従 | K14: ='参考様式４（管理者等経歴書） (2)'!C14 -> 田中 早苗 | R14: 7 | S14: 7 | V14: 7 | W14: 7 | X14: 7 | Y14: 7 | Z14: 7 | AC14: 7 | AD14: 7 | AE14: 7 | AF14: 7 | AG14: 7 | AJ14: 7 | AK14: 7 | AL14: 7 | AM14: 7 | AN14: 7 | AQ14: 7 | AR14: 7 | AS14: 7 | AT14: =SUM(R14:AS14) -> 140 | AW14: =AT14/4 -> 35 | AZ14: =ROUNDDOWN(AW14/AT33,1) -> 1 | BP14: 就労継続支援Ｂ型
B15: 職業指導員 | H15: 常勤・専従 | K15: 小宮 由紀博 | R15: 7 | S15: 7 | V15: 7 | W15: 7 | X15: 7 | Y15: 7 | Z15: 7 | AC15: 7 | AD15: 7 | AE15: 7 | AF15: 7 | AG15: 7 | AJ15: 7 | AK15: 7 | AL15: 7 | AM15: 7 | AN15: 7 | AQ15: 7 | AR15: 7 | AS15: 7 | AT15: =SUM(R15:AS15) -> 140 | AW15: =AT15/4 -> 35 | AZ15: =ROUNDDOWN(AW15/AT33,1) -> 1 | BP15: 重度障害者等包括支援
B16: 職業指導員 | H16: 非常勤・専従 | K16: 渡慶次 幸平 | R16: 4 | S16: 4 | V16: 4 | W16: 4 | X16: 4 | Y16: 4 | Z16: 4 | AC16: 4 | AD16: 4 | AE16: 4 | AF16: 4 | AG16: 4 | AJ16: 4 | AK16: 4 | AL16: 4 | AM16: 4 | AN16: 4 | AQ16: 4 | AR16: 4 | AS16: 4 | AT16: =SUM(R16:AS16) -> 80 | AW16: =AT16/4 -> 20 | AZ16: =ROUNDDOWN(AW16/AT33,1) -> 0.6 | BP16: 自立生活援助
B17: 職業指導員 | H17: 非常勤・専従 | K17: 黒田 哲広 | R17: 3 | S17: 3 | V17: 3 | W17: 3 | X17: 3 | Y17: 3 | Z17: 3 | AC17: 3 | AD17: 3 | AE17: 3 | AF17: 3 | AG17: 3 | AJ17: 3 | AK17: 3 | AL17: 3 | AM17: 3 | AN17: 3 | AQ17: 3 | AR17: 3 | AS17: 3 | AT17: =SUM(R17:AS17) -> 60 | AW17: =AT17/4 -> 15 | AZ17: =ROUNDDOWN(AW17/AT33,1) -> 0.4 | BP17: 就労定着支援
B18: 生活支援員 | H18: 非常勤・専従 | K18: 福田 美み子 | R18: 4 | S18: 4 | V18: 4 | W18: 4 | X18: 4 | Y18: 4 | Z18: 4 | AC18: 4 | AD18: 4 | AE18: 4 | AF18: 4 | AG18: 4 | AJ18: 4 | AK18: 4 | AL18: 4 | AM18: 4 | AN18: 4 | AQ18: 4 | AR18: 4 | AS18: 4 | AT18: =SUM(R18:AS18) -> 80 | AW18: =AT18/4 -> 20 | AZ18: =ROUNDDOWN(AW18/AT33,1) -> 0.6
B19: 生活支援員 | H19: 非常勤・専従 | K19: 川上 魁利 | R19: 7 | S19: 7 | V19: 7 | W19: 7 | X19: 7 | Y19: 7 | Z19: 7 | AC19: 7 | AD19: 7 | AE19: 7 | AF19: 7 | AG19: 7 | AJ19: 7 | AK19: 7 | AL19: 7 | AM19: 7 | AN19: 7 | AQ19: 7 | AR19: 7 | AS19: 7 | AT19: =SUM(R19:AS19) -> 140 | AW19: =AT19/4 -> 35 | AZ19: =ROUNDDOWN(AW19/AT33,1) -> 1
AT20: =SUM(R20:AS20) -> 0 | AW20: =AT20/4 -> 0 | AZ20: =ROUNDDOWN(AW20/AT33,1) -> 0
AT21: =SUM(R21:AS21) -> 0 | AW21: =AT21/4 -> 0 | AZ21: =ROUNDDOWN(AW21/AT33,1) -> 0
AT22: =SUM(R22:AS22) -> 0 | AW22: =AT22/4 -> 0 | AZ22: =ROUNDDOWN(AW22/AT33,1) -> 0
AT23: =SUM(R23:AS23) -> 0 | AW23: =AT23/4 -> 0 | AZ23: =ROUNDDOWN(AW23/AT33,1) -> 0
AT24: =SUM(R24:AS24) -> 0 | AW24: =AT24/4 -> 0 | AZ24: =ROUNDDOWN(AW24/AT33,1) -> 0
AT25: =SUM(R25:AS25) -> 0 | AW25: =AT25/4 -> 0 | AZ25: =ROUNDDOWN(AW25/AT33,1) -> 0
AT26: =SUM(R26:AS26) -> 0 | AW26: =AT26/4 -> 0 | AZ26: =ROUNDDOWN(AW26/AT33,1) -> 0
AT27: =SUM(R27:AS27) -> 0 | AW27: =AT27/4 -> 0 | AZ27: =ROUNDDOWN(AW27/AT33,1) -> 0
AT28: =SUM(R28:AS28) -> 0 | AW28: =AT28/4 -> 0 | AZ28: =ROUNDDOWN(AW28/AT33,1) -> 0
B29: 直接処遇職員 合計 | AT29: =SUM(AT15:AV28) -> 500 | AW29: =AT29/4 -> 125 | AZ29: =IF(AND(AW29=0,AT33=0),0,ROUNDDOWN(AW29/AT33,1)) -> 3.8
B30: 就労支援員 | H30: 常勤・兼務 | K30: =K13 -> 貝畑明典 | R30: 7 | S30: 7 | V30: 7 | W30: 7 | X30: 7 | Y30: 7 | Z30: 7 | AC30: 7 | AD30: 7 | AE30: 7 | AF30: 7 | AG30: 7 | AJ30: 7 | AK30: 7 | AL30: 7 | AM30: 7 | AN30: 7 | AQ30: 7 | AR30: 7 | AS30: 7 | AT30: =SUM(R30:AS30) -> 140 | AW30: =AT30/4 -> 35 | AZ30: =ROUNDDOWN(AW30/AT33,1) -> 1
B31: 就労支援員 | H31: 非常勤・専従 | K31: 山内雄司 | R31: 5 | S31: 5 | Y31: 5 | Z31: 5 | AF31: 5 | AG31: 5 | AM31: 5 | AN31: 5 | AT31: =SUM(R31:AS31) -> 40 | AW31: =AT31/4 -> 10 | AZ31: =ROUNDDOWN(AW31/AT34,1) -> #DIV/0!
AT32: =SUM(R32:AS32) -> 0 | AW32: =AT32/4 -> 0 | AZ32: =ROUNDDOWN(AW32/AT35,1) -> #DIV/0!
B33: 当該事業所・施設において常勤職員が1週間に勤務すべき時間数 | AT33: =6.5*5 -> 32.5
BF47: 常勤・専従
BF48: 常勤・兼務
BF49: 非常勤・専従
BF50: 非常勤・兼務

Sheet 別紙２-２　勤務形態一覧表（訪問・相談以外）
BA1: （訪問系サービス・一般相談支援を除くすべてのサービス） | BP1: ▼選択してください。
B2: 別紙２-２ | BP2: 療養介護
B3: 従業者の勤務の体制及び勤務形態一覧表 | BP3: 生活介護
BP4: 短期入所
B5: 事業所名 | BP5: 共同生活援助（介護サービス包括型）
B6: サービス種類 | K6: 就労移行支援（一般型） | BP6: 共同生活援助（外部サービス利用型）
BP7: 施設入所支援
B8: 職種 | H8: 勤務 形態 | K8: 氏名 | R8: 第１週 | Y8: 第２週 | AF8: 第３週 | AM8: 第４週 | AT8: 4週の合計 | AW8: 週平均の勤務時間 | AZ8: 常勤換算後の人数 | BA8: 加算等に係る資格 ・ 兼務先 | BP8: 自立訓練（生活訓練）宿泊型
P9: 日付 | R9: 1 | S9: 2 | T9: 3 | U9: 4 | V9: 5 | W9: 6 | X9: 7 | Y9: 8 | Z9: 9 | AA9: 10 | AB9: 11 | AC9: 12 | AD9: 13 | AE9: 14 | AF9: 15 | AG9: 16 | AH9: 17 | AI9: 18 | AJ9: 19 | AK9: 20 | AL9: 21 | AM9: 22 | AN9: 23 | AO9: 24 | AP9: 25 | AQ9: 26 | AR9: 27 | AS9: 28 | BP9: 自立訓練（生活訓練）
P10: 曜日 | R10: 月 | S10: 火 | T10: 水 | U10: 木 | V10: 金 | W10: 土 | X10: 日 | Y10: 月 | Z10: 火 | AA10: 水 | AB10: 木 | AC10: 金 | AD10: 土 | AE10: 日 | AF10: 月 | AG10: 火 | AH10: 水 | AI10: 木 | AJ10: 金 | AK10: 土 | AL10: 日 | AM10: 月 | AN10: 火 | AO10: 水 | AP10: 木 | AQ10: 金 | AR10: 土 | AS10: 日 | BP10: 自立訓練（機能訓練）
P11: 開所日 | BP11: 就労移行支援（一般型）
B12: 管理者 | H12: ='別紙2-2勤務体制一覧表（訪問・相談系以外）'!H13 -> 常勤・兼務 | AT12: =SUM(R12:AS12) -> 0 | AW12: =AT12/4 -> 0 | BP12: 就労移行支援（養成施設）
B13: サービス管理責任者 | AT13: =SUM(R13:AS13) -> 0 | AW13: =AT13/4 -> 0 | BP13: 就労継続支援Ａ型
AT14: =SUM(R14:AS14) -> 0 | AW14: =AT14/4 -> 0 | BP14: 就労継続支援Ｂ型
AT15: =SUM(R15:AS15) -> 0 | AW15: =AT15/4 -> 0 | BP15: 重度障害者等包括支援
AT16: =SUM(R16:AS16) -> 0 | AW16: =AT16/4 -> 0
AT17: =SUM(R17:AS17) -> 0 | AW17: =AT17/4 -> 0
AT18: =SUM(R18:AS18) -> 0 | AW18: =AT18/4 -> 0
AT19: =SUM(R19:AS19) -> 0 | AW19: =AT19/4 -> 0
AT20: =SUM(R20:AS20) -> 0 | AW20: =AT20/4 -> 0
AT21: =SUM(R21:AS21) -> 0 | AW21: =AT21/4 -> 0
AT22: =SUM(R22:AS22) -> 0 | AW22: =AT22/4 -> 0
AT23: =SUM(R23:AS23) -> 0 | AW23: =AT23/4 -> 0
AT24: =SUM(R24:AS24) -> 0 | AW24: =AT24/4 -> 0
AT25: =SUM(R25:AS25) -> 0 | AW25: 0
AT26: =SUM(R26:AS26) -> 0 | AW26: =AT26/4 -> 0
AT27: =SUM(R27:AS27) -> 0 | AW27: =AT27/4 -> 0
B28: 合計 | AT28: =SUM(AT14:AV27) -> 0 | AW28: =SUM(AW14:AY27) -> 0 | AZ28: =IF(AND(AW28=0,AT29=0),0,ROUNDDOWN(AW28/AT29,1)) -> 0
B29: 当該事業所・施設において常勤職員が1週間に勤務すべき時間数 | AT29: 0

Sheet 参考様式１（事業所・施設の平面図）
A1: 参考様式１ | E1: 事業所・施設の平面図
B3: 事業所の名称 | D3: シェル 川﨑
B6: 建物の名称
B7: 構造概要 | D7: 鉄筋３階建て ２階
B8: 事業所の共用の有無 | D8: 無し
K12: １F
K13: 内科診療所
A34: （備考）１ | B34: 各室、区画の用途及び面積を記載し、他の事業や施設と共用する場合は、その旨を記載し色分けする等わかりやすく表示してください。
A35: ２ | B35: 既製の平面図がある場合にはそれを添付してください。（その場合、Ａ３に縮尺の上、折り込んでください。）
A36: ３ | B36: 療養介護事業所、共同生活介護、共同生活援助、短期入所事業所、障害者支援施設においては既製の平面図を添付して下さい。短期入所事業所で、併設事業所の場合は、本体施設の平面図を添付してください。
A38: ４ | B38: 事業所の外観及び内部（各室、区画）の写真を添付してください。
A39: ５ | B39: 多機能型、従たる事業所や複数の共同生活住居がある場合は、それぞれの位置関係がわかる地図等を添付してください。

Sheet 参考様式１(記載例)
A3: 参考様式１ | E3: 事業所・施設の平面図
B5: 事業所の名称 | D5: （申請書記載の名称と同一であること）
B9: 建物の名称 | D9: ○○ビルディング（ビル、施設等の名称）
B10: 構造概要 | D10: ○造○階建 ○階
B11: 事業所の共用の有無 | D11: （○○介護保険事業所と共用等）
C14: ○○ビルディング ○階平面図 | L14: Ｎ
A38: （備考）１ | B38: 各室、区画の用途及び面積を記載し、他の事業や施設と共用する場合は、その旨を記載し色分けする等わかりやすく表示してください。
A39: ２ | B39: 既製の平面図がある場合にはそれを添付してください。（その場合、Ａ３に縮尺の上、折り込んでください。）
A40: ３ | B40: 療養介護事業所、共同生活介護、共同生活援助、短期入所事業所、障害者支援施設においては既製の平面図を添付して下さい。短期入所事業所で、併設事業所の場合は、本体施設の平面図を添付してください。
A42: ４ | B42: 事業所の外観及び内部（各室、区画）の写真を添付してください。
A43: ５ | B43: 多機能型、従たる事業所や複数の共同生活住居がある場合は、それぞれの位置関係がわかる地図等を添付してください。

Sheet 参考様式１（事業所・施設の平面図） (2)
A1: 参考様式１ | E1: 事業所・施設の平面図
B3: 事業所の名称 | D3: ='参考様式１（事業所・施設の平面図）'!D3 -> シェル 川﨑
B6: 建物の名称
B7: 構造概要 | D7: 木造２階建て
B8: 事業所の共用の有無 | D8: 無し
A34: （備考）１ | B34: 各室、区画の用途及び面積を記載し、他の事業や施設と共用する場合は、その旨を記載し色分けする等わかりやすく表示してください。
A35: ２ | B35: 既製の平面図がある場合にはそれを添付してください。（その場合、Ａ３に縮尺の上、折り込んでください。）
A36: ３ | B36: 療養介護事業所、共同生活介護、共同生活援助、短期入所事業所、障害者支援施設においては既製の平面図を添付して下さい。短期入所事業所で、併設事業所の場合は、本体施設の平面図を添付してください。
A38: ４ | B38: 事業所の外観及び内部（各室、区画）の写真を添付してください。
A39: ５ | B39: 多機能型、従たる事業所や複数の共同生活住居がある場合は、それぞれの位置関係がわかる地図等を添付してください。

Sheet 参考様式２（居室面積等一覧表）
A1: 参考様式２ | F1: 居室面積等一覧表
B3: 事業所の名称 | D3: ='参考様式１（事業所・施設の平面図）'!D3:I3 -> シェル 川﨑
B4: サービスの種類 | D4: 就労移行支援
B6: 設置階 | D6: 3 | E6: 階 | H6: 2 | I6: 階 | M6: 階 | Q6: 階 | S6: 合 計
A7: 種類 | C7: 室数 | D7: 面積 | F7: 備考 | G7: 室数 | H7: 面積 | J7: 備考 | K7: 室数 | L7: 面積 | N7: 備考 | O7: 室数 | P7: 面積 | R7: 備考 | S7: 室数 | T7: 面積 | U7: 備考
A8: 居室 | B8: １室の定員 | E8: 一人あたり | I8: 一人あたり | M8: 一人あたり | Q8: 一人あたり
E9: （ ） | I9: （ ） | M9: （ ） | Q9: （ ）
E10: （ ） | I10: （ ） | M10: （ ） | Q10: （ ）
E11: （ ） | I11: （ ） | M11: （ ） | Q11: （ ）
E12: （ ） | I12: （ ） | M12: （ ） | Q12: （ ）
E13: （ ） | I13: （ ） | M13: （ ） | Q13: （ ）
E14: （ ） | I14: （ ） | M14: （ ） | Q14: （ ）
E15: （ ） | I15: （ ） | M15: （ ） | Q15: （ ）
E16: （ ） | I16: （ ） | M16: （ ） | Q16: （ ）
A17: 居室以外
A18: 相談室兼事務所 | C18: 1
A19: 作業室１ | C19: 1
A20: 多目的室 | C20: 1
A21: 休憩室 | C21: 1
A22: トイレ | C22: 1
A23: 洗面所 | C23: 1
A28: 片廊下幅 | C28: （最も狭い個所） | F28: ｍ | G28: （最も狭い個所） | J28: ｍ | K28: （最も狭い個所） | N28: ｍ | O28: （最も狭い個所） | R28: ｍ
A29: 中廊下幅 | F29: ｍ | J29: ｍ | N29: ｍ | R29: ｍ
A30: 共用する事業所・施設名
A32: 備考１ | B32: 設備基準で定められた設備等について、設置階ごとに記載してください。
A33: ２ | B33: 居室については、「1室の定員」ごとに分けて記入してください。また、同じ定員でも面積に異なる居室がある場合には、それぞれの居室ごとに分けて記入してください。
A34: ３ | B34: 「1人あたりの面積」の算出が必要な設備は、面積欄の（ ）内に記入してください。（算出にあたっては小数点以下第二位を切捨て）
A35: ４ | B35: 部屋の種類ごとにまとめて、合計の室数、面積を記入してください。
A36: ５ | B36: 他の事業所、施設と共用がある場合は、備考欄に「共用」と記入し、「共用する事業所・施設名」欄に正式名称を記入し、共用先の当該部分の平面図を添付してください。
B37: （様式１で添付されている場合は省略可）
A38: ６ | B38: 同一の事業所又は施設の他の設備と兼用している場合は「備考欄」に「○○室と兼用」と記載してください。
A39: ７ | B39: 施設入所支援の場合は昼間実施するサービスとあわせて記載してください。

Sheet 参考様式２(記載例)
A3: 参考様式２ | F3: 居室面積等一覧表
B5: 事業所の名称 | D5: かながわ○△園
B6: サービスの種類 | D6: 生活介護・施設入所支援
B8: 設置階 | D8: 1 | E8: 階 | H8: 2 | I8: 階 | M8: 階 | Q8: 階 | S8: 合 計
A9: 種類 | C9: 室数 | D9: 面積 | F9: 備考 | G9: 室数 | H9: 面積 | J9: 備考 | K9: 室数 | L9: 面積 | N9: 備考 | O9: 室数 | P9: 面積 | R9: 備考 | S9: 室数 | T9: 面積 | U9: 備考
A10: 居室 | B10: １室の定員 | E10: 一人あたり | I10: 一人あたり | M10: 一人あたり | Q10: 一人あたり
A11: 1人部屋Ａ | B11: １人 | C11: 18 | D11: 10.8㎡ | E11: （10.8㎡） | I11: （ ） | M11: （ ） | Q11: （ ） | S11: 18 | T11: 194.4㎡
A12: 1人部屋Ｂ | B12: 1人 | E12: （ ） | G12: 22 | H12: 11.6㎡ | I12: （11.6㎡） | M12: （ ） | Q12: （ ） | S12: 22 | T12: 255.2㎡
A13: 4人部屋 | B13: 4人 | C13: 2 | D13: 48.8㎡ | E13: （12.2㎡） | I13: （ ） | M13: （ ） | Q13: （ ） | S13: 2 | T13: 97.6㎡
E14: （ ） | I14: （ ） | M14: （ ） | Q14: （ ）
E15: （ ） | I15: （ ） | M15: （ ） | Q15: （ ）
E16: （ ） | I16: （ ） | M16: （ ） | Q16: （ ）
E17: （ ） | I17: （ ） | M17: （ ） | Q17: （ ）
E18: （ ） | I18: （ ） | M18: （ ） | Q18: （ ）
A19: 居室以外
A20: 食堂 | C20: 1 | F20: 共用 | G20: 1 | J20: 共用
A21: 特別浴室 | C21: 1 | F21: 共用
A22: 一般浴室 | G22: 1 | J22: 共用
A23: 洗面所 | C23: 1 | F23: 共用 | G23: 1 | J23: 共用
A24: 便所 | C24: 2 | F24: 共用 | G24: 2 | J24: 共用
A25: 訓練・作業室 | C25: 1 | F25: 共用
A26: 相談室 | G26: 1 | J26: 共用
A27: 多目的室 | G27: 1 | J27: 共用
A30: 片廊下幅 | C30: （最も狭い個所） | E30: 1.55 | F30: ｍ | G30: （最も狭い個所） | I30: 1.55 | J30: ｍ | K30: （最も狭い個所） | N30: ｍ | O30: （最も狭い個所） | R30: ｍ
A31: 中廊下幅 | E31: 1.9 | F31: ｍ | I31: 1.9 | J31: ｍ | N31: ｍ | R31: ｍ
A32: 共用する事業所・施設名
A34: 備考１ | B34: 設備基準で定められた設備等について、設置階ごとに記載してください。
A35: ２ | B35: 居室については、「1室の定員」ごとに分けて記入してください。また、同じ定員でも面積に異なる居室がある場合には、それぞれの居室ごとに分けて記入してください。
A36: ３ | B36: 「1人あたりの面積」の算出が必要な設備は、面積欄の（ ）内に記入してください。（算出にあたっては小数点以下第二位を切捨て）
A37: ４ | B37: 部屋の種類ごとにまとめて、合計の室数、面積を記入してください。
A38: ５ | B38: 他の事業所、施設と共用がある場合は、備考欄に「共用」と記入し、「共用する事業所・施設名」欄に正式名称を記入し、共用先の当該部分の平面図を添付してください。
B39: （様式１で添付されている場合は省略可）
A40: ６ | B40: 同一の事業所又は施設の他の設備と兼用している場合は「備考欄」に「○○室と兼用」と記載してください。
A41: ７ | B41: 施設入所支援の場合は昼間実施するサービスとあわせて記載してください。

Sheet 参考様式３（事業所の設備・備品等一覧表）
A1: 参考様式３ | D1: 事業所の設備・備品等一覧表
B4: 事業所の名称 | D4: ='参考様式２（居室面積等一覧表）'!D3:L3 -> シェル 川﨑
B5: サービスの種類 | D5: ='参考様式２（居室面積等一覧表）'!D4:L4 -> 就労移行支援
A7: 設備の概要 | C7: 設備基準上適合すべき項目についての状況 | H7: 備品の品名及び数量 | K7: 適合の可否
A9: サービス提供上配慮すべき設備の概要
A12: 訓練作業室 | C12: 作業訓練に必要な広さと設備を備えている。 | H12: パソコン8台、机、イス
A14: 相談室 | C14: 利用者のプライバシーに配慮し、独立した部屋を | H14: 机１，イス2，本棚
C15: 設けている。
A16: 事務室 | C16: 利用者の個人ファイルは、鍵付きのキャビネットに | H16: 机1，イス2，電話１，ＦＡＸ１
C17: 保管している。 | H17: パソコン1
H18: 鍵付きキャビネット1，ロッカー２
A19: トイレ | C19: 必要に応じたトイレを備えている。 | H19: 洋式トイレ
A21: 手洗い | C21: 手指洗浄設備として衛生備品を備えている。 | H21: ペーパータオル，
H22: アルコール消毒剤
A23: 多目的室 | C23: 利用者の交流の場、作業訓練以外の部屋として | H23: 机、イス
C24: 利用する。
A27: 非常災害設備等 | H27: 消火器･･･１台
A49: 備考 １ | B49: 申請するサービスの種類に関して、基準省令で定められた設備基準上適合すべき項目のうち、「居室面積等一覧表」（参考様式２）に記載された項目以外の事項について記載してください。
A50: 2 | B50: 「適合の可否」欄には何も記載しないでください。

Sheet 参考様式３(記載例)
A3: 参考様式３ | D3: 事業所の設備・備品等一覧表
B6: 事業所の名称 | D6: かながわ○△園
B7: サービスの種類 | D7: 生活介護
A9: 設備の概要 | C9: 設備基準上適合すべき項目についての状況 | H9: 備品の品名及び数量 | K9: 適合の可否
A11: サービス提供上配慮すべき設備の概要
A21: 例）
A22: ・相談室 | C22: ・室内における談話の漏えいを防ぐための間仕切りを設けている | H22: 机 １、いす ４、パーテーション ２
A26: ・事務室 | C26: ・適切な事務を行うためのスペース及び備品を確保している。 | H26: 机４、いす５、鍵付き書庫 ２
A30: ・消毒設備 | C30: ・感染症予防のため、手指洗浄及び消毒のための設備を設けている。 | H30: 洗面台１、手指消毒剤２
A33: ・訓練・作業室 | C33: ・訓練又は作業に支障がない広さを有しており、訓練又は作業に必要な機械器具等を備えている。 | H33: 作業台３、いす１２
A38: 非常災害設備等
A40: 例）
A41: ・消火設備 | C41: ・消防法に適合したものを備えている。 | H41: 消火器 10、スプリンクラー設備
H42: 火災通報設備 ５
H43: 誘導灯 ４
A61: 備考 １ | B61: 申請するサービスの種類に関して、基準省令で定められた設備基準上適合すべき項目のうち、「居室面積等一覧表」（参考様式２）に記載された項目以外の事項について記載してください。
A62: 2 | B62: 「適合の可否」欄には何も記載しないでください。

Sheet 参考様式４（管理者等経歴書）
A2: 参考様式４ | D2: 管 理 者
D3: サービス管理責任者 | H3: 経 歴 書
D4: サービス提供責任者
D5: 相談支援専門員
A7: 事業所の名称 | C7: ='参考様式２（居室面積等一覧表）'!D3 -> シェル 川﨑
A8: サービスの種類 | C8: ='参考様式２（居室面積等一覧表）'!D4 -> 就労移行支援
A9: （管理者の場合で当該管理者が管理する事業所が複数の場合はその全てを記載してください。）
B10: 事業の名称
B11: サービスの種類
A13: フリガナ | C13: ｶｲﾊﾀ ｱｷﾉﾘ | H13: 生年月日 | I13: 25496
A14: 氏 名 | C14: 貝畑明典
A15: 住 所 | B15: (自宅） | C15: （〒719-0231） | E15: 岡山県浅口市鴨方町小坂西５０５２番地３
A16: 電話番号 | B16: (自宅） | C16: 080-5419-2741
A17: 主な職歴
A18: 期間 | D18: 勤務先 | I18: 職務内容
A19: 平成29年1月 ～ 現在 | D19: 一般社団法人アンマー | I19: 代表理事
A20: 平成29年12月 ～ 現在 | D20: 多機能型施設シェル | I20: 管理者
A28: 職務に関する資格
A29: 資格の種類 | F29: 資格取得年月日
A30: 社会福祉事業に２年以上従事した経験 | F30: 令和2年12月
A42: 備考（研修等の受講の状況等）
A52: 備考 | B52: 管理者、サービス管理責任者、サービス提供責任者、相談支援専門員のいずれかを○印で囲ってください。
B53: 管理者、サービス管理責任者、サービス提供責任者、相談支援専門員についてそれぞれ別葉で提出してください。

Sheet 参考様式４（管理者等経歴書） (2)
A2: 参考様式４ | D2: 管 理 者
D3: サービス管理責任者 | H3: 経 歴 書
D4: サービス提供責任者
D5: 相談支援専門員
A7: 事業所の名称 | C7: ='参考様式２（居室面積等一覧表）'!D3 -> シェル 川﨑
A8: サービスの種類 | C8: ='参考様式２（居室面積等一覧表）'!D4 -> 就労移行支援
A9: （管理者の場合で当該管理者が管理する事業所が複数の場合はその全てを記載してください。）
B10: 事業の名称
B11: サービスの種類
A13: フリガナ | C13: ﾀﾅｶ ｻﾅｴ | H13: 生年月日 | I13: 24585
A14: 氏 名 | C14: 田中 早苗
A15: 住 所 | B15: (自宅） | C15: （〒651-0056） | E15: 兵庫県神戸市中央区熊内町4-10-6 パレスエクセル新神戸1301
A16: 電話番号 | B16: (自宅） | C16: 080-3890-8696
A17: 主な職歴
A18: 期間 | D18: 勤務先 | I18: 職務内容
A19: 昭和63年4月～平成7年3月 | D19: 社会福祉法人光明会 小ざくら保育園 | I19: 保育士
A20: 平成7年4月～平成15年3月 | D20: 社会福祉法人いずみ福祉事業会 いずみ乙島保育園 | I20: 保育士
A21: 平成16年4月～平成16年6月 | D21: 社会福祉法人倉敷市総合福祉事業会 倉敷市ふじ園 | I21: 支援員
A22: 平成16年7月～平成24年10月 | D22: 社会福祉法人倉敷市総合福祉事業会 倉敷障がい者就業・生活支援センター | I22: 相談支援員
A23: 平成24年11月～平成25年5月 | D23: 社会福祉法人里庄町社会福祉協議会里庄町障がい者地域活動支援センター「四つ葉の家」 | I23: 管理者
A24: 平成25年6月～令和2年12月 | D24: 社会福祉法人里庄町社会福祉協議会 就労継続支援B型「四つ葉の家」 | I24: 管理者兼サービス管理責任者
A28: 職務に関する資格
A29: 資格の種類 | F29: 資格取得年月日
A30: 保育士 | F30: 平成15年11月
A42: 備考（研修等の受講の状況等）
A43: サービス管理責任者研修（就労）岡山県 修了 （平成22年11月30日）
A44: 相談支援従事者初任者研修 岡山県 修了 （平成23年9月28日）
A52: 備考 | B52: 管理者、サービス管理責任者、サービス提供責任者、相談支援専門員のいずれかを○印で囲ってください。
B53: 管理者、サービス管理責任者、サービス提供責任者、相談支援専門員についてそれぞれ別葉で提出してください。

Sheet 参考様式４(記載例)
A3: 参考様式４ | D3: 管 理 者
D4: サービス管理責任者 | H4: 経 歴 書
D5: サービス提供責任者
D6: 相談支援専門員
A8: 事業所の名称 | C8: かながわ○△園
A9: サービスの種類 | C9: 生活介護
A10: （管理者の場合で当該管理者が管理する事業所が複数の場合はその全てを記載してください。）
B11: 事業の名称 | C11: かながわ○△園
B12: サービスの種類 | C12: 施設入所支援
A14: フリガナ | C14: ｶﾅｶﾞﾜｲﾁﾛｳ | H14: 生年月日 | I14: 昭和○○年○月○日
A15: 氏 名 | C15: かながわ一郎
A16: 住 所 | B16: (自宅） | C16: （〒231-****） 神奈川県平塚市○○ー○○
A17: 電話番号 | B17: (自宅） | C17: 0463－○○ー○○○○
A18: 主な職歴
A19: 期間 | D19: 勤務先 | I19: 職務内容
A20: 昭和○○年○月～平成○○年○月 | D20: 社会福祉法人△△会特別養護老人ホーム○△□苑 | I20: 介護職員
A22: 平成○○年○月～平成○○年○月 | D22: 社会福祉法人かながわ福祉会かながわ○△園 | I22: 生活支援員
A24: 平成○○年○月～平成○○年○月 | D24: 同上 | I24: 生活支援課長
A29: 職務に関する資格
A30: 資格の種類 | F30: 資格取得年月日
B32: 介護福祉士 | G32: 平成○○年○月○日
B34: 社会福祉士 | G34: 平成○○年○月○日
A43: 備考（研修等の受講の状況等）
A54: 備考 | B54: 管理者、サービス管理責任者、サービス提供責任者、相談支援専門員のいずれかを○印で囲ってください。
B55: 管理者、サービス管理責任者、サービス提供責任者、相談支援専門員についてそれぞれ別葉で提出してください。

Sheet 参考様式５（実務経験証明書）
A1: （参考様式５）
A2: 実 務 経 験 (見 込) 証 明 書
D5: 横浜市長 様 | G5: 年 月 日
E7: 所在地 | F7: 岡山県笠岡市用之江８１０－１
E8: 名称 | F8: 一般社団法人アンマー
E9: 代表者 職・氏名 | G9: 代表理事 貝畑明典 | J9: 印
E10: 電話番号 | F10: ０８６５－６１－４３５１ | I10: 1969/10/20
A12: 下記の者の実務経験は、以下のとおりであることを証明します。
A14: 氏 名 | D14: 貝畑 明典 | G14: （生年月日 1969年10月20日）
A15: 現 住 所 | D15: 岡山県浅口市鴨方町小坂西５０５２番地３
A16: 施設又は事業所名 | D16: シェル
D17: 施設・事業所の種別（ 就労継続支援B型 ）
A18: 業 務 期 間
D19: 平成29年12月1日～ 令和2年12月31日 （ 2年1か月間）
A20: 上記のうち業務に従事した日数 | D20: 512日
A21: 業 務 内 容 | D21: 職名（ 管理者 ）
A25: （注） | B25: １． | C25: 見込証明でない場合は、表題の（見込）を二重線で消すこと。
B26: ２． | C26: 業務期間欄は、実務経験被証明者が要援護者に対する直接的な援助を行っていた期間（見込においては援助を行うと見込まれる期間）を記入すること。（産休・育休・療養休暇や長期研修期間等は業務期間となりません）
B28: ３． | C28: 施設又は事業所名欄には、知的障害者更生施設等の種別も記入すること。
B29: ４． | C29: 業務内容欄は、看護師、生活指導員等の職名を記入し、業務内容について、老人デイサービス事業における○○業務、○○実施要綱の○○事業の○○業務等具体的に記入すること。
B31: ５． | C31: 証明内容を訂正する場合は、二重線で消した上、証明者（代表者）の印を押すこと。

Sheet 参考様式５（記載例）
A2: （参考様式５）
A3: 実 務 経 験 (見 込) 証 明 書
D6: 横浜市長 様 | J6: ○年 ○月 ○日
E8: 所在地 | F8: 神奈川県○○市○○町○○－○○
E9: 名称 | F9: 社会福祉法人○△□会
E10: 代表者 職・氏名 | G10: 理事長 ○○ ○○ | J10: 印
E11: 電話番号 | F11: ○○○－○○○－○○○○
A13: 下記の者の実務経験は、以下のとおりであることを証明します。
A15: 氏 名 | D15: よこはま花子 | G15: (生年月日 昭和○○年 ○○月 ○○日）
A16: 現 住 所 | D16: 横浜市○○区○○町○○－○○
A17: 施設又は事業所名 | D17: ○○ホーム
D18: 施設・事業所の種別（ 身体障害者療護施設 ）
A19: 業 務 期 間
D20: 平成○○年 ○月 ○日 ～平成○○年 ○月 ○日（ ○年 ○月間）
A21: 上記のうち業務に従事した日数 | D21: 〇〇〇日
A22: 業 務 内 容 | D22: 職名（ 生活支援員 ）
D23: 入所者に対する介護業務
A26: （注） | B26: １． | C26: 見込証明でない場合は、表題の（見込）を二重線で消すこと。
B27: ２． | C27: 施設又は事業所名欄には、知的障害者更生施設等の種別も記入すること。
B28: ３． | C28: 業務期間欄は、実務経験被証明者が要援護者に対する直接的な援助を行っていた期間（見込においては援助を行うと見込まれる期間）を記入すること。（産休・育休・療養休暇や長期研修期間等は業務期間となりません）
B29: ４． | C29: 業務内容欄は、看護師、生活指導員等の職名を記入し、業務内容について、老人デイサービス事業における○○業務、○○実施要綱の○○事業の○○業務等具体的に記入すること。
B31: ５． | C31: 証明内容を訂正する場合は、二重線で消した上、証明者（代表者）の印を押すこと。

Sheet 参考様式６（苦情を解決するために講ずる措置の概要）
A1: （参考様式６）
A3: 利用者（入所者）又はその家族からの苦情を解決するために講ずる措置の概要
A5: 事業所又は施設名 | D5: ='参考様式１（事業所・施設の平面図）'!D3:I3 -> シェル 川﨑
A6: 申請するサービス種類 | D6: 就労移行支援
A8: 措 置 の 概 要
A9: １ 利用者（入所者）又はその家族からの相談又は苦情等に対応する常設の窓口（連絡先），担当者
B11: 相談，苦情に関する常設窓口として 田中早苗 を受付担当者としている。また，
B12: 担当者が不在の場合には苦情解決責任者をはじめ，他の者でも対応
B13: できるよう苦情受付シートを作成し、担当者に引き継いでいる。
B14: ・苦情受付担当者 サービス管理責任者 田中早苗
B15: ・苦情解決責任者 管理者 貝畑 明典
B16: ・電話：
B17: ・受付日時：月曜日〜金曜日及び隔週の土曜日 ９時００分から１５時３０分
B18: （ただし、国民の祝日、８月１３日から８月１６日、１２月２７日から１月４日までを除く）
B19: ※利用者には、この内容を印刷し、配布周知することとする。
A20: ２ 円滑かつ迅速に苦情を解決するための処理体制・手順
B22: ・苦情があった場合、利用者の状況を詳細に把握するため必要に応じ訪問等を
B23: 行い、事情の確認を行うとともに苦情受付シートを作成する。
B24: ・苦情受付担当者は、把握した状況を苦情解決責任者とともに検討し、対応を
B25: 決定する。
B26: ・対応方法に基づき連絡調整を行うとともに、苦情申立者に対応方法を含めた
B27: 結果報告を行う。
A29: ※具体的な対応方針
B30: ・苦情又は相談があった場合利用者の状況を詳細に把握するよう、必要に応じ状況
B31: の聞き取りのための訪問を実施し、事情の確認を行う。
B32: ・対応内容に基づき、必要に応じて関係者への連絡調整を行うとともに、利用者へ
B33: は必ず対応方法を含めた結果報告を行う、笠岡市の苦情窓口へ連絡する。
B34: （時間を要する内容もその旨を翌日までに連絡する）
B35: ・苦情受付シートの記録は５年間保管を行う
A37: ３ その他参考事項
B38: 当該事業所において，処理できない内容についても適切な対応方法を利用者の
B39: 立場にたって検討し，対応・紹介する。
B41: 【外部相談窓口】
B42: ・神奈川県障害者権利擁護センター 住所：岡山県岡山市北区南方二丁目１３番1号 きらめきプラザ3階 電話：046-265-0604 FAX：046-265-0664
B44: （受付日時：月曜日から金曜日 ９時から１７時、祝日、年末年始を除く）
B45: 【市町村担当窓口】
B46: ・宮前区地域みまもり支援センター高齢・障害課 住所：川崎市宮前区宮前平2-20-5 電話：044-200-0193 FAX：044-200-3610
B47: （受付日時：２４時間 365日）
A50: 備考 上の事項は例示であるので，これにかかわらず適宜項目を追加し，その内容について具体的
A51: に記載してください。

Sheet 参考様式６（苦情を解決するために講ずる措置の概要）2
A1: 参考様式6 | C1: 利用者（入所者）又はその家族からの苦情を解決するために講ずる措置の概要
A3: 事業所の名称
A4: サービスの種類
A6: 措置の概要
A7: 1 | B7: 利用者（入所者）又はその家族からの相談又は苦情等に対応する常設窓口（連絡先）、担当者
A28: 2 | B28: 円滑かつ迅速に苦情を解決するための処理体制・手順
B42: ※ | C42: 具体的な対応方針
A51: 3 | B51: その他参考事項
A64: 備考 | B64: 上記は例示であるので、これに関わらず、適宜項目を追加し、その内容について具体的に記載してください。

Sheet 参考様式６(記載例)
A3: 参考様式６ | C3: 利用者（入所者）又はその家族からの苦情を解決するために講ずる措置の概要
A5: 事業所の名称 | C5: かながわ○△園
A6: サービスの種類 | C6: 生活介護
A8: 措置の概要
A9: 1 | B9: 利用者（入所者）又はその家族からの相談又は苦情等に対応する常設窓口（連絡先）、担当者
A30: 2 | B30: 円滑かつ迅速に苦情を解決するための処理体制・手順
B44: ※ | C44: 具体的な対応方針
A53: 3 | B53: その他参考事項
A66: 備考 | B66: 上記は例示であるので、これに関わらず、適宜項目を追加し、その内容について具体的に記載してください。

Sheet 参考様式７（組織体制図）
A1: (参考様式７）
D3: 組 織 体 制 図
B5: 事業所の名称 | D5: コーリングサポ笠岡
B6: サービスの種類 | D6: ='参考様式２（居室面積等一覧表）'!D4 -> 就労移行支援
D12: 管理者
D13: 氏名 山﨑 裕昌（兼務）
B20: サービス管理責任者
B21: 氏名 | C21: 山内 雄司
B27: 従業者氏名 | F27: 意思決定支援会議アドバイザー
B28: 職業指導員 | F28: 事務局長 山内雄司
B29: 渡邊 資子
B30: 村上 亜矢乃
B32: 生活支援員
B33: 山内 ノリ子
B35: 就労支援員
B36: 山﨑 裕昌（兼務）
B37: 寺田 伊織
B58: 備考 既存の組織体制図がある場合は、その写し等の添付でかまいません。

Sheet 参考様式７（記載例）
A1: (参考様式７）
D3: 組 織 体 制 図
B5: 事業所の名称 | D5: ○△介護サービス
B6: サービスの種類 | D6: 居宅介護
D12: 管理者
D13: 氏名 ○○○○
B20: サービス提供責任者
B21: 氏名 | C21: ○○○○
B27: 従業者氏名 | F27: 事務員氏名
B28: ○○○○ | F28: ○○○○
B29: ○○○○ | F29: ○○○○
B30: ○○○○
B31: ○○○○
B32: ○○○○
B33: ○○○○
B53: 備考 既存の組織体制図がある場合は、その写し等の添付でかまいません。

Sheet 参考様式８（主たる対象者を特定する理由等）
A1: （参考様式８）
A3: 主たる対象者を特定する理由等
C6: 事業所名 | J6: ='参考様式７（組織体制図）'!D5 -> コーリングサポ笠岡
C7: サービスの種類 | J7: ='参考様式７（組織体制図）'!D6 -> 就労移行支援
A10: １ 申請に係るサービスの主たる対象者 | M10: ※該当するものを○で囲むこと。
B12: 身体障害者（肢体不自由 ・ 視覚 ・ 聴覚言語 ・ 内部障害）
B13: 知的障害者 ・ 障害児 ・ 精神障害者
A15: ２ 主たる対象者を１のとおり特定する理由
A28: ３ 今後における主たる対象者の拡充の予定
A30: （１）拡充予定の有無
C32: あり | D32: ・ | E32: なし
A34: （２）拡充予定の内容及び予定時期
B35: 令和4年4月には主たる対象者を定めない
A38: （３）拡充のための方策
B39: 従たる事業所の準備

Sheet 参考様式８(記載例)
A3: （参考様式８）
A5: 主たる対象者を特定する理由等
C8: 事業所名 | J8: ○△更生ホーム
C9: サービスの種類 | J9: 自立訓練（機能訓練）
A12: １ 申請に係るサービスの主たる対象者 | M12: ※該当するものを○で囲むこと。
B14: 身体障害者（肢体不自由 ・ 視覚 ・ 聴覚言語 ・ 内部障害）
B15: 知的障害者 ・ 障害児 ・ 精神障害者
A17: ２ 主たる対象者を１のとおり特定する理由
C19: 前身施設が身体障害者更生施設であり、施設の構造・設備や職員体制が
C20: 肢体不自由者の機能訓練に特化したものであるため。
A30: ３ 今後における主たる対象者の拡充の予定
A32: （１）拡充予定の有無
C34: あり | D34: ・ | E34: なし
A36: （２）拡充予定の内容及び予定時期
A40: （３）拡充のための方策

Sheet 参考様式９－１（第３６条第３項各号に関する誓約書）
A1: 参考様式９－１
A3: 障害者の日常生活及び社会生活を総合的に支援するための 法律第36条第３項各号の規定に該当しない旨の誓約書
O5: 令和 | S5: 平成 年 月 日
A6: 川崎市長 様
H7: 申請者 | J7: 所在地 | L7: 岡山県笠岡市用之江８１０－１
J8: 名 称 | L8: 一般社団法人アンマー
H9: 代表者 | J9: 住 所 | L9: 岡山県浅口市鴨方町小坂西５０５２番地３
J10: 職・氏名 | L10: 代表理事 貝畑明典 | R10: 印
A13: 当法人（別紙に記載する役員等を含む。）は、下記に掲げる障害者の日常生活及び社会生活を総合的に支援するための法律第36条第３項各号の規定のいずれにも該当しないことを誓約します。
A15: 記
B17: 【障害者の日常生活及び社会生活を総合的に支援するための法律第36条第３項各号の規定】（一部要約）
A19: １ | B19: 申請者が法人でないとき。
A20: ２ | B20: 当該申請に係るサービス事業所の従業者の知識及び技能並びに人員が、第43条第１項の都道府県の条例で定める基準を満たしていないとき。
A21: ３ | B21: 申請者が、第43条第２項の都道府県の条例で定める指定障害福祉サービスの事業の設備及び運営に関する基準に従って適正な障害福祉サービス事業の運営をすることができないと認められるとき。
A22: ４ | B22: 申請者が、禁錮以上の刑に処せられ、その執行を終わり、又は執行を受けることがなくなるまでの者であるとき。
A23: ５ | B23: 申請者が、この法律その他国民の保健医療若しくは福祉に関する法律で政令で定めるもの［＊］の規定により罰金の刑に処せられ、その執行を終わり、又は執行を受けることがなくなるまでの者であるとき。
B24: ＊ 児童福祉法、身体障害者福祉法、精神保健及び精神障害者福祉に関する法律、社会福祉法、 老人福祉法、社会福祉士及び介護福祉士法、介護保険法、精神保健福祉士法（療養介護を提供 するものにあっては、このほか医師法、歯科医師法、保健師助産師看護師法、医療法、薬事法、 薬剤師法）。
A25: ５の２ | B25: 申請者が、労働に関する法律の規定であって政令で定めるもの［＊］により罰金の刑に処せられ、その執行を終わり、又は執行を受けることがなくなるまでの者であるとき。
B26: ＊ ア 労働基準法第117条、第118条第1項（同法第６条及び第56条の規定に係る部分に限る。）、 第119条（同法第16条、第17条、第18条第１項及び第37条の規定に係る部分に限る。）及び 第120条（同法第18条第７項及び第23条から第27条までの規定に係る部分に限る。）の規定 並びにこれらの規定に係る同法第121条の規定（これらの規定が労働者派遣事業の適正な運 営の確保及び派遣労働者の保護等に関する法律第44条（第４項を除く。）の規定により適用 される場合を含む。）
B27: イ 最低賃金法第40条の規定及び同条の規定に係る同法第42条の規定
B28: ウ 賃金の支払の確保等に関する法律第18条の規定及び同条の規定に係る同法第20条の規定
A29: ６ | B29: 申請者が、第50条第１項(同条第３項において準用する場合を含む。以下この項において同じ。)又は第51条の29第１項若しくは第２項の規定により指定を取り消され、その取消しの日から起算して５年を経過しない者(当該指定を取り消された者が法人である場合においては、当該取消しの処分に係る行政手続法第15条の規定による通知があった日前60日以内に当該法人の役員又はそのサービス事業所を管理する者その他の政令で定める使用人［法第36条第１項に規定するサービス事業所を管理する者］(以下「役員等」という。)であった者で当該取消しの日から起算して５年を経過しないものを含み、当該指定を取り消された者が法人でない場合においては、当該通知があった日前60日以内に当該者の管理者であった者で当該取消しの日から起算して５年を経過しないものを含む。)であるとき。ただし、当該指定の取消しが、指定障害福祉サービス事業者の指定の取消しのうち当該指定の取消しの処分の理由となった事実及び当該事実の発生を防止するための当該指定障害福祉サービス事業者による業務管理体制の整備についての取組の状況その他の当該事実に関して当該指定障害福祉サービス事業者が有していた責任の程度を考慮して、この号本文に規定する指定の取消しに該当しないこととすることが相当であると認められるものとして厚生労働省令で定めるものに該当する場合を除く。
A31: ７ | B31: 申請者と密接な関係を有する者(申請者(法人に限る。以下この号において同じ。)の株式の所有その他の事由を通じて当該申請者の事業を実質的に支配し、若しくはその事業に重要な影響を与える関係にある者として厚生労働省令で定めるもの(以下この号において「申請者の親会社等」という。)、申請者の親会社等が株式の所有その他の事由を通じてその事業を実質的に支配し、若しくはその事業に重要な影響を与える関係にある者として厚生労働省令で定めるもの又は当該申請者が株式の所有その他の事由を通じてその事業を実質的に支配し、若しくはその事業に重要な影響を与える関係にある者として厚生労働省令で定めるもののうち、当該申請者と厚生労働省令で定める密接な関係を有する法人をいう。)が、第50条第１項又は第51条の29第１項若しくは第２項の規定により指定を取り消され、その取消しの日から起算して５年を経過していないとき。ただし、当該指定の取消しが、指定障害福祉サービス事業者の指定の取消しのうち当該指定の取消しの処分の理由となった事実及び当該事実の発生を防止するための当該指定障害福祉サービス事業者による業務管理体制の整備についての取組の状況その他の当該事実に関して当該指定障害福祉サービス事業者が有していた責任の程度を考慮して、この号本文に規定する指定の取消しに該当しないこととすることが相当であると認められるものとして厚生労働省令で定めるものに該当する場合を除く。［療養介護に係る申請にあっては、この号を除く。］
A33: ８ | B33: 申請者が、第50条第１項又は第51条の29第１項若しくは第２項の規定による指定の取消しの処分に係る行政手続法第15条の規定による通知があった日から当該処分をする日又は処分をしないことを決定する日までの間に第46条第２項又は第51条の25第２項若しくは第４項の規定による事業の廃止の届出をした者(当該事業の廃止について相当の理由がある者を除く。)で、当該届出の日から起算して５年を経過しないものであるとき。
A35: ９ | B35: 申請者が、第48条第１項(同条第３項において準用する場合を含む。)又は第51条の27第１項若しくは第２項の規定による検査が行われた日から聴聞決定予定日(当該検査の結果に基づき第50条第１項又は第51条の29第１項若しくは第２項の規定による指定の取消しの処分に係る聴聞を行うか否かの決定をすることが見込まれる日として厚生労働省令で定めるところにより都道府県知事が当該申請者に当該検査が行われた日から10日以内に特定の日を通知した場合における当該特定の日をいう。)までの間に第46条第２項又は第51条の25第２項若しくは第４項の規定による事業の廃止の届出をした者(当該事業の廃止について相当の理由がある者を除く。)で、当該届出の日から起算して５年を経過しないものであるとき。
A37: 10 | B37: 第８号に規定する期間内に第46条第２項又は第51条の25第２項若しくは第４項の規定による事業の廃止の届出があった場合において、申請者が、同号の通知の日前60日以内に当該届出に係る法人(当該事業の廃止について相当の理由がある法人を除く。)の役員等又は当該届出に係る法人でない者(当該事業の廃止について相当の理由がある者を除く。)の管理者であった者で、当該届出の日から起算して５年を経過しないものであるとき。
A38: 11 | B38: 申請者が、指定の更新の申請前５年以内に障害福祉サービスに関し不正又は著しく不当な行為をした者であるとき。
A39: 12 | B39: 申請者が、法人で、その役員等のうちに第４号から第６号まで又は第８号から前号までのいずれかに該当する者のあるものであるとき。
A40: 13 | B40: 申請者が、法人でない者で、その管理者が第４号から第６号まで又は第８号から第11号までのいずれかに該当する者であるとき。

Sheet 参考様式９-1(記載例)
A1: （参考様式９－１）
A3: 障害者の日常生活及び社会生活を総合的に支援するための法律第36条第３項各号の規定に該当しない旨の誓約書
S5: 平成 ○○年 ○月 ○日
A6: 横浜市長
H7: 申請者 | J7: 所在地 | L7: 神奈川県横浜市中区○○－○
J8: 名 称 | L8: 社会福祉法人よこはま福祉会
H9: 代表者 | J9: 住 所 | L9: 神奈川県平塚市○○－○○
J10: 職・氏名 | L10: 理事長 よこはま一郎 | R10: 印
A13: 当法人（別紙に記載する役員等を含む。）は、下記に掲げる障害者の日常生活及び社会生活を総合的に支援するための法律第36条第３項各号の規定のいずれにも該当しないことを誓約します。
A16: 記
B18: 【障害者の日常生活及び社会生活を総合的に支援するための法律第36条第３項各号の規定】（一部要約）
A20: １ | B20: 申請者が法人でないとき。
A21: ２ | B21: 当該申請に係るサービス事業所の従業者の知識及び技能並びに人員が、第43条第１項の厚生労働省令で定める基準を満たしていないとき。
A23: ３ | B23: 申請者が、第43条第２項の厚生労働省令で定める指定障害福祉サービスの事業の設備及び運営に関する基準に従って適正な障害福祉サービス事業の運営をすることができないと認められるとき。
A25: ４ | B25: 申請者が、禁錮以上の刑に処せられ、その執行を終わり、又は執行を受けることがなくなるまでの者であるとき。
A27: ５ | B27: 申請者が、この法律その他国民の保健医療若しくは福祉に関する法律で政令で定めるもの［＊］の規定により罰金の刑に処せられ、その執行を終わり、又は執行を受けることがなくなるまでの者であるとき。
B29: ＊ 児童福祉法、身体障害者福祉法、精神保健及び精神障害者福祉に関する法律、社会福祉法、老人福祉法、社会福祉士及び介護福祉士法、介護保険法、精神保健福祉士法（療養介護を提供するものにあっては、このほか医師法、歯科医師法、保健師助産師看護師法、医療法、薬事法、薬剤師法）。
B31: （以下省略）

Sheet 参考様式９-２　法第51条の19第２項非該当誓約書 
A1: （参考様式９-２）
A2: 障害者の日常生活及び社会生活を総合的に支援するための 法律第51条の19第２項において準用する同法第36条第３項 各号の規定に該当しない旨の誓約書
N4: 令和 年 月 日
A5: 川崎市長 殿
H6: 申請者 | J6: 所在地 | L6: ='参考様式９－１（第３６条第３項各号に関する誓約書）'!L7 -> 岡山県笠岡市用之江８１０－１
J7: 名 称 | L7: ='参考様式９－１（第３６条第３項各号に関する誓約書）'!L8 -> 一般社団法人アンマー
H8: 代表者 | J8: 住 所 | L8: ='参考様式９－１（第３６条第３項各号に関する誓約書）'!L9 -> 岡山県浅口市鴨方町小坂西５０５２番地３
J9: 氏 名 | L9: ='参考様式９－１（第３６条第３項各号に関する誓約書）'!L10 -> 代表理事 貝畑明典 | R9: 印
A11: 当法人（別紙に記載する役員等を含む。）は、下記に掲げる障害者の日常生活及び社会生活を総合的に支援するための法律第51条の19第２項において準用する同法第36条第３項（第４号、第10号及び第13号を除く。）の規定のいずれにも該当しないことを誓約します。
A15: 記
A17: 【障害者の日常生活及び社会生活を総合的に支援するための法律第36条第３項（第４号、第10号及び第13号を除く。）の読替後の規定】
A18: １ | B18: 申請者が法人でないとき。
A19: ２ | B19: 当該申請に係る一般相談支援事業所の従業者の知識及び技能並びに人員が、第51条の23第１項の厚生労働省令で定める基準を満たしていないとき。
A20: ３ | B20: 申請者が、第51条の23第2項の厚生労働省令で定める指定地域相談支援事業の運営に関する基準に従って適正な一般相談支援事業の運営をすることができないと認められるとき。
A21: ５ | B21: 申請者が、この法律その他国民の保健医療若しくは福祉に関する法律で政令で定めるもの(＊)の規定により罰金の刑に処せられ、その執行を終わり、又は執行を受けることがなくなるまでの者であるとき。
B22: ＊ 政令で定める法律 児童福祉法、身体障害者福祉法、精神保健及び精神障害者福祉に関する法律、生活保護法、社会福祉法、老人福祉法、社会福祉士及び介護福祉士法、介護保険法、精神保健福祉士法、児童買春、児童ポルノに係る行為等の規制及び処罰並びに児童の保護等に関する法律、児童虐待の防止等に関する法律、就学前の子どもに関する教育、保育等の総合的な提供の推進に関する法律、障害者虐待の防止、障害者の養護者に対する支援等に関する法律、子ども・子育て支援法、国家戦略特別区域法(第12条の５第15項及び第17項から第19項までの規定に限る。)、公認心理師法、民間あっせん機関による養子縁組のあっせんに係る児童の保護等に関する法律。
A23: ５の２ | B23: 申請者が、労働に関する法律の規定であって政令で定めるもの(＊)により罰金の刑に処せられ、その執行を終わり、又は執行を受けることがなくなるまでの者であるとき。
B24: ＊ 政令で定める労働に関する法律の規定 ・ 労働基準法第117条、第118条第１項(同法第６条及び第56条の規定に係る部分に限る。)、第119条(同法第16条、第17条、第18条第１項及び第37条の規定に係る部分に限る。)及び第120条(同法第18条第７項及び第23条から第27条までの規定に係る部分に限る。)の規定並びにこれらの規定に係る同法第121条の規定(これらの規定が労働者派遣事業の適正な運営の確保及び派遣労働者の保護等に関する法律第44条(第４項を除く。)の規定により適用される場合を含む。)
B25: ・ 最低賃金法第40条の規定及び同条の規定に係る同法第42条の規定
B26: ・ 賃金の支払の確保等に関する法律第18条の規定及び同条の規定に係る同法第20条の規定
A27: ６ | B27: 申請者が、第50条第１項(同条第３項において準用する場合を含む。以下この項において同じ。)、第51条の29第１項若しくは第２項又は第76条の３第６項の規定により指定を取り消され、その取消しの日から起算して５年を経過しない者(当該指定を取り消された者が法人である場合においては、当該取消しの処分に係る行政手続法第15条の規定による通知があった日前60日以内に当該法人の役員又はその一般相談支援事業所を管理する者(以下「役員等」という。)であった者で当該取消しの日から起算して５年を経過しないものを含み、当該指定を取り消された者が法人でない場合においては、当該通知があった日前60日以内に当該者の管理者であった者で当該取消しの日から起算して５年を経過しないものを含む。)であるとき。ただし、当該指定の取消しが、指定一般相談支援事業者の指定の取消しのうち当該指定の取消しの処分の理由となった事実及び当該事実の発生を防止するための当該指定一般相談支援事業者による業務管理体制の整備についての取組の状況その他の当該事実に関して当該指定一般相談支援事業者が有していた責任の程度を考慮して、この号本文に規定する指定の取消しに該当しないこととすることが相当であると認められるものとして厚生労働省令で定めるものに該当する場合を除く。
A28: ７ | B28: 申請者と密接な関係を有する者(申請者(法人に限る。以下この号において同じ。)の株式の所有その他の事由を通じて当該申請者の事業を実質的に支配し、若しくはその事業に重要な影響を与える関係にある者として厚生労働省令で定めるもの(以下この号において「申請者の親会社等」という。)、申請者の親会社等が株式の所有その他の事由を通じてその事業を実質的に支配し、若しくはその事業に重要な影響を与える関係にある者として厚生労働省令で定めるもの又は当該申請者が株式の所有その他の事由を通じてその事業を実質的に支配し、若しくはその事業に重要な影響を与える関係にある者として厚生労働省令で定めるもののうち、当該申請者と厚生労働省令で定める密接な関係を有する法人をいう。)が、第50条第１項、第51条の29第１項若しくは第２項又は第76条の３第６の規定により指定を取り消され、その取消しの日から起算して５年を経過していないとき。ただし、当該指定の取消しが、指定一般相談支援事業者の指定の取消しのうち当該指定の取消しの処分の理由となった事実及び当該事実の発生を防止するための当該指定一般相談支援事業者による業務管理体制の整備についての取組の状況その他の当該事実に関して当該指定一般相談支援事業者が有していた責任の程度を考慮して、この号本文に規定する指定の取消しに該当しないこととすることが相当であると認められるものとして厚生労働省令で定めるものに該当する場合を除く。
A29: ８ | B29: 申請者が、第50条第１項、第51条の29第１項若しくは第２項又は第76条の３第６項の規定による指定の取消しの処分に係る行政手続法第15条の規定による通知があった日から当該処分をする日又は処分をしないことを決定する日までの間に第46条第２項又は第51条の25第２項若しくは第４項の規定による事業の廃止の届出をした者(当該事業の廃止について相当の理由がある者を除く。)で、当該届出の日から起算して５年を経過しないものであるとき。
A30: ９ | B30: 申請者が、第48条第１項(同条第３項において準用する場合を含む。)又は第51条の27第１項若しくは第２項の規定による検査が行われた日から聴聞決定予定日(当該検査の結果に基づき第50条第１項又は第51条の29第１項若しくは第２項の規定による指定の取消しの処分に係る聴聞を行うか否かの決定をすることが見込まれる日として厚生労働省令で定めるところにより都道府県知事が当該申請者に当該検査が行われた日から10日以内に特定の日を通知した場合における当該特定の日をいう。)までの間に第46条第２項又は第51条の25第２項若しくは第４項の規定による事業の廃止の届出をした者(当該事業の廃止について相当の理由がある者を除く。)で、当該届出の日から起算して５年を経過しないものであるとき。
A31: 11 | B31: 申請者が、指定の申請前５年以内に相談支援に関し不正又は著しく不当な行為をした者であるとき。
A32: 12 | B32: 申請者が、法人で、その役員等のうちに第５号から第６号まで、第８号、第９号又は前号のいずれかに該当する者のあるものであるとき。

Sheet 参考様式９-４市条例同意書
A1: （参考様式９-４）
A2: 神奈川県警察本部への照会についての同意書
S4: 令和 年 月 日
A5: 横浜市長
H6: 申請者 | J6: 所在地 | L6: ='参考様式９－１（第３６条第３項各号に関する誓約書）'!L7:S7 -> 岡山県笠岡市用之江８１０－１
J7: 名 称 | L7: ='参考様式９－１（第３６条第３項各号に関する誓約書）'!L8:S8 -> 一般社団法人アンマー
H8: 代表者 | J8: 住 所 | L8: ='参考様式９－１（第３６条第３項各号に関する誓約書）'!L9:S9 -> 岡山県浅口市鴨方町小坂西５０５２番地３
J9: 職・氏名 | L9: ='参考様式９－１（第３６条第３項各号に関する誓約書）'!L10:Q10 -> 代表理事 貝畑明典 | S9: 印
A11: 横浜市指定障害福祉サービスの事業等の人員、設備、運営等の基準に関する条例第４条第２項、横浜市指定障害者支援施設等の人員、設備、運営等の基準に関する条例第４条の規定に基づき、当法人（別紙に記載する役員等を含む。）が暴力団等でないことを確認するため、本様式（および別紙役員等名簿）に記載された情報を神奈川県警察本部長に照会することについて、同意します。
A13: 記
A16: 横浜市指定障害福祉サービスの事業等の人員、設備、運営等の基準に関する条例（抜粋）
B17: 第４条 | C17: 法第36条第３項第１号の条例で定める者は、法人とする。ただし、療養介護に係る指定又は短期入所（病院又は診療所により行われるものに限る。） に係る指定の申請については、この限りでない。
B18: ２ | C18: 前項の法人は、横浜市暴力団排除条例（平成23年12月横浜市条例第51号）第２条第２号の暴力団、同条第５号の暴力団経営支配法人等又は同条例第７条の暴力団員等と密接な関係を有すると認められる者（以下この項において「暴力団等」という。） であってはならない。ただし、前項ただし書の申請については、暴力団等又は同条例第２条第４号の暴力団員等であってはならない。
A19: 横浜市指定障害者支援施設等の人員、設備、運営等の基準に関する条例（抜粋）
B20: 第４条 | C20: 法第38条第３項（法第39条第２項において準用する場合を含む。） において準用する法第36条第３項第１号の条例で定める者は、法人であって、横浜市暴力団排除条例（平成23年12月横浜市条例第51号） 第２条第２号の暴力団、同条第５号の暴力団経営支配法人等又は同条例第７条の暴力団員等と密接な関係を有すると認められる者でないものとする。
A21: 横浜市暴力団排除条例（抜粋）
B22: 第２条 | C22: この条例において、次の各号に掲げる用語の意義は、当該各号に定めるところによる。
D23: （２）暴力団 暴力団員による不当な行為の防止等に関する法律（平成３年法律第77 号。以下「法」という。） 第２条第２号に規定する暴力団をいう。 （４）暴力団員等 暴力団員又は暴力団員でなくなった日から５年を経過しない者をいう。 （５）暴力団経営支配法人等 法人その他の団体でその役員（業務を執行する社員、取締役、執行役又はこれらに準ずる者をいい、相談役、顧問その他いかなる名称を有する者であるかを問わず、当該団体に対し業務を執行する社員、取締役、執行役又はこれらに準ずる者と同等以上の支配力を有するものと認められる者を含む。） のうちに暴力団員等に該当する者があるもの及び暴力団員等が出資、融資、取引その他の関係を通じてその事業活動に支配的な影響力を有する者をいう。
B24: 第７条 | C24: 市は、公共工事の発注その他契約に関する事務（次条に規定する事業に関する事務を除く。） の執行により暴力団の活動を助長し、又は暴力団の運営に資することのないよう、暴力団、暴力団員等、暴力団経営支配法人等又は暴力団員等と密接な関係を有すると認められる者（法人その他の団体にあっては、その役員（業務を執行する社員、取締役、執行役又はこれらに準ずる者をいう。） が暴力団員等と密接な関係を有すると認められるものをいう。） の市が実施する入札への参加の制限その他の必要な措置を講ずるものとする。

Sheet 参考様式９-４（記載例）
A1: （参考様式９-４）
A2: 神奈川県警察本部への照会についての同意書
S4: 平成 年 月 日
A5: 横浜市長
H6: 申請者 | J6: 所在地 | L6: 神奈川県横浜市中区○○－○
J7: 名 称 | L7: 社会福祉法人よこはま福祉会
H8: 代表者 | J8: 住 所 | L8: 神奈川県平塚市○○－○○
J9: 職・氏名 | L9: 理事長 よこはま一郎 | S9: 印
A11: 横浜市指定障害福祉サービスの事業等の人員、設備、運営等の基準に関する条例第４条第２項、横浜市指定障害者支援施設等の人員、設備、運営等の基準に関する条例第４条の規定に基づき、当法人（別紙に記載する役員等を含む。）が暴力団等でないことを確認するため、本様式（および別紙役員等名簿）に記載された情報を神奈川県警察本部長に照会することについて、同意します。
A13: 記
A16: 横浜市指定障害福祉サービスの事業等の人員、設備、運営等の基準に関する条例（抜粋）
B17: 第４条 | C17: 法第36条第３項第１号の条例で定める者は、法人とする。ただし、療養介護に係る指定又は短期入所（病院又は診療所により行われるものに限る。） に係る指定の申請については、この限りでない。
B18: ２ | C18: 前項の法人は、横浜市暴力団排除条例（平成23年12月横浜市条例第51号）第２条第２号の暴力団、同条第５号の暴力団経営支配法人等又は同条例第７条の暴力団員等と密接な関係を有すると認められる者（以下この項において「暴力団等」という。） であってはならない。ただし、前項ただし書の申請については、暴力団等又は同条例第２条第４号の暴力団員等であってはならない。
A19: 横浜市指定障害者支援施設等の人員、設備、運営等の基準に関する条例（抜粋）
B20: 第４条 | C20: 法第38条第３項（法第39条第２項において準用する場合を含む。） において準用する法第36条第３項第１号の条例で定める者は、法人であって、横浜市暴力団排除条例（平成23年12月横浜市条例第51号） 第２条第２号の暴力団、同条第５号の暴力団経営支配法人等又は同条例第７条の暴力団員等と密接な関係を有すると認められる者でないものとする。
A21: 横浜市暴力団排除条例（抜粋）
B22: 第２条 | C22: この条例において、次の各号に掲げる用語の意義は、当該各号に定めるところによる。
D23: （２）暴力団 暴力団員による不当な行為の防止等に関する法律（平成３年法律第77 号。以下「法」という。） 第２条第２号に規定する暴力団をいう。 （４）暴力団員等 暴力団員又は暴力団員でなくなった日から５年を経過しない者をいう。 （５）暴力団経営支配法人等 法人その他の団体でその役員（業務を執行する社員、取締役、執行役又はこれらに準ずる者をいい、相談役、顧問その他いかなる名称を有する者であるかを問わず、当該団体に対し業務を執行する社員、取締役、執行役又はこれらに準ずる者と同等以上の支配力を有するものと認められる者を含む。） のうちに暴力団員等に該当する者があるもの及び暴力団員等が出資、融資、取引その他の関係を通じてその事業活動に支配的な影響力を有する者をいう。
B24: 第７条 | C24: 市は、公共工事の発注その他契約に関する事務（次条に規定する事業に関する事務を除く。） の執行により暴力団の活動を助長し、又は暴力団の運営に資することのないよう、暴力団、暴力団員等、暴力団経営支配法人等又は暴力団員等と密接な関係を有すると認められる者（法人その他の団体にあっては、その役員（業務を執行する社員、取締役、執行役又はこれらに準ずる者をいう。） が暴力団員等と密接な関係を有すると認められるものをいう。） の市が実施する入札への参加の制限その他の必要な措置を講ずるものとする。

Sheet 参考様式９別紙　役員等名簿 (2)
A1: 参考様式９別紙
A2: 役 員 等 名 簿
J4: 申請者（法人）名 | M4: （ ）
A5: （ふりがな） | E5: 生年月日 | J5: 住 所 | R5: 押印
A6: 氏 名 | E6: 役職名・呼称 | J6: TEL | N6: FAX
A7: 貝畑明典 | E7: 25496 | J7: 岡山県浅口市鴨方町小坂西５０５２番地３ | U7: 岡山県浅口市鴨方町小坂西５０５２番地３
E8: 代表理事 | J8: ='参考様式9別紙（役員等名簿）'!K6 -> 080-5419-2741
A9: 村越啓介 | E9: 26894 | J9: 広島県福山市神辺町大字下竹田２４３８番地２３ | U9: 広島県福山市神辺町大字下竹田２４３８番地２３
E10: 専務理事 | J10: ='参考様式9別紙（役員等名簿）'!K7 -> 080-3052-7684
A11: 進藤義夫 | E11: 23111 | J11: 東京都世田谷区上用賀３－１３－２２－２０８ | U11: 東京都世田谷区上用賀3-13-22-208
E12: 理事 | J12: ='参考様式9別紙（役員等名簿）'!K8 -> 090-8845-3565
A13: 貝畑明典 | E13: 25496 | J13: 岡山県浅口市鴨方町小坂西５０５２番地３
E14: 管理者 | J14: =J8 -> 080-5419-2741
A37: 注 | B37: 当該法人の役員（業務を執行する社員、取締役、執行役又はこれらに準ずる者をいい、相談役、顧問その他いかなる名称を有する者であるかを問わず、法人に対し業務を執行する社員、取締役、執行役又はこれらに準ずる者と同等以上の支配力を有するものと認められる者を含む。）及び事業所を管理する者について記入してください。

Sheet 参考様式9別紙（役員等名簿）
A1: 参考様式9別紙
A2: 役 員 等 名 簿
J3: 申請者（法人）名（ 一般社団法人アンマー ）
B4: 氏名（姓と名を１字開けてください） | D4: 生年月日 | H4: 性別 | I4: 住 所 | J4: 役職名 ・呼称 | K4: TEL | L4: FAX
B5: ｶﾅ（半角） | C5: 漢 字 | D5: m（明治） t（大正） s（昭和） h（平成） | E5: 年 | F5: 月 | G5: 日 | H5: 男性（m） 女性（f）
A6: 1 | B6: ｶｲﾊﾀ ｱｷﾉﾘ | C6: 貝畑 明典 | D6: S | E6: 44 | F6: 10 | G6: 20 | H6: m | I6: 岡山県浅口市鴨方町小坂西５０５２番地３ | J6: 代表理事 | K6: 080-5419-2741
A7: 2 | B7: ﾑﾗｺｼ ｹｲｽｹ | C7: 村越 啓介 | D7: S | E7: 48 | F7: 8 | G7: 18 | H7: m | I7: 広島県福山市神辺町大字下竹田２４３８番地２３ | J7: 理事 | K7: 080-3052-7684
A8: 3 | B8: ｼﾝﾄﾞｳ ﾖｼｵ | C8: 進藤 義夫 | D8: S | E8: 38 | F8: 4 | G8: 10 | H8: m | I8: 東京都世田谷区上用賀3-13-22-208 | J8: 理事 | K8: 090-8845-3565
A9: 4 | B9: ｶｲﾊﾀｱｷﾉﾘ | C9: 貝畑 明典 | D9: S | E9: 44 | F9: 10 | G9: 20 | H9: m | I9: 岡山県浅口市鴨方町小坂西５０５２番地３ | J9: 管理者 | K9: 080-5419-2741
A10: 5
A11: 6
A12: 7
A13: 8
A14: 9
A15: 10
A16: 11
A17: 12
A18: 注 | B18: ・役員等名簿に記載するのは当該法人の役員及び事業所の管理者です。 ・当該法人の役員とは、業務を執行する社員、取締役、執行役又はこれらに準ずる者をいい、相談役、顧問その他いかなる名称を有する者であるかを問わず、法人に対し業務を執行する社員、取締役、 執行役、幹事又はこれらに準ずる者と同等以上の支配力を有するものと認められる者を含みます。 ・当該法人の役員が変わる場合には、新たに就任する役員のみ記載してください（退任する役員については記載不要です）。

Sheet 参考様式9別紙（記載例）
A1: 参考様式9別紙
A2: 役 員 等 名 簿
J3: 申請者（法人）名（ よこはま居宅介護 ）
B4: 氏名（姓と名を１字開けてください） | D4: 生年月日 | H4: 性別 | I4: 住 所 | J4: 役職名 ・呼称 | K4: TEL | L4: FAX
B5: ｶﾅ（半角） | C5: 漢 字 | D5: m（明治） t（大正） s（昭和） h（平成） | E5: 年 | F5: 月 | G5: 日 | H5: 男性（m） 女性（f）
A6: 1 | B6: ﾖｺﾊﾏ ｲﾁﾛｳ | C6: 横浜 一郎 | D6: s | E6: 99 | F6: 99 | G6: 99 | H6: m | I6: 横浜市中区日本大通１８ | J6: 代表取締役 | K6: 045-999-9999 | L6: 045-999-9999
A7: 2 | B7: ｶﾅｶﾞﾜ ﾊﾅｺ | C7: 神奈川 花子 | D7: ｈ | E7: 11 | F7: 11 | G7: 11 | H7: ｆ | I7: 横浜市中区港町１－１ | J7: 取締役 | K7: 045-111-1111 | L7: 045-111-1111
A8: 3 | B8: ﾐﾅﾄ ﾀﾛｳ | C8: 港 太郎 | D8: s | E8: 1 | F8: 1 | G8: 1 | H8: m | I8: 東京都○○区〇〇 | J8: 管理者 | K8: 045-222-2222 | L8: 045-222-2222
A9: 4
A10: 5
A11: 6
A12: 7
A13: 8
A14: 9
A15: 10
A16: 11
A17: 12
A18: 注 | B18: ・役員等名簿に記載するのは当該法人の役員及び事業所の管理者です。 ・当該法人の役員とは、業務を執行する社員、取締役、執行役又はこれらに準ずる者をいい、相談役、顧問その他いかなる名称を有する者であるかを問わず、法人に対し業務を執行する社員、取締役、 執行役、幹事又はこれらに準ずる者と同等以上の支配力を有するものと認められる者を含みます。 ・当該法人の役員が変わる場合には、新たに就任する役員のみ記載してください（退任する役員については記載不要です）。

Sheet ■管理者誓約書【記載例】
A1: 指定障害福祉サービス事業所管理者誓約書
A3: 「横浜市指定障害福祉サービスの事業等の人員、設備、運営等の基準に関する条例（平成24年12月横浜市条例第64号）」の規定に従い、運営に関する基準を遵守し、当指定障害福祉サービス事業所の管理者の責務を適正に果たすことを誓約します。
M6: 平成 年 月 日
A8: 横浜市長
G10: 事業者名（開設法人名） | L10: 社会福祉法人よこはま福祉会
G13: 代表者 職・氏名 | L13: 理事長 よこはま一郎 | Q13: 印
Q14: （代表者印）
G16: 事業所名 | L16: よこはまサービス
G19: 管理者 氏名 | L19: 港 太郎 | Q19: 印
A24: 横浜市指定障害福祉サービスの事業等の人員、設備、運営等の基準に関する条例【抜粋】
A26: ■指定居宅介護事業所の場合
A27: （管理者及びサービス提供責任者の責務）
A28: 第31条 指定居宅介護事業所の管理者は、当該指定居宅介護事業所の従業者及び業務の管理を
A29: 一元的に行わなければならない。
A30: ２ 指定居宅介護事業所の管理者は、当該指定居宅介護事業所の従業者にこの章の規定を遵守させる
A31: ため必要な指揮命令を行うものとする。
A32: ＊第31条は、重度訪問介護、同行援護及び行動援護事業所に係る指定障害福祉サービスの事業について
A33: 準用されています。
A34: ■指定居宅介護事業所以外の指定障害福祉サービス事業所の場合
A35: （管理者の責務）
A36: 第68条 指定療養介護事業所の管理者は、当該指定療養介護事業所の従業者及び業務の管理その他の
... A42: 自立訓練（生活訓練）、就労移行支援、就労継続支援Ａ型、就労継続支援Ｂ型、共同生活援助。

Sheet 参考様式10（協力医療機関との契約の内容）
A1: 参考様式10 | C1: 協力医療機関との契約の内容
A3: 事業所の名称 | C3: =事業計画書②!D5 -> シェル 川﨑
A4: サービスの種類 | C4: =事業計画書②!D6 -> 就労移行支援
A6: 協力医療機関の名称
A7: 所在地
A8: 診療科目
A9: 事業所・施設からの距離 | E9: km | F9: （徒歩 分 車 分）
A10: 契約の内容
A43: 備考 | B43: 「契約の内容」は、契約書の写し等の添付でもかまいません。

Sheet 参考様式10(記載例)
A3: 参考様式10 | C3: 協力医療機関との契約の内容
A5: 事業所の名称 | C5: かながわ○○ホーム
A6: サービスの種類 | C6: 共同生活援助
A8: 協力医療機関の名称 | C8: 医療法人○○会 ○○○病院
A9: 所在地 | C9: 神奈川県○○市△△町○丁目○○番
A10: 診療科目 | C10: ○○科、○○科、○○科
A11: 事業所・施設からの距離 | C11: ○○ | E11: km | F11: （徒歩 ○○分 車 ○○分）
A12: 契約の内容
A45: 備考 | B45: 「契約の内容」は、契約書の写し等の添付でもかまいません。

Sheet 参考様式11（指定障害者支援施設等との連携体制）
A1: 参考様式11 | B1: 指定障害者支援施設等との連携体制及び支援の体制の概要
A3: 事業所の名称
A4: サービスの種類
A6: 連携及び支援を受ける施設の名称
A7: 所在地
A8: 事業所・施設からの距離 | E8: km | F8: （徒歩 分 車 分）
A9: 連携支援の概要
A50: 備考 | B50: バックアップ施設のない事業所は、運営法人等との連携体制、支援体制を記載して下さい。

Sheet 参考様式11(記載例）
A3: 参考様式11 | B3: 指定障害者支援施設等との連携体制及び支援の体制の概要
A5: 事業所の名称 | C5: かながわ○△ホーム
A6: サービスの種類 | C6: 共同生活援助
A8: 連携及び支援を受ける施設の名称 | C8: かながわ○△園
A9: 所在地 | C9: ○○市○○町○○－○○
A10: 事業所・施設からの距離 | C10: ○ | E10: km | F10: （徒歩 ○分 車 ○分）
A11: 連携支援の概要
A45: 備考 | B45: バックアップ施設のない事業所は、運営法人等との連携体制、支援体制を記載して下さい。

Sheet 参考様式12（障害福祉サービス事業等開始届出書）
A1: 障害福祉サービス事業等開始届出書
F2: 平成 年 月 日
A3: 横浜市長
D5: 届出者 所在地
D6: 名称
D7: 職・氏名
A9: 次のとおり障害福祉サービス事業等を開始しますので、届け出ます。
A11: １ 事業の種類及び内容
A14: ２ 経営者の氏名及び住所（法人であるときは、その名称及び主たる事務所の所在地）
A17: ３ 職員の定数及び職務の内容
A20: ４ 主な職員の氏名及び経歴
A23: ５ 事業を行おうとする区域（市町村の委託を受けて事業を行おうとする者にあって は、当該市町村の名称を含みます。）
A26: ６ 障害福祉サービス事業（療養介護、生活介護、短期入所、重度障害者等包括支援 （施設を必要とする障害福祉サービスに係るものに限る。）、自立訓練、就労移行 支援又は就労継続支援に限る。）を行おうとする者にあっては、当該事業の用に供 する施設の名称、種類（短期入所を行おうとする場合に限る。）、所在地及び利用 定員
A29: ７ 事業開始の予定年月日
A32: 備考 １ この届出書は、指定申請書と同時に提出してください。

Sheet 参考様式12(記載例)
A6: 障害福祉サービス事業等開始届出書
F7: 平成○○年○○月○○日
A8: 横浜市長
D11: 届出者 所在地
D12: 名称
D13: 職・氏名
A15: 次のとおり障害福祉サービス事業等を開始しますので、届け出ます。
A17: １ 事業の種類及び内容
A18: 種類：生活介護←指定申請書様式の第１号(事業等の種類)と合わせてください。
A19: 内容：生活介護計画の作成、食事の提供、入浴又は清拭、身体の介護、機能訓練、創作的 活動、生産的活動、余暇活動、健康管理、利用者又は家族に対する相談及び助言 ←運営規程(事業所が提供する事業の内容)と合わせてください。
A20: ２ 経営者の氏名及び住所（法人であるときは、その名称及び主たる事務所の所在地）
A21: 住所：神奈川県□□町××00-00←指定申請書様式の第１号(主たる事業所の所在地)と合わ せてください。
A22: 氏名：社会福祉法人××××←指定申請書様式の第１号(申請者の名称)と合わせてください。
A23: 理事長 △△ ○○ ←指定申請書様式の第１号(代表者)と合わせてください。
A24: ３ 職員の定数及び職務の内容←運営規程(職員の職種、員数及び職務内容)と合わせてください。
A25: 定数：２２名
A26: 職務：管理者 １名・事業所の従業者の管理及び業務の管理を一元的に行うとともに、業 所の従業者に対し法令等を遵守させるために必要な指揮命令を行う。 サービス管理責任者 １名・生活介護計画の作成に関することを行うほか、利用申 込者の心身の状況等の把握、利用者の自立した日常生活に向けた検討、他の従業 者に対する技術指導又は助言等を行う。 生活支援員 ８名・日常生活上の支援、相談、介護を行う。
A27: ４ 主な職員の氏名及び経歴←参考様式４経歴書(主な職歴)と合わせてください(１名のみ)。
... A39: 備考 １ この届出書は、指定申請書と同時に提出してください

Sheet 参考様式13（常時の連絡体制の確保の具体的方法）
A2: 参考様式1３
A3: 常時の連絡体制の確保の具体的方法
A5: 事業所の名称
A6: サービスの種類
A8: 連絡体制の内容 | C8: ※営業時間外の事業所の人員体制（宿直等）や利用者との連絡体制を含め、具体的に記載してください。

Sheet 参考様式13(記載例)
A2: 参考様式1３
A3: 常時の連絡体制の確保の具体的方法
A5: 事業所の名称 | C5: 自立生活援助事業所○○
A6: サービスの種類 | C6: 自立生活援助
A8: 連絡体制の内容 | C8: ※営業時間外の事業所の人員体制（宿直等）や利用者との連絡体制を含め、具体的に記載してください。
C10: 常時連絡可能な携帯電話（＊＊＊－＊＊＊＊－＊＊＊＊）を配備し、緊急事態発生時は速やかに、自立生活援助の職務を行う者が対応する。

Sheet 参考様式18(一般就労実績)
A1: 参考様式18 一般就労移行実績
A2: 平成 年 月 日
A4: 移行元サービス種類
A6: 【申請日の属する日から遡って過去3年間において、一般就労に移行した者を記載すること】
B7: 利用者の苗字のイニシャル | D7: 就職日 | F7: 就職先事業所名
A8: 1
A9: 2
A10: 3
A11: 4
A12: 5
A13: 6
A14: 7
A15: 8
A16: 9
A17: 10
A18: 11
A19: 12
... A37: 30
A38: 注１ 申請日の属する日から遡って過去３年間において、一般就労に移行した者について記入する。 一般就労の定義、雇用継続の状況は問わない。ただし、就労継続支援Ａ型事業所への移行は除く。 | M38: 生活介護
A39: 注２ 就労定着支援を申請する事業所ごとに作成し、指定申請書に添付すること。 | M39: 機能訓練
A40: 注３ 申請日の属する日から遡って過去３年間において、一般就労移行者数が３人以上いる場合は指定要件 を満たすこととなる。 | M40: 生活訓練
A41: 注４ 利用者の移行元事業所である一体的に運営する事業所（多機能型であってもどれか一つのサービスに 限る）のサービス種別を記入する。 | M41: 就労移行支援
A42: 注５ 適宜、欄は追加してください。 | M42: 就労継続支援A型
M43: 就労継続支援B型

Sheet 参考様式18(記載例)
A1: 参考様式18 一般就労移行実績
A2: 平成 30年 ８月 ５日
A4: 移行元サービス種類 | D4: 就労移行支援
A6: 【申請日の属する日から遡って過去3年間において、一般就労に移行した者を記載すること】
B7: 利用者の苗字のイニシャル | D7: 就職日 | F7: 就職先事業所名
A8: 1 | B8: I | D8: 43252 | F8: 〇〇市役所
A9: 2 | B9: A | D9: 43115 | F9: （株）〇〇〇
A10: 3 | B10: H | D10: 43052 | F10: （社福）○○○
A11: 4 | B11: O | D11: 43009 | F11: 〇〇病院
A12: 5 | B12: N | D12: 42826 | F12: （株）〇〇〇
A13: 6 | B13: M | D13: 42552 | F13: 〇〇市役所
A14: 7 | B14: K | D14: 42190 | F14: （社福）○○○
A15: 8
A16: 9
A17: 10
A18: 11
A19: 12
A20: 13
A21: 14
A22: 15
A23: 16
A24: 17
A25: 18
A26: 19
... A37: 30
A38: 注１ 申請日の属する日から遡って過去３年間において、一般就労に移行した者について記入する。 一般就労の定義、雇用継続の状況は問わない。ただし、就労継続支援Ａ型事業所への移行は除く。 | M38: 生活介護
A39: 注２ 就労定着支援を申請する事業所ごとに作成し、指定申請書に添付すること。 | M39: 機能訓練
A40: 注３ 申請日の属する日から遡って過去３年間において、一般就労移行者数が３人以上いる場合は指定要件 を満たすこととなる。 | M40: 生活訓練
A41: 注４ 利用者の移行元事業所である一体的に運営する事業所（多機能型であってもどれか一つのサービスに 限る）のサービス種別を記入する。 | M41: 就労移行支援
A42: 注５ 適宜、欄は追加してください。 | M42: 就労継続支援A型
M43: 就労継続支援B型

Sheet 参考様式19-１(利用者の推定数と就労定着支援員の員数)
A1: 参考様式19-１ | F1: 平成 年 月 日
A3: 利用者の推定数と従業者（就労定着支援員）の員数
A5: 起算日は指定申請日 | C5: 就労継続期間が６月に達した者の数
A6: 過去１年間 | D6: 人
A7: 過去２年間 | D7: 人
A8: 過去３年間 | D8: 人
A9: 合計 | C9: =SUM(C6:C8) -> 0 | D9: 人
A11: 利用者の推定数（過去３年間の総数×70％） | C11: =C9*0.7 -> 0 | D11: 人
A13: 就労定着支援員の員数 | C13: =ROUNDUP(C11/40,1) -> 0 | D13: 人 | E13: （常勤換算）
A15: 注 過去３年間のそれぞれの１年間において、一体的に運営する就労移行支援等を受けた後就労し、就労を継続している期間が６月に達した者の数を記入する。

Sheet 参考様式19-1(記載例)
A1: 参考様式19-１ | F1: 平成 年 月 日
A3: 利用者の推定数と従業者（就労定着支援員）の員数
A5: 起算日は指定申請日 | C5: 就労継続期間が６月に達した者の数
A6: 過去１年間 | C6: 4 | D6: 人
A7: 過去２年間 | C7: 1 | D7: 人
A8: 過去３年間 | C8: 1 | D8: 人
A9: 合計 | C9: =SUM(C6:C8) -> 6 | D9: 人
A11: 利用者の推定数（過去３年間の総数×70％） | C11: =C9*0.7 -> 4.2 | D11: 人
A13: 就労定着支援員の員数 | C13: =ROUNDUP(C11/40,1) -> 0.2 | D13: 人 | E13: （常勤換算）
A15: 注 過去３年間のそれぞれの１年間において、一体的に運営する就労移行支援等を受けた後就労し、就労を継続している期間が６月に達した者の数を記入する。

Sheet 参考様式19-２(６月定着者の状況)
A1: 参考様式19－２ | G1: 平成 年 月 日
A2: ６月定着者の状況（利用者の推定数・支援員数）
A3: ［指定申請年月日：平成 年 月 日］
A5: ①過去１年間において就労継続期間が６月に達した者
B6: 利用者の苗字のイニシャル | D6: 就職日 | F6: 就職先事業所名 | H6: 過去１年間※において6月に達した日 | J6: 届出時点の 継続状況 | K6: 移行元 サービス種別
A7: 1
A8: 2
A9: 3
A10: 4
A11: 5
H12: ※平成 年 月 日～平成 年 月 日
A14: ②過去２年前の１年間において就労継続期間が６月に達した者
B15: 利用者の苗字のイニシャル | D15: 就職日 | F15: 就職先事業所名 | H15: 過去２年前の１年間※において6月に達した日 | J15: 届出時点の 継続状況 | K15: 移行元 サービス種別
A16: 1
A17: 2
A18: 3
A19: 4
A20: 5
H21: ※平成 年 月 日～平成 年 月 日
A23: ③過去３年前の１年間において就労継続期間が６月に達した者
B24: 利用者の苗字のイニシャル | D24: 就職日 | F24: 就職先事業所名 | H24: 過去３年前の１年間※において6月に達した日 | J24: 届出時点の 継続状況 | K24: 移行元 サービス種別
A25: 1
A26: 2
A27: 3
A28: 4
A29: 5
H30: ※平成 年 月 日～平成 年 月 日 | L30: 継続 | M30: 生活介護
L31: 離職 | M31: 機能訓練
M32: 生活訓練
A33: 注１ 届出時点の継続状況には、就労が継続している場合には「継続」、離職している場合には「離職」と選択。 注２ 過去１～３年の起算日は指定申請日 注３ 行が足りない場合は適宜追加して記載。 注４ 利用者の移行元事業所である一体的に運営する事業所（多機能型であってもどれか一つのサービスに限る）のサービ ス種別を選択する。 | M33: 就労移行支援
M34: 就労継続支援A型
M35: 就労継続支援B型

Sheet 参考様式19-２(記載例)
A1: 参考様式19－２ | G1: 平成 30年 ８月 ５日
A2: ６月定着者の状況（利用者の推定数・支援員数）
A3: ［指定申請年月日：平成30年８月５日］
A5: ①過去１年間において就労継続期間が６月に達した者
B6: 利用者の苗字のイニシャル | D6: 就職日 | F6: 就職先事業所名 | H6: 過去１年間※において6月に達した日 | J6: 届出時点の 継続状況 | K6: 移行元 サービス種別
A7: 1 | B7: A | D7: 43115 | F7: （株）〇〇〇 | H7: 43295 | J7: 継続 | K7: 就労移行支援
A8: 2 | B8: H | D8: 43052 | F8: （社福）○○○ | H8: 43232 | J8: 継続 | K8: 就労移行支援
A9: 3 | B9: O | D9: 43009 | F9: 〇〇病院 | H9: 43190 | J9: 離職 | K9: 就労移行支援
A10: 4 | B10: N | D10: 42826 | F10: （株）〇〇〇 | H10: 43008 | J10: 継続 | K10: 就労移行支援
A11: 5
H12: ※平成29年８月６日～平成30年８月５日
A14: ②過去２年前の１年間において就労継続期間が６月に達した者
B15: 利用者の苗字のイニシャル | D15: 就職日 | F15: 就職先事業所名 | H15: 過去２年前の１年間※において6月に達した日 | J15: 届出時点の 継続状況 | K15: 移行元 サービス種別
A16: 1 | B16: M | D16: 42552 | F16: 〇〇市役所 | H16: 42735 | J16: 継続 | K16: 就労移行支援
A17: 2
A18: 3
A19: 4
A20: 5
H21: ※平成28年８月６日～平成29年８月５日
A23: ③過去３年前の１年間において就労継続期間が６月に達した者
B24: 利用者の苗字のイニシャル | D24: 就職日 | F24: 就職先事業所名 | H24: 過去３年前の１年間※において6月に達した日 | J24: 届出時点の 継続状況 | K24: 移行元 サービス種別
A25: 1 | B25: K | D25: 42190 | F25: （社福）○○○ | H25: 42373 | J25: 継続 | K25: 就労移行支援
A26: 2
A27: 3
A28: 4
A29: 5
H30: ※平成27年８月６日～平成28年８月５日 | L30: 継続 | M30: 生活介護
L31: 離職 | M31: 機能訓練
M32: 生活訓練
A33: 注１ 届出時点の継続状況には、就労が継続している場合には「継続」、離職している場合には「離職」と選択。 注２ 過去１～３年の起算日は指定申請日 注３ 行が足りない場合は適宜追加して記載。 注４ 利用者の移行元事業所である一体的に運営する事業所（多機能型であってもどれか一つのサービスに限る）のサービ ス種別を選択する。 | M33: 就労移行支援
M34: 就労継続支援A型
M35: 就労継続支援B型

Sheet 別紙2-1勤務体制一覧表(訪問系）
AX1: （訪問系サービス・相談支援） | CA1: ▼選択してください。
B2: 別紙２－１ | CA2: 居宅介護
B3: 従業者の勤務の体制及び勤務形態一覧表 | CA3: 重度訪問介護
CA4: 行動援護
B5: 事業所名 | CA5: 相談支援
B6: サービス種類 | K6: ▼選択してください。 | CA6: 同行援護
B8: 職種 | H8: 勤務 形態 | K8: 氏名 | R8: 第１週 | Y8: 第２週 | AF8: 第３週 | AM8: 第４週 | AT8: 4週の合計 | AW8: 週平均の勤務時間 | AZ8: 常勤換算後の人数 | BA8: 兼務先
P9: 日付 | R9: 1 | S9: 2 | T9: 3 | U9: 4 | V9: 5 | W9: 6 | X9: 7 | Y9: 8 | Z9: 9 | AA9: 10 | AB9: 11 | AC9: 12 | AD9: 13 | AE9: 14 | AF9: 15 | AG9: 16 | AH9: 17 | AI9: 18 | AJ9: 19 | AK9: 20 | AL9: 21 | AM9: 22 | AN9: 23 | AO9: 24 | AP9: 25 | AQ9: 26 | AR9: 27 | AS9: 28
P10: 曜日
P11: 開所日
B12: 管理者 | AT12: =SUM(R12:AS12) -> 0 | AW12: =AT12/4 -> 0
AT13: =SUM(R13:AS13) -> 0 | AW13: =AT13/4 -> 0
AT14: =SUM(R14:AS14) -> 0 | AW14: =AT14/4 -> 0
AT15: =SUM(R15:AS15) -> 0 | AW15: =AT15/4 -> 0
AT16: =SUM(R16:AS16) -> 0 | AW16: =AT16/4 -> 0
AT17: =SUM(R17:AS17) -> 0 | AW17: =AT17/4 -> 0
AT18: =SUM(R18:AS18) -> 0 | AW18: =AT18/4 -> 0
AT19: =SUM(R19:AS19) -> 0 | AW19: =AT19/4 -> 0
AT20: =SUM(R20:AS20) -> 0 | AW20: =AT20/4 -> 0
AT21: =SUM(R21:AS21) -> 0 | AW21: =AT21/4 -> 0
AT22: =SUM(R22:AS22) -> 0 | AW22: =AT22/4 -> 0
AT23: =SUM(R23:AS23) -> 0 | AW23: =AT23/4 -> 0
AT24: =SUM(R24:AS24) -> 0 | AW24: =AT24/4 -> 0
... AT27: =SUM(R27:AS27) -> 0 | AW27: =AT27/4 -> 0
B28: 合計 | AT28: =SUM(AT13:AT27) -> 0 | AW28: =SUM(AW13:AW27) -> 0 | AZ28: =IF(AND(AW28=0,AT29=0),0,ROUNDDOWN(AW28/AT29,1)) -> 0
B29: 当該事業所・施設において常勤職員が1週間に勤務すべき時間数 | AT29: 0

Sheet 別紙2-1【記載例】
AX1: （訪問系サービス） | CA1: ▼選択してください。
B2: 別紙２－１ | CA2: 居宅介護
B3: 従業者の勤務の体制及び勤務形態一覧表 | CA3: 重度訪問介護
CA4: 行動援護
B5: 事業所名 | K5: かながわ介護事業所 | CA5: 相談支援
B6: サービス種類 | K6: 居宅介護
B8: 職種 | H8: 勤務 形態 | K8: 氏名 | R8: 第１週 | Y8: 第２週 | AF8: 第３週 | AM8: 第４週 | AT8: 4週の合計 | AW8: 週平均の勤務時間 | AZ8: 常勤換算後の人数 | BA8: 兼務先
P9: 日付 | R9: 1 | S9: 2 | T9: 3 | U9: 4 | V9: 5 | W9: 6 | X9: 7 | Y9: 8 | Z9: 9 | AA9: 10 | AB9: 11 | AC9: 12 | AD9: 13 | AE9: 14 | AF9: 15 | AG9: 16 | AH9: 17 | AI9: 18 | AJ9: 19 | AK9: 20 | AL9: 21 | AM9: 22 | AN9: 23 | AO9: 24 | AP9: 25 | AQ9: 26 | AR9: 27 | AS9: 28
P10: 曜日 | R10: 月 | S10: 火 | T10: 水 | U10: 木 | V10: 金 | W10: 土 | X10: 日 | Y10: 月 | Z10: 火 | AA10: 水 | AB10: 木 | AC10: 金 | AD10: 土 | AE10: 日 | AF10: 月 | AG10: 火 | AH10: 水 | AI10: 木 | AJ10: 金 | AK10: 土 | AL10: 日 | AM10: 月 | AN10: 火 | AO10: 水 | AP10: 木 | AQ10: 金 | AR10: 土 | AS10: 日
P11: 開所日 | R11: ○ | S11: ○ | T11: ○ | U11: ○ | V11: ○ | Y11: ○ | Z11: ○ | AA11: ○ | AB11: ○ | AC11: ○ | AF11: ○ | AG11: ○ | AH11: ○ | AI11: ○ | AJ11: ○ | AM11: ○ | AN11: ○ | AO11: ○ | AP11: ○ | AQ11: ○
B12: 管理者 | H12: 常勤・兼務 | K12: かながわ 三郎 | R12: 8 | S12: 8 | T12: 8 | U12: 8 | V12: 8 | Y12: 8 | Z12: 8 | AA12: 8 | AB12: 8 | AC12: 8 | AF12: 8 | AG12: 8 | AH12: 8 | AI12: 8 | AJ12: 8 | AM12: 8 | AN12: 8 | AO12: 8 | AP12: 8 | AQ12: 8 | AT12: =SUM(R12:AS12) -> 160 | AW12: =AT12/4 -> 40 | BA12: かながわ介護事業所（訪問介護）
B13: サービス提供責任者 | H13: 常勤・兼務 | K13: きよかわ 村男 | R13: 8 | S13: 8 | T13: 8 | U13: 8 | V13: 8 | Y13: 8 | Z13: 8 | AA13: 8 | AB13: 8 | AC13: 8 | AF13: 8 | AG13: 8 | AH13: 8 | AI13: 8 | AJ13: 8 | AM13: 8 | AN13: 8 | AO13: 8 | AP13: 8 | AQ13: 8 | AT13: =SUM(R13:AS13) -> 160 | AW13: =AT13/4 -> 40 | BA13: かながわ介護事業所（訪問介護）
B14: ヘルパー | H14: 常勤・兼務 | K14: あいかわ 花子 | R14: 6 | S14: 6 | T14: 6 | U14: 6 | V14: 6 | Y14: 6 | Z14: 6 | AA14: 6 | AB14: 6 | AC14: 6 | AF14: 6 | AG14: 6 | AH14: 6 | AI14: 6 | AJ14: 6 | AM14: 6 | AN14: 6 | AO14: 6 | AP14: 6 | AQ14: 6 | AT14: =SUM(R14:AS14) -> 120 | AW14: =AT14/4 -> 30 | BA14: かながわ介護事業所（訪問介護）
B15: ヘルパー | H15: 非常勤・専従 | K15: 湯河 原野 | R15: 4 | S15: 4 | T15: 4 | U15: 4 | V15: 4 | Y15: 4 | Z15: 4 | AA15: 4 | AB15: 4 | AC15: 4 | AF15: 4 | AG15: 4 | AH15: 4 | AI15: 4 | AJ15: 4 | AM15: 4 | AN15: 4 | AO15: 4 | AP15: 4 | AQ15: 4 | AT15: =SUM(R15:AS15) -> 80 | AW15: =AT15/4 -> 20
B16: ヘルパー | H16: 非常勤・兼務 | K16: まな 鶴子 | R16: 4 | T16: 4 | U16: 4 | Y16: 4 | AA16: 4 | AB16: 4 | AF16: 4 | AH16: 4 | AI16: 4 | AM16: 4 | AO16: 4 | AP16: 4 | AT16: =SUM(R16:AS16) -> 48 | AW16: =AT16/4 -> 12 | BA16: かながわGH（世話人）
AT17: =SUM(R17:AS17) -> 0 | AW17: =AT17/4 -> 0
AT18: =SUM(R18:AS18) -> 0 | AW18: =AT18/4 -> 0
AT19: =SUM(R19:AS19) -> 0 | AW19: =AT19/4 -> 0
AT20: =SUM(R20:AS20) -> 0 | AW20: =AT20/4 -> 0
AT21: =SUM(R21:AS21) -> 0 | AW21: =AT21/4 -> 0
AT22: =SUM(R22:AS22) -> 0 | AW22: =AT22/4 -> 0
AT23: =SUM(R23:AS23) -> 0 | AW23: =AT23/4 -> 0
AT24: =SUM(R24:AS24) -> 0 | AW24: =AT24/4 -> 0
AT25: =SUM(R25:AS25) -> 0 | AW25: =AT25/4 -> 0
AT26: =SUM(R26:AS26) -> 0 | AW26: =AT26/4 -> 0
AT27: =SUM(R27:AS27) -> 0 | AW27: =AT27/4 -> 0
B28: 合計 | AT28: =SUM(AT13:AT27) -> 408 | AW28: =SUM(AW13:AW27) -> 102 | AZ28: =IF(AND(AW28=0,AT29=0),0,ROUNDDOWN(AW28/AT29,1)) -> 2.5
B29: 当該事業所・施設において常勤職員が1週間に勤務すべき時間数 | AT29: 40

Sheet ■管理者誓約書（障害福祉サービス事業者用）
A1: 指定障害福祉サービス事業所管理者誓約書
A3: 「横浜市指定障害福祉サービスの事業等の人員、設備、運営等の基準に関する条例（平成24年12月横浜市条例第64号）」の規定に従い、運営に関する基準を遵守し、当指定障害福祉サービス事業所の管理者の責務を適正に果たすことを誓約します。
M6: 平成 年 月 日
A8: 横浜市長
G10: 事業者名（開設法人名） | L10: 一般社団法人アンマー
G13: 代表者 職・氏名 | L13: 代表理事 貝畑明典 | Q13: 印
Q14: （代表者印）
G16: 事業所名 | L16: ='参考様式８（主たる対象者を特定する理由等）'!J6 -> コーリングサポ笠岡
G19: 管理者 氏名 | L19: 貝畑 明典 | Q19: 印
A24: 横浜市指定障害福祉サービスの事業等の人員、設備、運営等の基準に関する条例【抜粋】
A26: ■指定居宅介護事業所の場合
A27: （管理者及びサービス提供責任者の責務）
A28: 第31条 指定居宅介護事業所の管理者は、当該指定居宅介護事業所の従業者及び業務の管理を
A29: 一元的に行わなければならない。
A30: ２ 指定居宅介護事業所の管理者は、当該指定居宅介護事業所の従業者にこの章の規定を遵守させる
A31: ため必要な指揮命令を行うものとする。
A32: ＊第31条は、重度訪問介護、同行援護及び行動援護事業所に係る指定障害福祉サービスの事業について
A33: 準用されています。
A34: ■指定居宅介護事業所以外の指定障害福祉サービス事業所の場合
A35: （管理者の責務）
A36: 第68条 指定療養介護事業所の管理者は、当該指定療養介護事業所の従業者及び業務の管理その他の
... A42: 自立訓練（生活訓練）、就労移行支援、就労継続支援Ａ型、就労継続支援Ｂ型、共同生活援助。

Sheet 管理者誓約書（障害福祉サービス事業者用）
A1: 指定障害福祉サービス事業所管理者誓約書
A3: 「川崎市指定障害福祉サービスの事業等の人員、設備及び運営に関する基準等を
A4: 定める条例（平成24年川崎市条例第69号）」の規定に従い、運営に関する基準を遵守し、
A5: 当指定障害福祉サービス事業所の管理者の責務を適正に果たすことを誓約します。
A8: 令和 年 月 日
A10: 川崎市長 様
I12: 事業者名（開設法人名） 一般社団法人アンマー
I15: 代表者氏名 代表理事 貝畑 明典 | R15: 印
I18: 事業所名 シェル 川崎
I21: 管理者氏名 貝畑 明典 | R21: 印
A24: 川崎市指定障害福祉サービスの事業等の人員、設備及び運営に関する基準等を定める条例【抜粋】
A26: ■指定居宅介護事業所の場合
A27: （管理者及びサービス提供責任者の責務）
A28: 第31条 指定居宅介護事業所の管理者は、当該指定居宅介護事業所の従業者及び業務の管理を
A29: 一元的に行わなければならない。
A30: ２ 指定居宅介護事業所の管理者は、当該指定居宅介護事業所の従業者にこの節の規定を遵守
A31: させるため必要な指揮命令を行うものとする。
A32: ＊第31条は、重度訪問介護、同行援護及び行動援護事業所に係る指定障害福祉サービスの事業について準用されています。
A33: ■指定居宅介護事業所以外の指定障害福祉サービス事業所の場合
A34: （管理者の責務）
A35: 第68条 指定療養介護事業所の管理者は、当該指定療養介護事業所の従業者及び業務の管理
A36: その他の管理を一元的に行わなければならない。
... A41: 自立訓練（生活訓練）、就労移行支援、就労継続支援Ａ型、就労継続支援Ｂ型、共同生活援助。

Sheet Sheet1
B3: ①小宮 由紀博
B4: ②1980年4月21日
B5: ③東京都目黒区中目黒1-1-17 PWレジデンス201
B6: ④鍼灸師 、健康運動実践指導者、赤十字救急基礎講習終了者、アニマルフロー L1認定者
B7: ⑤2007年 ライトニングトーナメント優勝
B8: 2009年 RISE70kgトーナメント優勝
B9: 2016年 RKAウェルター級チャンピオン
B11: ①黒田哲広(クロダ アキヒロ)
B12: ②1978年4月28日
B13: ③杉並区堀ノ内1-5-5グランディール方南602
B14: ④自動車普通免許、日商簿記2級、JCAAベーシックトレーナー、ハイドロトーン認定トレーナー、食コンディショニングトレーナー
B15: ⑤第四代J-NETWORKライト級王者
... B37: 〒158-0098 東京都世田谷区上用賀３―１３―２２―２０８ 進藤義夫 でお願いします。電話番号は090-8845-3565です。

Sheet 別紙2-2【記載例】
AU2: （訪問系サービスを除くすべてのサービス） | BP2: ▼選択してください。
B3: 別紙２－２ | BP3: 療養介護
B4: 従業者の勤務の体制及び勤務形態一覧表 | BP4: 生活介護
BP5: 短期入所
B6: 事業所名 | K6: 生活介護かながわ | BP6: 共同生活援助
B7: サービス種類 | K7: 生活介護 | BP7: 施設入所支援
BP8: 自立訓練（生活訓練）宿泊型
B9: 職種 | H9: 勤務 形態 | K9: 氏名 | R9: 第１週 | Y9: 第２週 | AF9: 第３週 | AM9: 第４週 | AT9: 4週の合計 | AW9: 週平均の勤務時間 | AZ9: 常勤換算後の人数 | BA9: 加算等に係る資格 （実務経験） ・ 兼務先 | BP9: 自立訓練（生活訓練）
P10: 日付 | R10: 1 | S10: 2 | T10: 3 | U10: 4 | V10: 5 | W10: 6 | X10: 7 | Y10: 8 | Z10: 9 | AA10: 10 | AB10: 11 | AC10: 12 | AD10: 13 | AE10: 14 | AF10: 15 | AG10: 16 | AH10: 17 | AI10: 18 | AJ10: 19 | AK10: 20 | AL10: 21 | AM10: 22 | AN10: 23 | AO10: 24 | AP10: 25 | AQ10: 26 | AR10: 27 | AS10: 28 | BP10: 自立訓練（機能訓練）
P11: 曜日 | R11: 月 | S11: 火 | T11: 水 | U11: 木 | V11: 金 | W11: 土 | X11: 日 | Y11: 月 | Z11: 火 | AA11: 水 | AB11: 木 | AC11: 金 | AD11: 土 | AE11: 日 | AF11: 月 | AG11: 火 | AH11: 水 | AI11: 木 | AJ11: 金 | AK11: 土 | AL11: 日 | AM11: 月 | AN11: 火 | AO11: 水 | AP11: 木 | AQ11: 金 | AR11: 土 | AS11: 日 | BP11: 就労移行支援（一般型）
P12: 開所日 | R12: ○ | S12: ○ | T12: ○ | U12: ○ | V12: ○ | Y12: ○ | Z12: ○ | AA12: ○ | AB12: ○ | AC12: ○ | AF12: ○ | AG12: ○ | AH12: ○ | AI12: ○ | AJ12: ○ | AM12: ○ | AN12: ○ | AO12: ○ | AP12: ○ | AQ12: ○ | BP12: 就労移行支援（養成施設）
B13: 管理者 | H13: 常勤・兼務 | K13: かながわ 次郎 | R13: 8 | S13: 8 | T13: 8 | U13: 8 | V13: 8 | Y13: 8 | Z13: 8 | AA13: 8 | AB13: 8 | AC13: 8 | AF13: 8 | AG13: 8 | AH13: 8 | AI13: 8 | AJ13: 8 | AM13: 8 | AN13: 8 | AO13: 8 | AP13: 8 | AQ13: 8 | AT13: =SUM(R13:AS13) -> 160 | AW13: =AT13/4 -> 40 | AZ13: =ROUNDDOWN(AW13/AT33,1) -> 1 | BP13: 就労継続支援Ａ型
B14: サービス管理責任者 | H14: 常勤・専従 | K14: はこね 山雄 | R14: 8 | S14: 8 | T14: 8 | U14: 8 | V14: 8 | Y14: 8 | Z14: 8 | AA14: 8 | AB14: 8 | AC14: 8 | AF14: 8 | AG14: 8 | AH14: 8 | AI14: 8 | AJ14: 8 | AM14: 8 | AN14: 8 | AO14: 8 | AP14: 8 | AQ14: 8 | AT14: =SUM(R14:AS14) -> 160 | AW14: =AT14/4 -> 40 | AZ14: =ROUNDDOWN(AW14/AT33,1) -> 1 | BP14: 就労継続支援Ｂ型
B15: 生活支援員 | H15: 常勤・専従 | K15: やまだ 開成 | R15: 8 | S15: 8 | T15: 8 | U15: 8 | V15: 8 | Y15: 8 | Z15: 8 | AA15: 8 | AB15: 8 | AC15: 8 | AF15: 8 | AG15: 8 | AH15: 8 | AI15: 8 | AJ15: 8 | AM15: 8 | AN15: 8 | AO15: 8 | AP15: 8 | AQ15: 8 | AT15: =SUM(R15:AS15) -> 160 | AW15: =AT15/4 -> 40 | AZ15: =ROUNDDOWN(AW15/AT33,1) -> 1 | BA15: 介護福祉士 | BP15: 重度障害者等包括支援
B16: 生活支援員 | H16: 常勤・兼務 | K16: まつだ たろう | R16: 4 | S16: 4 | T16: 4 | U16: 4 | V16: 4 | Y16: 4 | Z16: 4 | AA16: 4 | AB16: 4 | AC16: 4 | AF16: 4 | AG16: 4 | AH16: 4 | AI16: 4 | AJ16: 4 | AM16: 4 | AN16: 4 | AO16: 4 | AP16: 4 | AQ16: 4 | AT16: =SUM(R16:AS16) -> 80 | AW16: =AT16/4 -> 20 | AZ16: =ROUNDDOWN(AW16/AT33,1) -> 0.5 | BA16: かながわＢ（生活支援員）/介護福祉士 | BP16: 自立生活援助
B17: 生活支援員 | H17: 常勤・専従 | K17: おおい 花子 | R17: 8 | S17: 8 | T17: 8 | U17: 8 | V17: 8 | Y17: 8 | Z17: 8 | AA17: 8 | AB17: 8 | AC17: 8 | AF17: 8 | AG17: 8 | AH17: 8 | AI17: 8 | AJ17: 8 | AM17: 8 | AN17: 8 | AO17: 8 | AP17: 8 | AQ17: 8 | AT17: =SUM(R17:AS17) -> 160 | AW17: =AT17/4 -> 40 | AZ17: =ROUNDDOWN(AW17/AT33,1) -> 1 | BA17: 社会福祉士 | BP17: 就労定着支援
B18: 生活支援員 | H18: 非常勤・兼務 | K18: なかい 春代 | R18: 3 | T18: 3 | V18: 3 | Y18: 3 | AA18: 3 | AC18: 3 | AF18: 3 | AH18: 3 | AJ18: 3 | AM18: 3 | AO18: 3 | AQ18: 3 | AT18: =SUM(R18:AS18) -> 36 | AW18: =AT18/4 -> 9 | AZ18: =ROUNDDOWN(AW18/AT33,1) -> 0.2 | BA18: かながわＢ（職業指導員)
B19: 生活支援員 | H19: 非常勤・専従 | K19: にのみや 夏子 | R19: 5 | S19: 5 | T19: 5 | Y19: 5 | Z19: 5 | AA19: 5 | AF19: 5 | AG19: 5 | AH19: 5 | AM19: 5 | AN19: 5 | AO19: 5 | AT19: =SUM(R19:AS19) -> 60 | AW19: =AT19/4 -> 15 | AZ19: =ROUNDDOWN(AW19/AT33,1) -> 0.3
B20: 生活支援員 | H20: 非常勤・専従 | K20: おおいそ 秋男 | S20: 5 | U20: 5 | V20: 5 | Z20: 5 | AB20: 5 | AC20: 5 | AG20: 5 | AI20: 5 | AJ20: 5 | AN20: 5 | AP20: 5 | AQ20: 5 | AT20: =SUM(R20:AS20) -> 60 | AW20: =AT20/4 -> 15 | AZ20: =ROUNDDOWN(AW20/AT33,1) -> 0.3
B21: 生活支援員 | H21: 非常勤・兼務 | K21: さむかわ 冬彦 | R21: 3 | T21: 3 | V21: 3 | Y21: 3 | AA21: 3 | AC21: 3 | AF21: 3 | AH21: 3 | AJ21: 3 | AM21: 3 | AO21: 3 | AQ21: 3 | AT21: =SUM(R21:AS21) -> 36 | AW21: =AT21/4 -> 9 | AZ21: =ROUNDDOWN(AW21/AT33,1) -> 0.2
B22: 看護師 | H22: 非常勤・専従 | K22: はやま 海子 | S22: 3 | U22: 3 | Z22: 3 | AB22: 3 | AG22: 3 | AI22: 3 | AN22: 3 | AP22: 3 | AT22: =SUM(R22:AS22) -> 24 | AW22: =AT22/4 -> 6 | AZ22: =ROUNDDOWN(AW22/AT33,1) -> 0.1 | BA22: 看護師
AT23: =SUM(R23:AS23) -> 0 | AW23: =AT23/4 -> 0 | AZ23: =ROUNDDOWN(AW23/AT33,1) -> 0
AT24: =SUM(R24:AS24) -> 0 | AW24: =AT24/4 -> 0 | AZ24: =ROUNDDOWN(AW24/AT33,1) -> 0
AT25: =SUM(R25:AS25) -> 0 | AW25: =AT25/4 -> 0 | AZ25: =ROUNDDOWN(AW25/AT33,1) -> 0
AT26: =SUM(R26:AS26) -> 0 | AW26: =AT26/4 -> 0 | AZ26: =ROUNDDOWN(AW26/AT33,1) -> 0
AT27: =SUM(R27:AS27) -> 0 | AW27: =AT27/4 -> 0 | AZ27: =ROUNDDOWN(AW27/AT33,1) -> 0
AT28: =SUM(R28:AS28) -> 0 | AW28: =AT28/4 -> 0 | AZ28: =ROUNDDOWN(AW28/AT33,1) -> 0
B29: 直接処遇職員 合計 | AT29: =SUM(AT15:AV28) -> 616 | AW29: =AT29/4 -> 154 | AZ29: =IF(AND(AW29=0,AT33=0),0,ROUNDDOWN(AW29/AT33,1)) -> 3.8
AT30: =SUM(R30:AS30) -> 0 | AW30: =AT30/4 -> 0 | AZ30: =ROUNDDOWN(AW30/AT33,1) -> 0
AT31: =SUM(R31:AS31) -> 0 | AW31: =AT31/4 -> 0 | AZ31: =ROUNDDOWN(AW31/AT34,1) -> #DIV/0!
AT32: =SUM(R32:AS32) -> 0 | AW32: =AT32/4 -> 0 | AZ32: =ROUNDDOWN(AW32/AT35,1) -> #DIV/0!
B33: 当該事業所・施設において常勤職員が1週間に勤務すべき時間数 | AT33: 40
BF47: 常勤・専従
BF48: 常勤・兼務
BF49: 非常勤・専従
BF50: 非常勤・兼務

Sheet 事業計画書① 
A1: 参考様式（事業計画書①）
A2: 事業計画書
B3: 事業所名又は施設名 | F3: ='別紙2-2勤務体制一覧表（訪問・相談系以外）'!K6 -> コーリングサポ笠岡
B4: サービスの種類 | F4: 就労移行支援
A6: １．事業の目的
A7: 支給決定を受けた利用者が適性な運営を管理するために必要な人員及び運営管理に関する事項を定め指定就労移行支援の円滑な運営管理を図るとともに、利用者の意思及び人格を尊重して、常に当該利用者の立場に立った適切な指定就労移行支援の提供を確保することを目的とする。
A11: ２．事業開始日 | D11: 令和 | F11: 3 | G11: 年 | H11: 4 | I11: 月 | J11: 1 | K11: 日
A12: ３．年間平均利用者数 | D12: 全体 | E12: 12.7 | G12: 人
F13: 就労移行支援 | M13: 12.7 | O13: 人
A15: ４．月別状況一覧表
B16: 令和 | C16: 3 | D16: 年 | E16: 4 | F16: 月 | G16: ～ | H16: 令和 | I16: 4 | J16: 年 | K16: 3 | L16: 月
A18: 月 項目 | B18: 4 | C18: 5 | D18: 6 | E18: 7 | F18: 8 | G18: 9 | H18: 10 | I18: 11 | J18: 12 | K18: 1 | L18: 2 | M18: 3 | N18: 合計 | P18: 月平均
B19: 月 | C19: 月 | D19: 月 | E19: 月 | F19: 月 | G19: 月 | H19: 月 | I19: 月 | J19: 月 | K19: 月 | L19: 月 | M19: 月
