Workbook

Sheet 6月分
A1: 平成 27年 6月度 | Q1: 出 勤 簿
B3: 日 | C3: 1 | D3: 2 | E3: 3 | F3: 4 | G3: 5 | H3: 6 | I3: 7 | J3: 8 | K3: 9 | L3: 10 | M3: 11 | N3: 12 | O3: 13 | P3: 14 | Q3: 15 | R3: 16 | S3: 17 | T3: 18 | U3: 19 | V3: 20 | W3: 21 | X3: 22 | Y3: 23 | Z3: 24 | AA3: 25 | AB3: 26 | AC3: 27 | AD3: 28 | AE3: 29 | AF3: 30 | AH3: 出勤日数 | AI3: 労働時間 | AJ3: 休日出勤日数 | AK3: 欠勤日数 | AL3: 遅刻早引時間 | AM3: 時間外労働
B4: 氏 名 曜 | C4: 月 | D4: 火 | E4: 水 | F4: 木 | G4: 金 | H4: 土 | I4: 日 | J4: 月 | K4: 火 | L4: 水 | M4: 木 | N4: 金 | O4: 土 | P4: 日 | Q4: 月 | R4: 火 | S4: 水 | T4: 木 | U4: 金 | V4: 土 | W4: 日 | X4: 月 | Y4: 火 | Z4: 水 | AA4: 木 | AB4: 金 | AC4: 土 | AD4: 日 | AE4: 月 | AF4: 火 | AM4: 早出残業 | AN4: 深夜 | AO4: 休日
A5: 1 | B5: 岡﨑 峻喬 | H5: 休 | I5: 休 | P5: 休 | V5: 休 | W5: 休 | AC5: 休 | AD5: 休 | AH5: 23 | AQ5: 280000 | AR5: 10000
A6: 2 | B6: 山内 雄司 | H6: 休 | I6: 休 | O6: 休 | P6: 休 | V6: 休 | W6: 休 | AC6: 休 | AD6: 休 | AH6: 22 | AQ6: 200000
A7: 3
A8: 4 | B8: 大元 照美 | I8: 休 | O8: 休 | P8: 休 | U8: 休 | W8: 休 | AC8: 休 | AD8: 休 | AH8: =時給計算書!C35 -> 24 | AI8: =時給計算書!F35 -> 6.8208333 | AQ8: 6000 | AS8: 858
A9: 5 | B9: 瀬戸 光代 | H9: 休 | I9: 休 | O9: 休 | P9: 休 | V9: 休 | W9: 休 | AC9: 休 | AD9: 休 | AH9: =時給計算書!C71 -> 21 | AI9: =時給計算書!F71 -> 4.93125 | AQ9: 800
A10: 6 | AQ10: 800
A11: 7
A12: 8 | B12: 山内 龍一 | H12: 休 | I12: 休 | N12: 休 | O12: 休 | P12: 休 | Q12: 休 | R12: 休 | S12: 休 | T12: 休 | U12: 休 | V12: 休 | W12: 休 | X12: 休 | Y12: 休 | Z12: 休 | AA12: 休 | AB12: 休 | AC12: 休 | AD12: 休 | AH12: 11 | AQ12: 1000
A13: 9 | B13: 山下恵美子 | H13: 休 | I13: 休 | N13: 休 | O13: 休 | P13: 休 | T13: 休 | V13: 休 | W13: 休 | AA13: 休 | AC13: 休 | AD13: 休 | AH13: 19 | AQ13: 1000
A14: 10 | B14: 川上 智樹 | AC14: 休 | AD14: 休 | AH14: 6 | AQ14: 1500
A15: 11 | B15: 上松 正和 | H15: 休 | I15: 休 | O15: 休 | P15: 休 | V15: 休 | W15: 休 | AC15: 休 | AD15: 休 | AH15: 22 | AQ15: 1500
A16: 12 | B16: 上松 浩二 | H16: 休 | I16: 休 | O16: 休 | P16: 休 | V16: 休 | W16: 休 | AC16: 休 | AD16: 休 | AH16: 22 | AQ16: 1500
A17: 13 | B17: 若林 哲也 | C17: 休 | G17: 休 | H17: 休 | I17: 休 | K17: 休 | O17: 休 | P17: 休 | R17: 休 | V17: 休 | W17: 休 | Y17: 休 | Z17: 休 | AA17: 休 | AB17: 休 | AC17: 休 | AD17: 休 | AE17: 休 | AF17: 休 | AH17: 12 | AQ17: 1000
A18: 14 | B18: 柏木 憲太 | H18: 休 | I18: 休 | O18: 休 | P18: 休 | V18: 休 | W18: 休 | AC18: 休 | AD18: 休 | AH18: 22 | AQ18: 1500
A19: 15 | B19: 大元裕美子 | H19: 休 | I19: 休 | O19: 休 | P19: 休 | U19: 休 | V19: 休 | W19: 休 | AC19: 休 | AD19: 休 | AH19: 20 | AQ19: 1000
A20: 16 | B20: 倉谷 円 | AQ20: 1000
A21: 17 | B21: 葛籠 沙葵 | C21: 休 | H21: 休 | I21: 休 | N21: 休 | O21: 休 | P21: 休 | V21: 休 | W21: 休 | Y21: 休 | AA21: 休 | AC21: 休 | AD21: 休 | AH21: 18 | AQ21: 1000
A22: 18 | B22: 岡田 直明 | D22: 休 | E22: 休 | F22: 休 | H22: 休 | I22: 休 | K22: 休 | M22: 休 | O22: 休 | P22: 休 | R22: 休 | T22: 休 | U22: 休 | V22: 休 | W22: 休 | Y22: 休 | AA22: 休 | AC22: 休 | AD22: 休 | AF22: 休 | AH22: 11 | AQ22: 1000
A23: 19 | B23: 神田 幸弘 | H23: 休 | I23: 休 | N23: 休 | O23: 休 | P23: 休 | R23: 休 | V23: 休 | W23: 休 | AC23: 休 | AD23: 休 | AH23: 20 | AQ23: 1000
A24: 20 | B24: 鹿室 泰洋 | D24: 休 | E24: 休 | F24: 休 | H24: 休 | I24: 休 | K24: 休 | L24: 休 | M24: 休 | O24: 休 | P24: 休 | Q24: 休 | R24: 休 | S24: 休 | T24: 休 | U24: 休 | V24: 休 | W24: 休 | X24: 休 | Y24: 休 | AA24: 休 | AC24: 休 | AD24: 休 | AE24: 休 | AF24: 休 | AH24: 6 | AQ24: 1000
A25: 21 | B25: 吉岡 一夫 | G25: 休 | H25: 休 | I25: 休 | O25: 休 | P25: 休 | V25: 休 | W25: 休 | AC25: 休 | AD25: 休 | AH25: 21 | AQ25: 1000
A26: 22 | B26: 宇江 寿江 | C26: 休 | H26: 休 | I26: 休 | M26: 休 | O26: 休 | P26: 休 | U26: 休 | V26: 休 | W26: 休 | AC26: 休 | AD26: 休 | AE26: 休 | AF26: 休 | AH26: 17 | AQ26: 1000
A27: 23 | B27: 吉原 祐平 | H27: 休 | I27: 休 | M27: 休 | O27: 休 | P27: 休 | V27: 休 | W27: 休 | AC27: 休 | AD27: 休 | AH27: 21 | AQ27: 1000
A28: 24 | B28: 櫻武 隆一 | H28: 休 | I28: 休 | O28: 休 | P28: 休 | V28: 休 | W28: 休 | AC28: 休 | AD28: 休 | AH28: 22 | AQ28: 1000
A29: 25 | B29: 志並 智美 | AB29: 休 | AC29: 休 | AD29: 休 | AE29: 休 | AH29: 5 | AQ29: 1000
A30: 26
A31: 27 | B31: 仁井 諭 | F31: 休 | G31: 休 | H31: 休 | I31: 休 | M31: 休 | N31: 休 | O31: 休 | P31: 休 | T31: 休 | U31: 休 | V31: 休 | W31: 休 | Z31: 休 | AA31: 休 | AB31: 休 | AC31: 休 | AD31: 休 | AH31: 13
A32: 28
A33: 29
A34: 30

Sheet 賃金集計表
A1: 賃 金 集 計 表
A2: 平成27年6月分
A4: 氏名 | B4: 労働日数 | C4: 給料体系 | D4: 労働時間数 | E4: 休日労働時間数 | F4: 早出残業時間数 | G4: 深夜労働時間数 | H4: 基本賃金 | I4: 家族手当 | J4: 住宅手当 | K4: 通勤手当 | L4: 精勤手当 | M4: 資格手当 | N4: 手当 | O4: 小計 | P4: 健康保険 | Q4: 厚生年金 | R4: 雇用保険 | S4: 所得税 | T4: 市民税 | V4: 弁当代 | W4: 小計 | X4: 差引支払金
A5: ='6月分'!B5 -> 岡﨑 峻喬 | B5: ='6月分'!AH5 -> 23 | C5: 280000 | H5: 280000 | M5: 10000 | O5: =SUM(H5:N5) -> 290000 | P5: 14042 | Q5: 24464 | R5: 1450 | S5: 4920 | W5: =SUM(P5:V5) -> 44876 | X5: =O5-W5 -> 245124
A6: 山内 雄司 | B6: ='6月分'!AH6 -> 22 | C6: 200000 | H6: 200000 | O6: =SUM(H6:N6) -> 200000 | S6: 3140 | U6: 50000 | W6: =SUM(P6:V6) -> 53140 | X6: =O6-W6 -> 146860
A8: 給料手当 | H8: =SUM(H5:H7) -> 480000 | L8: =SUM(L5:L7) -> 0 | M8: =SUM(M5:M7) -> 10000 | O8: =SUM(O5:O7) -> 490000 | P8: =SUM(P5:P7) -> 14042 | Q8: =SUM(Q5:Q7) -> 24464 | R8: =SUM(R5:R7) -> 1450 | S8: =SUM(S5:S7) -> 8060 | V8: =SUM(V5:V7) -> 0 | W8: =SUM(W5:W7) -> 98016 | X8: =SUM(X5:X7) -> 391984
A10: 大元 照美 | B10: ='6月分'!AH8 -> 24 | C10: 6000 | D10: =時給計算書!F35 -> 6.8208333 | E10: 1157 | F10: 1071 | G10: 1288 | H10: =B10*C10 -> 144000 | O10: =SUM(H10:N10) -> 144000 | P10: 8708 | Q10: 13106 | R10: =O10*5/1000 -> 720 | S10: 1850 | V10: 2800 | W10: =SUM(P10:V10) -> 27184 | X10: =O10-W10 -> 116816 | Z10: 25日/7Ｈ | AA10: 6000円 | AB10: 1H/858
A11: 瀬戸 光代 | B11: ='6月分'!AH9 -> 21 | C11: 800 | D11: ='6月分'!AI9 -> 4.93125 | F11: 1000 | H11: =D11*24*C11 -> 94680 | K11: 5000 | O11: =SUM(H11:N11) -> 99680 | S11: 720 | V11: 350 | W11: =SUM(P11:V11) -> 1070 | X11: =O11-W11 -> 98610
H12: =D12*24*C12 -> 0 | O12: =SUM(H12:N12) -> 0 | W12: =SUM(P12:V12) -> 0 | X12: =O12-W12 -> 0
A14: 原 賃金 | H14: =SUM(H10:H13) -> 238680 | K14: =SUM(K10:K12) -> 5000 | L14: =SUM(L9:L13) -> 0 | M14: =SUM(M10:M13) -> 0 | O14: =SUM(O10:O13) -> 243680 | P14: =SUM(P10:P12) -> 8708 | Q14: =SUM(Q10:Q13) -> 13106 | R14: =SUM(R10:R13) -> 720 | S14: =SUM(S10:S13) -> 2570 | V14: =SUM(V9:V13) -> 3150 | W14: =SUM(W10:W13) -> 28254 | X14: =O14-P14-Q14-R14-S14-V14 -> 215426
A16: 山内 龍一 | B16: ='6月分'!AH12 -> 11 | C16: 1000 | H16: =B16*C16 -> 11000 | O16: =SUM(H16:N16) -> 11000 | V16: 2900 | W16: =SUM(P16:V16) -> 2900 | X16: =O16-W16 -> 8100
A17: 山下恵美子 | B17: ='6月分'!AH13 -> 19 | C17: 1000 | H17: =B17*C17 -> 19000 | O17: =SUM(H17:N17) -> 19000 | V17: 6650 | W17: =SUM(P17:V17) -> 6650 | X17: =O17-W17 -> 12350
A18: 川上 智樹 | B18: ='6月分'!AH14 -> 6 | C18: 1500 | H18: =B18*C18 -> 9000 | O18: =SUM(H18:N18) -> 9000 | W18: =SUM(P18:V18) -> 0 | X18: =O18-W18 -> 9000
A19: 上松 正和 | B19: ='6月分'!AH15 -> 22 | C19: 1500 | H19: =B19*C19 -> 33000 | O19: =SUM(H19:N19) -> 33000 | V19: 1750 | W19: =SUM(P19:V19) -> 1750 | X19: =O19-W19 -> 31250
A20: 上松 浩二 | B20: ='6月分'!AH16 -> 22 | C20: 1500 | H20: =B20*C20 -> 33000 | O20: =SUM(H20:N20) -> 33000 | V20: 1750 | W20: =SUM(P20:V20) -> 1750 | X20: =O20-W20 -> 31250
A21: 若林 哲也 | B21: ='6月分'!AH17 -> 12 | C21: 1000 | H21: =B21*C21 -> 12000 | O21: =SUM(H21:N21) -> 12000 | W21: =SUM(P21:V21) -> 0 | X21: =O21-W21 -> 12000
A22: 柏木 憲太 | B22: ='6月分'!AH18 -> 22 | C22: 1500 | H22: =B22*C22 -> 33000 | N22: 5000 | O22: =SUM(H22:N22) -> 38000 | V22: 7700 | W22: =SUM(P22:V22) -> 7700 | X22: =O22-W22 -> 30300
A23: 大元裕美子 | B23: ='6月分'!AH19 -> 20 | C23: 1000 | H23: =B23*C23 -> 20000 | O23: =SUM(H23:N23) -> 20000 | W23: =SUM(P23:V23) -> 0 | X23: =O23-W23 -> 20000
A24: 倉谷 円 | B24: ='6月分'!AH20 -> 0 | C24: 1000 | H24: =B24*C24 -> 0 | O24: =SUM(H24:N24) -> 0 | W24: =SUM(P24:V24) -> 0 | X24: =O24-W24 -> 0
A25: 葛籠 沙葵 | B25: ='6月分'!AH21 -> 18 | C25: 1000 | H25: =B25*C25 -> 18000 | L25: 6650 | O25: =SUM(H25:N25) -> 24650 | V25: 6650 | W25: =SUM(P25:V25) -> 6650 | X25: =O25-W25 -> 18000
A26: ='6月分'!B22 -> 岡田 直明 | B26: ='6月分'!AH22 -> 11 | C26: 1000 | H26: =B26*C26 -> 11000 | O26: =SUM(H26:N26) -> 11000 | W26: =SUM(P26:V26) -> 0 | X26: =O26-W26 -> 11000
A27: ='6月分'!B23 -> 神田 幸弘 | B27: ='6月分'!AH23 -> 20 | C27: 1000 | H27: =B27*C27 -> 20000 | O27: =SUM(H27:N27) -> 20000 | V27: 2100 | W27: =SUM(P27:V27) -> 2100 | X27: =O27-W27 -> 17900
A28: 鹿室 泰洋 | B28: ='6月分'!AH24 -> 6 | C28: 1000 | H28: =B28*C28 -> 6000 | O28: =SUM(H28:N28) -> 6000 | W28: =SUM(P28:V28) -> 0 | X28: =O28-W28 -> 6000
A29: 吉岡 一夫 | B29: ='6月分'!AH25 -> 21 | C29: 1000 | H29: =B29*C29 -> 21000 | O29: =SUM(H29:N29) -> 21000 | V29: 5950 | W29: =SUM(P29:V29) -> 5950 | X29: =O29-W29 -> 15050
A30: 宇江 寿江 | B30: ='6月分'!AH26 -> 17 | C30: 1000 | H30: =B30*C30 -> 17000 | O30: =SUM(H30:N30) -> 17000 | W30: =SUM(P30:V30) -> 0 | X30: =O30-W30 -> 17000
A31: 吉原 祐平 | B31: ='6月分'!AH27 -> 21 | C31: 1000 | H31: =B31*C31 -> 21000 | L31: 7350 | O31: =SUM(H31:N31) -> 28350 | V31: 7350 | W31: =SUM(P31:V31) -> 7350 | X31: =O31-W31 -> 21000
A32: 櫻武 隆一 | B32: ='6月分'!AH28 -> 22 | C32: 1000 | H32: =B32*C32 -> 22000 | L32: 7700 | O32: =SUM(H32:N32) -> 29700 | V32: 7700 | W32: =SUM(P32:V32) -> 7700 | X32: =O32-W32 -> 22000
A33: 志並 智美 | B33: ='6月分'!AH29 -> 5 | C33: 1000 | H33: =B33*C33 -> 5000 | O33: =SUM(H33:N33) -> 5000 | W33: =SUM(P33:V33) -> 0 | X33: =O33-W33 -> 5000
A36: 訓練等給付費 | H36: =SUM(H16:H35) -> 311000 | K36: =SUM(K16:K35) -> 0 | L36: =SUM(L16:L25) -> 6650 | M36: =SUM(M16:M25) -> 0 | N36: =SUM(N15:N35) -> 5000 | O36: =SUM(O16:O34) -> 337700 | V36: =SUM(V16:V34) -> 50500 | W36: =SUM(W16:W35) -> 50500 | X36: =SUM(X16:X35) -> 287200
H38: =B38*C38 -> 0 | O38: =SUM(H38:N38) -> 0 | W38: =SUM(P38:V38) -> 0 | X38: =O38-W38 -> 0
H39: =B39*C39 -> 0 | O39: =SUM(H39:N39) -> 0 | W39: =SUM(P39:V39) -> 0 | X39: =O39-W39 -> 0
A40: 仁井 諭 | B40: ='6月分'!AH31 -> 13 | C40: 800 | H40: =B40*C40 -> 10400 | O40: =SUM(H40:N40) -> 10400 | W40: =SUM(P40:V40) -> 0 | X40: =O40-W40 -> 10400
H41: =B41*C41 -> 0 | O41: =SUM(H41:N41) -> 0 | V41: 0 | W41: =SUM(P41:V41) -> 0 | X41: =O41-W41 -> 0
H42: =B42*C42 -> 0 | O42: =SUM(H42:N42) -> 0 | V42: 0 | W42: =SUM(P42:V42) -> 0 | X42: =O42-W42 -> 0
A44: 謝金 | H44: =SUM(H38:H43) -> 10400 | L44: =SUM(L38:L43) -> 0 | M44: =SUM(M38:M42) -> 0 | O44: =SUM(O38:O43) -> 10400 | V44: =SUM(V38:V43) -> 0 | W44: =SUM(W38:W43) -> 0 | X44: =SUM(X38:X43) -> 10400
A45: 合計 | H45: =H8+H14+H36+H44 -> 1040080 | I45: =I8+I14+I36+I44 -> 0 | J45: =J8+J14+J36+J44 -> 0 | K45: =K8+K14+K36+K44 -> 5000 | L45: =L8+L14+L36+L44 -> 6650 | M45: =M8+M14+M36+M44 -> 10000 | N45: =N8+N14+N36+N44 -> 5000 | O45: =O8+O14+O36+O44 -> 1081780 | P45: =P8+P14+P36+P42 -> 22750 | Q45: =Q8+Q14+Q36+Q42 -> 37570 | R45: =R8+R14+R36+R42 -> 2170 | S45: =S8+S14+S36+S42 -> 10630 | T45: =T8+T14+T36+T42 -> 0 | U45: =U8+U14+U36+U42 -> 0 | V45: =V8+V14+V36+V44 -> 53650 | W45: =W8+W14+W36+W44 -> 176770 | X45: =O45-P45-Q45-R45-S45-V45 -> 955010
O47: =H45+I45+J45+K45+L45+M45+N45 -> 1066730

Sheet 給料支払明細書
A1: 給料支払明細書 | M1: 平成27年6月分
A3: 氏名 | C3: =賃金集計表!A5 -> 岡﨑 峻喬 | G3: 殿 | H3: 労働日数 | K3: 労働時間 | N3: 時間外労働時間
H4: =賃金集計表!B5 -> 23
A6: 基本給 | C6: 時間外労働時間 | I6: 手当
A7: =賃金集計表!H5 -> 280000 | I7: =賃金集計表!M5 -> 10000
A9: 社会保険料 | C9: 厚生年金 | E9: 雇用保険料 | G9: 市民税 | I9: 所得税 | O9: 弁当代
A10: =賃金集計表!P5 -> 14042 | C10: =賃金集計表!Q5 -> 24464 | E10: =賃金集計表!R5 -> 1450 | G10: =賃金集計表!T5 -> 0 | I10: =賃金集計表!S5 -> 4920 | O10: =賃金集計表!V5 -> 0
A12: 総支給額 | D12: 控除額 | G12: 差引支給額 | K12: 一般社団法人 チャレンジド尾道
A13: =SUM(A7:P7) -> 290000 | D13: =SUM(A10:P10) -> 44876 | G13: =A13-D13 -> 245124 | K13: 就労継続支援（Ｂ型）施設 カイト御調
A16: 給料支払明細書 | M16: 平成27年6月分
A18: 氏名 | C18: =賃金集計表!A6 -> 山内 雄司 | G18: 殿 | H18: 労働日数 | K18: 労働時間 | N18: 時間外労働時間
H19: =賃金集計表!B6 -> 22
A21: 基本給 | C21: 時間外労働時間 | I21: 手当
A22: =賃金集計表!H6 -> 200000
A24: 社会保険料 | C24: 厚生年金 | E24: 雇用保険料 | G24: 市民税 | I24: 所得税 | M24: ETC | O24: 弁当代
I25: =賃金集計表!S6 -> 3140 | M25: =賃金集計表!U6 -> 50000 | O25: =賃金集計表!V6 -> 0
A27: 総支給額 | D27: 控除額 | G27: 差引支給額 | K27: 一般社団法人 チャレンジド尾道
A28: =SUM(A22:P22) -> 200000 | D28: =SUM(A25:P25) -> 53140 | G28: =A28-D28 -> 146860 | K28: 就労継続支援（Ｂ型）施設 カイト御調
A31: 給料支払明細書 | M31: 平成27年6月分
A33: 氏名 | G33: 殿 | H33: 労働日数 | K33: 労働時間 | N33: 時間外労働時間
A36: 基本給 | C36: 時間外労働時間 | I36: 手当
A39: 社会保険料 | C39: 厚生年金 | E39: 雇用保険料 | G39: 市民税 | I39: 所得税 | O39: 弁当代
A42: 総支給額 | D42: 控除額 | G42: 差引支給額 | K42: 一般社団法人 チャレンジド尾道
A43: =SUM(A37:P37) -> 0 | D43: =SUM(A40:P40) -> 0 | G43: =A43-D43 -> 0 | K43: 就労継続支援（Ｂ型）施設 カイト御調
A46: 給料支払明細書 | M46: 平成27年6月分
A48: 氏名 | C48: =賃金集計表!A10 -> 大元 照美 | G48: 殿 | H48: 労働日数 | K48: 労働時間 | N48: 時間外労働時間
H49: =賃金集計表!B10 -> 24 | R49: 1日＝6000
A51: 基本給 | C51: 時間外労働時間 | I51: 手当
A52: =賃金集計表!H10 -> 144000 | I52: =賃金集計表!M10 -> 0
A54: 社会保険料 | C54: 厚生年金 | E54: 雇用保険料 | G54: 市民税 | I54: 所得税 | O54: 弁当代
A55: =賃金集計表!P10 -> 8708 | C55: =賃金集計表!Q10 -> 13106 | E55: =賃金集計表!R10 -> 720 | G55: =賃金集計表!T10 -> 0 | I55: =賃金集計表!S10 -> 1850 | O55: =賃金集計表!V10 -> 2800
A57: 総支給額 | D57: 控除額 | G57: 差引支給額 | K57: 一般社団法人 チャレンジド尾道
A58: =SUM(A52:P52) -> 144000 | D58: =SUM(A55:P55) -> 27184 | G58: =A58-D58 -> 116816 | K58: 就労継続支援（Ｂ型）施設 カイト御調
A61: 給料支払明細書 | M61: 平成27年6月分
A63: 氏名 | C63: =賃金集計表!A11 -> 瀬戸 光代 | G63: 殿 | H63: 労働日数 | K63: 労働時間 | N63: 時間外労働時間
H64: =賃金集計表!B11 -> 21 | K64: =賃金集計表!D11 -> 4.93125 | N64: ='6月分'!AM22 -> 0 | R64: 4.2263889 | S64: 800 | T64: =R64*S64 -> 3381.1111
A66: 基本給 | C66: 時間外労働時間 | I66: 手当
A67: =賃金集計表!H11 -> 94680 | I67: =賃金集計表!K11 -> 5000
A69: 社会保険料 | C69: 厚生年金 | E69: 雇用保険料 | G69: 市民税 | I69: 所得税 | O69: 弁当代
I70: =賃金集計表!S11 -> 720 | O70: =賃金集計表!V11 -> 350
...

Sheet 給料支払明細書（2）
A1: 給料支払明細書 | J1: 給料支払明細書 | S1: 給料支払明細書 | AB1: 給料支払明細書
C3: 平成 | D3: 27 | E3: 年 | F3: 5 | G3: 月分 | L3: 平成 | M3: 27 | N3: 年 | O3: 5 | P3: 月分 | U3: 平成 | V3: 27 | W3: 年 | X3: 5 | Y3: 月分 | AD3: 平成 | AE3: 27 | AF3: 年 | AG3: 5 | AH3: 月分
A4: 所属 | B4: ： | C4: カイト御調 | J4: 所属 | K4: ： | L4: カイト御調 | S4: 所属 | T4: ： | U4: カイト御調 | AB4: 所属 | AC4: ： | AD4: カイト御調
A5: ='6月分'!B5 -> 岡﨑 峻喬 | J5: =賃金集計表!A6 -> 山内 雄司 | S5: =賃金集計表!A10 -> 大元 照美 | AB5: =賃金集計表!A11 -> 瀬戸 光代
H6: 殿 | Q6: 殿 | Z6: 殿 | AI6: 殿
A8: 賃金計算期間 | E8: 5月1日～5月31日 | J8: 賃金計算期間 | N8: 5月1日～5月31日 | S8: 賃金計算期間 | W8: 5月1日～5月31日 | AB8: 賃金計算期間 | AF8: 5月1日～5月31日
A9: 労働日数 | G9: ='6月分'!AH5 -> 23 | H9: 日 | J9: 労働日数 | P9: ='6月分'!AH7 -> 0 | Q9: 日 | S9: 労働日数 | Y9: 23 | Z9: 日 | AB9: 労働日数 | AH9: ='6月分'!AH11 -> 0 | AI9: 日
A10: 労働時間数 | F10: 時間 | H10: 分 | J10: 労働時間数 | O10: 時間 | Q10: 分 | S10: 労働時間数 | X10: 時間 | Z10: 分 | AB10: 労働時間数 | AF10: 103 | AG10: 時間 | AH10: 28 | AI10: 分
A11: 休日労働時間数 | F11: 時間 | H11: 分 | J11: 休日労働時間数 | O11: 時間 | Q11: 分 | S11: 休日労働時間数 | X11: 時間 | Z11: 分 | AB11: 休日労働時間数 | AG11: 時間 | AI11: 分
A12: 早出残業時間数 | F12: 時間 | H12: 分 | J12: 早出残業時間数 | O12: 時間 | Q12: 分 | S12: 早出残業時間数 | X12: 時間 | Z12: 分 | AB12: 早出残業時間数 | AG12: 時間 | AI12: 分
A13: 深夜労働時間数 | F13: 時間 | H13: 分 | J13: 深夜労働時間数 | O13: 時間 | Q13: 分 | S13: 深夜労働時間数 | X13: 時間 | Z13: 分 | AB13: 深夜労働時間数 | AG13: 時間 | AI13: 分
A14: 基本賃金 | E14: =賃金集計表!H5 -> 280000 | J14: 基本賃金 | N14: =賃金集計表!H6 -> 200000 | S14: 基本賃金 | W14: =賃金集計表!H10 -> 144000 | AB14: 基本賃金 | AF14: =賃金集計表!H11 -> 94680
A15: 所定時間外割増賃金 | J15: 所定時間外割増賃金 | S15: 所定時間外割増賃金 | AB15: 所定時間外割増賃金
A16: 手当 | B16: 家族手当 | J16: 手当 | K16: 家族手当 | S16: 手当 | T16: 家族手当 | AB16: 手当 | AC16: 家族手当
B17: 住宅手当 | K17: 住宅手当 | T17: 住宅手当 | AC17: 住宅手当
B18: 通勤手当 | K18: 通勤手当 | T18: 通勤手当 | AC18: 通勤手当 | AF18: =賃金集計表!K11 -> 5000
B19: 精勤手当 | K19: 精勤手当 | T19: 精勤手当 | AC19: 精勤手当
B20: 資格手当 | E20: =賃金集計表!M5 -> 10000 | K20: 資格手当 | T20: 資格手当 | W20: =賃金集計表!M10 -> 0 | AC20: 資格手当
A22: 小計 | E22: =賃金集計表!O5 -> 290000 | J22: 小計 | N22: =賃金集計表!O6 -> 200000 | S22: 小計 | W22: =賃金集計表!O10 -> 144000 | AB22: 小計 | AF22: =賃金集計表!O11 -> 99680
A23: 控除額 | B23: 健康保険 | E23: =賃金集計表!P5 -> 14042 | J23: 控除額 | K23: 健康保険 | S23: 控除額 | T23: 健康保険 | AB23: 控除額 | AC23: 健康保険
B24: 厚生年金 | E24: =賃金集計表!Q5 -> 24464 | K24: 厚生年金 | T24: 厚生年金 | AC24: 厚生年金
B25: 雇用保険 | E25: =賃金集計表!R5 -> 1450 | K25: 雇用保険 | T25: 雇用保険 | AC25: 雇用保険
B26: 所得税 | E26: =賃金集計表!S5 -> 4920 | K26: 所得税 | N26: =賃金集計表!S6 -> 3140 | T26: 所得税 | W26: =賃金集計表!S10 -> 1850 | AC26: 所得税
B27: 市民税 | E27: =賃金集計表!T5 -> 0 | K27: 市民税 | T27: 市民税 | AC27: 市民税
T29: 弁当代 | W29: =賃金集計表!V10 -> 2800 | AC29: 弁当代 | AF29: =賃金集計表!V11 -> 350
B30: 小計 | E30: =賃金集計表!W5 -> 44876 | K30: 小計 | N30: =賃金集計表!W6 -> 53140 | T30: 小計 | W30: =賃金集計表!W10 -> 27184 | AC30: 小計 | AF30: =賃金集計表!W11 -> 1070
A31: 差引支払額 | E31: =賃金集計表!X5 -> 245124 | J31: 差引支払額 | N31: =賃金集計表!X6 -> 146860 | S31: 差引支払額 | W31: =賃金集計表!X10 -> 116816 | AB31: 差引支払額 | AF31: =賃金集計表!X11 -> 98610
A32: （事業所名） | G32: 印 | J32: （事業所名） | P32: 印 | S32: （事業所名） | Y32: 印 | AB32: （事業所名） | AH32: 印
A33: 一般社団法人 チャレンジド尾道 | J33: 一般社団法人 チャレンジド尾道 | S33: 一般社団法人 チャレンジド尾道 | AB33: 一般社団法人 チャレンジド尾道
A34: カイト 御調 | J34: カイト 御調 | S34: カイト 御調 | AB34: カイト 御調
A35: 給料支払明細書 | J35: 給料支払明細書 | S35: 給料支払明細書 | AB35: 給料支払明細書
C37: 平成 | D37: 27 | E37: 年 | F37: 5 | G37: 月分 | L37: 平成 | N37: 年 | P37: 月分 | U37: 平成 | W37: 年 | Y37: 月分 | AD37: 平成 | AF37: 年 | AH37: 月分
A38: 所属 | B38: ： | C38: カイト御調 | J38: 所属 | K38: ： | L38: カイト御調 | S38: 所属 | T38: ： | U38: カイト御調 | AB38: 所属 | AC38: ： | AD38: カイト御調
A39: =賃金集計表!A12 -> 0
H40: 殿 | Q40: 殿 | Z40: 殿 | AI40: 殿
A42: 賃金計算期間 | E42: 5月1日～5月31日 | J42: 賃金計算期間 | N42: 5月1日～5月31日 | S42: 賃金計算期間 | W42: 5月1日～5月31日 | AB42: 賃金計算期間 | AF42: 5月1日～5月31日
A43: 労働日数 | H43: 日 | J43: 労働日数 | Q43: 日 | S43: 労働日数 | Z43: 日 | AB43: 労働日数 | AI43: 日
A44: 労働時間数 | F44: 時間 | H44: 分 | J44: 労働時間数 | O44: 時間 | Q44: 分 | S44: 労働時間数 | X44: 時間 | Z44: 分 | AB44: 労働時間数 | AG44: 時間 | AI44: 分
A45: 休日労働時間数 | F45: 時間 | H45: 分 | J45: 休日労働時間数 | O45: 時間 | Q45: 分 | S45: 休日労働時間数 | X45: 時間 | Z45: 分 | AB45: 休日労働時間数 | AG45: 時間 | AI45: 分
A46: 早出残業時間数 | F46: 時間 | H46: 分 | J46: 早出残業時間数 | O46: 時間 | Q46: 分 | S46: 早出残業時間数 | X46: 時間 | Z46: 分 | AB46: 早出残業時間数 | AG46: 時間 | AI46: 分
...

Sheet 時給計算書
C1: 氏名 | D1: 大元 照美
C2: 計算年月 | D2: 平成27年 | E2: 6月
A3: 日 | B3: 曜日 | C3: 出社時間 | D3: 退社時間 | E3: 休憩時間 | F3: 勤務時間
A4: 1 | B4: 月 | C4: 0.36944444 | D4: 0.72430556 | E4: 0.041666667 | F4: =D4-C4-E4 -> 0.31319444 | G4: 0.021527778
A5: 2 | B5: 火 | C5: 0.36736111 | D5: 0.70763889 | E5: 0.041666667 | F5: =D5-C5-E5 -> 0.29861111 | G5: 0.0069444444
A6: 3 | B6: 水 | C6: 0.36666667 | D6: 0.70972222 | E6: 0.041666667 | F6: =D6-C6-E6 -> 0.30138889 | G6: 0.0097222222
A7: 4 | B7: 木 | C7: 0.36944444 | D7: 0.72013889 | E7: 0.041666667 | F7: =D7-C7-E7 -> 0.30902778 | G7: 0.017361111
A8: 5 | B8: 金 | C8: 0.36875 | D8: 0.71041667 | E8: 0.041666667 | F8: =D8-C8-E8 -> 0.3 | G8: 0.0083333333
A9: 6 | B9: 土 | C9: 0.375 | D9: 0.62708333 | E9: 0.041666667 | F9: =D9-C9-E9 -> 0.21041667 | G9: 0.0020833333
A10: 7 | B10: 日 | F10: =D10-C10-E10 -> 0
A11: 8 | B11: 月 | C11: 0.36944444 | D11: 0.70902778 | E11: 0.041666667 | F11: =D11-C11-E11 -> 0.29791667 | G11: 0.00625
A12: 9 | B12: 火 | C12: 0.375 | D12: 0.71805556 | E12: 0.041666667 | F12: =D12-C12-E12 -> 0.30138889 | G12: 0.0097222222
A13: 10 | B13: 水 | C13: 0.37222222 | D13: 0.66875 | E13: 0.041666667 | F13: =D13-C13-E13 -> 0.25486111 | H13: 0.036805556
A14: 11 | B14: 木 | C14: 0.36597222 | D14: 0.71527778 | E14: 0.041666667 | F14: =D14-C14-E14 -> 0.30763889 | G14: 0.015972222
A15: 12 | B15: 金 | C15: 0.36875 | D15: 0.70972222 | E15: 0.041666667 | F15: =D15-C15-E15 -> 0.29930556 | G15: 0.0076388889
A16: 13 | B16: 土 | F16: =D16-C16-E16 -> 0
A17: 14 | B17: 日 | F17: =D17-C17-E17 -> 0
A18: 15 | B18: 月 | C18: 0.36875 | D18: 0.70902778 | E18: 0.041666667 | F18: =D18-C18-E18 -> 0.29861111 | G18: 0.0069444444
A19: 16 | B19: 火 | C19: 0.37152778 | D19: 0.71041667 | E19: 0.041666667 | F19: =D19-C19-E19 -> 0.29722222 | G19: 0.0055555556
A20: 17 | B20: 水 | C20: 0.36597222 | D20: 0.71458333 | E20: 0.041666667 | F20: =D20-C20-E20 -> 0.30694444 | G20: 0.015277778
A21: 18 | B21: 木 | C21: 0.36944444 | D21: 0.71875 | E21: 0.041666667 | F21: =D21-C21-E21 -> 0.30763889 | G21: 0.015972222
A22: 19 | B22: 金 | F22: =D22-C22-E22 -> 0
A23: 20 | B23: 土 | C23: 0.37222222 | D23: 0.60972222 | E23: 0.041666667 | F23: =D23-C23-E23 -> 0.19583333 | H23: 0.0125
A24: 21 | B24: 日 | F24: =D24-C24-E24 -> 0
A25: 22 | B25: 月 | C25: 0.44027778 | D25: 0.70763889 | E25: 0.041666667 | F25: =D25-C25-E25 -> 0.22569444 | H25: 0.065972222
A26: 23 | B26: 火 | C26: 0.36736111 | D26: 0.70833333 | E26: 0.041666667 | F26: =D26-C26-E26 -> 0.29930556 | G26: 0.0076388889
A27: 24 | B27: 水 | C27: 0.36666667 | D27: 0.70972222 | E27: 0.041666667 | F27: =D27-C27-E27 -> 0.30138889 | G27: 0.0097222222
A28: 25 | B28: 木 | C28: 0.37222222 | D28: 0.71111111 | E28: 0.041666667 | F28: =D28-C28-E28 -> 0.29722222 | G28: 0.0055555556
A29: 26 | B29: 金 | C29: 0.36597222 | D29: 0.70972222 | E29: 0.041666667 | F29: =D29-C29-E29 -> 0.30208333 | G29: 0.010416667
A30: 27 | B30: 土 | C30: 0.37222222 | D30: 0.58472222 | E30: 0.041666667 | F30: =D30-C30-E30 -> 0.17083333 | H30: 0.0375
A31: 28 | B31: 日 | F31: =D31-C31-E31 -> 0
A32: 29 | B32: 月 | C32: 0.36805556 | D32: 0.73472222 | E32: 0.041666667 | F32: =D32-C32-E32 -> 0.325 | G32: 0.033333333
A33: 30 | B33: 火 | C33: 0.37152778 | D33: 0.7125 | E33: 0.041666667 | F33: =D33-C33-E33 -> 0.29930556 | G33: 0.0076388889
F34: =D34-C34-E34 -> 0
C35: 24 | E35: 合計 | F35: =SUM(F4:F34) -> 6.8208333 | G35: =SUM(G4:G34) -> 0.22361111 | H35: =SUM(H4:H34) -> 0.15277778
C37: 氏名 | D37: 瀬戸 光代
C38: 計算年月 | D38: 平成27年 | E38: 6月
A39: 日 | B39: 曜日 | C39: 出社時間 | D39: 退社時間 | E39: 休憩時間 | F39: 勤務時間
A40: 1 | B40: 月 | C40: 0.37708333 | D40: 0.64861111 | E40: 0.041666667 | F40: =D40-C40-E40 -> 0.22986111
A41: 2 | B41: 火 | C41: 0.39097222 | D41: 0.64930556 | E41: 0.041666667 | F41: =D41-C41-E41 -> 0.21666667
...

Sheet 6月集計表
A1: 6月集計表
A2: 支払先 | C2: 内容 | G2: 支払予定 | H2: 金額 | I2: 支払方法
A3: ゴトウ石油㈱ | C3: ガソリン代 | G3: 42202 | H3: 138512 | I3: 振込み
A4: こさこ電気 | C4: 中古冷蔵庫1台 廃棄冷蔵庫処分代2台 | G4: 42202 | H4: 22956 | I4: 振込み
A5: ミール | C5: 弁当代 | G5: 42202 | H5: 57620 | I5: 現金
A9: 従業員 | C9: 6月分給料 | G9: 42202 | H9: 657410 | I9: 現金
A10: 利用者 | C10: 6月分工賃 | G10: 42202 | H10: 297600 | I10: 現金
G12: 合計 | H12: =SUM(H3:H11) -> 1174098
A14: 請求先 | C14: 内容 | G14: 入金予定 | H14: 金額
A15: 広島県国保連 | C15: 訓練給付金(6月請求金額） | G15: 42231 | H15: 1679050
A16: 藤鳶工業(株) | C16: パチンコ台解体費 | G16: 42200 | H16: 198029
G19: 合計 | H19: =SUM(H15:H18) -> 1877079
A21: 未払金 | C21: 内容 | H21: 金額
A22: 藤鳶工業(株) | C22: 6月分家賃 | H22: 324000
A23: 藤鳶工業(株) | C23: 6月分技術指導料 | H23: 270000
G26: 合計 | H26: =SUM(H22:H25) -> 594000
A28: 国保7月15日入金予定額 | G28: 給料支払い金種表
A29: 尾道市 | C29: 686410 | G29: 10000 | H29: 860000 | I29: 86 | K29: 955010 | L29: 支払金
A30: 笠岡市 | G30: 5000 | H30: 60000 | I30: 12 | K30: 162332 | L30: 支払金
A31: 今治市 | C31: 256960 | G31: 1000 | H31: 30000 | I31: 30 | K31: 57620 | L31: 支払金
A32: 福山市 | C32: 410480 | G32: 500 | H32: 2000 | I32: 4 | K32: 25038 | L32: 手持ち金
A33: 三原市 | C33: 128480 | G33: 100 | H33: 2700 | I33: 27
A34: 世羅町 | G34: 50 | H34: 250 | I34: 5 | K34: =SUM(K29:K33) -> 1200000 | L34: 御調へ渡す金額
G35: 10 | H35: 50 | I35: 5
G36: 5 | H36: 5 | I36: 1
G37: 1 | H37: 5 | I37: 5
A38: 合計 | C38: =SUM(C29:F37) -> 1482330 | G38: 合計 | H38: =SUM(H29:H37) -> 955010

Sheet Sheet2
